File: data/DyBCO/DyBCO_MVT_1000Oe_50-120K_Continuous.csv
Time Stamp (sec),Temperature (K),Magnetic Field (Oe),Moment (emu),M. Std. Err. (emu),Transport Action,Averaging Time (sec),Frequency (Hz),Peak Amplitude (mm),Center Position (mm),Coil Signal' (mV),"Coil Signal"" (mV)",Range (mV),M. Quad. Signal (emu),M. Raw' (emu),"M. Raw"" (emu)",Min. Temperature (K),Max. Temperature (K),Min. Field (Oe),Max. Field (Oe),Mass (grams),Motor Lag (deg),Pressure (Torr),VSM Status (code),Motor Status (code),Measure Status (code),Measure Count,System Temp. (K),Temp. Status (code),Field Status (code),Chamber Status (code),Motor Current (amps),Motor Heatsink Temp. (C),Map 01,Map 02,Map 03,Map 04,Map 05,Map 06,Map 07,Map 08,Map 09,Map 10,Map 11,Map 12,Map 13,Map 14,Map 15,Map 16
3772629943,49.61020279,999.9766235,,,2,,,,10.40200003,,,,,,,49.61020279,49.61020279,999.9766235,999.9766235,,,45.31484604,,,,40,48.85038376,0,0,0,0,44.47702789,,,,,,,,,,,,,,,,
3772630145,50.7864933,999.9743347,0.001611807,2.69E-06,1,0.999253354,40.02988815,1.989964569,10.40000003,0.017378001,0.003304944,0.25,1.13E-05,0.001610647,2.33E-05,50.77610397,50.77610397,999.9674072,999.9812622,43.40695819,17.52047972,45.48706055,0,0,0,40,50.88694763,2,4,1,1.95098877,53.27468491,,,,,,,,,,,,,,,,
3772630197,51.65102959,999.9789429,0.001570684,2.51E-06,1,0.999253354,40.02988815,1.989874565,10.39000042,0.016953273,0.003140413,0.25,3.52E-06,0.001570033,1.52E-05,51.64027405,51.64027405,999.9766235,999.9812622,43.72820751,17.51689936,45.70388031,0,0,0,40,51.81522751,2,4,1,1.943359375,56.20723343,,,,,,,,,,,,,,,,
3772630249,52.50961494,999.9789429,0.001530799,2.45E-06,1,0.999253354,40.02988815,1.989851575,10.39000042,0.016529782,0.003046174,0.25,2.04E-06,0.001530582,1.34E-05,52.50220871,52.50220871,999.9766235,999.9812622,43.85092319,17.51745923,45.99482346,0,0,0,40,52.69316101,2,4,1,1.952972412,58.65102768,,,,,,,,,,,,,,,,
3772630301,53.36711884,1000.0112,0.00146913,2.90E-06,1,0.999253354,40.02988815,1.989950671,10.39000042,0.015855625,0.002996279,0.25,8.64E-06,0.001469258,1.95E-05,53.35832596,53.35832596,999.9812622,1000.041138,43.43040704,17.52851392,46.32638168,0,0,0,40,53.58901978,2,4,1,1.961517334,56.69599533,,,,,,,,,,,,,,,,
3772630353,54.22924423,999.9720459,0.001400468,3.39E-06,1,0.999253354,40.02988815,1.989921376,10.40000003,0.015099764,0.002958331,0.25,1.77E-05,0.001400884,2.80E-05,54.22153854,54.22153854,999.9720459,999.9720459,43.56015738,17.53005997,46.61222076,0,0,0,40,54.46467972,2,4,1,1.955566406,57.67351151,,,,,,,,,,,,,,,,
3772630405,55.0838623,999.997345,0.001335282,2.20E-06,1,0.999253354,40.02988815,1.990100481,10.40000003,0.014400377,0.002829342,0.25,1.76E-05,0.001336011,2.74E-05,55.07516861,55.07516861,999.9766235,1000.018066,43.61096323,17.5330868,46.86920929,0,0,0,40,55.33828354,2,4,1,1.951141357,58.16226959,,,,,,,,,,,,,,,,
3772630457,55.9437561,999.9697266,0.001286848,2.07E-06,1,0.999253354,40.02988815,1.989989086,10.39000042,0.013867976,0.002797196,0.25,2.35E-05,0.001287824,3.29E-05,55.93338013,55.93338013,999.9628296,999.9766235,43.86733738,17.53654958,47.07515717,0,0,0,40,56.22407532,2,4,1,1.955718994,58.16226959,,,,,,,,,,,,,,,,
3772630509,56.80510139,999.9927368,0.001225372,2.68E-06,1,0.999253354,40.02988815,1.989946523,10.39000042,0.013202444,0.002696788,0.25,2.55E-05,0.001226577,3.44E-05,56.79787064,56.79787064,999.9674072,1000.018066,43.8540497,17.53460787,47.25602341,0,0,0,40,57.09248352,2,4,1,1.954650879,59.13978577,,,,,,,,,,,,,,,,
3772630586,58.07992172,999.9789429,0.001228389,2.73E-06,1,0.999253354,40.02988815,1.989783369,10.28000005,0.013275427,0.002501956,0.25,6.97E-06,0.001230156,1.57E-05,58.07236099,58.07236099,999.9674072,999.9904785,43.8540497,17.52721148,47.44621277,0,0,0,40,58.37745667,2,4,1,1.952819824,57.18475342,,,,,,,,,,,,,,,,
3772630638,58.94165802,1000.041168,0.001156797,2.61E-06,1,0.999253354,40.02988815,1.989861057,10.28000005,0.012491408,0.002431156,0.25,1.35E-05,0.001158673,2.17E-05,58.93302917,58.93302917,1000.03656,1000.045776,43.77119708,17.53022523,47.60599899,0,0,0,40,59.2516861,2,4,1,1.954345703,58.16226959,,,,,,,,,,,,,,,,
3772630690,59.80280304,999.9996643,0.001081857,2.24E-06,1,0.999253354,40.02988815,1.989971574,10.28000005,0.011674688,0.002332547,0.25,1.81E-05,0.001083807,2.57E-05,59.79561615,59.79561615,999.9766235,1000.022705,43.76885219,17.53564883,47.73205566,0,0,0,40,60.11982727,2,4,1,1.954650879,58.16226959,,,,,,,,,,,,,,,,
3772630742,60.66881943,1000.013458,0.001023877,1.23E-06,1,0.999253354,40.02988815,1.98992651,10.28999966,0.011052496,0.002200221,0.25,1.65E-05,0.001025943,2.36E-05,60.66032791,60.66032791,999.9996338,1000.027283,43.65707931,17.53653218,47.83680344,0,0,0,40,60.98800659,2,4,1,1.954345703,59.62854385,,,,,,,,,,,,,,,,
3772630794,61.52617836,999.9812012,0.00095539,1.84E-06,1,0.999253354,40.02988815,1.98990656,10.28999966,0.010310776,0.002077486,0.25,1.77E-05,0.000957494,2.43E-05,61.5135498,61.5135498,999.9766235,999.9857788,43.63988349,17.53782421,47.93844223,0,0,0,40,61.85725021,2,4,1,1.95526123,60.11730194,,,,,,,,,,,,,,,,
3772630846,62.38803482,999.9996643,0.000897128,1.60E-06,1,0.999253354,40.02988815,1.989890736,10.28999966,0.009681232,0.001965174,0.25,1.80E-05,0.000899267,2.41E-05,62.37855911,62.37855911,999.9720459,1000.027283,43.58126135,17.535209,48.03431702,0,0,0,40,62.72413254,2,4,1,1.945953369,59.62854385,,,,,,,,,,,,,,,,
3772630898,63.25160408,999.997345,0.000827707,2.09E-06,1,0.999253354,40.02988815,1.989882353,10.28999966,0.008935422,0.00180395,0.25,1.58E-05,0.00082984,2.14E-05,63.24445724,63.24445724,999.9674072,1000.027283,43.60783672,17.53852326,48.14128494,0,0,0,40,63.5945816,2,4,1,1.956176758,59.62854385,,,,,,,,,,,,,,,,
3772630950,64.11708069,999.9651184,0.000766948,1.93E-06,1,0.999253354,40.02988815,1.989833915,10.28000005,0.008272913,0.001714988,0.25,1.87E-05,0.000769034,2.38E-05,64.11004639,64.11004639,999.9628296,999.9674072,43.88609647,17.53691212,48.18855286,0,0,0,40,64.46294403,2,4,1,1.954650879,60.60606384,,,,,,,,,,,,,,,,
3772631002,64.98255157,999.9789429,0.000695258,1.94E-06,1,0.999253354,40.02988815,1.989848916,10.28000005,0.007513661,0.001484898,0.25,1.06E-05,0.000697307,1.51E-05,64.97336578,64.97336578,999.9766235,999.9812622,43.93690232,17.53879154,48.29019547,0,0,0,40,65.33346558,2,4,1,1.954956055,60.11730194,,,,,,,,,,,,,,,,
3772631054,65.84591675,1000.031921,0.000640977,1.79E-06,1,0.999253354,40.02988815,1.989730774,10.28999966,0.006910195,0.001465726,0.25,1.87E-05,0.000642912,2.29E-05,65.83724976,65.83724976,1000.027283,1000.03656,43.82356619,17.53841588,48.3556633,0,0,0,40,66.19740295,2,4,1,1.945800781,60.60606384,,,,,,,,,,,,,,,,
3772631106,66.70885086,1000.031921,0.00057921,2.36E-06,1,0.999253354,40.02988815,1.989748542,10.28000005,0.006251477,0.001290681,0.25,1.39E-05,0.000581066,1.75E-05,66.69941711,66.69941711,1000.031921,1000.031921,43.66958537,17.53656038,48.42068863,0,0,0,40,67.08287811,2,4,1,1.956481934,61.09482193,,,,,,,,,,,,,,,,
3772631158,67.57581329,999.9950562,0.000512249,2.59E-06,1,0.999253354,40.02988815,1.989686798,10.28000005,0.005525247,0.001164457,0.25,1.44E-05,0.000513952,1.76E-05,67.57091522,67.57091522,999.9674072,1000.022705,43.68912608,17.53657321,48.498806,0,0,0,40,67.95423126,2,4,1,1.946105957,60.11730194,,,,,,,,,,,,,,,,
3772631235,68.85494232,999.9697266,0.000420424,1.29E-06,1,0.999253354,40.02988815,1.989735373,10.33999957,0.004527868,0.000999705,0.25,1.59E-05,0.000421881,1.85E-05,68.84747314,68.84747314,999.9628296,999.9766235,43.79073779,17.53824262,48.58335876,0,0,0,40,69.24212646,2,4,1,1.95602417,60.11730194,,,,,,,,,,,,,,,,
3772631287,69.72206497,999.9881287,0.000367209,1.92E-06,1,0.999253354,40.02988815,1.989720953,10.33999957,0.003950328,0.000900335,0.25,1.65E-05,0.000368514,1.87E-05,69.71534729,69.71534729,999.9581909,1000.018066,43.78604802,17.54147356,48.65393066,0,0,0,40,70.11647797,2,4,1,1.945495605,60.11730194,,,,,,,,,,,,,,,,
3772631338,70.58607101,999.9605103,0.000316976,1.86E-06,1,0.999253354,40.02988815,1.989712044,10.33999957,0.003391992,0.000878513,0.25,2.36E-05,0.000318088,2.55E-05,70.57891846,70.57891846,999.9581909,999.9628296,43.670367,17.54487583,48.73027039,0,0,0,40,70.98887634,2,4,1,1.963806152,61.09482193,,,,,,,,,,,,,,,,
3772631390,71.45383453,999.9996643,0.000264666,2.21E-06,1,0.999253354,40.02988815,1.989658336,10.32999996,0.002834961,0.000719886,0.25,1.84E-05,0.000265633,2.00E-05,71.44609833,71.44609833,999.9766235,1000.022705,43.90563718,17.53888972,48.78819656,0,0,0,40,71.8715744,2,4,1,1.943664551,60.60606384,,,,,,,,,,,,,,,,
3772631442,72.31336594,1000.025024,0.000226864,2.10E-06,1,0.999253354,40.02988815,1.989672485,10.32999996,0.00242433,0.000650248,0.25,1.89E-05,0.0002277,2.02E-05,72.30628204,72.30628204,1000.013489,1000.03656,43.76963382,17.54147731,48.84833527,0,0,0,40,72.74530792,2,4,1,1.954650879,61.09482193,,,,,,,,,,,,,,,,
3772631494,73.18520737,1000.022675,0.000184455,1.88E-06,1,0.999253354,40.02988815,1.989742769,10.33999957,0.001955638,0.000615983,0.25,2.34E-05,0.00018511,2.45E-05,73.17810822,73.17810822,1000.018066,1000.027283,43.80637036,17.54505513,48.92334747,0,0,0,40,73.61894989,2,4,1,1.956176758,61.09482193,,,,,,,,,,,,,,,,
3772631546,74.04698944,999.9720154,0.000145661,1.86E-06,1,0.999253354,40.02988815,1.989764498,10.33999957,0.00152816,0.00057697,0.25,2.68E-05,0.000146149,2.77E-05,74.03862,74.03862,999.9674072,999.9766235,43.65082628,17.54955015,48.96973038,0,0,0,40,74.50032043,2,4,1,1.955871582,62.0723381,,,,,,,,,,,,,,,,
3772631598,74.91011429,999.9835205,0.000114353,2.55E-06,1,0.999253354,40.02988815,1.989732704,10.33999957,0.001185095,0.000534439,0.25,2.86E-05,0.000114709,2.93E-05,74.90218353,74.90218353,999.9489746,1000.018066,43.83841713,17.55256333,49.07247925,0,0,0,40,75.36998749,2,4,1,1.954803467,61.09482193,,,,,,,,,,,,,,,,
3772631650,75.77309418,999.9927368,7.82E-05,2.21E-06,1,0.999253354,40.02988815,1.989770816,10.33999957,0.000805994,0.000393012,0.25,2.21E-05,7.85E-05,2.26E-05,75.76592255,75.76592255,999.9674072,1000.018066,44.06274451,17.55031887,49.13994598,0,0,0,40,76.24315643,2,4,1,1.952819824,61.09482193,,,,,,,,,,,,,,,,
3772631702,76.63691711,999.9996643,6.50E-05,2.15E-06,1,0.999253354,40.02988815,1.989648707,10.33999957,0.000665715,0.000349238,0.25,2.04E-05,6.52E-05,2.09E-05,76.62979126,76.62979126,999.9674072,1000.031921,43.85873947,17.54970815,49.21184921,0,0,0,40,77.11786652,2,4,1,1.955718994,60.60606384,,,,,,,,,,,,,,,,
3772631754,77.50041962,999.997345,4.88E-05,1.59E-06,1,0.999253354,40.02988815,1.989686731,10.32999996,0.00049182,0.000305137,0.25,1.93E-05,4.89E-05,1.96E-05,77.49415588,77.49415588,999.9674072,1000.027283,43.66802211,17.54988032,49.26244736,0,0,0,40,77.98175049,2,4,1,1.953735352,60.60606384,,,,,,,,,,,,,,,,
3772631831,78.77891159,999.997345,3.09E-05,1.72E-06,1,0.999253354,40.02988815,2.001790773,10.32000035,0.000319141,0.000163487,0.25,9.40E-06,3.10E-05,9.59E-06,78.77046204,78.77046204,999.9674072,1000.027283,43.71882797,17.547097,49.34455872,0,0,0,40,79.28623199,2,4,1,1.962432861,60.60606384,,,,,,,,,,,,,,,,
3772631883,79.64332581,1000.022705,2.58E-05,1.52E-06,1,0.999253354,40.02988815,2.001773915,10.32000035,0.000270763,0.00011409,0.25,5.79E-06,2.59E-05,5.94E-06,79.63777924,79.63777924,1000.00885,1000.03656,43.60705509,17.5463746,49.39471436,0,0,0,40,80.16217804,2,4,1,1.97052002,61.09482193,,,,,,,,,,,,,,,,
3772631935,80.50994873,1000.03653,9.78E-06,1.56E-06,1,0.999253354,40.02988815,2.001764779,10.30999981,9.92E-05,6.19E-05,0.25,3.91E-06,9.81E-06,3.97E-06,80.50017548,80.50017548,1000.022705,1000.050354,43.86186599,17.5427517,49.46062851,0,0,0,40,81.03574371,2,4,1,1.950836182,61.09482193,,,,,,,,,,,,,,,,
3772631987,81.37435913,999.9812622,1.52E-05,6.65E-07,1,0.999253354,40.02988815,2.002007086,10.30999981,0.00016826,1.99E-05,0.25,-9.19E-07,1.53E-05,-8.53E-07,81.3657074,81.3657074,999.9674072,999.9951172,43.92595952,17.5505157,49.51943588,0,0,0,40,81.89593506,2,4,1,1.966705322,61.09482193,,,,,,,,,,,,,,,,
3772632039,82.2378006,999.997345,9.44E-06,4.51E-07,1,0.999253354,40.02988815,2.001891854,10.30999981,0.00010467,1.02E-05,0.25,-7.65E-07,9.49E-06,-7.27E-07,82.22988129,82.22988129,999.9766235,1000.018066,43.93768395,17.54469183,49.57758331,0,0,0,40,82.77276611,2,4,1,1.964111328,59.62854385,,,,,,,,,,,,,,,,
3772632091,83.10128403,1000.0112,9.08E-06,3.87E-07,1,0.999253354,40.02988815,2.001473391,10.30999981,9.81E-05,2.39E-05,0.25,5.51E-07,9.13E-06,5.94E-07,83.09355927,83.09355927,999.9766235,1000.045776,44.05570986,17.53431886,49.64171982,0,0,0,40,83.64501953,2,4,1,1.967468262,62.56109619,,,,,,,,,,,,,,,,
3772632143,83.96268463,1000.029602,9.14E-06,3.54E-07,1,0.999253354,40.02988815,2.001725465,10.30999981,9.90E-05,2.26E-05,0.25,4.26E-07,9.18E-06,4.68E-07,83.9564209,83.9564209,1000.027283,1000.031921,44.01741006,17.54381062,49.7049675,0,0,0,40,84.51953125,2,4,1,1.967926025,61.58358002,,,,,,,,,,,,,,,,
3772632195,84.82624054,1000.038849,9.09E-06,4.74E-07,1,0.999253354,40.02988815,2.001578746,10.30999981,9.91E-05,1.84E-05,0.25,5.59E-08,9.13E-06,9.49E-08,84.81897736,84.81897736,1000.031921,1000.045776,44.25346187,17.5415971,49.74802017,0,0,0,40,85.39524841,2,4,1,1.960449219,57.67351151,,,,,,,,,,,,,,,,
3772632247,85.69177246,1000.03656,8.69E-06,4.12E-07,1,0.999253354,40.02988815,2.001537807,10.30999981,9.47E-05,1.81E-05,0.25,9.66E-08,8.73E-06,1.33E-07,85.68206787,85.68206787,1000.03656,1000.03656,43.97207561,17.53682473,49.79906464,0,0,0,40,86.27020264,2,4,1,1.966552734,62.0723381,,,,,,,,,,,,,,,,
3772632299,86.55694962,999.9996643,9.31E-06,4.21E-07,1,0.999253354,40.02988815,2.001475423,10.30999981,0.000101338,2.05E-05,0.25,2.09E-07,9.36E-06,2.48E-07,86.55026245,86.55026245,999.9766235,1000.022705,44.06196289,17.53845559,49.80749512,0,0,0,40,87.14182281,2,4,1,1.967315674,61.58358002,,,,,,,,,,,,,,,,
3772632351,87.41833496,1000.004242,8.87E-06,4.64E-07,1,0.999253354,40.02988815,2.001539505,10.32000035,9.61E-05,2.17E-05,0.25,3.91E-07,8.91E-06,4.29E-07,87.40887451,87.40887451,999.9996338,1000.00885,43.87984344,17.53909623,49.87096786,0,0,0,40,88.01519775,2,4,1,1.9581604,61.58358002,,,,,,,,,,,,,,,,
3772632428,88.69971466,999.9697266,8.99E-06,4.08E-07,1,0.999253354,40.02988815,2.001538487,10.28999966,9.75E-05,2.15E-05,0.25,3.57E-07,9.03E-06,3.94E-07,88.68981934,88.68981934,999.9628296,999.9766235,44.30426773,17.53892471,49.92222977,0,0,0,40,89.30796814,2,4,1,1.957244873,60.60606384,,,,,,,,,,,,,,,,
3772632480,89.56376266,1000.006592,9.22E-06,4.53E-07,1,0.999253354,40.02988815,2.001525653,10.3000002,0.000100372,2.01E-05,0.25,1.88E-07,9.27E-06,2.24E-07,89.55671692,89.55671692,999.9720459,1000.041138,43.92205138,17.53729792,49.93377304,0,0,0,40,90.18447113,2,4,1,1.957397461,61.09482193,,,,,,,,,,,,,,,,
3772632532,90.42783356,1000.004272,8.89E-06,3.30E-07,1,0.999253354,40.02988815,2.001518608,10.28999966,9.71E-05,1.71E-05,0.25,-2.38E-08,8.93E-06,9.88E-09,90.4198761,90.4198761,999.9812622,1000.027283,43.81965805,17.53852836,49.97260666,0,0,0,40,91.0668869,2,4,1,1.959228516,60.60606384,,,,,,,,,,,,,,,,
3772632583,91.28940582,1000.027283,9.29E-06,4.13E-07,1,0.999253354,40.02988815,2.00151071,10.28999966,0.000101248,1.97E-05,0.25,1.36E-07,9.34E-06,1.72E-07,91.28200531,91.28200531,1000.027283,1000.027283,43.94237372,17.5338829,50.00367737,0,0,0,40,91.91918945,2,4,1,1.956787109,61.09482193,,,,,,,,,,,,,,,,
3772632635,92.15555954,1000.008911,9.04E-06,4.25E-07,1,0.999253354,40.02988815,2.001513842,10.28999966,9.94E-05,1.44E-05,0.25,-3.00E-07,9.09E-06,-2.69E-07,92.14923096,92.14923096,999.9720459,1000.045776,43.68756283,17.53442718,50.04850769,0,0,0,40,92.80485535,2,4,1,1.9581604,61.09482193,,,,,,,,,,,,,,,,
3772632687,93.01848984,999.9628296,9.10E-06,3.56E-07,1,0.999253354,40.02988815,2.001526848,10.3000002,9.87E-05,2.18E-05,0.25,3.63E-07,9.15E-06,3.98E-07,93.01130676,93.01130676,999.9536133,999.9720459,44.04711194,17.53707775,50.08512497,0,0,0,40,93.67801666,2,4,1,1.957702637,61.09482193,,,,,,,,,,,,,,,,
3772632739,93.88298416,999.9789124,9.08E-06,4.26E-07,1,0.999253354,40.02988815,2.001468965,10.3000002,9.91E-05,1.81E-05,0.25,2.90E-08,9.12E-06,6.14E-08,93.87338257,93.87338257,999.9720459,999.9857788,43.78213988,17.5364776,50.09888458,0,0,0,40,94.54582977,2,4,1,1.9581604,62.56109619,,,,,,,,,,,,,,,,
3772632791,94.74505615,999.9766541,9.15E-06,4.29E-07,1,0.999253354,40.02988815,2.001426009,10.28999966,0.000100027,1.79E-05,0.25,-1.70E-10,9.20E-06,3.18E-08,94.73839569,94.73839569,999.9720459,999.9812622,43.93690232,17.53763746,50.14016342,0,0,0,40,95.41593933,2,4,1,1.957244873,61.58358002,,,,,,,,,,,,,,,,
3772632843,95.61159897,1000.038818,9.41E-06,4.72E-07,1,0.999253354,40.02988815,2.00133735,10.28999966,0.000102706,1.91E-05,0.25,6.73E-08,9.46E-06,1.00E-07,95.60111237,95.60111237,1000.027283,1000.050354,44.0103754,17.53516645,50.19852829,0,0,0,40,96.29296112,2,4,1,1.958312988,61.58358002,,,,,,,,,,,,,,,,
3772632895,96.47208786,1000.020386,8.88E-06,3.81E-07,1,0.999253354,40.02988815,2.001367493,10.28999966,9.71E-05,1.72E-05,0.25,-1.74E-08,8.93E-06,1.26E-08,96.46341705,96.46341705,1000.018066,1000.022705,44.02444472,17.53626636,50.24380112,0,0,0,40,97.16483307,2,4,1,1.9581604,61.58358002,,,,,,,,,,,,,,,,
3772632947,97.33884811,999.9996948,9.40E-06,3.60E-07,1,0.999253354,40.02988815,2.001434795,10.28999966,0.000101855,2.34E-05,0.25,4.60E-07,9.45E-06,4.94E-07,97.32907867,97.32907867,999.9628296,1000.03656,44.27222096,17.53794631,50.29462051,0,0,0,40,98.03670502,2,4,1,1.966247559,62.0723381,,,,,,,,,,,,,,,,
3772632999,98.20628738,1000.024994,9.35E-06,4.42E-07,1,0.999253354,40.02988815,2.001318027,10.28999966,0.00010252,1.60E-05,0.25,-2.04E-07,9.40E-06,-1.74E-07,98.19989777,98.19989777,1000.022705,1000.027283,44.17373576,17.53740285,50.34277725,0,0,0,40,98.90177155,2,4,1,1.961517334,61.09482193,,,,,,,,,,,,,,,,
3772633076,99.48544312,999.9674072,8.85E-06,4.08E-07,1,0.999253354,40.02988815,1.989039196,10.25999989,9.69E-05,1.34E-05,0.25,-3.50E-07,8.90E-06,-3.24E-07,99.47846985,99.47846985,999.9674072,999.9674072,44.39181012,17.53795209,50.38405609,0,0,0,40,100.196228,2,4,1,1.9581604,61.58358002,,,,,,,,,,,,,,,,
3772633128,100.3511925,1000.03653,9.09E-06,4.51E-07,1,0.999253354,40.02988815,1.988995306,10.25999989,9.86E-05,1.87E-05,0.25,9.92E-08,9.14E-06,1.28E-07,100.3421936,100.3421936,1000.031921,1000.041138,44.01506517,17.53882884,50.39515305,0,0,0,40,101.0726395,2,4,1,1.943817139,60.60606384,,,,,,,,,,,,,,,,
3772633180,101.2127686,999.9605103,9.45E-06,4.05E-07,1,0.999253354,40.02988815,1.989024912,10.25999989,0.000103079,1.60E-05,0.25,-2.17E-07,9.50E-06,-1.89E-07,101.2028503,101.2028503,999.9581909,999.9628296,43.67427514,17.53669562,50.44308853,0,0,0,40,101.9451523,2,4,1,1.946716309,61.58358002,,,,,,,,,,,,,,,,
3772633232,102.0760994,999.9720154,8.83E-06,4.81E-07,1,0.999253354,40.02988815,1.989080143,10.27000044,9.56E-05,1.88E-05,0.25,1.58E-07,8.87E-06,1.86E-07,102.0668488,102.0668488,999.9674072,999.9766235,43.97207561,17.5394736,50.45218658,0,0,0,40,102.819313,2,4,1,1.943206787,60.60606384,,,,,,,,,,,,,,,,
3772633284,102.9379044,1000.022705,9.05E-06,4.63E-07,1,0.999253354,40.02988815,1.989088707,10.25999989,9.70E-05,2.52E-05,0.25,7.09E-07,9.10E-06,7.40E-07,102.9291916,102.9291916,1000.013489,1000.031921,43.63832023,17.54448067,50.47948456,0,0,0,40,103.6934509,2,4,1,1.947937012,61.09482193,,,,,,,,,,,,,,,,
3772633336,103.8055573,999.9627991,9.21E-06,4.54E-07,1,0.999253354,40.02988815,1.989122148,10.25999989,9.97E-05,2.04E-05,0.25,2.33E-07,9.26E-06,2.61E-07,103.7977371,103.7977371,999.9581909,999.9674072,44.23157627,17.5406127,50.52009583,0,0,0,40,104.5665436,2,4,1,1.950378418,61.58358002,,,,,,,,,,,,,,,,
3772633388,104.6698341,1000.029602,9.03E-06,4.11E-07,1,0.999253354,40.02988815,1.989042942,10.27000044,9.74E-05,2.18E-05,0.25,3.94E-07,9.08E-06,4.22E-07,104.6634216,104.6634216,1000.027283,1000.031921,43.85326807,17.54150673,50.52875137,0,0,0,40,105.430397,2,4,1,1.956329346,60.60606384,,,,,,,,,,,,,,,,
3772633440,105.5308685,1000.004272,9.16E-06,4.38E-07,1,0.999253354,40.02988815,1.989002337,10.27000044,9.92E-05,1.97E-05,0.25,1.79E-07,9.21E-06,2.06E-07,105.5245056,105.5245056,999.9674072,1000.041138,43.6922526,17.53740711,50.59399796,0,0,0,40,106.3147736,2,4,1,1.954650879,61.09482193,,,,,,,,,,,,,,,,
3772633492,106.3988838,999.9674377,9.35E-06,4.16E-07,1,0.999253354,40.02988815,1.988974944,10.25999989,0.000101068,2.07E-05,0.25,2.41E-07,9.40E-06,2.69E-07,106.391655,106.391655,999.9628296,999.9720459,43.87280878,17.53935455,50.60820007,0,0,0,40,107.1818237,2,4,1,1.958007813,61.09482193,,,,,,,,,,,,,,,,
3772633544,107.2602043,999.9789124,9.48E-06,5.79E-07,1,0.999253354,40.02988815,1.989000178,10.25999989,0.000101832,2.52E-05,0.25,6.28E-07,9.53E-06,6.58E-07,107.252327,107.252327,999.9443359,1000.013489,44.27691073,17.54114161,50.63838196,0,0,0,40,108.0471344,2,4,1,1.949005127,61.09482193,,,,,,,,,,,,,,,,
3772633596,108.1267395,1000.020386,9.70E-06,5.19E-07,1,0.999253354,40.02988815,1.988894756,10.25999989,0.000105406,1.88E-05,0.25,5.33E-09,9.76E-06,3.23E-08,108.1185684,108.1185684,1000.013489,1000.027283,43.65238954,17.53723039,50.690979,0,0,0,40,108.9186096,2,4,1,1.958465576,59.62854385,,,,,,,,,,,,,,,,
3772633673,109.4044609,999.9651184,9.12E-06,4.27E-07,1,0.999253354,40.02988815,1.988849884,10.25999989,9.85E-05,2.11E-05,0.25,3.19E-07,9.17E-06,3.46E-07,109.3942337,109.3942337,999.9581909,999.9720459,43.92439627,17.53305947,50.73381042,0,0,0,40,110.210495,2,4,1,1.947784424,60.60606384,,,,,,,,,,,,,,,,
3772633725,110.2715225,999.990448,9.00E-06,3.80E-07,1,0.999253354,40.02988815,1.988926113,10.25999989,9.70E-05,2.18E-05,0.25,4.04E-07,9.05E-06,4.31E-07,110.2650528,110.2650528,999.9581909,1000.022705,43.98848981,17.53534768,50.76332855,0,0,0,40,111.0845261,2,4,1,1.946868896,60.11730194,,,,,,,,,,,,,,,,
3772633777,111.1337433,999.9628296,9.11E-06,4.14E-07,1,0.999253354,40.02988815,1.988862873,10.25999989,9.84E-05,2.10E-05,0.25,3.14E-07,9.16E-06,3.40E-07,111.1275406,111.1275406,999.9628296,999.9628296,44.01662843,17.53623848,50.8163681,0,0,0,40,111.9592438,2,4,1,1.949768066,60.60606384,,,,,,,,,,,,,,,,
3772633829,111.9975548,1000.027313,8.78E-06,4.60E-07,1,0.999253354,40.02988815,1.988770483,10.25999989,9.48E-05,2.05E-05,0.25,3.28E-07,8.83E-06,3.52E-07,111.9877548,111.9877548,1000.022705,1000.031921,44.04085892,17.53516703,50.84610367,0,0,0,40,112.8321838,2,4,1,1.934967041,61.09482193,,,,,,,,,,,,,,,,
3772633881,112.8646584,1000.027283,9.36E-06,3.29E-07,1,0.999253354,40.02988815,1.988718488,10.27000044,0.000101178,2.10E-05,0.25,2.67E-07,9.41E-06,2.93E-07,112.8575821,112.8575821,1000.027283,1000.027283,43.89000461,17.53324155,50.86962891,0,0,0,40,113.6986465,2,4,1,1.950073242,61.09482193,,,,,,,,,,,,,,,,
3772633932,113.7264366,1000.029633,8.77E-06,4.27E-07,1,0.999253354,40.02988815,1.988825329,10.25999989,9.54E-05,1.66E-05,0.25,-3.51E-08,8.82E-06,-1.29E-08,113.7187653,113.7187653,1000.013489,1000.045776,43.75321962,17.53280395,50.92111588,0,0,0,40,114.5656433,2,4,1,1.946105957,61.58358002,,,,,,,,,,,,,,,,
3772633984,114.5894165,999.9697266,9.05E-06,3.73E-07,1,0.999253354,40.02988815,1.988742368,10.25999989,9.72E-05,2.40E-05,0.25,5.98E-07,9.10E-06,6.24E-07,114.5810013,114.5810013,999.9581909,999.9812622,43.74384008,17.53590922,50.96017456,0,0,0,40,115.4493332,2,4,1,1.951141357,60.60606384,,,,,,,,,,,,,,,,
3772634036,115.4546432,1000.011169,8.83E-06,3.30E-07,1,0.999253354,40.02988815,1.98883599,10.25999989,9.56E-05,1.88E-05,0.25,1.59E-07,8.88E-06,1.82E-07,115.4458084,115.4458084,1000.00885,1000.013489,44.09400966,17.53513259,50.97304535,0,0,0,40,116.3125458,2,4,1,1.946411133,60.60606384,,,,,,,,,,,,,,,,
3772634088,116.3225517,1000.029633,8.83E-06,4.03E-07,1,0.999253354,40.02988815,1.988763577,10.25999989,9.57E-05,1.82E-05,0.25,1.09E-07,8.88E-06,1.31E-07,116.3143692,116.3143692,1000.022705,1000.03656,44.21516208,17.53673724,50.99701309,0,0,0,40,117.1791306,2,4,1,1.9480896,63.53861237,,,,,,,,,,,,,,,,
3772634140,117.1824036,1000.041138,8.81E-06,5.09E-07,1,0.999253354,40.02988815,1.988816048,10.25999989,9.54E-05,1.85E-05,0.25,1.33E-07,8.86E-06,1.55E-07,117.1748352,117.1748352,1000.041138,1000.041138,43.84623341,17.53679081,51.01277161,0,0,0,40,118.0566864,2,4,1,1.946563721,61.09482193,,,,,,,,,,,,,,,,
3772634192,118.0508881,1000.018097,9.59E-06,3.55E-07,1,0.999253354,40.02988815,1.988788616,10.25999989,0.000104327,1.79E-05,0.25,-6.11E-08,9.64E-06,-3.85E-08,118.0412598,118.0412598,1000.013489,1000.022705,44.13699922,17.53985174,51.05648804,0,0,0,40,118.929863,2,4,1,1.945343018,61.09482193,,,,,,,,,,,,,,,,
3772634269,119.3340988,999.9927368,9.00E-06,3.91E-07,1,0.999253354,40.02988815,2.001023991,10.23999974,9.79E-05,1.99E-05,0.25,2.21E-07,9.05E-06,2.44E-07,119.3291473,119.3291473,999.9674072,1000.018066,43.86186599,17.532351,51.11929321,0,0,0,40,120.2037735,2,4,1,1.959991455,58.65102768,,,,,,,,,,,,,,,,
3772634321,120.1449776,999.9627991,9.24E-06,4.44E-07,1,0.999253354,40.02988815,2.000992227,10.23999974,9.98E-05,2.45E-05,0.25,6.01E-07,9.28E-06,6.26E-07,120.1396484,120.1396484,999.9581909,999.9674072,43.76025428,17.53211213,51.16767502,0,0,0,40,120.7030106,5,4,1,1.958770752,61.09482193,,,,,,,,,,,,,,,,
3772634373,120.350708,999.9743347,9.14E-06,4.63E-07,1,0.999253354,40.02988815,2.001029403,10.23000013,9.96E-05,1.93E-05,0.25,1.47E-07,9.19E-06,1.69E-07,120.353981,120.353981,999.9720459,999.9766235,44.16904599,17.53540203,51.17255783,0,0,0,40,119.8479538,5,4,1,1.956787109,60.60606384,,,,,,,,,,,,,,,,
3772634738,120.0224953,999.9720459,8.65E-06,4.77E-07,1,0.999253354,40.02988815,2.00098201,10.23999974,9.42E-05,1.83E-05,0.25,1.36E-07,8.69E-06,1.57E-07,120.0239258,120.0239258,999.9720459,999.9720459,44.05727311,17.53255715,51.26398849,0,0,0,40,119.258728,6,4,1,1.969451904,62.0723381,,,,,,,,,,,,,,,,
3772634790,119.3598518,999.9812317,9.39E-06,4.79E-07,1,0.999253354,40.02988815,2.001048639,10.23999974,0.000102391,1.95E-05,0.25,1.18E-07,9.44E-06,1.41E-07,119.368248,119.368248,999.9536133,1000.00885,43.78135825,17.53182021,51.24978638,0,0,0,40,117.66082,6,4,1,1.957855225,61.09482193,,,,,,,,,,,,,,,,
3772634842,118.5043907,999.9996643,9.47E-06,6.36E-07,1,0.999253354,40.02988815,2.000962554,10.23999974,0.000103076,2.08E-05,0.25,2.17E-07,9.52E-06,2.41E-07,118.5138855,118.5138855,999.9674072,1000.031921,44.03382426,17.53136032,51.17965698,0,0,0,40,116.6762238,2,4,1,1.955413818,61.09482193,,,,,,,,,,,,,,,,
3772634919,117.2305489,1000.008911,9.27E-06,4.95E-07,1,0.999253354,40.02988815,2.000963639,10.27000044,0.000100791,2.08E-05,0.25,2.55E-07,9.32E-06,2.79E-07,117.2371445,117.2371445,999.9720459,1000.045776,43.76181753,17.53182124,51.14392853,0,0,0,40,115.3050232,2,4,1,1.947631836,61.09482193,,,,,,,,,,,,,,,,
3772634971,116.3664093,999.9651184,9.39E-06,4.78E-07,1,0.999253354,40.02988815,2.000905938,10.27000044,0.000102544,1.87E-05,0.25,3.90E-08,9.44E-06,6.23E-08,116.3757858,116.3757858,999.9581909,999.9720459,43.82591107,17.52949188,51.15058517,0,0,0,40,114.4095154,2,4,1,1.960144043,61.09482193,,,,,,,,,,,,,,,,
3772635023,115.4944,1000.013519,9.70E-06,4.95E-07,1,0.999253354,40.02988815,2.00090517,10.27000044,0.00010536,2.21E-05,0.25,2.99E-07,9.75E-06,3.25E-07,115.5031815,115.5031815,1000.004333,1000.022705,44.01506517,17.5308162,51.10398102,0,0,0,40,113.5307007,2,4,1,1.957550049,61.09482193,,,,,,,,,,,,,,,,
3772635075,114.6274223,999.9996643,8.73E-06,4.10E-07,1,0.999253354,40.02988815,2.000969013,10.28000005,9.57E-05,1.55E-05,0.25,-1.36E-07,8.78E-06,-1.14E-07,114.6368484,114.6368484,999.9720459,1000.027283,43.79777245,17.53205901,51.07868195,0,0,0,40,112.6468201,2,4,1,1.967163086,61.09482193,,,,,,,,,,,,,,,,
3772635127,113.7556686,1000.013519,9.06E-06,4.97E-07,1,0.999253354,40.02988815,2.000889607,10.27000044,9.87E-05,1.92E-05,0.25,1.45E-07,9.11E-06,1.69E-07,113.7636719,113.7636719,1000.004333,1000.022705,44.31130238,17.53022132,51.06470108,0,0,0,40,111.7700958,2,4,1,1.967773438,61.09482193,,,,,,,,,,,,,,,,
3772635178,112.8908157,999.9628296,8.97E-06,4.48E-07,1,0.999253354,40.02988815,2.000852838,10.27000044,9.79E-05,1.81E-05,0.25,6.51E-08,9.02E-06,8.86E-08,112.8981094,112.8981094,999.9536133,999.9720459,44.23313953,17.53263384,51.00389481,0,0,0,40,110.9109726,2,4,1,1.958770752,61.09482193,,,,,,,,,,,,,,,,
3772635230,112.0271683,999.9766541,8.92E-06,4.87E-07,1,0.999253354,40.02988815,2.000867741,10.27000044,9.67E-05,2.20E-05,0.25,4.26E-07,8.97E-06,4.52E-07,112.0351257,112.0351257,999.9720459,999.9812622,44.42932829,17.53093639,51.00034332,0,0,0,40,110.0385208,2,4,1,1.95892334,61.58358002,,,,,,,,,,,,,,,,
3772635282,111.157486,999.9996643,9.35E-06,5.74E-07,1,0.999253354,40.02988815,2.000865654,10.28000005,0.000101585,2.17E-05,0.25,3.23E-07,9.40E-06,3.50E-07,111.1654892,111.1654892,999.9674072,1000.031921,44.18233368,17.53270764,50.95018768,0,0,0,40,109.173233,2,4,1,1.948394775,62.0723381,,,,,,,,,,,,,,,,
3772635334,110.2915611,1000.03653,9.38E-06,4.66E-07,1,0.999253354,40.02988815,2.000820283,10.27000044,0.00010246,1.83E-05,0.25,1.41E-09,9.43E-06,2.66E-08,110.3011322,110.3011322,1000.027283,1000.045776,43.86577413,17.53044207,50.92821884,0,0,0,40,108.3070145,2,4,1,1.959838867,61.09482193,,,,,,,,,,,,,,,,
3772635386,109.4266891,1000.031921,8.95E-06,4.62E-07,1,0.999253354,40.02988815,2.000781937,10.27000044,9.70E-05,2.18E-05,0.25,4.00E-07,9.00E-06,4.27E-07,109.4344635,109.4344635,1000.027283,1000.03656,43.68365468,17.53003713,50.90558243,0,0,0,40,107.4393616,2,4,1,1.960906982,61.09482193,,,,,,,,,,,,,,,,
3772635438,108.5568733,999.9973755,9.25E-06,4.27E-07,1,0.999253354,40.02988815,2.00076025,10.27000044,0.000101602,1.51E-05,0.25,-2.62E-07,9.30E-06,-2.38E-07,108.563942,108.563942,999.9720459,1000.022705,44.02757123,17.53207168,50.87584305,0,0,0,40,106.5757675,2,4,1,1.960144043,61.09482193,,,,,,,,,,,,,,,,
3772635515,107.2789497,999.9950562,9.04E-06,5.07E-07,1,0.999253354,40.02988815,2.000814691,10.25999989,9.89E-05,1.74E-05,0.25,-1.59E-08,9.09E-06,9.44E-09,107.2853699,107.2853699,999.9674072,1000.022705,43.97911026,17.52889241,50.76909637,0,0,0,40,105.3117218,2,4,1,1.959991455,59.13978577,,,,,,,,,,,,,,,,
3772635567,106.4106026,1000.03653,9.24E-06,4.37E-07,1,0.999253354,40.02988815,2.000763319,10.25000028,9.96E-05,2.61E-05,0.25,7.38E-07,9.29E-06,7.68E-07,106.4214859,106.4214859,1000.031921,1000.041138,43.75321962,17.5319759,50.77175903,0,0,0,40,104.4328003,2,4,1,1.959075928,61.58358002,,,,,,,,,,,,,,,,
3772635619,105.5441055,1000.029602,8.82E-06,5.01E-07,1,0.999253354,40.02988815,2.000760657,10.25000028,9.60E-05,1.93E-05,0.25,1.92E-07,8.86E-06,2.19E-07,105.5539932,105.5539932,1000.027283,1000.031921,43.98692655,17.52791513,50.74890137,0,0,0,40,103.570755,2,4,1,1.957397461,61.09482193,,,,,,,,,,,,,,,,
3772635671,104.674202,999.9651184,9.57E-06,4.56E-07,1,0.999253354,40.02988815,2.00070253,10.25000028,0.000104114,2.10E-05,0.25,2.21E-07,9.62E-06,2.50E-07,104.6811905,104.6811905,999.9628296,999.9674072,43.75869102,17.52960442,50.69142151,0,0,0,40,102.7101822,2,4,1,1.960144043,60.11730194,,,,,,,,,,,,,,,,
3772635723,103.8116188,999.9559021,8.90E-06,5.54E-07,1,0.999253354,40.02988815,2.000723737,10.25000028,9.62E-05,2.29E-05,0.25,5.13E-07,8.95E-06,5.42E-07,103.821991,103.821991,999.9489746,999.9628296,43.80246222,17.52796803,50.63793945,0,0,0,40,101.8462753,2,4,1,1.958770752,60.60606384,,,,,,,,,,,,,,,,
3772635775,102.9414177,999.9720459,9.20E-06,4.35E-07,1,0.999253354,40.02988815,2.00082209,10.25000028,0.000100949,1.55E-05,0.25,-2.24E-07,9.25E-06,-1.97E-07,102.9485855,102.9485855,999.9720459,999.9720459,43.92674115,17.53229446,50.58889389,0,0,0,40,100.9829865,2,4,1,1.960601807,61.09482193,,,,,,,,,,,,,,,,
3772635827,102.0735168,999.9651184,8.81E-06,4.29E-07,1,0.999253354,40.02988815,2.000733153,10.25999989,9.60E-05,1.82E-05,0.25,9.81E-08,8.85E-06,1.26E-07,102.0796967,102.0796967,999.9581909,999.9720459,43.77979499,17.53047663,50.55205536,0,0,0,40,100.1295013,2,4,1,1.949462891,61.09482193,,,,,,,,,,,,,,,,
3772635879,101.2118759,999.997345,9.25E-06,4.19E-07,1,0.999253354,40.02988815,2.000741883,10.25000028,0.000100699,2.00E-05,0.25,1.77E-07,9.30E-06,2.07E-07,101.2186813,101.2186813,999.9766235,1000.018066,44.2816005,17.5279471,50.48214722,0,0,0,40,99.27220154,2,4,1,1.962890625,61.09482193,,,,,,,,,,,,,,,,
3772635931,100.341526,1000.008881,8.81E-06,4.60E-07,1,0.999253354,40.02988815,2.000784243,10.25000028,9.56E-05,2.07E-05,0.25,3.24E-07,8.86E-06,3.53E-07,100.3495636,100.3495636,999.9766235,1000.041138,43.91032695,17.53084684,50.40513992,0,0,0,40,98.41304016,2,4,1,1.958465576,61.58358002,,,,,,,,,,,,,,,,
3772635983,99.4717598,1000.004303,9.27E-06,4.30E-07,1,0.999253354,40.02988815,2.000716905,10.25999989,0.000101535,1.64E-05,0.25,-1.57E-07,9.32E-06,-1.28E-07,99.47662354,99.47662354,999.9720459,1000.03656,43.72977077,17.5283574,50.39559555,0,0,0,40,97.5537796,2,4,1,1.95892334,61.09482193,,,,,,,,,,,,,,,,
3772636035,98.60337448,1000.031921,9.04E-06,4.37E-07,1,0.999253354,40.02988815,2.000872706,10.25000028,9.84E-05,1.98E-05,0.25,2.00E-07,9.09E-06,2.31E-07,98.61301422,98.61301422,1000.027283,1000.03656,43.6813098,17.53356209,50.35964584,0,0,0,40,96.69197083,2,4,1,1.958770752,60.60606384,,,,,,,,,,,,,,,,
3772636087,97.73739624,1000.006592,9.39E-06,3.71E-07,1,0.999253354,40.02988815,2.000684091,10.25000028,0.000102246,2.05E-05,0.25,1.96E-07,9.44E-06,2.28E-07,97.7468338,97.7468338,999.9812622,1000.031921,43.81731316,17.53166157,50.32302856,0,0,0,40,95.83333588,2,4,1,1.957702637,61.58358002,,,,,,,,,,,,,,,,
3772636164,96.45101929,1000.03653,9.36E-06,4.91E-07,1,0.999253354,40.02988815,1.98909665,10.27000044,0.000101018,2.19E-05,0.25,3.43E-07,9.41E-06,3.76E-07,96.45748138,96.45748138,1000.027283,1000.045776,43.81184176,17.54199186,50.29151535,0,0,0,40,94.56273651,2,4,1,1.952209473,62.0723381,,,,,,,,,,,,,,,,
3772636216,95.58784866,999.9720154,9.15E-06,4.09E-07,1,0.999253354,40.02988815,1.989121351,10.27000044,9.88E-05,2.08E-05,0.25,2.78E-07,9.20E-06,3.11E-07,95.5970993,95.5970993,999.9674072,999.9766235,43.48277615,17.53760036,50.23625565,0,0,0,40,93.70124817,2,4,1,1.957550049,60.60606384,,,,,,,,,,,,,,,,
3772636268,94.71479416,999.9651184,9.71E-06,3.85E-07,1,0.999253354,40.02988815,1.989104041,10.28000005,0.000104577,2.42E-05,0.25,4.89E-07,9.76E-06,5.26E-07,94.72299194,94.72299194,999.9536133,999.9766235,44.21281719,17.53892833,50.19120407,0,0,0,40,92.84455872,2,4,1,1.954650879,61.09482193,,,,,,,,,,,,,,,,
3772636320,93.84859085,1000.001953,9.21E-06,3.79E-07,1,0.999253354,40.02988815,1.989223229,10.27000044,9.84E-05,2.70E-05,0.25,8.40E-07,9.25E-06,8.77E-07,93.85771942,93.85771942,999.9766235,1000.027283,44.21985185,17.54179186,50.14437866,0,0,0,40,91.99434662,2,4,1,1.957550049,61.09482193,,,,,,,,,,,,,,,,
3772636372,92.9803772,999.9950562,9.37E-06,3.81E-07,1,0.999253354,40.02988815,1.989202366,10.27000044,0.000101945,1.76E-05,0.25,-5.67E-08,9.42E-06,-2.31E-08,92.98908997,92.98908997,999.9674072,1000.022705,44.0103754,17.53983377,50.09289169,0,0,0,40,91.13130951,2,4,1,1.95892334,61.09482193,,,,,,,,,,,,,,,,
3772636424,92.11138916,999.9881287,8.75E-06,3.98E-07,1,0.999253354,40.02988815,1.989434552,10.28000005,9.48E-05,1.86E-05,0.25,1.41E-07,8.80E-06,1.74E-07,92.12081146,92.12081146,999.9581909,1000.018066,44.05102009,17.53914072,50.033638,0,0,0,40,90.27310181,2,4,1,1.953125,61.09482193,,,,,,,,,,,,,,,,
3772636476,91.24314499,999.9881287,9.41E-06,3.93E-07,1,0.999253354,40.02988815,1.989351457,10.28000005,0.000102256,1.81E-05,0.25,-2.21E-08,9.46E-06,1.29E-08,91.25106049,91.25106049,999.9581909,1000.018066,44.4598118,17.54077389,50.02187729,0,0,0,40,89.41645813,2,4,1,1.955413818,61.09482193,,,,,,,,,,,,,,,,
3772636527,90.37257385,1000.020386,8.77E-06,3.67E-07,1,0.999253354,40.02988815,1.989287718,10.27000044,9.52E-05,1.76E-05,0.25,4.98E-08,8.82E-06,8.34E-08,90.37918854,90.37918854,1000.013489,1000.027283,43.98848981,17.5382808,49.93887711,0,0,0,40,88.56008148,2,4,1,1.957702637,62.0723381,,,,,,,,,,,,,,,,
3772636580,89.50381851,1000.024994,9.15E-06,4.06E-07,1,0.999253354,40.02988815,1.989350369,10.27000044,9.88E-05,2.13E-05,0.25,3.17E-07,9.20E-06,3.54E-07,89.5116272,89.5116272,1000.022705,1000.027283,43.98614492,17.53297203,49.88983154,0,0,0,40,87.70266724,2,4,1,1.95526123,61.09482193,,,,,,,,,,,,,,,,
3772636631,88.633461,999.990448,9.17E-06,4.47E-07,1,0.999253354,40.02988815,1.989190591,10.28000005,9.90E-05,2.14E-05,0.25,3.27E-07,9.22E-06,3.65E-07,88.6397171,88.6397171,999.9581909,1000.022705,44.0979178,17.5321052,49.84278107,0,0,0,40,86.85326385,2,4,1,1.94442749,61.09482193,,,,,,,,,,,,,,,,
3772636683,87.76472855,1000.024994,9.30E-06,3.65E-07,1,0.999253354,40.02988815,1.989142107,10.27000044,0.000101232,1.71E-05,0.25,-9.09E-08,9.35E-06,-5.41E-08,87.77178192,87.77178192,1000.022705,1000.027283,44.23079465,17.53687126,49.79085159,0,0,0,40,85.99703217,2,4,1,1.946868896,61.09482193,,,,,,,,,,,,,,,,
3772636760,86.48637772,999.9996643,8.87E-06,4.24E-07,1,0.999253354,40.02988815,1.989003715,10.28000005,9.57E-05,2.07E-05,0.25,3.16E-07,8.91E-06,3.54E-07,86.49311829,86.49311829,999.9904785,1000.00885,44.42854666,17.53242655,49.71073532,0,0,0,40,84.72988892,2,4,1,1.959838867,60.11730194,,,,,,,,,,,,,,,,
3772636812,85.61231232,999.9858398,9.31E-06,3.73E-07,1,0.999253354,40.02988815,1.989226044,10.28999966,0.00010042,2.23E-05,0.25,3.79E-07,9.36E-06,4.20E-07,85.62174225,85.62174225,999.9581909,1000.013489,44.35976335,17.53799238,49.64549255,0,0,0,40,83.87347412,2,4,1,1.9480896,60.60606384,,,,,,,,,,,,,,,,
3772636864,84.74188614,1000.008911,9.69E-06,4.82E-07,1,0.999253354,40.02988815,1.989033823,10.28000005,0.000105656,1.64E-05,0.25,-2.31E-07,9.74E-06,-1.91E-07,84.75158691,84.75158691,1000.004333,1000.013489,44.25815164,17.52932383,49.62240982,0,0,0,40,83.01866913,2,4,1,1.94519043,61.09482193,,,,,,,,,,,,,,,,
3772636916,83.87334824,1000.031921,9.15E-06,4.62E-07,1,0.999253354,40.02988815,1.989070594,10.28000005,9.97E-05,1.59E-05,0.25,-1.79E-07,9.19E-06,-1.40E-07,83.87838745,83.87838745,1000.031921,1000.031921,44.09635454,17.53709907,49.56404495,0,0,0,40,82.16442108,2,4,1,1.939086914,60.60606384,,,,,,,,,,,,,,,,
3772636968,83.0038414,1000.020386,9.26E-06,3.87E-07,1,0.999253354,40.02988815,1.989026995,10.28999966,0.00010112,1.46E-05,0.25,-3.19E-07,9.30E-06,-2.80E-07,83.01229095,83.01229095,1000.018066,1000.022705,44.36992452,17.53498225,49.52609634,0,0,0,40,81.31552124,2,4,1,1.957855225,58.65102768,,,,,,,,,,,,,,,,
3772637020,82.13087463,999.990448,9.53E-06,3.88E-07,1,0.999253354,40.02988815,1.989010955,10.28999966,0.000102291,2.51E-05,0.25,5.98E-07,9.57E-06,6.44E-07,82.1388855,82.1388855,999.9628296,1000.018066,44.17060925,17.53924098,49.44264984,0,0,0,40,80.45835114,2,4,1,1.946716309,62.0723381,,,,,,,,,,,,,,,,
3772637072,81.26237869,1000.013519,9.16E-06,4.70E-07,1,0.999253354,40.02988815,1.989193732,10.28000005,9.91E-05,2.00E-05,0.25,1.95E-07,9.21E-06,2.38E-07,81.27183533,81.27183533,1000.004333,1000.022705,44.13543597,17.53664263,49.37940216,0,0,0,40,79.60501862,2,4,1,1.945037842,61.09482193,,,,,,,,,,,,,,,,
3772637124,80.39173508,999.9881287,8.43E-06,4.56E-07,1,0.999253354,40.02988815,1.988985724,10.28000005,9.66E-05,-1.13E-05,0.25,-2.56E-06,8.49E-06,-2.53E-06,80.40047455,80.40047455,999.9581909,1000.018066,44.61301099,17.53240481,49.3130455,0,0,0,40,78.75254822,2,4,1,1.946411133,61.58358002,,,,,,,,,,,,,,,,
3772637176,79.52306747,1000.022705,8.85E-06,9.10E-07,1,0.999253354,40.02988815,1.989079005,10.28000005,0.000102098,-1.63E-05,0.25,-3.10E-06,8.91E-06,-3.07E-06,79.53235626,79.53235626,1000.022705,1000.022705,44.114332,17.5339795,49.24935532,0,0,0,40,77.89772797,2,4,1,1.955566406,61.09482193,,,,,,,,,,,,,,,,
3772637228,78.65418243,1000.03653,6.29E-06,1.30E-06,1,0.999253354,40.02988815,1.98897698,10.28000005,7.91E-05,-4.79E-05,0.25,-5.54E-06,6.34E-06,-5.54E-06,78.6636734,78.6636734,1000.031921,1000.041138,44.08228523,17.53429766,49.16280365,0,0,0,40,77.05277252,2,4,1,1.956787109,61.09482193,,,,,,,,,,,,,,,,
3772637280,77.78084564,1000.020386,2.20E-06,1.91E-06,1,0.999253354,40.02988815,1.989033527,10.28999966,2.30E-05,9.09E-06,0.25,4.41E-07,2.21E-06,4.54E-07,77.78907776,77.78907776,1000.018066,1000.022705,44.141689,17.53234071,49.05716705,0,0,0,40,76.19306946,2,4,1,1.95602417,65.00489044,,,,,,,,,,,,,,,,
3772637357,76.49724579,1000.013458,-1.49E-06,3.85E-06,1,0.999253354,40.02988815,2.001173626,10.27000044,-6.50E-06,-5.73E-05,0.25,-4.98E-06,-1.48E-06,-5.01E-06,76.50780487,76.50780487,999.9996338,1000.027283,43.97911026,17.53273532,48.9948082,0,0,0,40,74.95063019,2,4,1,1.961669922,60.11730194,,,,,,,,,,,,,,,,
3772637409,75.62366104,1000.022705,-4.91E-06,9.93E-06,1,0.999253354,40.02988815,2.001264004,10.25999989,-3.09E-05,-0.000135407,0.25,-1.15E-05,-4.87E-06,-1.16E-05,75.63460541,75.63460541,1000.013489,1000.031921,44.42463852,17.53121633,48.92245865,0,0,0,40,74.08841705,2,4,1,1.968231201,60.60606384,,,,,,,,,,,,,,,,
3772637461,74.75063705,999.9927673,-1.45E-05,3.23E-06,1,0.999253354,40.02988815,2.001299287,10.25999989,-0.000147755,-8.45E-05,0.25,-5.13E-06,-1.45E-05,-5.23E-06,74.75839233,74.75839233,999.9489746,1000.03656,44.15653994,17.53620335,48.84900284,0,0,0,40,73.2306366,2,4,1,1.964263916,60.60606384,,,,,,,,,,,,,,,,
3772637513,73.87892151,999.9973755,-2.66E-05,3.24E-06,1,0.999253354,40.02988815,2.001327201,10.25999989,-0.000269811,-0.000163015,0.25,-1.01E-05,-2.66E-05,-1.03E-05,73.88457489,73.88457489,999.9628296,1000.031921,44.12761968,17.53590071,48.76711273,0,0,0,40,72.38772583,2,4,1,1.967010498,61.09482193,,,,,,,,,,,,,,,,
3772637565,73.00783157,1000.001984,-3.11E-05,1.86E-06,1,0.999253354,40.02988815,2.001288433,10.25999989,-0.000347591,-1.65E-05,0.25,4.11E-06,-3.13E-05,3.96E-06,73.01522827,73.01522827,999.9720459,1000.031921,44.46293832,17.53519735,48.69720459,0,0,0,40,71.53394318,2,4,1,1.956939697,61.09482193,,,,,,,,,,,,,,,,
3772637617,72.13584518,1000.001984,-3.61E-05,2.38E-06,1,0.999253354,40.02988815,2.001281162,10.27000044,-0.0003868,-0.000109954,0.25,-3.55E-06,-3.62E-05,-3.76E-06,72.14520264,72.14520264,999.9674072,1000.03656,44.15653994,17.53083388,48.64904785,0,0,0,40,70.68480682,2,4,1,1.955108643,61.09482193,,,,,,,,,,,,,,,,
3772637669,71.26469803,1000.027313,-3.30E-05,2.19E-06,1,0.999253354,40.02988815,2.001225826,10.25999989,-0.000402636,0.000169772,0.25,2.15E-05,-3.33E-05,2.14E-05,71.27453613,71.27453613,1000.022705,1000.031921,44.37930406,17.53479194,48.5693779,0,0,0,40,69.83579254,2,4,1,1.957244873,61.09482193,,,,,,,,,,,,,,,,
3772637721,70.39478302,999.9950562,-5.13E-05,2.50E-06,1,0.999253354,40.02988815,2.001123053,10.27000044,-0.00060006,0.000123499,0.25,2.06E-05,-5.16E-05,2.04E-05,70.4028244,70.4028244,999.9766235,1000.013489,44.4981116,17.53286526,48.50879288,0,0,0,40,68.98661041,2,4,1,1.96105957,61.09482193,,,,,,,,,,,,,,,,
3772637773,69.52221298,1000.020386,-5.22E-05,1.86E-06,1,0.999253354,40.02988815,2.001415767,10.25999989,-0.000582935,-2.72E-05,0.25,6.97E-06,-5.24E-05,6.69E-06,69.53016663,69.53016663,1000.018066,1000.022705,44.11902177,17.53088714,48.43866348,0,0,0,40,68.1374588,2,4,1,1.968688965,61.09482193,,,,,,,,,,,,,,,,
3772637824,68.65135193,1000.022675,-4.06E-05,3.47E-06,1,0.999253354,40.02988815,2.00128276,10.25999989,-0.000442468,-8.26E-05,0.25,-2.06E-07,-4.08E-05,-4.50E-07,68.66014099,68.66014099,1000.018066,1000.027283,44.26596793,17.53258753,48.35411072,0,0,0,40,67.28813171,2,4,1,1.95892334,61.58358002,,,,,,,,,,,,,,,,
3772637876,67.77581024,1000.022705,-6.52E-05,2.33E-06,1,0.999253354,40.02988815,2.001368576,10.25999989,-0.000706545,-0.000153615,0.25,-2.25E-06,-6.54E-05,-2.66E-06,67.78432465,67.78432465,1000.022705,1000.022705,44.50749114,17.53305689,48.2302742,0,0,0,40,66.44337463,2,4,1,1.9581604,61.09482193,,,,,,,,,,,,,,,,
3772637928,66.90696716,999.9697266,-4.95E-05,4.19E-06,1,0.999253354,40.02988815,2.001304909,10.27000044,-0.000571732,8.18E-05,0.25,1.65E-05,-4.97E-05,1.62E-05,66.91342926,66.91342926,999.9628296,999.9766235,44.20265602,17.53853625,48.08757782,0,0,0,40,65.59886932,2,4,1,1.956939697,61.58358002,,,,,,,,,,,,,,,,
3772638005,65.61473083,1000.022705,-4.74E-05,4.52E-06,1,0.999253354,40.02988815,1.989119929,10.27000044,-0.000483503,-0.000257997,0.25,-1.52E-05,-4.74E-05,-1.55E-05,65.62424469,65.62424469,1000.022705,1000.022705,44.26049653,17.53398338,47.98238373,0,0,0,40,64.33841705,2,4,1,1.953430176,60.11730194,,,,,,,,,,,,,,,,
3772638057,64.73919296,1000.025024,-5.71E-05,4.23E-06,1,0.999253354,40.02988815,1.989001627,10.25999989,-0.000604661,-0.000186026,0.25,-6.80E-06,-5.72E-05,-7.18E-06,64.74703217,64.74703217,1000.013489,1000.03656,43.91267184,17.5336952,47.89139557,0,0,0,40,63.48393631,2,4,1,1.947937012,60.60606384,,,,,,,,,,,,,,,,
3772638109,63.8656044,1000.018066,-7.84E-05,3.86E-06,1,0.999253354,40.02988815,1.989085792,10.25999989,-0.000866569,-5.70E-05,0.25,9.00E-06,-7.87E-05,8.51E-06,63.87268448,63.87268448,1000.018066,1000.018066,44.5364114,17.53180567,47.81172562,0,0,0,40,62.63957596,2,4,1,1.943969727,61.09482193,,,,,,,,,,,,,,,,
3772638161,62.99482536,1000.004242,-8.34E-05,2.45E-06,1,0.999253354,40.02988815,1.988992873,10.27000044,-0.000900853,-0.000177245,0.25,-1.18E-06,-8.36E-05,-1.74E-06,63.00107193,63.00107193,999.9857788,1000.022705,44.0815036,17.53668115,47.69943237,0,0,0,40,61.79916763,2,4,1,1.946716309,61.58358002,,,,,,,,,,,,,,,,
3772638213,62.12020111,999.9605103,-7.99E-05,4.29E-06,1,0.999253354,40.02988815,1.989090934,10.27000044,-0.000855365,-0.000209474,0.25,-4.79E-06,-8.00E-05,-5.35E-06,62.12840652,62.12840652,999.9581909,999.9628296,44.3089575,17.53675367,47.63063431,0,0,0,40,60.94280243,2,4,1,1.943969727,60.11730194,,,,,,,,,,,,,,,,
3772638265,61.24254799,1000.004272,-8.85E-05,2.82E-06,1,0.999253354,40.02988815,1.988969032,10.25999989,-0.000976365,-7.41E-05,0.25,9.29E-06,-8.88E-05,8.70E-06,61.24995041,61.24995041,999.9766235,1000.031921,44.476226,17.53764187,47.53298569,0,0,0,40,60.1003952,2,4,1,1.956634521,60.60606384,,,,,,,,,,,,,,,,
3772638317,60.37342453,1000.022705,-9.79E-05,3.39E-06,1,0.999253354,40.02988815,1.989114998,10.25999989,-0.001094603,-5.89E-07,0.25,1.78E-05,-9.82E-05,1.72E-05,60.38034821,60.38034821,1000.00885,1000.03656,44.29098004,17.53850267,47.42468643,0,0,0,40,59.25092316,2,4,1,1.944274902,60.60606384,,,,,,,,,,,,,,,,
3772638369,59.50200272,1000.029602,-0.000109297,3.48E-06,1,0.999253354,40.02988815,1.988924681,10.27000044,-0.001185882,-0.000196625,0.25,1.77E-06,-0.000109511,1.00E-06,59.50855637,59.50855637,1000.027283,1000.031921,44.01819169,17.53686974,47.32038116,0,0,0,40,58.40658188,2,4,1,1.959075928,61.58358002,,,,,,,,,,,,,,,,
3772638421,58.62526894,999.997345,-0.000115532,2.60E-06,1,0.999253354,40.02988815,1.989036555,10.25999989,-0.001232868,-0.000319846,0.25,-8.48E-06,-0.000115659,-9.31E-06,58.63512421,58.63512421,999.9674072,1000.027283,44.73260016,17.53077004,47.23316574,0,0,0,40,57.5559082,2,4,1,1.957702637,61.09482193,,,,,,,,,,,,,,,,
3772638473,57.75423622,999.9512634,-0.000122195,3.74E-06,1,0.999253354,40.02988815,1.989045649,10.25999989,-0.001305359,-0.000328977,0.25,-8.11E-06,-0.000122307,-8.99E-06,57.76464462,57.76464462,999.9443359,999.9581909,44.60206819,17.53247707,47.11865234,0,0,0,40,56.70529175,2,4,1,1.957855225,61.58358002,,,,,,,,,,,,,,,,
3772638525,56.87747002,999.990448,-0.000115104,3.74E-06,1,0.999253354,40.02988815,1.988900467,10.27000044,-0.001251732,-0.000186572,0.25,3.77E-06,-0.000115264,2.94E-06,56.88452148,56.88452148,999.9674072,1000.013489,44.30817587,17.53678223,47.03343582,0,0,0,40,55.85600662,2,4,1,1.962738037,60.60606384,,,,,,,,,,,,,,,,
3772638602,55.58533096,999.9812622,-0.0001213,4.11E-06,1,0.999253354,40.02988815,2.00117559,10.27000044,-0.001333829,-0.000156734,0.25,7.75E-06,-0.000121452,6.87E-06,55.59379959,55.59379959,999.9581909,1000.004333,44.39259175,17.53540568,46.84701538,0,0,0,40,54.60963058,2,4,1,1.955413818,60.11730194,,,,,,,,,,,,,,,,
3772638654,54.70710945,999.9927673,-0.000130161,3.81E-06,1,0.999253354,40.02988815,2.001373086,10.27000044,-0.001390018,-0.000392515,0.25,-1.23E-05,-0.000130139,-1.33E-05,54.71397018,54.71397018,999.9628296,1000.022705,44.2651863,17.53133575,46.72939682,0,0,0,40,53.77166748,2,4,1,1.964874268,60.60606384,,,,,,,,,,,,,,,,
3772638706,53.83280373,999.9996948,-0.000127779,2.90E-06,1,0.999253354,40.02988815,2.001288953,10.27000044,-0.001403097,-0.00017235,0.25,7.50E-06,-0.000127869,6.56E-06,53.84221268,53.84221268,999.9628296,1000.03656,44.3144289,17.53607134,46.58625412,0,0,0,40,52.92004395,2,4,1,1.968231201,61.09482193,,,,,,,,,,,,,,,,
3772638758,52.95605469,1000.013458,-0.000134107,3.14E-06,1,0.999253354,40.02988815,2.001261784,10.27000044,-0.001463663,-0.000227386,0.25,3.59E-06,-0.000134135,2.60E-06,52.96547318,52.96547318,1000.00885,1000.018066,44.41604061,17.53391545,46.35501099,0,0,0,40,52.07010269,2,4,1,1.974945068,61.09482193,,,,,,,,,,,,,,,,
3772638810,52.08590889,999.990448,-0.000141298,3.35E-06,1,0.999253354,40.02988815,2.001258559,10.28000005,-0.001577009,-4.66E-05,0.25,2.16E-05,-0.000141421,2.05E-05,52.09453964,52.09453964,999.9674072,1000.013489,44.06665266,17.53378177,46.14973068,0,0,0,40,51.22589874,2,4,1,1.969604492,60.60606384,,,,,,,,,,,,,,,,
3772638862,51.20747757,999.990448,-0.00014611,3.27E-06,1,0.999253354,40.02988815,2.001155118,10.27000044,-0.001566186,-0.000398117,0.25,-9.95E-06,-0.000145958,-1.10E-05,51.21687317,51.21687317,999.9628296,1000.018066,44.4707546,17.53214568,45.89074326,0,0,0,40,50.37851334,2,4,1,1.957244873,60.60606384,,,,,,,,,,,,,,,,
3772638914,50.33274078,999.9996643,-0.000140607,2.97E-06,1,0.999253354,40.02988815,2.001203552,10.27000044,-0.001554504,-0.000122336,0.25,1.44E-05,-0.0001406,1.34E-05,50.34069061,50.34069061,999.9674072,1000.031921,44.42776503,17.53258096,45.55630112,0,0,0,40,49.53413391,2,4,1,1.958770752,61.09482193,,,,,,,,,,,,,,,,
3772638966,50.14840508,999.9858398,-0.000138046,2.53E-06,1,0.999253354,40.02988815,2.001275411,10.27000044,-0.001530291,-9.75E-05,0.25,1.63E-05,-0.000138047,1.52E-05,50.14529037,50.14529037,999.9628296,1000.00885,44.45199552,17.53460646,45.43845749,0,0,0,40,49.92967224,5,4,1,1.95892334,61.58358002,,,,,,,,,,,,,,,,
3772639018,50.21972084,999.9996643,-0.000154675,2.91E-06,1,0.999253354,40.02988815,2.001333657,10.27000044,-0.001663539,-0.000389041,0.25,-7.56E-06,-0.000154488,-8.70E-06,50.21958923,50.21958923,999.9720459,1000.027283,44.28238213,17.53499048,45.35435104,0,0,0,40,49.91194916,5,4,1,1.960296631,61.58358002,,,,,,,,,,,,,,,,
3772639039,50.22065735,999.9950562,-0.000143642,4.59E-06,1,0.999253354,40.02988815,2.001322969,10.27000044,-0.001502815,-0.000591207,0.25,-2.82E-05,-0.000143311,-2.92E-05,50.22065735,50.22065735,999.9628296,1000.027283,44.56845817,17.53190353,45.32683182,0,0,0,40,49.90969849,1,4,1,1.96105957,61.58358002,,,,,,,,,,,,,,,,