File: data/DyBCO/DyBCO_MVT_2000Oe_50-120K_Continuous_2.csv
Time Stamp (sec),Temperature (K),Magnetic Field (Oe),Moment (emu),M. Std. Err. (emu),Transport Action,Averaging Time (sec),Frequency (Hz),Peak Amplitude (mm),Center Position (mm),Coil Signal' (mV),"Coil Signal"" (mV)",Range (mV),M. Quad. Signal (emu),M. Raw' (emu),"M. Raw"" (emu)",Min. Temperature (K),Max. Temperature (K),Min. Field (Oe),Max. Field (Oe),Mass (grams),Motor Lag (deg),Pressure (Torr),VSM Status (code),Motor Status (code),Measure Status (code),Measure Count,System Temp. (K),Temp. Status (code),Field Status (code),Chamber Status (code),Motor Current (amps),Motor Heatsink Temp. (C),Map 01,Map 02,Map 03,Map 04,Map 05,Map 06,Map 07,Map 08,Map 09,Map 10,Map 11,Map 12,Map 13,Map 14,Map 15,Map 16
3772693921,50.17927551,2000.013794,-0.001742667,7.66E-06,1,0.999253354,40.02988815,2.001306458,10.28000005,-0.018874238,-0.003663854,0.25,-1.88E-05,-0.001741096,-3.18E-05,50.1794014,50.1794014,1999.983765,2000.043823,44.43010992,17.55404969,43.61933899,0,0,0,40,49.89830017,1,4,1,1.97052002,62.0723381,,,,,,,,,,,,,,,,
3772693962,50.50512505,1999.983887,-0.001744596,7.02E-06,1,0.999253354,40.02988815,2.001310217,10.28000005,-0.018930641,-0.003484867,0.25,-1.97E-06,-0.001743327,-1.49E-05,50.49526215,50.49526215,1999.979248,1999.988525,44.12136665,17.55417493,43.67593002,0,0,0,40,50.60544205,6,4,1,1.970214844,60.11730194,,,,,,,,,,,,,,,,
3772694022,51.50342751,1999.979248,-0.001718938,9.63E-06,1,0.999253354,40.02988815,2.001216459,10.28000005,-0.018595693,-0.003770728,0.25,-3.29E-05,-0.00171799,-4.57E-05,51.49405289,51.49405289,1999.979248,1999.979248,44.7036799,17.5520601,43.88698196,0,0,0,40,51.69150543,2,4,1,1.962890625,61.58358002,,,,,,,,,,,,,,,,
3772694064,52.20040321,1999.988464,-0.001675716,1.11E-05,1,0.999253354,40.02988815,2.001298528,10.28000005,-0.018151684,-0.003573172,0.25,-2.25E-05,-0.001675224,-3.50E-05,51.97472382,51.97472382,1999.983765,1999.993164,44.46840972,17.55021981,44.13731384,0,0,0,40,52.6257515,2,4,1,1.965789795,59.62854385,,,,,,,,,,,,,,,,
3772694113,53.00668907,1999.990845,-0.0016534,4.89E-06,1,0.999253354,40.02988815,2.001156353,10.28000005,-0.017843446,-0.003907398,0.25,-5.74E-05,-0.001653061,-6.96E-05,52.99966812,52.99966812,1999.988525,1999.993164,44.04085892,17.54924481,44.32617188,0,0,0,40,53.2301178,2,4,1,1.967163086,60.60606384,,,,,,,,,,,,,,,,
3772694174,54.01318932,2000.018494,-0.00152553,7.98E-06,1,0.999253354,40.02988815,2.001197471,10.27000044,-0.016649502,-0.002618158,0.25,3.80E-05,-0.001526353,2.67E-05,54.00556564,54.00556564,1999.993164,2000.043823,44.43714458,17.55220878,44.77290726,0,0,0,40,54.26848602,2,4,1,1.962432861,60.60606384,,,,,,,,,,,,,,,,
3772694234,55.00409698,2000.020752,-0.001443706,6.25E-06,1,0.999253354,40.02988815,2.001382628,10.28000005,-0.015703913,-0.002798815,0.25,6.41E-06,-0.001444688,-4.18E-06,54.99609756,54.99609756,1999.997681,2000.043823,44.44183435,17.55581716,45.17414856,0,0,0,40,55.29003906,2,4,1,1.967926025,61.58358002,,,,,,,,,,,,,,,,
3772694295,56.0150013,1999.988464,-0.001367468,7.65E-06,1,0.999253354,40.02988815,2.001271824,10.28000005,-0.014794631,-0.003108712,0.25,-3.61E-05,-0.001368488,-4.60E-05,56.00848389,56.00848389,1999.979248,1999.997681,44.35116544,17.55199008,45.55541229,0,0,0,40,56.3277092,2,4,1,1.970367432,62.0723381,,,,,,,,,,,,,,,,
3772694355,57.00762367,1999.981506,-0.001264135,4.93E-06,1,0.999253354,40.02988815,2.001253763,10.28000005,-0.013732828,-0.002587319,0.25,-7.00E-06,-0.00126562,-1.61E-05,56.99959183,56.99959183,1999.979248,1999.983765,44.4433976,17.55171334,45.87054825,0,0,0,40,57.34125137,2,4,1,1.971893311,62.0723381,,,,,,,,,,,,,,,,
3772694415,58.00298119,2000.020752,-0.001184991,6.08E-06,1,0.999253354,40.02988815,2.001177577,10.27000044,-0.012843906,-0.002601773,0.25,-2.28E-05,-0.001186584,-3.13E-05,57.99595642,57.99595642,1999.993164,2000.04834,44.65521893,17.55285252,46.13197327,0,0,0,40,58.35068512,2,4,1,1.968231201,63.04985428,,,,,,,,,,,,,,,,
3772694476,59.01373672,2000.018433,-0.001117212,6.40E-06,1,0.999253354,40.02988815,2.001240057,10.27000044,-0.012115784,-0.002437353,0.25,-2.01E-05,-0.001119018,-2.80E-05,59.00642014,59.00642014,1999.988525,2000.04834,44.36445312,17.55290597,46.3470192,0,0,0,40,59.38723373,2,4,1,1.96182251,64.51612854,,,,,,,,,,,,,,,,
3772694536,60.01121902,1999.979248,-0.001022893,6.83E-06,1,0.999253354,40.02988815,2.001287217,10.28000005,-0.011143523,-0.001971213,0.25,5.47E-06,-0.001024967,-1.64E-06,60.00449371,60.00449371,1999.974731,1999.983765,44.24017419,17.55544279,46.50968933,0,0,0,40,60.39102936,2,4,1,1.956939697,63.53861237,,,,,,,,,,,,,,,,
3772694596,61.01319695,2000.020752,-0.000946083,6.35E-06,1,0.999253354,40.02988815,2.001530836,10.27000044,-0.010255289,-0.002125967,0.25,-2.28E-05,-0.000948035,-2.93E-05,61.00444031,61.00444031,1999.993164,2000.04834,44.25033536,17.54501367,46.69633102,0,0,0,40,61.39492798,2,4,1,1.965942383,63.04985428,,,,,,,,,,,,,,,,
3772694656,62.00585175,2000.013794,-0.000832217,5.70E-06,1,0.999253354,40.02988815,2.001646645,10.28000005,-0.009075837,-0.001583559,0.25,6.22E-06,-0.0008343,6.15E-07,61.99943542,61.99943542,1999.983765,2000.043823,44.37852244,17.55316501,46.82415771,0,0,0,40,62.40146637,2,4,1,1.959228516,62.56109619,,,,,,,,,,,,,,,,
3772694694,62.64962769,2000.009155,-0.000779417,5.66E-06,1,0.999253354,40.02988815,1.989425153,10.28000005,-0.008455666,-0.001454764,0.25,7.62E-06,-0.000781488,2.42E-06,62.64533997,62.64533997,1999.983765,2000.034546,44.1362176,17.55157509,46.88452148,0,0,0,40,63.04353714,2,4,1,1.970062256,61.09482193,,,,,,,,,,,,,,,,
3772694746,63.50418854,1999.986145,-0.000705572,1.00E-05,1,0.999253354,40.02988815,1.98919053,10.28000005,-0.007728105,-0.000915588,0.25,4.39E-05,-0.000707816,3.94E-05,63.49682999,63.49682999,1999.983765,1999.988525,44.12371154,17.55299229,46.97151566,0,0,0,40,63.89626312,2,4,1,1.957092285,62.56109619,,,,,,,,,,,,,,,,
3772694806,64.50377655,1999.981506,-0.000619958,4.94E-06,1,0.999253354,40.02988815,1.989323046,10.28000005,-0.006767264,-0.000941191,0.25,2.59E-05,-0.000621966,2.20E-05,64.4932251,64.4932251,1999.979248,1999.983765,45.09683905,17.55501702,47.07337952,0,0,0,40,64.91192627,2,4,1,1.956634521,62.56109619,,,,,,,,,,,,,,,,
3772694865,65.50391006,1999.988525,-0.000564888,4.72E-06,1,0.999253354,40.02988815,1.989200894,10.28999966,-0.006181359,-0.000778091,0.25,3.09E-05,-0.000566866,2.74E-05,65.49485016,65.49485016,1999.988525,1999.988525,44.66381685,17.5551199,47.16925049,0,0,0,40,65.90851593,2,4,1,1.968994141,62.56109619,,,,,,,,,,,,,,,,
3772694926,66.5014267,1999.979309,-0.000485623,3.69E-06,1,0.999253354,40.02988815,1.989301682,10.28000005,-0.005321377,-0.000634684,0.25,2.97E-05,-0.000487425,2.67E-05,66.49269104,66.49269104,1999.970093,1999.988525,44.29410656,17.55576986,47.26556778,0,0,0,40,66.92385864,2,4,1,1.947021484,63.04985428,,,,,,,,,,,,,,,,
3772694985,67.50163269,2000.011475,-0.00042476,4.97E-06,1,0.999253354,40.02988815,1.989282545,10.28000005,-0.004674194,-0.000450242,0.25,3.56E-05,-0.000426462,3.31E-05,67.49295807,67.49295807,1999.983765,2000.039185,44.2925433,17.55655465,47.36432266,0,0,0,40,67.92407227,2,4,1,1.959686279,63.04985428,,,,,,,,,,,,,,,,
3772695045,68.50302505,2000.018433,-0.000341369,5.88E-06,1,0.999253354,40.02988815,1.989377449,10.28999966,-0.003758467,-0.000355212,0.25,2.92E-05,-0.00034279,2.72E-05,68.49611664,68.49611664,1999.983765,2000.053101,44.20578253,17.55501828,47.44288635,0,0,0,40,68.93015289,2,4,1,1.96685791,65.00489044,,,,,,,,,,,,,,,,
3772695105,69.50325394,2000.009155,-0.000264018,4.24E-06,1,0.999253354,40.02988815,1.989274575,10.28000005,-0.002930017,-0.000148227,0.25,3.42E-05,-0.000265222,3.28E-05,69.49490356,69.49490356,1999.983765,2000.034546,44.37539592,17.55453136,47.5116806,0,0,0,40,69.9376297,2,4,1,1.959533691,62.56109619,,,,,,,,,,,,,,,,
3772695165,70.50149155,2000.018433,-0.000227192,4.50E-06,1,0.999253354,40.02988815,1.989247976,10.28999966,-0.002549923,2.88E-05,0.25,4.38E-05,-0.000228338,4.27E-05,70.4933548,70.4933548,1999.983765,2000.053101,44.46919134,17.55527429,47.60644531,0,0,0,40,70.95388031,2,4,1,1.958007813,63.04985428,,,,,,,,,,,,,,,,
3772695225,71.50345993,1999.986145,-0.0001823,3.48E-06,1,0.999253354,40.02988815,1.989238298,10.28000005,-0.002034804,-4.02E-05,0.25,2.93E-05,-0.000183205,2.84E-05,71.49578857,71.49578857,1999.983765,1999.988525,44.32459007,17.55606653,47.69321823,0,0,0,40,71.96472168,2,4,1,1.959686279,63.53861237,,,,,,,,,,,,,,,,
3772695299,72.71977997,1999.997681,,,2,,,,10.27199997,,,,,,,72.71977997,72.71977997,1999.997681,1999.997681,,,47.81549835,,,,40,73.19091034,0,0,0,0.04196167,62.56109619,,,,,,,,,,,,,,,,
3772695316,73.01357269,2000.025391,-0.000112838,3.56E-06,1,0.999253354,40.02988815,1.989349051,10.25999989,-0.001286866,0.000125118,0.25,3.19E-05,-0.000113491,3.15E-05,73.00561523,73.00561523,1999.997681,2000.053101,44.35194707,17.553833,47.84368134,0,0,0,40,73.48567963,2,4,1,1.947479248,61.58358002,,,,,,,,,,,,,,,,
3772695376,74.00858307,2000.016174,-8.30E-05,3.09E-06,1,0.999253354,40.02988815,1.989242216,10.27000044,-0.00098886,0.000323279,0.25,4.48E-05,-8.36E-05,4.46E-05,73.99803162,73.99803162,1999.974731,2000.057617,44.11042385,17.55819883,47.94443512,0,0,0,40,74.49673462,2,4,1,1.95892334,62.0723381,,,,,,,,,,,,,,,,
3772695436,75.0051384,1999.986145,-4.85E-05,2.48E-06,1,0.999253354,40.02988815,1.989246176,10.25999989,-0.000591118,0.000263433,0.25,3.30E-05,-4.89E-05,3.29E-05,74.99589539,74.99589539,1999.983765,1999.988525,44.40900595,17.5552925,48.02277374,0,0,0,40,75.50476837,2,4,1,1.954650879,63.04985428,,,,,,,,,,,,,,,,
3772695496,76.00548935,1999.990723,-4.35E-05,3.70E-06,1,0.999253354,40.02988815,1.98912259,10.27000044,-0.000520461,0.000183163,0.25,2.47E-05,-4.38E-05,2.46E-05,75.99807739,75.99807739,1999.983765,1999.997681,44.66694336,17.55982937,48.13462448,0,0,0,40,76.50182343,2,4,1,1.961364746,62.56109619,,,,,,,,,,,,,,,,
3772695556,77.00061417,1999.983765,-8.26E-07,1.01E-07,1,0.999253354,40.02988815,1.989194483,10.25999989,-9.17E-05,0.000457152,0.25,4.23E-05,-1.04E-06,4.25E-05,76.99272156,76.99272156,1999.983765,1999.983765,44.4269834,17.55845199,48.22872162,0,0,0,40,77.51215363,2,4,1,1.946716309,63.04985428,,,,,,,,,,,,,,,,
3772695617,78.01589966,1999.983765,6.62E-06,2.20E-06,1,0.999253354,40.02988815,1.988956477,10.25999989,1.77E-05,0.000313777,0.25,2.77E-05,6.52E-06,2.79E-05,78.00689697,78.00689697,1999.983765,1999.983765,44.1307462,17.55331153,48.34123611,0,0,0,40,78.5417099,2,4,1,1.96105957,63.53861237,,,,,,,,,,,,,,,,
3772695677,79.01247787,2000.013855,4.67E-06,2.23E-06,1,0.999253354,40.02988815,1.989184897,10.25999989,1.94E-05,0.000182882,0.25,1.60E-05,4.61E-06,1.61E-05,79.00522614,79.00522614,1999.988525,2000.039185,44.68492082,17.5558833,48.41513824,0,0,0,40,79.55010986,2,4,1,1.947937012,63.53861237,,,,,,,,,,,,,,,,
3772695737,80.01232529,1999.992981,1.33E-05,5.60E-06,1,0.999253354,40.02988815,1.989126736,10.25999989,0.000109833,0.000218245,0.25,1.77E-05,1.33E-05,1.79E-05,80.00392914,80.00392914,1999.983765,2000.002197,44.19640299,17.55162336,48.47816467,0,0,0,40,80.55075073,2,4,1,1.948242188,63.04985428,,,,,,,,,,,,,,,,
3772695797,81.00759506,2000.036865,1.91E-05,2.01E-06,1,0.999253354,40.02988815,1.989275621,10.27000044,0.000196344,9.69E-05,0.25,5.49E-06,1.91E-05,5.61E-06,80.99729919,80.99729919,2000.034546,2000.039185,44.19014996,17.55578766,48.5589447,0,0,0,40,81.56424713,2,4,1,1.948242188,63.04985428,,,,,,,,,,,,,,,,
3772695857,82.00774002,2000.023071,2.08E-05,4.46E-07,1,0.999253354,40.02988815,1.989211001,10.25999989,0.000223472,5.12E-05,0.25,9.81E-07,2.09E-05,1.08E-06,81.99893951,81.99893951,1999.988525,2000.057617,44.14559714,17.55522048,48.63328934,0,0,0,40,82.57069397,2,4,1,1.95892334,63.04985428,,,,,,,,,,,,,,,,
3772695916,82.98601532,2000.062256,,,2,,,,10.25199981,,,,,,,82.98601532,82.98601532,2000.062256,2000.062256,,,48.6927681,,,,40,83.55958557,0,0,0,0.040435791,60.60606384,,,,,,,,,,,,,,,,
3772695947,83.50026321,1999.983887,2.10E-05,5.87E-07,1,0.999253354,40.02988815,1.989211463,10.23999974,0.00022728,4.57E-05,0.25,4.32E-07,2.11E-05,5.26E-07,83.49168396,83.49168396,1999.979248,1999.988525,44.59737842,17.55393059,48.73004913,0,0,0,40,84.08474731,2,4,1,1.9581604,62.56109619,,,,,,,,,,,,,,,,
3772696008,84.51683044,1999.988525,2.03E-05,3.83E-07,1,0.999253354,40.02988815,1.989242013,10.23999974,0.000220945,3.80E-05,0.25,-1.46E-07,2.04E-05,-6.00E-08,84.50872803,84.50872803,1999.988525,1999.988525,44.37695918,17.5546858,48.78619766,0,0,0,40,85.11076355,2,4,1,1.962127686,62.56109619,,,,,,,,,,,,,,,,
3772696068,85.51043701,2000.013855,2.03E-05,4.62E-07,1,0.999253354,40.02988815,1.98917848,10.25000028,0.000219506,4.34E-05,0.25,3.54E-07,2.04E-05,4.41E-07,85.50179291,85.50179291,1999.988525,2000.039185,44.37617755,17.55568608,48.83768463,0,0,0,40,86.12264252,2,4,1,1.957244873,63.04985428,,,,,,,,,,,,,,,,
3772696127,86.50875473,2000.018433,2.06E-05,4.65E-07,1,0.999253354,40.02988815,1.989144769,10.23999974,0.00022394,4.00E-05,0.25,-1.63E-08,2.07E-05,6.82E-08,86.49889374,86.49889374,1999.979248,2000.057617,44.39728152,17.55682882,48.90980911,0,0,0,40,87.12794495,2,4,1,1.960144043,62.56109619,,,,,,,,,,,,,,,,
3772696187,87.50919342,1999.990845,2.01E-05,5.76E-07,1,0.999253354,40.02988815,1.989035762,10.23999974,0.000218622,3.97E-05,0.25,4.20E-08,2.02E-05,1.23E-07,87.50132751,87.50132751,1999.974731,2000.006958,44.49889323,17.55564688,48.97505569,0,0,0,40,88.13526917,2,4,1,1.9480896,63.04985428,,,,,,,,,,,,,,,,
3772696247,88.50416565,1999.979248,2.07E-05,5.12E-07,1,0.999253354,40.02988815,1.989099635,10.25000028,0.000224355,4.16E-05,0.25,1.26E-07,2.08E-05,2.09E-07,88.49945831,88.49945831,1999.974731,1999.983765,44.42385689,17.56074453,49.03830338,0,0,0,40,89.13774872,2,4,1,1.957855225,64.02737427,,,,,,,,,,,,,,,,
3772696307,89.50333023,1999.979309,2.03E-05,4.18E-07,1,0.999253354,40.02988815,1.989102921,10.25000028,0.000219425,4.33E-05,0.25,3.52E-07,2.04E-05,4.33E-07,89.4957962,89.4957962,1999.970093,1999.988525,44.73494504,17.55725343,49.116642,0,0,0,40,90.13679504,2,4,1,1.946258545,62.56109619,,,,,,,,,,,,,,,,
3772696368,90.5160141,2000.013794,2.08E-05,5.08E-07,1,0.999253354,40.02988815,1.989222917,10.23999974,0.000225512,4.46E-05,0.25,3.74E-07,2.09E-05,4.54E-07,90.50714111,90.50714111,1999.983765,2000.043823,44.34960218,17.55975406,49.1694603,0,0,0,40,91.1738205,2,4,1,1.95892334,63.53861237,,,,,,,,,,,,,,,,
3772696428,91.51397324,2000.011536,2.06E-05,4.87E-07,1,0.999253354,40.02988815,1.989129023,10.23999974,0.000223608,4.16E-05,0.25,1.43E-07,2.07E-05,2.21E-07,91.5036087,91.5036087,1999.993164,2000.029907,44.33318798,17.55843455,49.25268173,0,0,0,40,92.18338013,2,4,1,1.950531006,63.04985428,,,,,,,,,,,,,,,,
3772696488,92.51071167,2000.009216,2.07E-05,4.98E-07,1,0.999253354,40.02988815,1.989019515,10.23999974,0.00022401,4.61E-05,0.25,5.35E-07,2.08E-05,6.14E-07,92.50266266,92.50266266,1999.979248,2000.039185,44.1088606,17.55677461,49.32192612,0,0,0,40,93.18852234,2,4,1,1.958312988,63.53861237,,,,,,,,,,,,,,,,
3772696529,93.19224167,2000.013855,2.06E-05,4.34E-07,1,0.999253354,40.02988815,2.00138122,10.25000028,0.000223974,4.42E-05,0.25,3.69E-07,2.07E-05,4.45E-07,92.96554565,92.96554565,1999.988525,2000.039185,44.80685486,17.5547167,49.38805771,0,0,0,40,94.08817291,2,4,1,1.967468262,61.09482193,,,,,,,,,,,,,,,,
3772696578,94.00523376,1999.986145,2.07E-05,4.86E-07,1,0.999253354,40.02988815,2.001508984,10.25000028,0.000223947,5.16E-05,0.25,1.03E-06,2.08E-05,1.11E-06,93.99736786,93.99736786,1999.983765,1999.988525,44.59659679,17.55525802,49.4226799,0,0,0,40,94.69277954,2,4,1,1.97052002,62.56109619,,,,,,,,,,,,,,,,
3772696638,95.0030098,1999.970093,2.09E-05,4.22E-07,1,0.999253354,40.02988815,2.001586814,10.25999989,0.000227041,4.63E-05,0.25,5.06E-07,2.10E-05,5.82E-07,94.99555969,94.99555969,1999.970093,1999.970093,44.20421928,17.55312516,49.51610947,0,0,0,40,95.69707489,2,4,1,1.968994141,62.56109619,,,,,,,,,,,,,,,,
3772696698,96.00148773,1999.97467,2.04E-05,4.27E-07,1,0.999253354,40.02988815,2.001531102,10.25999989,0.000223046,3.86E-05,0.25,-1.17E-07,2.05E-05,-4.75E-08,95.99409485,95.99409485,1999.970093,1999.979248,44.35663684,17.55422735,49.58757019,0,0,0,40,96.70561981,2,4,1,1.961517334,63.53861237,,,,,,,,,,,,,,,,
3772696758,97.00042725,2000.020752,2.05E-05,4.93E-07,1,0.999253354,40.02988815,2.001415744,10.25000028,0.000223783,4.39E-05,0.25,3.50E-07,2.07E-05,4.21E-07,96.99600983,96.99600983,1999.993164,2000.04834,44.72243898,17.55347341,49.66968155,0,0,0,40,97.71430206,2,4,1,1.96105957,64.02737427,,,,,,,,,,,,,,,,
3772696819,98.01244354,1999.981506,2.06E-05,3.88E-07,1,0.999253354,40.02988815,2.001420239,10.25000028,0.000224505,4.40E-05,0.25,3.49E-07,2.07E-05,4.19E-07,98.00305176,98.00305176,1999.979248,1999.983765,44.38868361,17.55986489,49.73670197,0,0,0,40,98.73727417,2,4,1,1.959228516,64.02737427,,,,,,,,,,,,,,,,
3772696879,99.01077652,1999.993103,2.04E-05,4.48E-07,1,0.999253354,40.02988815,2.001242321,10.25999989,0.00022034,5.49E-05,0.25,1.38E-06,2.05E-05,1.46E-06,99.00312805,99.00312805,1999.974731,2000.011475,44.32849821,17.55609823,49.80594254,0,0,0,40,99.74165344,2,4,1,1.968688965,63.04985428,,,,,,,,,,,,,,,,
3772696939,100.0060387,1999.995361,2.07E-05,4.50E-07,1,0.999253354,40.02988815,2.001367901,10.25999989,0.000225423,4.30E-05,0.25,2.42E-07,2.08E-05,3.09E-07,99.99647522,99.99647522,1999.983765,2000.006958,44.67006987,17.56019765,49.86142349,0,0,0,40,100.7585602,2,4,1,1.969604492,63.53861237,,,,,,,,,,,,,,,,
3772696999,101.0002785,2000.002319,2.08E-05,5.42E-07,1,0.999253354,40.02988815,2.001445173,10.25000028,0.000227085,4.15E-05,0.25,8.96E-08,2.09E-05,1.55E-07,100.993248,100.993248,1999.997681,2000.006958,44.59034377,17.56483461,49.9078064,0,0,0,40,101.7686996,2,4,1,1.969299316,64.02737427,,,,,,,,,,,,,,,,
3772697059,102.0015335,2000.048462,2.06E-05,4.55E-07,1,0.999253354,40.02988815,2.001585905,10.25000028,0.000224591,4.34E-05,0.25,2.97E-07,2.07E-05,3.62E-07,101.9927063,101.9927063,2000.043823,2000.053101,44.45668529,17.56063342,49.96794891,0,0,0,40,102.7719116,2,4,1,1.96975708,64.02737427,,,,,,,,,,,,,,,,
3772697119,103.0016632,2000.004578,2.05E-05,5.19E-07,1,0.999253354,40.02988815,2.001292907,10.25000028,0.000222706,4.99E-05,0.25,9.05E-07,2.06E-05,9.72E-07,102.9944916,102.9944916,1999.979248,2000.029907,44.36210824,17.55474694,50.00456619,0,0,0,40,103.7721481,2,4,1,1.97052002,62.56109619,,,,,,,,,,,,,,,,
3772697160,103.6833153,1999.993164,2.05E-05,3.67E-07,1,0.999253354,40.02988815,1.989354866,10.23999974,0.000222523,4.27E-05,0.25,2.68E-07,2.06E-05,3.31E-07,103.6742706,103.6742706,1999.993164,1999.993164,44.05492823,17.53841857,50.01322174,0,0,0,40,104.457756,2,4,1,1.954498291,62.0723381,,,,,,,,,,,,,,,,
3772697210,104.511837,2000.013794,2.09E-05,5.08E-07,1,0.999253354,40.02988815,1.989228524,10.23999974,0.000225313,4.97E-05,0.25,8.49E-07,2.10E-05,9.15E-07,104.5036392,104.5036392,1999.983765,2000.043823,44.03851403,17.53922114,50.0489502,0,0,0,40,105.3041916,2,4,1,1.951904297,62.56109619,,,,,,,,,,,,,,,,
3772697270,105.5085526,2000.013855,2.09E-05,4.64E-07,1,0.999253354,40.02988815,1.989272363,10.25000028,0.000226977,3.91E-05,0.25,-1.22E-07,2.10E-05,-6.26E-08,105.5014572,105.5014572,1999.988525,2000.039185,44.55595211,17.54320443,50.10287857,0,0,0,40,106.3153305,2,4,1,1.965026855,63.04985428,,,,,,,,,,,,,,,,
3772697330,106.5079918,1999.988464,2.02E-05,4.42E-07,1,0.999253354,40.02988815,1.989253896,10.23999974,0.000217527,5.06E-05,0.25,1.06E-06,2.03E-05,1.12E-06,106.4993591,106.4993591,1999.983765,1999.993164,44.49654834,17.55230695,50.15281296,0,0,0,40,107.3083954,2,4,1,1.956634521,63.04985428,,,,,,,,,,,,,,,,
3772697390,107.5025215,1999.981628,2.12E-05,6.10E-07,1,0.999253354,40.02988815,1.989227655,10.25000028,0.000229566,4.55E-05,0.25,4.08E-07,2.13E-05,4.69E-07,107.4964981,107.4964981,1999.970093,1999.993164,44.43636295,17.55230833,50.20518494,0,0,0,40,108.3167725,2,4,1,1.957550049,63.04985428,,,,,,,,,,,,,,,,
3772697450,108.5015793,1999.988525,2.12E-05,4.75E-07,1,0.999253354,40.02988815,1.989006002,10.25000028,0.000229049,5.14E-05,0.25,9.48E-07,2.14E-05,1.01E-06,108.4952698,108.4952698,1999.988525,1999.988525,44.57158468,17.55355178,50.2433548,0,0,0,40,109.3268661,2,4,1,1.957702637,63.53861237,,,,,,,,,,,,,,,,
3772697510,109.5130768,2000.016052,2.10E-05,5.04E-07,1,0.999253354,40.02988815,1.988865104,10.23999974,0.000226619,4.75E-05,0.25,6.39E-07,2.11E-05,7.00E-07,109.5026855,109.5026855,1999.983765,2000.04834,44.69117384,17.55688889,50.30815887,0,0,0,40,110.3484726,2,4,1,1.949615479,63.53861237,,,,,,,,,,,,,,,,
3772697570,110.5103951,1999.997803,2.03E-05,4.79E-07,1,0.999253354,40.02988815,1.988911911,10.23999974,0.000218849,4.88E-05,0.25,8.78E-07,2.04E-05,9.37E-07,110.5010147,110.5010147,1999.974731,2000.020874,44.43714458,17.55472976,50.34832764,0,0,0,40,111.3544617,2,4,1,1.9581604,62.0723381,,,,,,,,,,,,,,,,
3772697630,111.5095139,1999.979309,2.11E-05,5.17E-07,1,0.999253354,40.02988815,1.989051682,10.25000028,0.00022781,4.69E-05,0.25,5.72E-07,2.12E-05,6.31E-07,111.5022812,111.5022812,1999.965454,1999.993164,44.09010151,17.56159227,50.3889389,0,0,0,40,112.3575668,2,4,1,1.959075928,65.00489044,,,,,,,,,,,,,,,,
3772697690,112.507225,2000.004639,2.08E-05,4.45E-07,1,0.999253354,40.02988815,1.988864832,10.23999974,0.00022531,4.16E-05,0.25,1.38E-07,2.09E-05,1.93E-07,112.4997406,112.4997406,1999.974731,2000.034546,44.47153623,17.56284017,50.43021774,0,0,0,40,113.3661957,2,4,1,1.959381104,63.53861237,,,,,,,,,,,,,,,,
3772697765,113.7455521,2000.04834,,,2,,,,10.21199998,,,,,,,113.7455521,113.7455521,2000.04834,2000.04834,,,50.48281479,,,,40,114.6129074,0,0,0,0.041046143,60.11730194,,,,,,,,,,,,,,,,
3772697780,114.0077972,2000.020752,2.05E-05,6.55E-07,1,0.999253354,40.02988815,1.989080953,10.20000037,0.000221582,4.53E-05,0.25,5.26E-07,2.06E-05,5.81E-07,114.0006485,114.0006485,2000.006958,2000.034546,44.41369572,17.55733659,50.48703003,0,0,0,40,114.8703384,2,4,1,1.95098877,63.04985428,,,,,,,,,,,,,,,,
3772697840,115.0002518,2000.011536,2.07E-05,4.65E-07,1,0.999253354,40.02988815,1.989045584,10.20999998,0.000223829,4.82E-05,0.25,7.46E-07,2.08E-05,8.02E-07,114.993042,114.993042,1999.979248,2000.043823,44.54500931,17.56207287,50.52853012,0,0,0,40,115.8698044,2,4,1,1.95602417,61.58358002,,,,,,,,,,,,,,,,
3772697901,116.0117455,2000.011475,2.05E-05,4.22E-07,1,0.999253354,40.02988815,1.989015012,10.20000037,0.000222547,3.99E-05,0.25,2.61E-08,2.06E-05,7.67E-08,116.0041962,116.0041962,1999.983765,2000.039185,44.89361563,17.56046244,50.5582695,0,0,0,40,116.894516,2,4,1,1.957092285,63.04985428,,,,,,,,,,,,,,,,
3772697961,117.0074425,2000.009216,2.15E-05,4.58E-07,1,0.999253354,40.02988815,1.98887243,10.20000037,0.000232485,4.75E-05,0.25,5.56E-07,2.16E-05,6.11E-07,116.9998016,116.9998016,1999.979248,2000.039185,43.94471861,17.55796575,50.59421921,0,0,0,40,117.902092,2,4,1,1.960296631,62.56109619,,,,,,,,,,,,,,,,
3772698021,118.0065079,2000.009277,2.09E-05,3.83E-07,1,0.999253354,40.02988815,1.989027379,10.20000037,0.000225642,5.01E-05,0.25,8.89E-07,2.10E-05,9.44E-07,117.9969711,117.9969711,1999.993164,2000.025391,44.2761291,17.56320413,50.61774445,0,0,0,40,118.9099045,2,4,1,1.958618164,63.53861237,,,,,,,,,,,,,,,,
3772698081,119.0059662,1999.992981,2.08E-05,4.84E-07,1,0.999253354,40.02988815,1.988900846,10.20000037,0.000225347,4.63E-05,0.25,5.62E-07,2.10E-05,6.14E-07,118.9979935,118.9979935,1999.983765,2000.002197,44.60910285,17.56239654,50.66057587,0,0,0,40,119.9138641,2,4,1,1.958465576,64.02737427,,,,,,,,,,,,,,,,
3772698231,120.1819916,1999.986145,2.06E-05,3.91E-07,1,0.999253354,40.02988815,1.989008664,10.20999998,0.000223793,3.94E-05,0.25,-3.07E-08,2.07E-05,1.69E-08,120.1850281,120.1850281,1999.983765,1999.988525,44.46293832,17.5656998,50.74668121,0,0,0,40,119.5297165,1,4,1,1.958312988,63.04985428,,,,,,,,,,,,,,,,
3772698491,120.1028175,2000.011536,2.12E-05,4.74E-07,1,0.999253354,40.02988815,1.989036744,10.18999983,0.000228882,4.81E-05,0.25,6.64E-07,2.13E-05,7.17E-07,120.1035614,120.1035614,1999.993164,2000.029907,44.46606483,17.56328263,50.77486801,0,0,0,40,119.5063553,1,4,1,1.950378418,63.04985428,,,,,,,,,,,,,,,,
3772698567,119.4917374,2000.011475,2.15E-05,6.22E-07,1,0.999253354,40.02988815,1.988945416,10.18999983,0.000233539,4.35E-05,0.25,1.84E-07,2.16E-05,2.35E-07,119.5000839,119.5000839,1999.983765,2000.039185,44.72243898,17.56961569,50.78130341,0,0,0,40,117.8343124,6,4,1,1.957397461,63.53861237,,,,,,,,,,,,,,,,
3772698627,118.4976387,2000.009216,2.05E-05,5.47E-07,1,0.999253354,40.02988815,1.988848793,10.20000037,0.000220149,5.16E-05,0.25,1.11E-06,2.06E-05,1.17E-06,118.5054092,118.5054092,1999.979248,2000.039185,44.53875628,17.5654431,50.76465988,0,0,0,40,116.6760559,2,4,1,1.958465576,63.04985428,,,,,,,,,,,,,,,,
3772698688,117.4881134,1999.995483,2.12E-05,5.65E-07,1,0.999253354,40.02988815,1.988919972,10.20000037,0.000229529,4.75E-05,0.25,6.02E-07,2.13E-05,6.56E-07,117.4963226,117.4963226,1999.970093,2000.020874,44.85297095,17.56098487,50.72582245,0,0,0,40,115.5893021,2,4,1,1.952514648,63.04985428,,,,,,,,,,,,,,,,
3772698747,116.4963493,2000.006958,2.05E-05,5.71E-07,1,0.999253354,40.02988815,1.98896681,10.18999983,0.000221164,4.71E-05,0.25,6.92E-07,2.06E-05,7.46E-07,116.5036545,116.5036545,1999.970093,2000.043823,44.45121389,17.56113958,50.69208908,0,0,0,40,114.5658112,2,4,1,1.957244873,64.51612854,,,,,,,,,,,,,,,,
3772698808,115.4928284,1999.979248,2.10E-05,6.84E-07,1,0.999253354,40.02988815,1.988877553,10.18999983,0.000227154,4.82E-05,0.25,6.93E-07,2.11E-05,7.49E-07,115.5018616,115.5018616,1999.974731,1999.983765,44.65756382,17.56470354,50.68254471,0,0,0,40,113.5367126,2,4,1,1.950531006,63.04985428,,,,,,,,,,,,,,,,
3772698867,114.4965057,2000.013794,2.06E-05,5.89E-07,1,0.999253354,40.02988815,1.9889714,10.20000037,0.000224022,3.98E-05,0.25,-5.84E-09,2.07E-05,4.60E-08,114.5042572,114.5042572,1999.983765,2000.043823,44.30426773,17.56561997,50.66123962,0,0,0,40,112.5310211,2,4,1,1.946411133,63.04985428,,,,,,,,,,,,,,,,
3772698927,113.494545,2000.011536,2.08E-05,4.24E-07,1,0.999253354,40.02988815,1.988799769,10.18999983,0.000225354,4.51E-05,0.25,4.45E-07,2.09E-05,5.00E-07,113.5045547,113.5045547,1999.974731,2000.04834,45.02492922,17.56568126,50.66168594,0,0,0,40,111.5275421,2,4,1,1.949462891,63.53861237,,,,,,,,,,,,,,,,
3772698998,112.3281555,1999.983765,,,2,,,,10.21199998,,,,,,,112.3281555,112.3281555,1999.983765,1999.983765,,,50.63993835,,,,40,110.3525314,0,0,0,0.038757324,60.11730194,,,,,,,,,,,,,,,,
3772699017,111.9936829,2000.011536,2.08E-05,5.23E-07,1,0.999253354,40.02988815,1.988998717,10.20999998,0.000225302,4.65E-05,0.25,5.77E-07,2.09E-05,6.34E-07,112.0013733,112.0013733,1999.974731,2000.04834,44.01115703,17.55884249,50.62950516,0,0,0,40,110.0382538,2,4,1,1.959991455,61.58358002,,,,,,,,,,,,,,,,
3772699077,110.9995422,2000.034546,2.09E-05,5.33E-07,1,0.999253354,40.02988815,1.98885451,10.20999998,0.000227576,3.91E-05,0.25,-1.23E-07,2.10E-05,-6.77E-08,111.0081711,111.0081711,2000.034546,2000.034546,44.25189862,17.56029574,50.62107468,0,0,0,40,109.0212326,2,4,1,1.957855225,62.56109619,,,,,,,,,,,,,,,,
3772699137,109.9988556,2000.018433,2.08E-05,4.92E-07,1,0.999253354,40.02988815,1.98897173,10.20999998,0.000225134,4.69E-05,0.25,6.13E-07,2.09E-05,6.73E-07,110.008873,110.008873,1999.988525,2000.04834,44.36992452,17.56442111,50.60886765,0,0,0,40,108.021019,2,4,1,1.94519043,63.53861237,,,,,,,,,,,,,,,,
3772699197,108.9989815,2000.041504,2.04E-05,6.03E-07,1,0.999253354,40.02988815,1.988847283,10.20000037,0.000221408,4.28E-05,0.25,3.03E-07,2.05E-05,3.60E-07,109.0102615,109.0102615,2000.039185,2000.043823,44.34882055,17.55704231,50.56692505,0,0,0,40,107.0236588,2,4,1,1.961517334,63.04985428,,,,,,,,,,,,,,,,
3772699257,107.9995689,2000.016052,2.09E-05,4.59E-07,1,0.999253354,40.02988815,1.988877743,10.20000037,0.000226927,4.44E-05,0.25,3.54E-07,2.11E-05,4.14E-07,108.0068588,108.0068588,1999.983765,2000.04834,44.64740265,17.55946259,50.52342606,0,0,0,40,106.0282745,2,4,1,1.950836182,62.56109619,,,,,,,,,,,,,,,,
3772699317,106.9991684,2000.011536,2.14E-05,5.49E-07,1,0.999253354,40.02988815,1.988858676,10.20000037,0.000232026,4.30E-05,0.25,1.53E-07,2.15E-05,2.14E-07,107.0085068,107.0085068,1999.993164,2000.029907,44.90846657,17.55120236,50.47815323,0,0,0,40,105.0317383,2,4,1,1.959533691,63.04985428,,,,,,,,,,,,,,,,
3772699377,105.9999428,2000.016174,2.07E-05,5.42E-07,1,0.999253354,40.02988815,1.988835334,10.20999998,0.000224313,4.45E-05,0.25,4.04E-07,2.08E-05,4.66E-07,106.0092163,106.0092163,1999.988525,2000.043823,44.50436463,17.56247696,50.42932892,0,0,0,40,104.031311,2,4,1,1.950531006,63.04985428,,,,,,,,,,,,,,,,
3772699437,104.9993095,2000.009277,2.07E-05,5.98E-07,1,0.999253354,40.02988815,1.989008384,10.20000037,0.000225039,4.22E-05,0.25,1.88E-07,2.09E-05,2.49E-07,105.0085983,105.0085983,1999.974731,2000.043823,44.67475965,17.56347818,50.38516617,0,0,0,40,103.0370789,2,4,1,1.959381104,63.04985428,,,,,,,,,,,,,,,,
3772699498,103.9855614,1999.986145,2.05E-05,6.02E-07,1,0.999253354,40.02988815,1.988875065,10.20999998,0.000221782,4.64E-05,0.25,6.08E-07,2.06E-05,6.72E-07,103.9924774,103.9924774,1999.983765,1999.988525,44.70211664,17.55747708,50.33012772,0,0,0,40,102.035759,2,4,1,1.957244873,63.04985428,,,,,,,,,,,,,,,,
3772699558,102.9860687,2000.002319,2.08E-05,5.68E-07,1,0.999253354,40.02988815,1.989025161,10.20000037,0.000223965,5.16E-05,0.25,1.04E-06,2.09E-05,1.11E-06,102.9925232,102.9925232,1999.970093,2000.034546,44.68570244,17.56429951,50.29062653,0,0,0,40,101.0378494,2,4,1,1.95098877,62.56109619,,,,,,,,,,,,,,,,
3772699614,102.0550766,1999.979248,,,2,,,,10.22200005,,,,,,,102.0550766,102.0550766,1999.979248,1999.979248,,,50.25756073,,,,40,100.1116028,0,0,0,0,60.11730194,,,,,,,,,,,,,,,,
3772699648,101.4902916,1999.997681,2.07E-05,3.96E-07,1,0.999253354,40.02988815,1.988837149,10.20999998,0.000223928,4.41E-05,0.25,3.74E-07,2.08E-05,4.40E-07,101.4978409,101.4978409,1999.979248,2000.016113,44.90065029,17.55412699,50.23980713,0,0,0,40,99.55600739,2,4,1,1.960449219,62.0723381,,,,,,,,,,,,,,,,
3772699708,100.4885483,2000.016052,2.04E-05,5.70E-07,1,0.999253354,40.02988815,1.988735244,10.20999998,0.000221939,4.04E-05,0.25,6.79E-08,2.06E-05,1.33E-07,100.4963379,100.4963379,1999.983765,2000.04834,44.20265602,17.5632113,50.19719696,0,0,0,40,98.55660248,2,4,1,1.956634521,62.56109619,,,,,,,,,,,,,,,,
3772699767,99.49882507,1999.972351,2.03E-05,6.00E-07,1,0.999253354,40.02988815,1.988942185,10.21999959,0.000220833,3.86E-05,0.25,-7.29E-08,2.04E-05,-8.14E-09,99.5089798,99.5089798,1999.965454,1999.979248,44.141689,17.56118578,50.16080093,0,0,0,40,97.58076477,2,4,1,1.960754395,62.0723381,,,,,,,,,,,,,,,,
3772699827,98.49904633,2000.013794,2.07E-05,4.95E-07,1,0.999253354,40.02988815,1.988655645,10.21999959,0.000223694,4.73E-05,0.25,6.55E-07,2.08E-05,7.26E-07,98.50595093,98.50595093,1999.983765,2000.043823,44.27847399,17.55771753,50.12706757,0,0,0,40,96.5851059,2,4,1,1.959228516,63.04985428,,,,,,,,,,,,,,,,
3772699887,97.49708939,2000.009155,2.07E-05,5.67E-07,1,0.999253354,40.02988815,1.98889006,10.21999959,0.000224564,4.47E-05,0.25,4.08E-07,2.09E-05,4.79E-07,97.50518036,97.50518036,1999.983765,2000.034546,44.40197129,17.56579621,50.10443115,0,0,0,40,95.59450531,2,4,1,1.954193115,63.04985428,,,,,,,,,,,,,,,,
3772699947,96.49359131,2000.016174,2.10E-05,4.86E-07,1,0.999253354,40.02988815,1.98882444,10.20999998,0.000227576,4.30E-05,0.25,2.04E-07,2.11E-05,2.76E-07,96.50440216,96.50440216,1999.979248,2000.053101,44.88579935,17.56382985,50.08623505,0,0,0,40,94.60459137,2,4,1,1.95022583,63.53861237,,,,,,,,,,,,,,,,
3772700007,95.49240875,2000.023132,2.10E-05,6.17E-07,1,0.999253354,40.02988815,1.988724641,10.21999959,0.000226382,4.97E-05,0.25,8.25E-07,2.11E-05,9.02E-07,95.50196838,95.50196838,1999.993164,2000.053101,44.14325225,17.5618022,50.05693817,0,0,0,40,93.61336517,2,4,1,1.957702637,63.53861237,,,,,,,,,,,,,,,,
3772700067,94.49161148,2000.011475,2.07E-05,5.85E-07,1,0.999253354,40.02988815,1.988771791,10.21999959,0.000222715,5.28E-05,0.25,1.16E-06,2.08E-05,1.24E-06,94.4980545,94.4980545,1999.983765,2000.039185,44.31911867,17.56361291,50.02453995,0,0,0,40,92.62280273,2,4,1,1.960449219,62.56109619,,,,,,,,,,,,,,,,
3772700127,93.48560715,1999.993103,2.07E-05,5.25E-07,1,0.999253354,40.02988815,1.98874052,10.20999998,0.000224115,4.57E-05,0.25,4.96E-07,2.08E-05,5.73E-07,93.4930954,93.4930954,1999.974731,2000.011475,43.8595211,17.56314518,49.96461868,0,0,0,40,91.63398743,2,4,1,1.959075928,63.53861237,,,,,,,,,,,,,,,,
3772700186,92.48513031,2000.009216,2.06E-05,5.01E-07,1,0.999253354,40.02988815,1.988728547,10.20999998,0.000222717,4.50E-05,0.25,4.57E-07,2.07E-05,5.35E-07,92.49449921,92.49449921,2000.006958,2000.011475,44.77168158,17.56336423,49.89337921,0,0,0,40,90.64539337,2,4,1,1.950531006,63.04985428,,,,,,,,,,,,,,,,
3772700225,91.83332443,1999.97699,2.06E-05,4.14E-07,1,0.999253354,40.02988815,1.988885558,10.21999959,0.000223494,4.19E-05,0.25,1.70E-07,2.07E-05,2.47E-07,92.06354523,92.06354523,1999.974731,1999.979248,44.34256752,17.55866014,49.82746887,0,0,0,40,89.79651642,2,4,1,1.957550049,61.09482193,,,,,,,,,,,,,,,,
3772700276,90.98791504,2000.013794,2.01E-05,5.20E-07,1,0.999253354,40.02988815,1.988871648,10.20999998,0.000217792,3.96E-05,0.25,5.28E-08,2.02E-05,1.28E-07,90.99491882,90.99491882,1999.983765,2000.043823,44.52703186,17.56068342,49.80239105,0,0,0,40,89.15785217,2,4,1,1.959381104,61.58358002,,,,,,,,,,,,,,,,
3772700336,89.98275375,2000.009216,2.05E-05,5.57E-07,1,0.999253354,40.02988815,1.988722789,10.21999959,0.000220648,5.27E-05,0.25,1.17E-06,2.06E-05,1.26E-06,89.99000549,89.99000549,1999.979248,2000.039185,44.33787775,17.5613832,49.74025345,0,0,0,40,88.18083954,2,4,1,1.959075928,63.04985428,,,,,,,,,,,,,,,,
3772700395,88.99671936,1999.981506,2.08E-05,5.23E-07,1,0.999253354,40.02988815,1.988758232,10.21999959,0.000225689,4.45E-05,0.25,3.63E-07,2.10E-05,4.47E-07,89.00535583,89.00535583,1999.979248,1999.983765,44.31911867,17.55881583,49.6896553,0,0,0,40,87.21078491,2,4,1,1.951904297,62.56109619,,,,,,,,,,,,,,,,
3772700455,87.99322891,1999.986145,2.06E-05,5.38E-07,1,0.999253354,40.02988815,1.98861182,10.21999959,0.000222389,4.62E-05,0.25,5.67E-07,2.07E-05,6.52E-07,88.00222778,88.00222778,1999.983765,1999.988525,44.60988448,17.55952202,49.63838959,0,0,0,40,86.2133255,2,4,1,1.945953369,62.56109619,,,,,,,,,,,,,,,,
3772700515,86.9890213,2000.007019,2.06E-05,5.29E-07,1,0.999253354,40.02988815,1.98865544,10.20999998,0.000221867,5.10E-05,0.25,9.98E-07,2.07E-05,1.09E-06,86.99829102,86.99829102,1999.993164,2000.020874,44.22454162,17.56354998,49.59466934,0,0,0,40,85.2250824,2,4,1,1.959991455,62.56109619,,,,,,,,,,,,,,,,
3772700575,85.9924202,2000.020691,2.06E-05,4.28E-07,1,0.999253354,40.02988815,1.98869343,10.20999998,0.000222658,4.52E-05,0.25,4.71E-07,2.07E-05,5.59E-07,85.99941254,85.99941254,1999.983765,2000.057617,44.39728152,17.56350254,49.53120041,0,0,0,40,84.24772644,2,4,1,1.949005127,63.53861237,,,,,,,,,,,,,,,,
3772700635,84.98427582,1999.979248,2.08E-05,5.11E-07,1,0.999253354,40.02988815,1.988604492,10.20999998,0.000224262,4.76E-05,0.25,6.50E-07,2.09E-05,7.42E-07,84.99246216,84.99246216,1999.974731,1999.983765,44.2980147,17.56015263,49.49103165,0,0,0,40,83.2599411,2,4,1,1.9581604,63.53861237,,,,,,,,,,,,,,,,
3772700694,83.9994278,1999.988464,2.06E-05,4.05E-07,1,0.999253354,40.02988815,1.988524619,10.20999998,0.000223195,4.29E-05,0.25,2.49E-07,2.07E-05,3.39E-07,84.00807953,84.00807953,1999.983765,1999.993164,44.45355877,17.56207882,49.43998718,0,0,0,40,82.29008484,2,4,1,1.959838867,63.04985428,,,,,,,,,,,,,,,,
3772700754,82.99816132,1999.981628,2.06E-05,3.98E-07,1,0.999253354,40.02988815,1.988620171,10.21999959,0.000222465,4.55E-05,0.25,4.91E-07,2.07E-05,5.84E-07,83.00706482,83.00706482,1999.974731,1999.988525,44.53484814,17.56226306,49.38872528,0,0,0,40,81.30528259,2,4,1,1.94442749,63.53861237,,,,,,,,,,,,,,,,
3772700814,81.99397659,2000.011475,2.09E-05,4.87E-07,1,0.999253354,40.02988815,1.988702186,10.20999998,0.00022554,4.88E-05,0.25,7.37E-07,2.10E-05,8.35E-07,82.00202942,82.00202942,1999.983765,2000.039185,44.02209983,17.56177279,49.31482315,0,0,0,40,80.32019806,2,4,1,1.96105957,66.95992279,,,,,,,,,,,,,,,,
3772700854,81.31782913,2000.016174,2.07E-05,4.27E-07,1,0.999253354,40.02988815,1.975466267,10.21999959,0.000220848,5.31E-05,0.25,1.20E-06,2.08E-05,1.30E-06,81.32447815,81.32447815,1999.993164,2000.039185,44.26049653,17.55818544,49.26910782,0,0,0,40,79.67306519,2,4,1,1.925964355,61.09482193,,,,,,,,,,,,,,,,
3772700904,80.48976135,1999.986145,2.01E-05,8.07E-07,1,0.999253354,40.02988815,1.97528068,10.21999959,0.000199974,0.00013064,0.25,8.50E-06,2.01E-05,8.63E-06,80.49676514,80.49676514,1999.983765,1999.988525,44.47309949,17.55929398,49.21362305,0,0,0,40,78.84343719,2,4,1,1.938171387,62.56109619,,,,,,,,,,,,,,,,
3772700964,79.48447418,1999.97699,2.60E-05,1.74E-06,1,0.999253354,40.02988815,1.975304672,10.21999959,0.000258196,0.000174838,0.25,1.15E-05,2.61E-05,1.17E-05,79.4938736,79.4938736,1999.974731,1999.979248,44.67710453,17.5615962,49.14105606,0,0,0,40,77.85887909,2,4,1,1.935882568,63.04985428,,,,,,,,,,,,,,,,
3772701023,78.49401093,1999.983887,8.26E-06,3.45E-06,1,0.999253354,40.02988815,1.975599462,10.21999959,3.78E-05,0.00030079,0.25,2.64E-05,8.18E-06,2.66E-05,78.50340271,78.50340271,1999.979248,1999.988525,44.23313953,17.54602509,49.06071854,0,0,0,40,76.88882446,2,4,1,1.944732666,63.04985428,,,,,,,,,,,,,,,,
3772701083,77.49334717,2000.018433,-3.03E-06,4.28E-07,1,0.999253354,40.02988815,1.975594465,10.21999959,-9.08E-05,0.000316496,0.25,2.99E-05,-3.19E-06,3.00E-05,77.5004425,77.5004425,1999.988525,2000.04834,44.28238213,17.5458878,48.98659515,0,0,0,40,75.91426849,2,4,1,1.926879883,63.53861237,,,,,,,,,,,,,,,,
3772701143,76.4901886,2000.002319,-3.48E-05,1.46E-06,1,0.999253354,40.02988815,1.975407455,10.21999959,-0.000421543,0.000188665,0.25,2.38E-05,-3.51E-05,2.37E-05,76.49697113,76.49697113,1999.988525,2000.016113,44.46059343,17.54372265,48.89671707,0,0,0,40,74.93212128,2,4,1,1.952362061,63.04985428,,,,,,,,,,,,,,,,
3772701203,75.48389435,2000.016174,-3.31E-05,2.87E-06,1,0.999253354,40.02988815,1.975445105,10.21999959,-0.000402056,0.000187269,0.25,2.33E-05,-3.33E-05,2.33E-05,75.49307251,75.49307251,1999.979248,2000.053101,44.68961059,17.55820557,48.8185997,0,0,0,40,73.95094299,2,4,1,1.940002441,63.04985428,,,,,,,,,,,,,,,,
3772701262,74.49596786,1999.983948,-4.11E-05,3.29E-06,1,0.999253354,40.02988815,1.975352128,10.21999959,-0.000495414,0.000212083,0.25,2.71E-05,-4.14E-05,2.70E-05,74.50508118,74.50508118,1999.974731,1999.993164,44.2651863,17.5583934,48.73937225,0,0,0,40,72.98334503,2,4,1,1.941375732,63.04985428,,,,,,,,,,,,,,,,
3772701322,73.48760605,1999.981506,-2.81E-05,3.19E-06,1,0.999253354,40.02988815,1.975209598,10.21999959,-0.000355897,0.000241682,0.25,2.75E-05,-2.83E-05,2.75E-05,73.49699402,73.49699402,1999.979248,1999.983765,44.46840972,17.55993012,48.67456818,0,0,0,40,72.0016861,2,4,1,1.925811768,62.56109619,,,,,,,,,,,,,,,,
3772701381,72.49894333,1999.974731,-2.37E-06,6.85E-07,1,0.999253354,40.02988815,1.975240499,10.21999959,-8.90E-05,0.000345764,0.25,3.25E-05,-2.56E-06,3.26E-05,72.50756836,72.50756836,1999.974731,1999.974731,44.58252748,17.55752474,48.59556198,0,0,0,40,71.03909302,2,4,1,1.935882568,63.04985428,,,,,,,,,,,,,,,,
3772701455,71.25081635,2000.006958,,,2,,,,10.25199981,,,,,,,71.25081635,71.25081635,2000.006958,2000.006958,,,48.50723648,,,,40,69.80912781,0,0,0,0.029296875,60.60606384,,,,,,,,,,,,,,,,
3772701470,70.99024582,1999.97699,-4.12E-05,3.81E-06,1,0.999253354,40.02988815,2.00120259,10.23999974,-0.000521466,0.000318484,0.25,3.67E-05,-4.15E-05,3.66E-05,70.99936676,70.99936676,1999.974731,1999.979248,44.55126234,17.5586239,48.47639084,0,0,0,40,69.58283997,2,4,1,1.966552734,61.09482193,,,,,,,,,,,,,,,,
3772701530,69.98704147,2000.02533,-6.59E-05,4.86E-06,1,0.999253354,40.02988815,2.001168639,10.25000028,-0.000764191,0.000117975,0.25,2.28E-05,-6.63E-05,2.25E-05,69.99584961,69.99584961,2000.011475,2000.039185,44.46450157,17.55989627,48.3996048,0,0,0,40,68.5868454,2,4,1,1.965026855,62.56109619,,,,,,,,,,,,,,,,
3772701589,68.99766922,2000.041504,-3.03E-05,5.37E-06,1,0.999253354,40.02988815,2.001134394,10.25000028,-0.000394974,0.000298522,0.25,3.29E-05,-3.06E-05,3.28E-05,69.00645447,69.00645447,2000.039185,2000.043823,44.54891745,17.56551932,48.34257126,0,0,0,40,67.62162018,2,4,1,1.97555542,64.02737427,,,,,,,,,,,,,,,,
3772701649,67.98675537,1999.983887,-5.41E-05,5.50E-06,1,0.999253354,40.02988815,2.001225701,10.25000028,-0.000638984,0.000164811,0.25,2.49E-05,-5.44E-05,2.47E-05,67.99237823,67.99237823,1999.979248,1999.988525,44.69977176,17.56279624,48.27355194,0,0,0,40,66.64486694,2,4,1,1.958007813,59.13978577,,,,,,,,,,,,,,,,
3772701709,66.98647308,1999.983887,-7.07E-05,5.92E-06,1,0.999253354,40.02988815,2.000958455,10.23999974,-0.000864589,0.000380023,0.25,4.77E-05,-7.12E-05,4.74E-05,66.99551392,66.99551392,1999.979248,1999.988525,44.78496927,17.56655913,48.19166183,0,0,0,40,65.6712265,2,4,1,1.957397461,63.53861237,,,,,,,,,,,,,,,,
3772701768,65.99464035,2000.013794,-0.0001217,5.34E-06,1,0.999253354,40.02988815,2.001052936,10.23999974,-0.001366492,-1.92E-05,0.25,2.04E-05,-0.000122223,1.97E-05,66.00453949,66.00453949,1999.979248,2000.04834,44.29332493,17.55967727,48.10266876,0,0,0,40,64.7051239,2,4,1,1.969909668,63.53861237,,,,,,,,,,,,,,,,
3772701828,64.98905563,2000.02301,-0.000162499,4.91E-06,1,0.999253354,40.02988815,2.001041609,10.25000028,-0.001739951,-0.000489435,0.25,-1.54E-05,-0.000162897,-1.65E-05,64.99976349,64.99976349,1999.997681,2000.04834,44.27769236,17.56158251,48.01323318,0,0,0,40,63.73218918,2,4,1,1.968231201,63.04985428,,,,,,,,,,,,,,,,
3772701887,63.99757385,2000.011536,-0.000164682,4.79E-06,1,0.999253354,40.02988815,2.001020269,10.23999974,-0.001805164,-0.000263975,0.25,5.73E-06,-0.000165192,4.67E-06,64.00537109,64.00537109,1999.988525,2000.034546,44.48326066,17.56080565,47.91780472,0,0,0,40,62.76224899,2,4,1,1.961517334,63.53861237,,,,,,,,,,,,,,,,
3772701947,62.99006462,2000.009277,-0.000133649,6.33E-06,1,0.999253354,40.02988815,2.000988034,10.23999974,-0.001481437,-0.000122149,0.25,1.31E-05,-0.000134092,1.23E-05,62.99704742,62.99704742,1999.965454,2000.053101,44.25346187,17.56169029,47.81017303,0,0,0,40,61.79109573,2,4,1,1.96105957,63.04985428,,,,,,,,,,,,,,,,
3772702006,61.99851799,1999.979248,-8.60E-05,4.90E-06,1,0.999253354,40.02988815,2.000966661,10.25000028,-0.001035023,0.000372083,0.25,4.98E-05,-8.65E-05,4.94E-05,62.00614548,62.00614548,1999.974731,1999.983765,44.5364114,17.56761795,47.69343948,0,0,0,40,60.82966232,2,4,1,1.967010498,63.53861237,,,,,,,,,,,,,,,,
3772702067,60.97384644,1999.993164,,,2,,,,10.25199981,,,,,,,60.97384644,60.97384644,1999.993164,1999.993164,,,47.58780289,,,,40,59.82619095,0,0,0,0,60.11730194,,,,,,,,,,,,,,,,
3772702096,60.49145508,2000.013794,-0.000124464,7.54E-06,1,0.999253354,40.02988815,2.001074426,10.23999974,-0.001400938,6.89E-06,0.25,2.33E-05,-0.000124887,2.25E-05,60.50170898,60.50170898,1999.983765,2000.043823,44.19483973,17.56215331,47.51523209,0,0,0,40,59.34805298,2,4,1,1.968231201,62.56109619,,,,,,,,,,,,,,,,
3772702155,59.49537849,1999.979248,-0.000127661,5.59E-06,1,0.999253354,40.02988815,2.001106943,10.23999974,-0.001424943,-5.70E-05,0.25,1.81E-05,-0.000128025,1.72E-05,59.50486755,59.50486755,1999.974731,1999.983765,44.41994875,17.56073989,47.41469955,0,0,0,40,58.40652466,2,4,1,1.968231201,63.04985428,,,,,,,,,,,,,,,,
3772702215,58.48727798,2000,-7.90E-05,1.03E-05,1,0.999253354,40.02988815,2.001188401,10.23999974,-0.000896574,4.80E-05,0.25,1.88E-05,-7.92E-05,1.83E-05,58.4954071,58.4954071,1999.970093,2000.029907,44.20421928,17.56498688,47.29419708,0,0,0,40,57.4162178,2,4,1,1.972351074,62.56109619,,,,,,,,,,,,,,,,
3772702274,57.49375153,1999.986206,-0.000121772,5.70E-06,1,0.999253354,40.02988815,2.001017328,10.23999974,-0.001429039,0.000331969,0.25,5.28E-05,-0.000122315,5.20E-05,57.50183868,57.50183868,1999.979248,1999.993164,44.62708031,17.56680598,47.19078064,0,0,0,40,56.45373917,2,4,1,1.96975708,63.04985428,,,,,,,,,,,,,,,,
3772702334,56.48609161,2000.016052,-0.000118282,4.34E-06,1,0.999253354,40.02988815,2.00103967,10.23999974,-0.001348747,0.000108845,0.25,3.16E-05,-0.000118638,3.08E-05,56.49332428,56.49332428,1999.983765,2000.04834,44.6489659,17.56665536,47.04674911,0,0,0,40,55.47402573,2,4,1,1.969451904,63.04985428,,,,,,,,,,,,,,,,
3772702393,55.49674034,2000.006836,-0.000134651,4.50E-06,1,0.999253354,40.02988815,2.001023066,10.25000028,-0.001521124,4.81E-05,0.25,2.90E-05,-0.00013497,2.81E-05,55.50366211,55.50366211,1999.983765,2000.029907,44.4543404,17.56775467,46.91270828,0,0,0,40,54.520504,2,4,1,1.971282959,63.04985428,,,,,,,,,,,,,,,,
3772702452,54.49936867,1999.981506,-0.000162046,5.98E-06,1,0.999253354,40.02988815,2.000784318,10.25000028,-0.001830609,6.18E-05,0.25,3.53E-05,-0.000162387,3.41E-05,54.50788498,54.50788498,1999.979248,1999.983765,44.36679801,17.57510074,46.7216301,0,0,0,40,53.55207062,2,4,1,1.973114014,63.53861237,,,,,,,,,,,,,,,,
3772702512,53.49077034,1999.995361,-0.000185903,5.73E-06,1,0.999253354,40.02988815,2.000966773,10.23999974,-0.002076324,-5.69E-05,0.25,2.88E-05,-0.000186153,2.74E-05,53.4980278,53.4980278,1999.983765,2000.006958,44.80060184,17.56847624,46.49193573,0,0,0,40,52.59376526,2,4,1,1.971893311,63.04985428,,,,,,,,,,,,,,,,
3772702571,52.49903107,2000.043762,-0.000159781,3.48E-06,1,0.999253354,40.02988815,2.00113744,10.23999974,-0.001821933,0.000157514,0.25,4.37E-05,-0.000160089,4.25E-05,52.50959396,52.50959396,2000.039185,2000.04834,44.476226,17.57017094,46.21097946,0,0,0,40,51.63443756,2,4,1,1.968231201,62.56109619,,,,,,,,,,,,,,,,
3772702631,51.48945618,2000.006958,-0.000172694,6.61E-06,1,0.999253354,40.02988815,2.000886418,10.23999974,-0.001934063,-1.72E-05,0.25,3.00E-05,-0.000172846,2.87E-05,51.4969635,51.4969635,1999.970093,2000.043823,44.37539592,17.56924951,45.89873123,0,0,0,40,50.6574707,2,4,1,1.96105957,62.0723381,,,,,,,,,,,,,,,,
3772702677,50.69827271,1999.997681,,,2,,,,10.27199997,,,,,,,50.69827271,50.69827271,1999.997681,1999.997681,,,45.60468292,,,,40,49.88938141,0,0,0,0.043487549,60.11730194,,,,,,,,,,,,,,,,
3772702823,50.22151947,2000.004578,-0.000223566,6.86E-06,1,0.999253354,40.02988815,1.988655507,10.27000044,-0.00244221,-0.000274188,0.25,1.55E-05,-0.0002235,1.38E-05,50.22124481,50.22124481,1999.979248,2000.029907,44.35976335,17.56660612,45.31839752,0,0,0,40,49.91102219,1,4,1,1.952819824,62.56109619,,,,,,,,,,,,,,,,