File: Data/DyBCO/DyBCO_MVF_90K_-5000-5000Oe_Continuous.csv
Time Stamp (sec),Temperature (K),Magnetic Field (Oe),Moment (emu),M. Std. Err. (emu),Transport Action,Averaging Time (sec),Frequency (Hz),Peak Amplitude (mm),Center Position (mm),Coil Signal' (mV),"Coil Signal"" (mV)",Range (mV),M. Quad. Signal (emu),M. Raw' (emu),"M. Raw"" (emu)",Min. Temperature (K),Max. Temperature (K),Min. Field (Oe),Max. Field (Oe),Mass (grams),Motor Lag (deg),Pressure (Torr),VSM Status (code),Motor Status (code),Measure Status (code),Measure Count,System Temp. (K),Temp. Status (code),Field Status (code),Chamber Status (code),Motor Current (amps),Motor Heatsink Temp. (C),Map 01,Map 02,Map 03,Map 04,Map 05,Map 06,Map 07,Map 08,Map 09,Map 10,Map 11,Map 12,Map 13,Map 14,Map 15,Map 16
3772711977,90.08171082,0.006266713,,,2,,,,10.25199981,,,,,,,90.08171082,90.08171082,0.006266713,0.006266713,,,50.68986893,,,,40,89.52541351,0,0,0,0.041046143,46.43206406,,,,,,,,,,,,,,,,
3772711999,90.06794357,71.29020119,7.59E-07,6.67E-07,1,0.999253354,40.02988815,1.988190268,10.23999974,8.13E-06,2.06E-06,0.25,5.39E-08,7.62E-07,5.71E-08,90.06822205,90.06822205,58.08861923,84.49178314,43.37334816,17.53240711,50.69031525,0,0,0,40,89.53356934,1,6,1,1.959686279,48.87585831,,,,,,,,,,,,,,,,
3772712004,90.06691742,198.5092392,1.77E-06,1.39E-06,1,0.999253354,40.02988815,1.988204456,10.25000028,1.87E-05,6.22E-06,0.25,2.57E-07,1.77E-06,2.65E-07,90.06728363,90.06728363,185.2938232,211.7246552,43.32957696,17.53944748,50.68964767,0,0,0,40,89.53450775,1,6,1,1.947784424,50.34213257,,,,,,,,,,,,,,,,
3772712009,90.0654335,321.1019592,2.93E-06,6.00E-07,1,0.999253354,40.02988815,1.988294438,10.23999974,3.26E-05,1.22E-06,0.25,-4.12E-07,2.94E-06,-4.03E-07,90.06573486,90.06573486,309.6191101,332.5848083,43.83607224,17.53933048,50.70074463,0,0,0,40,89.53468323,1,6,1,1.949462891,50.34213257,,,,,,,,,,,,,,,,
3772712013,90.06246948,443.6600952,3.42E-06,1.16E-06,1,0.999253354,40.02988815,1.988282214,10.23999974,3.64E-05,1.07E-05,0.25,3.76E-07,3.44E-06,3.91E-07,90.06233978,90.06233978,432.4421997,454.8779907,43.83529062,17.53847809,50.70096588,0,0,0,40,89.53570557,1,6,1,1.952209473,50.34213257,,,,,,,,,,,,,,,,
3772712019,90.06098557,571.309967,5.02E-06,1.04E-06,1,0.999253354,40.02988815,1.988204573,10.23999974,5.37E-05,1.45E-05,0.25,4.34E-07,5.04E-06,4.56E-07,90.06126404,90.06126404,558.3110962,584.3088379,43.62815906,17.53836376,50.70118713,0,0,0,40,89.5377121,1,6,1,1.951141357,50.83089066,,,,,,,,,,,,,,,,
3772712023,90.0590744,691.5365295,6.38E-06,9.93E-07,1,0.999253354,40.02988815,1.988259381,10.23999974,6.78E-05,2.02E-05,0.25,7.20E-07,6.41E-06,7.48E-07,90.0590744,90.0590744,678.6690063,704.4040527,43.51169641,17.53647577,50.69675064,0,0,0,40,89.53886414,1,6,1,1.955566406,50.83089066,,,,,,,,,,,,,,,,
3772712028,90.05862808,818.1680298,7.20E-06,6.81E-07,1,0.999253354,40.02988815,1.988188958,10.25000028,7.89E-05,1.04E-05,0.25,-3.30E-07,7.24E-06,-3.04E-07,90.05847931,90.05847931,805.1876221,831.1484375,43.72117285,17.53997234,50.70806885,0,0,0,40,89.53988647,1,6,1,1.949310303,51.80840683,,,,,,,,,,,,,,,,
3772712034,90.05819702,943.9309998,8.65E-06,5.63E-07,1,0.999253354,40.02988815,1.988193199,10.25000028,9.41E-05,1.59E-05,0.25,-8.25E-08,8.69E-06,-4.99E-08,90.05843353,90.05843353,932.4158936,955.446106,43.86577413,17.53980041,50.70962143,0,0,0,40,89.53993225,1,6,1,1.947784424,51.80840683,,,,,,,,,,,,,,,,
3772712038,90.05688477,1066.57666,1.04E-05,9.19E-07,1,0.999253354,40.02988815,1.988128426,10.23999974,0.00011385,1.52E-05,0.25,-4.63E-07,1.05E-05,-4.25E-07,90.05722809,90.05722809,1055.266602,1077.886719,43.82278456,17.53896721,50.71317291,0,0,0,40,89.54074097,1,6,1,1.958465576,52.78592682,,,,,,,,,,,,,,,,
3772712043,90.05692673,1188.40918,1.16E-05,5.36E-07,1,0.999253354,40.02988815,1.98804149,10.23999974,0.000126388,2.06E-05,0.25,-1.79E-07,1.17E-05,-1.35E-07,90.05675507,90.05675507,1175.292847,1201.525513,43.65238954,17.53590734,50.71783066,0,0,0,40,89.54151154,1,6,1,1.96182251,51.80840683,,,,,,,,,,,,,,,,
3772712048,90.05682373,1317.215576,1.25E-05,4.82E-07,1,0.999253354,40.02988815,1.988126305,10.23999974,0.000135664,2.56E-05,0.25,1.13E-07,1.26E-05,1.62E-07,90.05680084,90.05680084,1304.018555,1330.412598,43.95409815,17.53856859,50.72249222,0,0,0,40,89.54121399,1,6,1,1.949462891,52.78592682,,,,,,,,,,,,,,,,
3772712053,90.05570602,1439.379639,1.32E-05,6.55E-07,1,0.999253354,40.02988815,1.988133859,10.23999974,0.000142566,3.02E-05,0.25,4.18E-07,1.33E-05,4.71E-07,90.05581665,90.05581665,1427.869141,1450.890137,43.53670852,17.53896097,50.73381042,0,0,0,40,89.54198456,1,6,1,1.948852539,52.78592682,,,,,,,,,,,,,,,,
3772712059,90.05484772,1565.223328,1.54E-05,6.22E-07,1,0.999253354,40.02988815,1.988135412,10.23999974,0.000166769,3.19E-05,0.25,1.76E-07,1.55E-05,2.36E-07,90.05513,90.05513,1550.724609,1579.722046,43.83998039,17.54200937,50.7349205,0,0,0,40,89.54151154,1,6,1,1.937255859,53.27468491,,,,,,,,,,,,,,,,
3772712064,90.05463028,1687.783813,1.62E-05,5.90E-07,1,0.999253354,40.02988815,1.988146517,10.25000028,0.000175489,3.40E-05,0.25,2.30E-07,1.63E-05,2.94E-07,90.05469513,90.05469513,1679.984985,1695.582642,43.86733738,17.54204152,50.74423981,0,0,0,40,89.54180908,1,6,1,1.951599121,52.78592682,,,,,,,,,,,,,,,,
3772712068,90.05360413,1812.4823,1.83E-05,6.54E-07,1,0.999253354,40.02988815,1.988119166,10.25000028,0.000197181,4.22E-05,0.25,6.13E-07,1.84E-05,6.86E-07,90.05371094,90.05371094,1799.471924,1825.492676,43.47495987,17.53977577,50.73358917,0,0,0,40,89.54317474,1,6,1,1.964874268,54.74095917,,,,,,,,,,,,,,,,
3772712074,90.05422211,1939.811951,1.94E-05,8.71E-07,1,0.999253354,40.02988815,1.988129594,10.23999974,0.000209384,4.30E-05,0.25,4.89E-07,1.95E-05,5.65E-07,90.05435181,90.05435181,1928.50647,1951.117432,43.96035118,17.54109136,50.72271347,0,0,0,40,89.54309082,1,6,1,1.963806152,54.25220108,,,,,,,,,,,,,,,,
3772712078,90.0537529,2062.30542,2.15E-05,9.70E-07,1,0.999253354,40.02988815,1.988122918,10.23999974,0.000233019,4.67E-05,0.25,4.43E-07,2.17E-05,5.27E-07,90.05387878,90.05387878,2049.306641,2075.304199,44.10182594,17.54186197,50.73025894,0,0,0,40,89.54373169,1,6,1,1.96105957,54.25220108,,,,,,,,,,,,,,,,
3772712083,90.05317307,2182.914551,2.25E-05,8.11E-07,1,0.999253354,40.02988815,1.988094287,10.23999974,0.000243296,5.17E-05,0.25,7.21E-07,2.27E-05,8.11E-07,90.05319214,90.05319214,2170.102295,2195.726807,43.71491982,17.54094999,50.73270035,0,0,0,40,89.54407501,1,6,1,1.951904297,53.76344299,,,,,,,,,,,,,,,,
3772712089,90.05323792,2314.232422,2.40E-05,6.60E-07,1,0.999253354,40.02988815,1.988203128,10.23999974,0.000259075,5.39E-05,0.25,6.69E-07,2.41E-05,7.64E-07,90.05319214,90.05319214,2302.629883,2325.834961,43.96425932,17.54430728,50.73669434,0,0,0,40,89.54407501,1,6,1,1.947479248,54.25220108,,,,,,,,,,,,,,,,
3772712093,90.05431366,2434.470459,2.53E-05,1.28E-06,1,0.999253354,40.02988815,1.988165011,10.23999974,0.000273108,5.75E-05,0.25,7.61E-07,2.54E-05,8.62E-07,90.05418396,90.05418396,2423.070557,2445.870361,44.11120548,17.54148213,50.7413559,0,0,0,40,89.54454041,1,6,1,1.94229126,54.25220108,,,,,,,,,,,,,,,,
3772712098,90.05459213,2559.724121,2.67E-05,6.30E-07,1,0.999253354,40.02988815,1.988033699,10.23999974,0.000289399,5.28E-05,0.25,8.04E-08,2.68E-05,1.83E-07,90.05487061,90.05487061,2548.321777,2571.126465,44.41135083,17.53820683,50.73891449,0,0,0,40,89.54522705,1,6,1,1.951904297,55.71847534,,,,,,,,,,,,,,,,
3772712103,90.05437851,2683.512695,2.84E-05,6.89E-07,1,0.999253354,40.02988815,1.988128331,10.23999974,0.000307445,5.99E-05,0.25,4.30E-07,2.85E-05,5.41E-07,90.05444336,90.05444336,2672.006836,2695.018555,44.18702345,17.54450955,50.73647308,0,0,0,40,89.5449295,1,6,1,1.951446533,55.22971725,,,,,,,,,,,,,,,,
3772712108,90.05473709,2809.416016,3.00E-05,6.19E-07,1,0.999253354,40.02988815,1.988155653,10.23999974,0.000325275,5.99E-05,0.25,1.47E-07,3.01E-05,2.62E-07,90.05490875,90.05490875,2797.912354,2820.919678,43.83450899,17.54323916,50.74290848,0,0,0,40,89.54471588,1,6,1,1.959533691,54.74095917,,,,,,,,,,,,,,,,
3772712113,90.05407333,2932.05481,3.17E-05,8.37E-07,1,0.999253354,40.02988815,1.988138458,10.23999974,0.000341958,7.45E-05,0.25,1.18E-06,3.19E-05,1.30E-06,90.05426788,90.05426788,2922.73999,2941.369629,44.19562136,17.54202486,50.74224472,0,0,0,40,89.54454041,1,6,1,1.952514648,54.25220108,,,,,,,,,,,,,,,,
3772712118,90.05358124,3059.03186,3.25E-05,9.72E-07,1,0.999253354,40.02988815,1.988033625,10.23999974,0.000351236,7.41E-05,0.25,1.00E-06,3.27E-05,1.13E-06,90.05366516,90.05366516,3046.217285,3071.846436,43.70788517,17.54081079,50.74446487,0,0,0,40,89.54522705,1,6,1,1.958007813,55.71847534,,,,,,,,,,,,,,,,
3772712123,90.05503845,3184.96521,3.47E-05,6.66E-07,1,0.999253354,40.02988815,1.988045888,10.23999974,0.000375703,7.18E-05,0.25,4.05E-07,3.49E-05,5.39E-07,90.05490875,90.05490875,3168.860596,3201.069824,43.84076202,17.54246464,50.74668121,0,0,0,40,89.54531097,1,6,1,1.953582764,55.71847534,,,,,,,,,,,,,,,,
3772712128,90.05574799,3305.247192,3.56E-05,9.56E-07,1,0.999253354,40.02988815,1.988162933,10.23999974,0.000385983,7.18E-05,0.25,2.39E-07,3.58E-05,3.76E-07,90.05590057,90.05590057,3292.347412,3318.146973,44.06743429,17.54522476,50.75600433,0,0,0,40,89.54514313,1,6,1,1.948699951,54.25220108,,,,,,,,,,,,,,,,
3772712133,90.0549736,3433.512207,3.73E-05,6.44E-07,1,0.999253354,40.02988815,1.988202769,10.23999974,0.000404522,7.36E-05,0.25,1.01E-07,3.75E-05,2.44E-07,90.05503845,90.05503845,3425.3125,3441.711914,43.8157499,17.54381875,50.76488113,0,0,0,40,89.54633331,1,6,1,1.946411133,55.22971725,,,,,,,,,,,,,,,,
3772712138,90.05516815,3554.773193,3.91E-05,1.04E-06,1,0.999253354,40.02988815,1.988122726,10.23999974,0.000424119,8.10E-05,0.25,4.45E-07,3.93E-05,5.96E-07,90.05516815,90.05516815,3538.551025,3570.995361,43.94706349,17.54295004,50.76776505,0,0,0,40,89.54642487,1,6,1,1.950531006,54.74095917,,,,,,,,,,,,,,,,
3772712143,90.05519104,3678.644531,4.00E-05,1.04E-06,1,0.999253354,40.02988815,1.988033866,10.23999974,0.000433579,8.45E-05,0.25,6.12E-07,4.03E-05,7.68E-07,90.05525208,90.05525208,3664.249512,3693.039551,44.07134243,17.54500455,50.77109528,0,0,0,40,89.54616547,1,6,1,1.946563721,55.71847534,,,,,,,,,,,,,,,,
3772712148,90.05566025,3805.020264,4.21E-05,5.97E-07,1,0.999253354,40.02988815,1.988156605,10.23999974,0.00045624,8.64E-05,0.25,4.15E-07,4.23E-05,5.77E-07,90.0555954,90.0555954,3793.505127,3816.5354,43.95097164,17.54437445,50.76066208,0,0,0,40,89.54663849,1,6,1,1.953125,55.22971725,,,,,,,,,,,,,,,,
3772712153,90.05615616,3929.557495,4.39E-05,1.10E-06,1,0.999253354,40.02988815,1.98807109,10.23999974,0.000476713,8.80E-05,0.25,2.31E-07,4.42E-05,4.00E-07,90.05619812,90.05619812,3918.13916,3940.97583,44.05570986,17.54020287,50.75578308,0,0,0,40,89.545784,1,6,1,1.949157715,55.22971725,,,,,,,,,,,,,,,,
3772712158,90.05602646,4052.534912,4.46E-05,6.58E-07,1,0.999253354,40.02988815,1.988108757,10.23999974,0.000483289,9.15E-05,0.25,4.41E-07,4.48E-05,6.13E-07,90.05619812,90.05619812,4037.815186,4067.254639,43.87749856,17.53922564,50.76088715,0,0,0,40,89.54611969,1,6,1,1.953887939,55.71847534,,,,,,,,,,,,,,,,
3772712163,90.05604935,4172.512939,4.59E-05,7.91E-07,1,0.999253354,40.02988815,1.988128362,10.23999974,0.000498641,9.02E-05,0.25,7.41E-08,4.62E-05,2.50E-07,90.05615997,90.05615997,4159.523438,4185.502441,44.38555709,17.54347519,50.754673,0,0,0,40,89.54642487,1,6,1,1.951141357,56.20723343,,,,,,,,,,,,,,,,
3772712168,90.05688858,4301.867432,4.81E-05,7.64E-07,1,0.999253354,40.02988815,1.988167177,10.25000028,0.000521815,9.63E-05,0.25,2.48E-07,4.84E-05,4.33E-07,90.056633,90.056633,4288.962891,4314.771973,43.74462171,17.54823248,50.75822067,0,0,0,40,89.54693604,1,6,1,1.945037842,55.22971725,,,,,,,,,,,,,,,,
3772712173,90.05809021,4428.247803,4.93E-05,8.13E-07,1,0.999253354,40.02988815,1.988155532,10.25000028,0.000536586,9.11E-05,0.25,-4.46E-07,4.96E-05,-2.61E-07,90.05804443,90.05804443,4415.246582,4441.249023,43.68443631,17.54307993,50.76199341,0,0,0,40,89.54685211,1,6,1,1.953125,56.20723343,,,,,,,,,,,,,,,,
3772712178,90.05839157,4548.188721,5.09E-05,7.06E-07,1,0.999253354,40.02988815,1.988127235,10.23999974,0.000553037,9.85E-05,0.25,-5.24E-08,5.12E-05,1.42E-07,90.05864716,90.05864716,4533.673828,4562.703613,44.19249485,17.54220997,50.7699852,0,0,0,40,89.54642487,1,6,1,1.950531006,56.20723343,,,,,,,,,,,,,,,,
3772712183,90.0579834,4673.516602,5.23E-05,7.11E-07,1,0.999253354,40.02988815,1.988184085,10.25000028,0.000566919,0.000104604,0.25,2.71E-07,5.25E-05,4.72E-07,90.05783081,90.05783081,4662.174316,4684.858887,43.93455744,17.54904403,50.7704277,0,0,0,40,89.54557037,1,6,1,1.950531006,55.71847534,,,,,,,,,,,,,,,,
3772712188,90.05809021,4797.431641,5.33E-05,1.02E-06,1,0.999253354,40.02988815,1.988084093,10.25000028,0.000578276,0.000103452,0.25,-1.31E-08,5.35E-05,1.90E-07,90.05804443,90.05804443,4781.320313,4813.542969,44.32771658,17.5464602,50.76976395,0,0,0,40,89.54685211,1,6,1,1.938781738,55.71847534,,,,,,,,,,,,,,,,
3772712193,90.05864716,4922.162354,5.46E-05,6.29E-07,1,0.999253354,40.02988815,1.987902761,10.23999974,0.000592123,0.00011066,0.25,4.09E-07,5.49E-05,6.19E-07,90.05886078,90.05886078,4909.359375,4934.965332,43.82825596,17.54220477,50.76865387,0,0,0,40,89.54689026,1,6,1,1.946411133,56.20723343,,,,,,,,,,,,,,,,
3772712206,90.05918503,4984.622314,5.61E-05,2.08E-06,1,0.999253354,40.02988815,1.988173331,10.23999974,0.000610382,0.000102872,0.25,-5.78E-07,5.64E-05,-3.67E-07,90.0592041,90.0592041,4976.427246,4992.817383,44.06274451,17.54621813,50.76820755,0,0,0,40,89.54718781,1,6,1,1.962432861,56.20723343,,,,,,,,,,,,,,,,
3772712211,90.05877686,4859.034424,5.38E-05,1.12E-06,1,0.999253354,40.02988815,1.98815494,10.25000028,0.000583885,0.000104637,0.25,2.97E-09,5.41E-05,2.08E-07,90.05877686,90.05877686,4846.125488,4871.943359,43.75947265,17.54574977,50.77109528,0,0,0,40,89.54710388,1,6,1,1.947631836,56.69599533,,,,,,,,,,,,,,,,
3772712216,90.05950546,4738.80127,5.22E-05,6.33E-07,1,0.999253354,40.02988815,1.988151475,10.23999974,0.000566579,0.000104225,0.25,2.43E-07,5.25E-05,4.43E-07,90.0594635,90.0594635,4725.708008,4751.894531,44.14950528,17.54190087,50.76599121,0,0,0,40,89.54723358,1,6,1,1.951293945,56.20723343,,,,,,,,,,,,,,,,
3772712222,90.06017303,4608.526855,5.08E-05,7.05E-07,1,0.999253354,40.02988815,1.988130653,10.23999974,0.000552078,9.85E-05,0.25,-3.58E-08,5.11E-05,1.58E-07,90.06027985,90.06027985,4595.511719,4621.541992,43.65082628,17.54790055,50.77553177,0,0,0,40,89.54800415,1,6,1,1.938171387,56.20723343,,,,,,,,,,,,,,,,
3772712226,90.06075287,4486.574463,4.97E-05,7.68E-07,1,0.999253354,40.02988815,1.988106159,10.23999974,0.000539729,9.48E-05,0.25,-1.73E-07,4.99E-05,1.53E-08,90.06049347,90.06049347,4471.891602,4501.257324,44.00255912,17.5423173,50.77064896,0,0,0,40,89.54749298,1,6,1,1.962890625,56.69599533,,,,,,,,,,,,,,,,
3772712231,90.06129074,4362.599365,4.84E-05,1.39E-06,1,0.999253354,40.02988815,1.988059715,10.25000028,0.000523051,0.000106257,0.25,1.12E-06,4.86E-05,1.31E-06,90.06109619,90.06109619,4348.584473,4376.614258,43.7883929,17.54310974,50.76488113,0,0,0,40,89.54779053,1,6,1,1.952667236,56.69599533,,,,,,,,,,,,,,,,
3772712236,90.06150436,4237.032227,4.63E-05,6.40E-07,1,0.999253354,40.02988815,1.9881601,10.23999974,0.000500905,9.90E-05,0.25,8.24E-07,4.65E-05,1.00E-06,90.06143951,90.06143951,4225.724609,4248.339844,44.11042385,17.5486699,50.76754379,0,0,0,40,89.54779053,1,6,1,1.952667236,56.69599533,,,,,,,,,,,,,,,,
3772712241,90.06201935,4115.381836,4.54E-05,9.87E-07,1,0.999253354,40.02988815,1.988152193,10.23999974,0.000492113,9.32E-05,0.25,4.46E-07,4.56E-05,6.21E-07,90.06212616,90.06212616,4102.283691,4128.47998,43.697724,17.549704,50.76310349,0,0,0,40,89.54689026,1,6,1,1.952209473,57.18475342,,,,,,,,,,,,,,,,
3772712246,90.06199646,3988.001587,4.39E-05,9.52E-07,1,0.999253354,40.02988815,1.988119568,10.23999974,0.000475347,8.95E-05,0.25,3.83E-07,4.41E-05,5.52E-07,90.06186676,90.06186676,3972.005371,4003.997803,44.29332493,17.55240471,50.77420044,0,0,0,40,89.54693604,1,6,1,1.951141357,56.69599533,,,,,,,,,,,,,,,,
3772712251,90.06225586,3861.439209,4.19E-05,9.44E-07,1,0.999253354,40.02988815,1.988037813,10.23999974,0.000455056,8.13E-05,0.25,-2.11E-08,4.21E-05,1.39E-07,90.06191254,90.06191254,3851.735107,3871.143311,44.14403388,17.54485148,50.7872963,0,0,0,40,89.54740143,1,6,1,1.965789795,57.18475342,,,,,,,,,,,,,,,,
3772712256,90.06287766,3742.585815,4.12E-05,6.15E-07,1,0.999253354,40.02988815,1.988146349,10.23999974,0.000446131,8.96E-05,0.25,8.67E-07,4.15E-05,1.03E-06,90.06272888,90.06272888,3731.091553,3754.080078,43.96894909,17.54766744,50.78219223,0,0,0,40,89.5474472,1,6,1,1.950531006,56.69599533,,,,,,,,,,,,,,,,
3772712261,90.06257629,3611.519165,3.91E-05,9.12E-07,1,0.999253354,40.02988815,1.988042403,10.25000028,0.000423502,7.88E-05,0.25,2.64E-07,3.93E-05,4.15E-07,90.06255341,90.06255341,3598.785156,3624.253174,43.87828018,17.54493937,50.78196716,0,0,0,40,89.54676056,1,6,1,1.948242188,57.18475342,,,,,,,,,,,,,,,,
3772712266,90.06362915,3492.041382,3.74E-05,7.20E-07,1,0.999253354,40.02988815,1.988057657,10.23999974,0.000404779,7.99E-05,0.25,6.57E-07,3.76E-05,8.03E-07,90.06341553,90.06341553,3478.961914,3505.12085,44.05570986,17.54360592,50.79284286,0,0,0,40,89.54800415,1,6,1,1.952514648,56.69599533,,,,,,,,,,,,,,,,
3772712271,90.06352234,3367.278442,3.62E-05,6.45E-07,1,0.999253354,40.02988815,1.988016721,10.23999974,0.000392066,7.79E-05,0.25,6.86E-07,3.64E-05,8.28E-07,90.06354523,90.06354523,3355.862305,3378.69458,44.05570986,17.54568686,50.78551865,0,0,0,40,89.54792023,1,6,1,1.937408447,57.67351151,,,,,,,,,,,,,,,,
3772712276,90.06412506,3241.114624,3.48E-05,8.43E-07,1,0.999253354,40.02988815,1.988174849,10.23999974,0.000376596,7.19E-05,0.25,3.91E-07,3.49E-05,5.26E-07,90.06401825,90.06401825,3229.72168,3252.507568,44.16122971,17.54833912,50.78907013,0,0,0,40,89.54779053,1,6,1,1.964111328,57.18475342,,,,,,,,,,,,,,,,
3772712281,90.06440353,3121.275146,3.37E-05,1.02E-06,1,0.999253354,40.02988815,1.98810649,10.23999974,0.000364168,7.24E-05,0.25,6.40E-07,3.38E-05,7.72E-07,90.0645752,90.0645752,3108.257813,3134.29248,43.83841713,17.54757848,50.78462982,0,0,0,40,89.54787445,1,6,1,1.947021484,56.69599533,,,,,,,,,,,,,,,,
3772712286,90.06521988,2994.095337,3.14E-05,7.82E-07,1,0.999253354,40.02988815,1.988099116,10.25000028,0.000341003,6.08E-05,0.25,-2.39E-08,3.16E-05,9.59E-08,90.06491852,90.06491852,2986.208984,3001.981689,43.98848981,17.54390919,50.78174591,0,0,0,40,89.54749298,1,6,1,1.960754395,57.67351151,,,,,,,,,,,,,,,,
3772712291,90.06581879,2868.611206,3.04E-05,1.02E-06,1,0.999253354,40.02988815,1.988176539,10.23999974,0.000330011,6.25E-05,0.25,3.04E-07,3.06E-05,4.22E-07,90.06568909,90.06568909,2855.699951,2881.522461,44.07134243,17.54719416,50.77531052,0,0,0,40,89.54723358,1,6,1,1.947479248,57.18475342,,,,,,,,,,,,,,,,
3772712296,90.06622696,2744.852661,2.83E-05,6.82E-07,1,0.999253354,40.02988815,1.988240263,10.25000028,0.000304862,6.62E-05,0.25,1.03E-06,2.84E-05,1.15E-06,90.06637573,90.06637573,2730.453125,2759.252197,44.00021423,17.54721338,50.77753067,0,0,0,40,89.54689026,1,6,1,1.951599121,57.67351151,,,,,,,,,,,,,,,,
3772712301,90.06626892,2622.073486,2.73E-05,6.54E-07,1,0.999253354,40.02988815,1.988080192,10.25000028,0.000294184,6.67E-05,0.25,1.25E-06,2.75E-05,1.36E-06,90.06637573,90.06637573,2607.556396,2636.590576,44.06665266,17.54873696,50.77975082,0,0,0,40,89.54642487,1,6,1,1.946868896,58.16226959,,,,,,,,,,,,,,,,
3772712306,90.06626892,2495.914307,2.58E-05,6.80E-07,1,0.999253354,40.02988815,1.988064698,10.23999974,0.000279874,5.43E-05,0.25,3.74E-07,2.60E-05,4.75E-07,90.06637573,90.06637573,2484.323242,2507.505371,43.92048812,17.54299409,50.778862,0,0,0,40,89.54672241,1,6,1,1.958770752,57.67351151,,,,,,,,,,,,,,,,
3772712311,90.06755829,2373.346924,2.49E-05,8.88E-07,1,0.999253354,40.02988815,1.988071329,10.23999974,0.000267801,6.07E-05,0.25,1.13E-06,2.50E-05,1.23E-06,90.0675354,90.0675354,2355.224121,2391.469727,43.97207561,17.54811149,50.7635498,0,0,0,40,89.54718781,1,6,1,1.952056885,59.13978577,,,,,,,,,,,,,,,,
3772712316,90.06805038,2251.184937,2.27E-05,6.87E-07,1,0.999253354,40.02988815,1.988086336,10.23999974,0.000245421,5.27E-05,0.25,7.78E-07,2.29E-05,8.69E-07,90.06809235,90.06809235,2239.589111,2262.780762,44.20031113,17.54990067,50.78462982,0,0,0,40,89.54624939,1,6,1,1.952362061,57.67351151,,,,,,,,,,,,,,,,
3772712321,90.06818008,2127.343506,2.13E-05,5.91E-07,1,0.999253354,40.02988815,1.98808028,10.23999974,0.000230329,4.83E-05,0.25,6.25E-07,2.14E-05,7.10E-07,90.0677948,90.0677948,2114.333252,2140.35376,44.0924464,17.54534912,50.78618622,0,0,0,40,89.54672241,1,6,1,1.951141357,58.16226959,,,,,,,,,,,,,,,,
3772712326,90.06843948,1999.002441,2.03E-05,9.65E-07,1,0.999253354,40.02988815,1.988101186,10.23999974,0.000219073,4.45E-05,0.25,4.64E-07,2.04E-05,5.44E-07,90.06861115,90.06861115,1989.178345,2008.826538,44.34569404,17.54867895,50.79328537,0,0,0,40,89.54611969,1,6,1,1.951293945,58.16226959,,,,,,,,,,,,,,,,
3772712331,90.06824493,1876.082581,1.92E-05,6.07E-07,1,0.999253354,40.02988815,1.988039306,10.23999974,0.000207611,4.24E-05,0.25,4.66E-07,1.93E-05,5.42E-07,90.06809235,90.06809235,1864.470703,1887.694458,43.92205138,17.54561438,50.79395294,0,0,0,40,89.545784,1,6,1,1.951599121,58.16226959,,,,,,,,,,,,,,,,
3772712336,90.06839752,1747.640198,1.72E-05,6.44E-07,1,0.999253354,40.02988815,1.988136713,10.25000028,0.000185981,3.57E-05,0.25,2.10E-07,1.73E-05,2.76E-07,90.06839752,90.06839752,1731.630127,1763.650269,44.02053657,17.54595729,50.80149841,0,0,0,40,89.54624939,1,6,1,1.95098877,57.67351151,,,,,,,,,,,,,,,,
3772712341,90.06807327,1628.685425,1.54E-05,8.46E-07,1,0.999253354,40.02988815,1.988003744,10.23999974,0.000166065,3.79E-05,0.25,7.24E-07,1.55E-05,7.86E-07,90.06839752,90.06839752,1615.958496,1641.412354,43.98770818,17.54710232,50.80393982,0,0,0,40,89.54629517,1,6,1,1.946868896,57.67351151,,,,,,,,,,,,,,,,
3772712346,90.06809616,1502.332581,1.44E-05,9.33E-07,1,0.999253354,40.02988815,1.988232487,10.23999974,0.0001569,2.46E-05,0.25,-3.09E-07,1.45E-05,-2.56E-07,90.0679245,90.0679245,1492.766602,1511.89856,44.02835286,17.54866958,50.80638123,0,0,0,40,89.54672241,1,6,1,1.952819824,57.67351151,,,,,,,,,,,,,,,,
3772712351,90.06921387,1374.560608,1.27E-05,8.95E-07,1,0.999253354,40.02988815,1.988032011,10.25000028,0.000136361,3.25E-05,0.25,7.17E-07,1.28E-05,7.69E-07,90.06921387,90.06921387,1360.257813,1388.863403,43.99161632,17.54543944,50.79373169,0,0,0,40,89.54706573,1,6,1,1.951599121,57.67351151,,,,,,,,,,,,,,,,
3772712356,90.07007217,1252.191467,1.15E-05,8.07E-07,1,0.999253354,40.02988815,1.988100792,10.23999974,0.000123882,2.53E-05,0.25,2.75E-07,1.15E-05,3.21E-07,90.06990051,90.06990051,1239.190308,1265.192627,44.36679801,17.54558919,50.80060959,0,0,0,40,89.54706573,1,6,1,1.9480896,57.67351151,,,,,,,,,,,,,,,,
3772712361,90.07022095,1132.040894,1.03E-05,9.50E-07,1,0.999253354,40.02988815,1.988205446,10.25000028,0.000110231,2.90E-05,0.25,8.22E-07,1.04E-05,8.66E-07,90.07024384,90.07024384,1122.735229,1141.346558,44.0267896,17.54791437,50.78995895,0,0,0,40,89.54689026,1,6,1,1.960144043,57.67351151,,,,,,,,,,,,,,,,
3772712366,90.07133865,1006.257172,9.07E-06,9.48E-07,1,0.999253354,40.02988815,1.987990467,10.23999974,9.83E-05,1.82E-05,0.25,4.80E-08,9.11E-06,8.30E-08,90.07131958,90.07131958,993.2583618,1019.255981,43.92595952,17.54347583,50.78929138,0,0,0,40,89.54616547,1,6,1,1.949920654,58.65102768,,,,,,,,,,,,,,,,
3772712371,90.0717659,881.5794067,7.17E-06,1.01E-06,1,0.999253354,40.02988815,1.987972564,10.23999974,7.74E-05,1.62E-05,0.25,2.12E-07,7.20E-06,2.41E-07,90.07191467,90.07191467,870.3707275,892.7880859,44.11276874,17.54545684,50.78418732,0,0,0,40,89.54624939,1,6,1,1.943054199,58.16226959,,,,,,,,,,,,,,,,
3772712376,90.07148743,757.1412659,6.00E-06,8.01E-07,1,0.999253354,40.02988815,1.98808101,10.23999974,6.45E-05,1.55E-05,0.25,3.51E-07,6.03E-06,3.76E-07,90.07148743,90.07148743,747.3310547,766.9514771,43.91501672,17.54584872,50.78684998,0,0,0,40,89.5456543,1,6,1,1.938171387,57.67351151,,,,,,,,,,,,,,,,
3772712381,90.07095337,633.288269,4.75E-06,1.35E-06,1,0.999253354,40.02988815,1.988043812,10.23999974,5.06E-05,1.44E-05,0.25,4.80E-07,4.77E-06,5.01E-07,90.07080078,90.07080078,617.1721802,649.4043579,44.15106854,17.54302764,50.79750443,0,0,0,40,89.54633331,1,6,1,1.952667236,58.16226959,,,,,,,,,,,,,,,,
3772712386,90.07146454,511.6585999,3.06E-06,1.09E-06,1,0.999253354,40.02988815,1.988104055,10.23999974,3.33E-05,5.61E-06,0.25,-3.08E-08,3.07E-06,-1.93E-08,90.07157135,90.07157135,502.4543457,520.862854,44.23079465,17.54716287,50.80127716,0,0,0,40,89.54560852,1,6,1,1.952362061,57.67351151,,,,,,,,,,,,,,,,
3772712391,90.07172394,386.4486237,1.97E-06,9.86E-07,1,0.999253354,40.02988815,1.988081464,10.23999974,2.07E-05,8.12E-06,0.25,3.94E-07,1.98E-06,4.04E-07,90.07174683,90.07174683,373.6364136,399.2608337,44.30739424,17.54717778,50.80371857,0,0,0,40,89.54616547,1,6,1,1.937561035,57.67351151,,,,,,,,,,,,,,,,
3772712396,90.07223892,261.2939301,9.79E-07,7.20E-07,1,0.999253354,40.02988815,1.988029655,10.23999974,1.01E-05,4.69E-06,0.25,2.56E-07,9.83E-07,2.61E-07,90.07204437,90.07204437,246.5786743,276.0091858,44.24564559,17.54508796,50.81769943,0,0,0,40,89.54633331,1,6,1,1.960144043,58.16226959,,,,,,,,,,,,,,,,
3772712401,90.072155,137.6575356,5.66E-07,3.33E-06,1,0.999253354,40.02988815,1.988091682,10.23999974,4.90E-06,8.02E-06,0.25,6.37E-07,5.66E-07,6.42E-07,90.07204437,90.07204437,126.3405685,148.9745026,44.17373576,17.54420031,50.81059647,0,0,0,40,89.54642487,1,6,1,1.949768066,59.62854385,,,,,,,,,,,,,,,,
3772712406,90.0718956,12.643383,-2.26E-06,1.12E-06,1,0.999253354,40.02988815,1.988133195,10.25000028,-2.72E-05,1.02E-05,0.25,1.35E-06,-2.28E-06,1.35E-06,90.07183075,90.07183075,-0.362363875,25.64912987,43.92283301,17.54548852,50.8050499,0,0,0,40,89.54663849,1,6,1,1.95022583,58.16226959,,,,,,,,,,,,,,,,
3772712411,90.07191849,-109.9654579,-1.67E-06,9.63E-07,1,0.999253354,40.02988815,1.988133965,10.23999974,-1.82E-05,-3.10E-06,0.25,1.42E-08,-1.68E-06,7.87E-09,90.07221985,90.07221985,-119.2687683,-100.6621475,44.15106854,17.54633363,50.79972076,0,0,0,40,89.54672241,1,6,1,1.960449219,58.16226959,,,,,,,,,,,,,,,,
3772712416,90.0724144,-234.9911118,-2.54E-06,8.65E-07,1,0.999253354,40.02988815,1.988072903,10.25000028,-2.80E-05,-2.40E-06,0.25,2.34E-07,-2.55E-06,2.25E-07,90.07226563,90.07226563,-246.5108185,-223.471405,43.96504095,17.5458163,50.80660248,0,0,0,40,89.54676056,1,6,1,1.96182251,57.18475342,,,,,,,,,,,,,,,,
3772712421,90.07299042,-358.0791931,-3.32E-06,6.14E-07,1,0.999253354,40.02988815,1.988123102,10.25000028,-3.60E-05,-6.26E-06,0.25,1.78E-08,-3.33E-06,5.22E-09,90.07277679,90.07277679,-371.1817017,-344.9766846,44.11745851,17.54504721,50.81414795,0,0,0,40,89.54560852,1,6,1,1.951141357,58.16226959,,,,,,,,,,,,,,,,
3772712426,90.07384872,-485.8488464,-4.72E-06,9.09E-07,1,0.999253354,40.02988815,1.988063771,10.23999974,-5.14E-05,-8.62E-06,0.25,5.24E-08,-4.75E-06,3.46E-08,90.07380676,90.07380676,-497.2671509,-474.430542,44.19171322,17.54464199,50.81947327,0,0,0,40,89.54603577,1,6,1,1.96182251,58.16226959,,,,,,,,,,,,,,,,
3772712431,90.07558823,-611.0657654,-6.37E-06,6.12E-07,1,0.999253354,40.02988815,1.987986246,10.23999974,-6.93E-05,-1.15E-05,0.25,8.27E-08,-6.41E-06,5.87E-08,90.07539368,90.07539368,-624.2696533,-597.8618774,44.29098004,17.54480068,50.79439545,0,0,0,40,89.54697418,1,6,1,1.950836182,58.65102768,,,,,,,,,,,,,,,,
3772712436,90.07552338,-734.5247498,-6.70E-06,4.76E-07,1,0.999253354,40.02988815,1.988098172,10.23999974,-7.38E-05,-7.10E-06,0.25,5.47E-07,-6.74E-06,5.24E-07,90.07565308,90.07565308,-744.0285034,-725.0209961,44.30661261,17.54793713,50.81081772,0,0,0,40,89.54654694,1,6,1,1.941833496,58.65102768,,,,,,,,,,,,,,,,
3772712441,90.07468796,-860.0411072,-8.03E-06,8.64E-07,1,0.999253354,40.02988815,1.988108733,10.25000028,-8.90E-05,-5.83E-06,0.25,9.03E-07,-8.08E-06,8.77E-07,90.07466888,90.07466888,-873.0445557,-847.0376587,44.38946524,17.54614199,50.81991959,0,0,0,40,89.54616547,1,6,1,1.938171387,58.65102768,,,,,,,,,,,,,,,,
3772712446,90.07582474,-985.7303162,-9.24E-06,8.98E-07,1,0.999253354,40.02988815,1.988155184,10.23999974,-0.000101044,-1.36E-05,0.25,3.99E-07,-9.29E-06,3.66E-07,90.07578278,90.07578278,-998.5356445,-972.9249878,44.24642722,17.54753828,50.82302475,0,0,0,40,89.54531097,1,6,1,1.958465576,59.13978577,,,,,,,,,,,,,,,,
3772712451,90.07537842,-1105.979858,-1.19E-05,2.11E-06,1,0.999253354,40.02988815,1.98807389,10.25000028,-0.000125216,-4.25E-05,0.25,-1.79E-06,-1.19E-05,-1.85E-06,90.07561493,90.07561493,-1120.179077,-1091.78064,43.89703927,17.54815121,50.82147217,0,0,0,40,89.54659271,1,6,1,1.942749023,58.65102768,,,,,,,,,,,,,,,,
3772712456,90.07509613,-1234.516846,-1.22E-05,5.22E-07,1,0.999253354,40.02988815,1.988024028,10.23999974,-0.000132617,-2.22E-05,0.25,1.38E-07,-1.23E-05,9.19E-08,90.07530975,90.07530975,-1246.223145,-1222.810547,44.67163313,17.54318446,50.81126404,0,0,0,40,89.54928589,1,6,1,1.961975098,57.67351151,,,,,,,,,,,,,,,,
3772712461,90.07587051,-1353.259705,-1.35E-05,5.61E-07,1,0.999253354,40.02988815,1.988115158,10.23999974,-0.000147927,-1.87E-05,0.25,7.00E-07,-1.36E-05,6.52E-07,90.07556915,90.07556915,-1361.070068,-1345.449341,44.1307462,17.54607804,50.81103897,0,0,0,40,89.55014038,1,6,1,1.946868896,59.13978577,,,,,,,,,,,,,,,,
3772712466,90.0769043,-1477.128723,-1.46E-05,8.59E-07,1,0.999253354,40.02988815,1.988053631,10.23999974,-0.000158356,-3.02E-05,0.25,-1.66E-07,-1.47E-05,-2.22E-07,90.0769043,90.0769043,-1490.136841,-1464.120605,44.22219673,17.54313635,50.8163681,0,0,0,40,89.55014038,1,6,1,1.951446533,58.65102768,,,,,,,,,,,,,,,,
3772712471,90.07752228,-1604.559631,-1.61E-05,6.31E-07,1,0.999253354,40.02988815,1.988123393,10.23999974,-0.000175219,-2.91E-05,0.25,2.05E-07,-1.62E-05,1.44E-07,90.07733154,90.07733154,-1617.553833,-1591.56543,44.16826436,17.54374025,50.82479858,0,0,0,40,89.55014038,1,6,1,1.948852539,58.65102768,,,,,,,,,,,,,,,,
3772712476,90.07808304,-1730.54834,-1.74E-05,6.70E-07,1,0.999253354,40.02988815,1.988091187,10.23999974,-0.000189198,-3.05E-05,0.25,3.04E-07,-1.75E-05,2.39E-07,90.07801819,90.07801819,-1738.653564,-1722.443115,44.12058503,17.54487321,50.82169342,0,0,0,40,89.54928589,1,6,1,1.952362061,58.65102768,,,,,,,,,,,,,,,,
3772712481,90.0784874,-1855.889771,-1.89E-05,5.88E-07,1,0.999253354,40.02988815,1.988144449,10.23999974,-0.00020532,-3.74E-05,0.25,-5.35E-08,-1.90E-05,-1.26E-07,90.07844543,90.07844543,-1869.06604,-1842.713501,44.15497668,17.54952236,50.83101273,0,0,0,40,89.5484314,1,6,1,1.947021484,58.65102768,,,,,,,,,,,,,,,,
3772712486,90.07915878,-1980.039856,-2.09E-05,5.67E-07,1,0.999253354,40.02988815,1.988146939,10.23999974,-0.000227069,-3.95E-05,0.25,1.02E-07,-2.10E-05,2.28E-08,90.07922363,90.07922363,-1993.146973,-1966.932739,44.1307462,17.54604607,50.82147217,0,0,0,40,89.54787445,1,6,1,1.952972412,59.13978577,,,,,,,,,,,,,,,,
3772712491,90.07958603,-2101.791504,-2.21E-05,8.54E-07,1,0.999253354,40.02988815,1.988073703,10.23999974,-0.000239801,-4.43E-05,0.25,-1.23E-07,-2.22E-05,-2.08E-07,90.07965088,90.07965088,-2114.688965,-2088.894043,44.27691073,17.54572973,50.81126404,0,0,0,40,89.54718781,1,6,1,1.939849854,58.65102768,,,,,,,,,,,,,,,,
3772712496,90.07868195,-2226.321777,-2.29E-05,6.05E-07,1,0.999253354,40.02988815,1.988043146,10.25000028,-0.000248498,-4.55E-05,0.25,-8.75E-08,-2.30E-05,-1.75E-07,90.07883453,90.07883453,-2239.341309,-2213.302246,43.98770818,17.54499567,50.81925201,0,0,0,40,89.54573822,1,6,1,1.951446533,59.13978577,,,,,,,,,,,,,,,,
3772712501,90.07911301,-2354.091797,-2.43E-05,9.62E-07,1,0.999253354,40.02988815,1.988072929,10.23999974,-0.00026258,-5.21E-05,0.25,-4.53E-07,-2.44E-05,-5.49E-07,90.07917786,90.07917786,-2365.376465,-2342.807129,44.10182594,17.5478699,50.81592178,0,0,0,40,89.545784,1,6,1,1.947479248,59.13978577,,,,,,,,,,,,,,,,
3772712506,90.07949829,-2476.749023,-2.64E-05,5.87E-07,1,0.999253354,40.02988815,1.988130804,10.23999974,-0.00028653,-5.42E-05,0.25,-2.56E-07,-2.66E-05,-3.58E-07,90.0797348,90.0797348,-2493.254395,-2460.243652,44.40744269,17.54888284,50.8208046,0,0,0,40,89.54531097,1,6,1,1.95022583,60.11730194,,,,,,,,,,,,,,,,
3772712511,90.07868195,-2596.574463,-2.79E-05,4.97E-07,1,0.999253354,40.02988815,1.988044906,10.23999974,-0.000302313,-5.78E-05,0.25,-3.24E-07,-2.80E-05,-4.33E-07,90.07883453,90.07883453,-2609.677002,-2583.471924,44.33162473,17.54459768,50.82213593,0,0,0,40,89.54603577,1,6,1,1.936645508,59.13978577,,,,,,,,,,,,,,,,
3772712516,90.07872772,-2726.68042,-2.89E-05,6.89E-07,1,0.999253354,40.02988815,1.988082561,10.23999974,-0.000314044,-5.74E-05,0.25,-9.80E-08,-2.91E-05,-2.09E-07,90.07883453,90.07883453,-2739.794434,-2713.566406,44.17529902,17.5495225,50.81969452,0,0,0,40,89.54642487,1,6,1,1.960906982,59.13978577,,,,,,,,,,,,,,,,
3772712521,90.07911301,-2848.814697,-3.05E-05,6.52E-07,1,0.999253354,40.02988815,1.988086895,10.23999974,-0.000332453,-5.12E-05,0.25,7.48E-07,-3.07E-05,6.35E-07,90.07896423,90.07896423,-2860.203125,-2837.42627,44.30504936,17.54752464,50.8296814,0,0,0,40,89.54714966,1,6,1,1.950836182,58.65102768,,,,,,,,,,,,,,,,
3772712526,90.0799942,-2975.678955,-3.25E-05,1.02E-06,1,0.999253354,40.02988815,1.988046073,10.23999974,-0.00035297,-6.47E-05,0.25,-1.32E-07,-3.27E-05,-2.57E-07,90.08020782,90.08020782,-2990.094727,-2961.263184,44.20109276,17.54515996,50.83301163,0,0,0,40,89.54697418,1,6,1,1.95602417,58.65102768,,,,,,,,,,,,,,,,
3772712531,90.08072281,-3096.82019,-3.34E-05,9.94E-07,1,0.999253354,40.02988815,1.988006557,10.23999974,-0.000362013,-6.57E-05,0.25,-7.82E-08,-3.35E-05,-2.06E-07,90.08033752,90.08033752,-3109.719971,-3083.92041,44.16982762,17.54670914,50.8296814,0,0,0,40,89.54611969,1,6,1,1.937866211,59.13978577,,,,,,,,,,,,,,,,
3772712536,90.08166504,-3219.44043,-3.53E-05,4.89E-07,1,0.999253354,40.02988815,1.988075946,10.23999974,-0.000382944,-6.78E-05,0.25,7.01E-08,-3.54E-05,-6.41E-08,90.08132172,90.08132172,-3232.565918,-3206.314941,44.421512,17.5488171,50.82768631,0,0,0,40,89.54544067,1,6,1,1.939086914,59.13978577,,,,,,,,,,,,,,,,
3772712541,90.08282852,-3347.461426,-3.65E-05,5.83E-07,1,0.999253354,40.02988815,1.988006513,10.23999974,-0.000395253,-7.50E-05,0.25,-3.70E-07,-3.67E-05,-5.11E-07,90.08287048,90.08287048,-3357.310791,-3337.612061,44.31755541,17.54507543,50.84455109,0,0,0,40,89.54514313,1,6,1,1.937866211,58.65102768,,,,,,,,,,,,,,,,
3772712546,90.08278656,-3471.975464,-3.80E-05,5.47E-07,1,0.999253354,40.02988815,1.987964039,10.23999974,-0.000411756,-7.76E-05,0.25,-3.44E-07,-3.82E-05,-4.90E-07,90.08300018,90.08300018,-3484.995117,-3458.955811,44.09557291,17.54445171,50.85342789,0,0,0,40,89.54407501,1,6,1,1.954345703,58.65102768,,,,,,,,,,,,,,,,
3772712551,90.0813446,-3598.911011,-3.97E-05,9.55E-07,1,0.999253354,40.02988815,1.988010295,10.23999974,-0.000430471,-8.00E-05,0.25,-2.60E-07,-3.99E-05,-4.13E-07,90.08132172,90.08132172,-3608.407959,-3589.414063,44.36914289,17.5484173,50.84277725,0,0,0,40,89.54424286,1,6,1,1.951293945,59.62854385,,,,,,,,,,,,,,,,
3772712556,90.08123779,-3725.07019,-4.10E-05,7.61E-07,1,0.999253354,40.02988815,1.988004052,10.23999974,-0.000444943,-8.00E-05,0.25,-3.00E-08,-4.12E-05,-1.87E-07,90.08110809,90.08110809,-3738.087402,-3712.052979,43.57031855,17.54488526,50.847435,0,0,0,40,89.54330444,1,6,1,1.953582764,60.11730194,,,,,,,,,,,,,,,,
3772712561,90.08132553,-3844.395996,-4.20E-05,1.03E-06,1,0.999253354,40.02988815,1.988008847,10.23999974,-0.000455925,-8.34E-05,0.25,-1.50E-07,-4.22E-05,-3.11E-07,90.08145142,90.08145142,-3857.274902,-3831.51709,44.16591948,17.5456415,50.85675812,0,0,0,40,89.54454041,1,6,1,1.949615479,57.18475342,,,,,,,,,,,,,,,,
3772712566,90.08098221,-3972.960693,-4.38E-05,1.18E-06,1,0.999253354,40.02988815,1.988109085,10.25000028,-0.000476348,-8.29E-05,0.25,2.18E-07,-4.41E-05,5.21E-08,90.08119965,90.08119965,-3984.369873,-3961.551514,44.16748274,17.54405436,50.84566116,0,0,0,40,89.5449295,1,6,1,1.953277588,59.13978577,,,,,,,,,,,,,,,,
3772712571,90.08128357,-4094.410645,-4.60E-05,6.75E-07,1,0.999253354,40.02988815,1.98805997,10.23999974,-0.000499811,-8.94E-05,0.25,8.84E-09,-4.63E-05,-1.67E-07,90.08119965,90.08119965,-4107.414063,-4081.407227,43.87437204,17.5491843,50.84233093,0,0,0,40,89.54424286,1,6,1,1.936035156,59.13978577,,,,,,,,,,,,,,,,
3772712576,90.08139038,-4221.906006,-4.66E-05,1.19E-06,1,0.999253354,40.02988815,1.988139733,10.25000028,-0.000505135,-9.44E-05,0.25,-3.47E-07,-4.68E-05,-5.27E-07,90.08128357,90.08128357,-4236.075195,-4207.736816,44.2104723,17.55255599,50.83922577,0,0,0,40,89.5449295,1,6,1,1.953277588,59.13978577,,,,,,,,,,,,,,,,
3772712606,90.08203506,-4966.634277,-5.58E-05,8.53E-07,1,0.999253354,40.02988815,1.988234545,10.23000013,-0.000605751,-0.000108993,0.25,-4.22E-08,-5.61E-05,-2.55E-07,90.08209991,90.08209991,-4981.036133,-4952.232422,44.37930406,17.54334191,50.85209656,0,0,0,40,89.54714966,1,6,1,1.940765381,57.67351151,,,,,,,,,,,,,,,,
3772712619,90.08336639,-4924.571533,-5.62E-05,9.45E-07,1,0.999253354,40.02988815,1.988099826,10.23000013,-0.000610463,-0.0001075,0.25,1.66E-07,-5.65E-05,-4.69E-08,90.08300018,90.08300018,-4937.381348,-4911.761719,44.06118126,17.54018972,50.85897827,0,0,0,40,89.54710388,1,6,1,1.95098877,58.65102768,,,,,,,,,,,,,,,,
3772712624,90.08441925,-4800.755371,-5.37E-05,7.88E-07,1,0.999253354,40.02988815,1.988074319,10.23000013,-0.000582212,-0.000110398,0.25,-5.44E-07,-5.40E-05,-7.52E-07,90.08420563,90.08420563,-4813.977539,-4787.533203,44.09088314,17.54123818,50.85165405,0,0,0,40,89.54706573,1,6,1,1.952667236,58.16226959,,,,,,,,,,,,,,,,
3772712629,90.08501816,-4677.029053,-5.25E-05,8.93E-07,1,0.999253354,40.02988815,1.98814039,10.23000013,-0.000569755,-0.000101124,0.25,8.46E-08,-5.27E-05,-1.15E-07,90.08518982,90.08518982,-4690.080566,-4663.977539,44.28238213,17.54767129,50.85320663,0,0,0,40,89.54672241,1,6,1,1.952209473,58.65102768,,,,,,,,,,,,,,,,
3772712634,90.08499908,-4552.326172,-5.09E-05,6.50E-07,1,0.999253354,40.02988815,1.987974744,10.23000013,-0.000551973,-0.00010095,0.25,-1.84E-07,-5.11E-05,-3.79E-07,90.08502197,90.08502197,-4566.954102,-4537.698242,44.08072197,17.54236152,50.85187531,0,0,0,40,89.54689026,1,6,1,1.948394775,58.16226959,,,,,,,,,,,,,,,,
3772712639,90.08407211,-4431.483887,-4.95E-05,5.84E-07,1,0.999253354,40.02988815,1.988088738,10.23000013,-0.000536609,-9.87E-05,0.25,-2.26E-07,-4.97E-05,-4.16E-07,90.08398438,90.08398438,-4444.494141,-4418.473633,44.18546019,17.54886626,50.85542679,0,0,0,40,89.54659271,1,6,1,1.948699951,59.13978577,,,,,,,,,,,,,,,,
3772712644,90.08441925,-4301.85498,-4.85E-05,1.03E-06,1,0.999253354,40.02988815,1.988172519,10.23000013,-0.000527912,-8.75E-05,0.25,6.29E-07,-4.88E-05,4.48E-07,90.08463287,90.08463287,-4314.870117,-4288.839844,44.09948106,17.54534639,50.8494339,0,0,0,40,89.54663849,1,6,1,1.946563721,58.65102768,,,,,,,,,,,,,,,,
3772712649,90.08529663,-4179.301514,-4.61E-05,1.15E-06,1,0.999253354,40.02988815,1.988074087,10.23000013,-0.000499142,-9.54E-05,0.25,-5.38E-07,-4.63E-05,-7.16E-07,90.0848465,90.0848465,-4190.577148,-4168.025879,44.31833704,17.54529746,50.85054398,0,0,0,40,89.54611969,1,6,1,1.936645508,58.65102768,,,,,,,,,,,,,,,,
3772712654,90.08493423,-4051.942017,-4.57E-05,9.68E-07,1,0.999253354,40.02988815,1.988068605,10.23000013,-0.000495496,-9.18E-05,0.25,-2.72E-07,-4.59E-05,-4.47E-07,90.08518982,90.08518982,-4067.94751,-4035.936523,44.12449317,17.54462677,50.86097336,0,0,0,40,89.54642487,1,6,1,1.9480896,58.16226959,,,,,,,,,,,,,,,,
3772712659,90.08459091,-3930.883545,-4.29E-05,1.12E-06,1,0.999253354,40.02988815,1.98808599,10.23000013,-0.000463503,-9.58E-05,0.25,-1.14E-06,-4.31E-05,-1.31E-06,90.08454895,90.08454895,-3945.290039,-3916.477051,44.01428355,17.54395492,50.86053085,0,0,0,40,89.54718781,1,6,1,1.960906982,59.13978577,,,,,,,,,,,,,,,,
3772712664,90.0849762,-3809.364624,-4.19E-05,6.27E-07,1,0.999253354,40.02988815,1.988080456,10.23000013,-0.000454396,-8.65E-05,0.25,-4.55E-07,-4.22E-05,-6.17E-07,90.08493042,90.08493042,-3822.678955,-3796.050293,43.81340502,17.54649334,50.87540054,0,0,0,40,89.54710388,1,6,1,1.938323975,58.65102768,,,,,,,,,,,,,,,,
3772712669,90.08518982,-3683.104004,-4.03E-05,6.50E-07,1,0.999253354,40.02988815,1.988096699,10.23000013,-0.00043807,-7.44E-05,0.25,3.61E-07,-4.05E-05,2.09E-07,90.08518982,90.08518982,-3697.588867,-3668.619141,44.34491241,17.54646963,50.86341476,0,0,0,40,89.54685211,1,6,1,1.949615479,59.13978577,,,,,,,,,,,,,,,,
3772712674,90.08491135,-3557.043945,-3.91E-05,9.90E-07,1,0.999253354,40.02988815,1.988038287,10.23000013,-0.000424634,-7.54E-05,0.25,6.17E-08,-3.93E-05,-8.72E-08,90.0849762,90.0849762,-3569.955322,-3544.132568,43.96425932,17.54439316,50.85431671,0,0,0,40,89.54740143,1,6,1,1.951446533,58.65102768,,,,,,,,,,,,,,,,
3772712679,90.08454895,-3434.603149,-3.70E-05,8.13E-07,1,0.999253354,40.02988815,1.987968129,10.23000013,-0.00040214,-6.90E-05,0.25,2.70E-07,-3.72E-05,1.30E-07,90.08454895,90.08454895,-3446.108887,-3423.097412,44.08853826,17.54197497,50.85742188,0,0,0,40,89.54714966,1,6,1,1.949768066,58.65102768,,,,,,,,,,,,,,,,
3772712684,90.08467865,-3304.755493,-3.63E-05,6.66E-07,1,0.999253354,40.02988815,1.988006114,10.23000013,-0.000393959,-7.12E-05,0.25,-5.10E-08,-3.65E-05,-1.90E-07,90.08467865,90.08467865,-3316.567871,-3292.943115,43.85873947,17.54574568,50.84188843,0,0,0,40,89.5473175,1,6,1,1.95098877,59.13978577,,,,,,,,,,,,,,,,
3772712689,90.08538437,-3183.494385,-3.43E-05,7.33E-07,1,0.999253354,40.02988815,1.987971062,10.23000013,-0.000371747,-6.85E-05,0.25,-1.67E-07,-3.45E-05,-2.99E-07,90.08502197,90.08502197,-3196.279053,-3170.709717,44.03695077,17.54541108,50.85653687,0,0,0,40,89.54718781,1,6,1,1.937713623,59.13978577,,,,,,,,,,,,,,,,
3772712694,90.086586,-3055.547363,-3.30E-05,9.11E-07,1,0.999253354,40.02988815,1.988027171,10.23000013,-0.000357857,-6.64E-05,0.25,-2.01E-07,-3.32E-05,-3.29E-07,90.08660889,90.08660889,-3066.862061,-3044.232666,44.33553287,17.54949946,50.86208344,0,0,0,40,89.54718781,1,6,1,1.937561035,58.65102768,,,,,,,,,,,,,,,,
3772712699,90.08729553,-2932.189697,-3.21E-05,6.72E-07,1,0.999253354,40.02988815,1.987980473,10.23000013,-0.00034823,-6.17E-05,0.25,5.77E-08,-3.22E-05,-6.45E-08,90.08712006,90.08712006,-2943.596436,-2920.782959,44.29098004,17.54215438,50.85786819,0,0,0,40,89.54714966,1,6,1,1.947174072,59.62854385,,,,,,,,,,,,,,,,
3772712704,90.08763885,-2810.891846,-3.01E-05,8.55E-07,1,0.999253354,40.02988815,1.987987738,10.23000013,-0.000326011,-5.97E-05,0.25,-1.19E-07,-3.02E-05,-2.34E-07,90.08763885,90.08763885,-2823.819336,-2797.964355,44.3308431,17.54399074,50.85364914,0,0,0,40,89.54659271,1,6,1,1.950073242,59.13978577,,,,,,,,,,,,,,,,
3772712709,90.08705902,-2690.478516,-2.92E-05,9.12E-07,1,0.999253354,40.02988815,1.987908018,10.23000013,-0.000314676,-6.70E-05,0.25,-9.51E-07,-2.93E-05,-1.07E-06,90.08716583,90.08716583,-2703.69165,-2677.265381,44.30270447,17.54717475,50.84921265,0,0,0,40,89.54629517,1,6,1,1.935882568,59.62854385,,,,,,,,,,,,,,,,
3772712714,90.08678055,-2560.421265,-2.75E-05,5.38E-07,1,0.999253354,40.02988815,1.987979338,10.23000013,-0.00029819,-5.36E-05,0.25,-1.52E-08,-2.76E-05,-1.20E-07,90.08695221,90.08695221,-2573.431641,-2547.410889,44.54579094,17.55152097,50.84899139,0,0,0,40,89.54616547,1,6,1,1.95098877,59.62854385,,,,,,,,,,,,,,,,
3772712719,90.08624268,-2437.192505,-2.57E-05,6.93E-07,1,0.999253354,40.02988815,1.988089836,10.23000013,-0.000277759,-5.48E-05,0.25,-4.49E-07,-2.58E-05,-5.49E-07,90.08613586,90.08613586,-2450.193604,-2424.191406,44.0541466,17.55184878,50.84477234,0,0,0,40,89.54527283,1,6,1,1.947937012,59.13978577,,,,,,,,,,,,,,,,
3772712724,90.08703613,-2311.729248,-2.39E-05,5.23E-07,1,0.999253354,40.02988815,1.988031167,10.23000013,-0.000260354,-4.30E-05,0.25,3.29E-07,-2.40E-05,2.39E-07,90.08690643,90.08690643,-2326.333984,-2297.124512,43.72351774,17.54988643,50.84610367,0,0,0,40,89.54659271,1,6,1,1.952972412,59.62854385,,,,,,,,,,,,,,,,
3772712729,90.08666992,-2187.272461,-2.24E-05,9.26E-07,1,0.999253354,40.02988815,1.98808301,10.23000013,-0.000243037,-4.56E-05,0.25,-1.82E-07,-2.25E-05,-2.68E-07,90.08677673,90.08677673,-2200.27124,-2174.273682,43.90641881,17.54742131,50.84654999,0,0,0,40,89.54616547,1,6,1,1.951293945,59.13978577,,,,,,,,,,,,,,,,
3772712734,90.08531952,-2067.414429,-2.14E-05,5.50E-07,1,0.999253354,40.02988815,1.98797002,10.23000013,-0.000232649,-4.18E-05,0.25,-1.48E-08,-2.15E-05,-9.68E-08,90.08540344,90.08540344,-2080.420166,-2054.408691,44.032261,17.5453503,50.84766006,0,0,0,40,89.54685211,1,6,1,1.939544678,59.62854385,,,,,,,,,,,,,,,,
3772712739,90.08652496,-1936.163574,-2.01E-05,6.68E-07,1,0.999253354,40.02988815,1.988093656,10.23000013,-0.000217348,-4.12E-05,0.25,-2.02E-07,-2.02E-05,-2.80E-07,90.08652496,90.08652496,-1944.059204,-1928.267944,44.33865938,17.54757112,50.83988953,0,0,0,40,89.54779053,1,6,1,1.938171387,59.13978577,,,,,,,,,,,,,,,,
3772712744,90.08633041,-1814.232178,-1.80E-05,9.26E-07,1,0.999253354,40.02988815,1.988108809,10.23000013,-0.000196986,-2.61E-05,0.25,8.17E-07,-1.81E-05,7.52E-07,90.08639526,90.08639526,-1825.645874,-1802.818481,44.21359882,17.54915716,50.84166718,0,0,0,40,89.54813385,1,6,1,1.952667236,59.62854385,,,,,,,,,,,,,,,,
3772712749,90.08621979,-1688.842407,-1.72E-05,6.22E-07,1,0.999253354,40.02988815,1.988107369,10.23000013,-0.000186121,-3.51E-05,0.25,-1.54E-07,-1.73E-05,-2.20E-07,90.08647919,90.08647919,-1698.754028,-1678.930786,44.70289827,17.54759028,50.83988953,0,0,0,40,89.5483017,1,6,1,1.961212158,56.20723343,,,,,,,,,,,,,,,,
3772712754,90.08792114,-1566.293579,-1.54E-05,5.03E-07,1,0.999253354,40.02988815,1.988123032,10.23000013,-0.000167435,-2.66E-05,0.25,2.99E-07,-1.55E-05,2.42E-07,90.08802795,90.08802795,-1579.308594,-1553.278564,44.40744269,17.55008868,50.84566116,0,0,0,40,89.54868317,1,6,1,1.950836182,59.13978577,,,,,,,,,,,,,,,,
3772712759,90.08817673,-1441.553589,-1.36E-05,6.13E-07,1,0.999253354,40.02988815,1.988015487,10.23000013,-0.000147726,-2.74E-05,0.25,-8.74E-08,-1.37E-05,-1.40E-07,90.0880661,90.0880661,-1449.453857,-1433.65332,43.60392857,17.54552875,50.83966827,0,0,0,40,89.54846954,1,6,1,1.953735352,59.62854385,,,,,,,,,,,,,,,,
3772712764,90.08757782,-1317.320496,-1.27E-05,6.42E-07,1,0.999253354,40.02988815,1.987994843,10.23000013,-0.000138627,-2.25E-05,0.25,2.04E-07,-1.28E-05,1.57E-07,90.08747101,90.08747101,-1330.432251,-1304.20874,44.08853826,17.54430795,50.84033585,0,0,0,40,89.54787445,1,6,1,1.952362061,60.11730194,,,,,,,,,,,,,,,,
3772712769,90.0880661,-1190.336487,-1.08E-05,5.74E-07,1,0.999253354,40.02988815,1.988063557,10.23000013,-0.000116914,-2.02E-05,0.25,6.32E-08,-1.08E-05,2.24E-08,90.0880661,90.0880661,-1200.139771,-1180.533203,44.30661261,17.54938582,50.84410858,0,0,0,40,89.54792023,1,6,1,1.946258545,57.67351151,,,,,,,,,,,,,,,,
3772712774,90.08856583,-1064.393738,-1.02E-05,1.30E-06,1,0.999253354,40.02988815,1.988009811,10.23000013,-0.000111656,-1.16E-05,0.25,7.46E-07,-1.02E-05,7.11E-07,90.08863068,90.08863068,-1077.293457,-1051.494019,44.23392116,17.54567236,50.84410858,0,0,0,40,89.54779053,1,6,1,1.948852539,60.11730194,,,,,,,,,,,,,,,,
3772712779,90.08805084,-945.3560486,-8.21E-06,8.43E-07,1,0.999253354,40.02988815,1.987965428,10.23000013,-8.91E-05,-1.67E-05,0.25,-6.87E-08,-8.26E-06,-1.00E-07,90.08781433,90.08781433,-958.2626953,-932.4494019,44.14325225,17.54656146,50.84388733,0,0,0,40,89.54761505,1,6,1,1.96472168,59.62854385,,,,,,,,,,,,,,,,
3772712784,90.0885849,-819.2175903,-6.74E-06,6.03E-07,1,0.999253354,40.02988815,1.987960784,10.23000013,-7.41E-05,-8.17E-06,0.25,4.55E-07,-6.78E-06,4.32E-07,90.08850098,90.08850098,-832.2325439,-806.2026367,44.08931988,17.54443993,50.84233093,0,0,0,40,89.54761505,1,6,1,1.95526123,59.62854385,,,,,,,,,,,,,,,,
3772712789,90.08922958,-696.424469,-6.02E-06,6.80E-07,1,0.999253354,40.02988815,1.988009319,10.23000013,-6.59E-05,-8.88E-06,0.25,2.60E-07,-6.05E-06,2.39E-07,90.08914185,90.08914185,-709.3495483,-683.4993896,44.08072197,17.54504626,50.84432983,0,0,0,40,89.54749298,1,6,1,1.952209473,59.62854385,,,,,,,,,,,,,,,,
3772712794,90.08963776,-568.6778259,-4.14E-06,1.10E-06,1,0.999253354,40.02988815,1.987998579,10.23000013,-4.52E-05,-6.40E-06,0.25,1.52E-07,-4.16E-06,1.37E-07,90.08940125,90.08940125,-583.1535034,-554.2021484,44.23548442,17.54500179,50.83634186,0,0,0,40,89.54718781,1,6,1,1.940155029,59.62854385,,,,,,,,,,,,,,,,
3772712799,90.0884552,-448.2808075,-3.09E-06,7.94E-07,1,0.999253354,40.02988815,1.988075253,10.23000013,-3.42E-05,-2.23E-06,0.25,3.48E-07,-3.11E-06,3.38E-07,90.08840942,90.08840942,-459.8005066,-436.7611084,44.20969068,17.54975666,50.83944702,0,0,0,40,89.5474472,1,6,1,1.951141357,60.11730194,,,,,,,,,,,,,,,,
3772712804,90.08922958,-320.6078949,-2.29E-06,5.23E-07,1,0.999253354,40.02988815,1.988043737,10.23000013,-2.52E-05,-2.48E-06,0.25,1.82E-07,-2.30E-06,1.74E-07,90.08931732,90.08931732,-333.5214844,-307.6943054,44.36523475,17.54494703,50.84499359,0,0,0,40,89.5473175,1,6,1,1.950683594,59.62854385,,,,,,,,,,,,,,,,
3772712809,90.08880234,-197.623497,-9.90E-07,6.03E-07,1,0.999253354,40.02988815,1.987988395,10.23000013,-1.09E-05,-1.01E-06,0.25,8.41E-08,-9.95E-07,8.08E-08,90.088974,90.088974,-210.4357147,-184.8112793,44.18155205,17.54946371,50.84188843,0,0,0,40,89.54792023,1,6,1,1.963806152,60.11730194,,,,,,,,,,,,,,,,
3772712814,90.08961487,-75.48697472,2.14E-07,1.95E-05,1,0.999253354,40.02988815,1.988012353,10.23000013,1.57E-06,4.60E-06,0.25,3.86E-07,2.14E-07,3.88E-07,90.08961487,90.08961487,-88.57106018,-62.40288925,44.31599215,17.54704369,50.84899139,0,0,0,40,89.54761505,1,6,1,1.948242188,60.60606384,,,,,,,,,,,,,,,,
3772712817,90.08985138,-5.198336728,2.28E-06,1.79E-06,1,0.999253354,40.02988815,1.988040881,10.23000013,2.53E-05,1.19E-06,0.25,-2.99E-07,2.29E-06,-2.91E-07,90.08987427,90.08987427,-10.55500031,0.158326849,44.25111699,17.54889165,50.84699249,0,0,0,40,89.54766083,1,4,1,1.955566406,59.62854385,,,,,,,,,,,,,,,,