File: Data/YBCO/YBCO_MVT_50K_-30000-30000Oe_Continuous.csv
Time Stamp (sec),Temperature (K),Magnetic Field (Oe),Moment (emu),M. Std. Err. (emu),Transport Action,Averaging Time (sec),Frequency (Hz),Peak Amplitude (mm),Center Position (mm),Coil Signal' (mV),"Coil Signal"" (mV)",Range (mV),M. Quad. Signal (emu),M. Raw' (emu),"M. Raw"" (emu)",Min. Temperature (K),Max. Temperature (K),Min. Field (Oe),Max. Field (Oe),Mass (grams),Motor Lag (deg),Pressure (Torr),VSM Status (code),Motor Status (code),Measure Status (code),Measure Count,System Temp. (K),Temp. Status (code),Field Status (code),Chamber Status (code),Motor Current (amps),Motor Heatsink Temp. (C),Map 01,Map 02,Map 03,Map 04,Map 05,Map 06,Map 07,Map 08,Map 09,Map 10,Map 11,Map 12,Map 13,Map 14,Map 15,Map 16
3773001718,50.17621994,-0.015851112,,,2,,,,9.251999891,,,,,,,50.17621994,50.17621994,-0.015851112,-0.015851112,,,4.434127808,,,,40,49.86156845,0,0,0,0.002441406,42.52199554,,,,,,,,,,,,,,,,
3773001785,50.16294098,1242.398254,-0.003209174,2.16E-06,1,0.999253354,40.02988815,1.996761567,9.239999577,-0.03471414,-0.006554437,0.25,-1.83E-05,-0.003206296,-4.21E-05,50.16296387,50.16296387,1231.196533,1253.599976,42.93954433,17.50520537,4.432786465,0,0,0,40,49.85749054,1,6,1,1.954040527,49.85337448,,,,,,,,,,,,,,,,
3773001838,50.16127777,2540.341919,-0.00227533,6.47E-07,1,0.999253354,40.02988815,1.996711549,9.239999577,-0.024613327,-0.004646782,0.25,-1.29E-05,-0.002273402,-2.98E-05,50.16138458,50.16138458,2528.739258,2551.94458,43.53670852,17.50528324,4.432592392,0,0,0,40,49.85678864,1,6,1,1.946258545,51.31964874,,,,,,,,,,,,,,,,
3773001889,50.16143417,3833.343384,-0.001913083,7.48E-07,1,0.999253354,40.02988815,1.996760553,9.239999577,-0.020698148,-0.003897472,0.25,-9.95E-06,-0.001911575,-2.42E-05,50.16143417,50.16143417,3820.563477,3846.123291,43.58126135,17.5126285,4.433239937,0,0,0,40,49.85588455,1,6,1,1.944580078,52.78592682,,,,,,,,,,,,,,,,
3773001941,50.16199493,5125.794922,-0.001712472,7.66E-07,1,0.999253354,40.02988815,1.996735192,9.239999577,-0.0185279,-0.003492524,0.25,-9.24E-06,-0.00171122,-2.20E-05,50.16181564,50.16181564,5114.457031,5137.132813,44.10964223,17.51610792,4.432892323,0,0,0,40,49.85560989,1,6,1,1.945953369,54.25220108,,,,,,,,,,,,,,,,
3773001993,50.16209793,6419.088623,-0.001579296,6.93E-07,1,0.999253354,40.02988815,1.996656333,9.239999577,-0.017087428,-0.003220965,0.25,-8.51E-06,-0.001578238,-2.03E-05,50.162117,50.162117,6409.584961,6428.592285,44.02991612,17.51224496,4.433134556,0,0,0,40,49.85578918,1,6,1,1.959533691,55.22971725,,,,,,,,,,,,,,,,
3773002045,50.16279793,7717.018799,-0.00148656,6.68E-07,1,0.999253354,40.02988815,1.99656593,9.239999577,-0.01608444,-0.003031641,0.25,-7.99E-06,-0.001485659,-1.90E-05,50.16267776,50.16267776,7705.805664,7728.231934,44.13699922,17.50961625,4.432870865,0,0,0,40,49.854599,1,6,1,1.943817139,56.20723343,,,,,,,,,,,,,,,,
3773002097,50.16119957,9010.87207,-0.001420053,8.30E-07,1,0.999253354,40.02988815,1.996539657,9.239999577,-0.015365565,-0.002896579,0.25,-7.67E-06,-0.001419284,-1.82E-05,50.16130066,50.16130066,8997.87793,9023.866211,44.00099586,17.51427543,4.433014393,0,0,0,40,49.85476685,1,6,1,1.96395874,57.67351151,,,,,,,,,,,,,,,,
3773002149,50.16230583,10306.7085,-0.001364271,9.44E-07,1,0.999253354,40.02988815,1.99661081,9.239999577,-0.014763891,-0.002780752,0.25,-7.16E-06,-0.001363625,-1.73E-05,50.16243744,50.16243744,10295.5,10317.91699,43.83138247,17.51287957,4.433110714,0,0,0,40,49.85439682,1,6,1,1.949615479,57.18475342,,,,,,,,,,,,,,,,
3773002201,50.16149521,11599.29297,-0.001319117,7.55E-07,1,0.999253354,40.02988815,1.996390089,9.239999577,-0.014272588,-0.002700145,0.25,-7.99E-06,-0.001318572,-1.78E-05,50.16150665,50.16150665,11586.29199,11612.29395,44.00724889,17.5126667,4.433025837,0,0,0,40,49.85313797,1,6,1,1.946716309,57.18475342,,,,,,,,,,,,,,,,
3773002253,50.16198349,12897.3999,-0.001283403,8.59E-07,1,0.999253354,40.02988815,1.996357936,9.239999577,-0.013889719,-0.002611844,0.25,-6.36E-06,-0.001282972,-1.59E-05,50.16188812,50.16188812,12884.58105,12910.21875,43.62581417,17.5144037,4.433585644,0,0,0,40,49.85259247,1,6,1,1.949462891,56.69599533,,,,,,,,,,,,,,,,
3773002305,50.16172028,14191.56689,-0.001247852,9.82E-07,1,0.999253354,40.02988815,1.996278224,9.239999577,-0.013504809,-0.002542685,0.25,-6.47E-06,-0.001247516,-1.57E-05,50.1616478,50.1616478,14178.38574,14204.74805,43.76807056,17.51772686,4.433320045,0,0,0,40,49.8519516,1,6,1,1.944122314,55.22971725,,,,,,,,,,,,,,,,
3773002381,50.16307259,16085.63721,-0.001212533,1.11E-06,1,0.999253354,40.02988815,1.996599738,9.239999577,-0.013124875,-0.00247707,0.25,-6.82E-06,-0.001212327,-1.58E-05,50.16313171,50.16313171,16072.72363,16098.55078,43.6648956,17.5151465,4.432729244,0,0,0,40,49.84952545,1,6,1,1.945037842,56.69599533,,,,,,,,,,,,,,,,
3773002433,50.16138649,17381.56934,-0.001184096,1.04E-06,1,0.999253354,40.02988815,1.996397393,9.239999577,-0.012819884,-0.002401638,0.25,-5.07E-06,-0.001183989,-1.39E-05,50.16155243,50.16155243,17370.05469,17393.08398,44.12136665,17.5128194,4.433049679,0,0,0,40,49.84972763,1,6,1,1.954803467,58.16226959,,,,,,,,,,,,,,,,
3773002485,50.16178703,18675.56055,-0.001161362,9.62E-07,1,0.999253354,40.02988815,1.99639101,9.239999577,-0.012572084,-0.002369443,0.25,-6.25E-06,-0.00116133,-1.49E-05,50.16178131,50.16178131,18662.64844,18688.47266,43.72117285,17.5186389,4.433609962,0,0,0,40,49.84918213,1,6,1,1.932983398,58.65102768,,,,,,,,,,,,,,,,
3773002537,50.16184044,19969.24902,-0.001140623,9.08E-07,1,0.999253354,40.02988815,1.996337539,9.239999577,-0.012349615,-0.002319142,0.25,-5.40E-06,-0.001140677,-1.39E-05,50.16186523,50.16186523,19954.82813,19983.66992,43.69068934,17.51457229,4.433520794,0,0,0,40,49.84783936,1,6,1,1.960449219,58.16226959,,,,,,,,,,,,,,,,
3773002589,50.1616745,21262.79688,-0.001116189,1.23E-06,1,0.999253354,40.02988815,1.996298931,9.239999577,-0.012088119,-0.002256353,0.25,-4.07E-06,-0.00111633,-1.23E-05,50.16148376,50.16148376,21249.77734,21275.81641,44.23548442,17.51764332,4.433112144,0,0,0,40,49.84720993,1,6,1,1.95526123,59.62854385,,,,,,,,,,,,,,,,
3773002641,50.16200256,22553.02148,-0.00108426,1.32E-06,1,0.999253354,40.02988815,1.996417618,9.239999577,-0.011742044,-0.0022018,0.25,-4.86E-06,-0.001084467,-1.29E-05,50.16192627,50.16192627,22543.60938,22562.43359,43.86968227,17.521842,4.433872223,0,0,0,40,49.84699249,1,6,1,1.946868896,58.65102768,,,,,,,,,,,,,,,,
3773002693,50.16266632,23849.07129,-0.001063797,1.27E-06,1,0.999253354,40.02988815,1.99647086,9.239999577,-0.011519987,-0.002168989,0.25,-5.56E-06,-0.001064069,-1.34E-05,50.1625824,50.1625824,23837.65039,23860.49219,44.18077042,17.51496485,4.433736801,0,0,0,40,49.84623337,1,6,1,1.947784424,59.62854385,,,,,,,,,,,,,,,,
3773002745,50.162714,25144.29004,-0.001050357,8.29E-07,1,0.999253354,40.02988815,1.996554341,9.239999577,-0.011376315,-0.002138478,0.25,-5.19E-06,-0.001050703,-1.30E-05,50.16250992,50.16250992,25132.87695,25155.70313,43.96816746,17.51572444,4.433454037,0,0,0,40,49.84589005,1,6,1,1.947784424,59.62854385,,,,,,,,,,,,,,,,
3773002797,50.16283417,26436.40527,-0.0010224,1.09E-06,1,0.999253354,40.02988815,1.996505501,9.239999577,-0.011075366,-0.002074377,0.25,-4.39E-06,-0.001022813,-1.19E-05,50.16283417,50.16283417,26423.48438,26449.32617,44.13778085,17.52214891,4.433736801,0,0,0,40,49.84442902,1,6,1,1.947784424,60.60606384,,,,,,,,,,,,,,,,
3773002849,50.16330528,27733.31348,-0.000992343,1.18E-06,1,0.999253354,40.02988815,1.996598725,9.239999577,-0.010749647,-0.002021009,0.25,-4.96E-06,-0.000992809,-1.23E-05,50.16345596,50.16345596,27721.91602,27744.71094,44.20031113,17.51749814,4.433845043,0,0,0,40,49.84307098,1,6,1,1.943206787,60.11730194,,,,,,,,,,,,,,,,
3773002901,50.16358185,29024.94434,-0.000973639,8.31E-07,1,0.999253354,40.02988815,1.996796484,9.239999577,-0.01055046,-0.001973994,0.25,-4.02E-06,-0.000974171,-1.12E-05,50.16355133,50.16355133,29012.13281,29037.75586,44.18624182,17.51215611,4.433894157,0,0,0,40,49.8421936,1,6,1,1.944732666,59.62854385,,,,,,,,,,,,,,,,
3773002984,50.16592026,29596.55273,-0.000245363,1.32E-06,1,0.999253354,40.02988815,1.996789802,9.229999967,-0.002662296,-0.000478661,0.25,7.21E-07,-0.000245518,-1.08E-06,50.1660881,50.1660881,29583.44141,29609.66406,43.69068934,17.51277615,4.434034824,0,0,0,40,49.83878326,1,6,1,1.945037842,58.65102768,,,,,,,,,,,,,,,,
3773003036,50.16379738,28301.83594,-0.00023527,1.26E-06,1,0.999253354,40.02988815,1.996788558,9.229999967,-0.002551531,-0.000464763,0.25,1.56E-07,-0.000235397,-1.58E-06,50.16388702,50.16388702,28288.93164,28314.74023,43.96504095,17.51281074,4.434201241,0,0,0,40,49.84099197,1,6,1,1.956634521,59.62854385,,,,,,,,,,,,,,,,
3773003088,50.16484833,27007.61133,-0.000244609,1.40E-06,1,0.999253354,40.02988815,1.996641609,9.229999967,-0.002654091,-0.000474128,0.25,9.97E-07,-0.00024473,-8.07E-07,50.1645546,50.1645546,26997.99414,27017.22852,44.12449317,17.51224735,4.4338274,0,0,0,40,49.84815979,1,6,1,1.9480896,60.11730194,,,,,,,,,,,,,,,,
3773003140,50.16236687,25710.89453,-0.000256857,1.16E-06,1,0.999253354,40.02988815,1.996611626,9.229999967,-0.0027839,-0.000513401,0.25,-3.88E-07,-0.000256955,-2.28E-06,50.16222382,50.16222382,25699.78125,25722.00781,43.90485555,17.5171822,4.433809757,0,0,0,40,49.84313202,1,6,1,1.945800781,59.62854385,,,,,,,,,,,,,,,,
3773003192,50.16256332,24421.51074,-0.00026467,1.00E-06,1,0.999253354,40.02988815,1.996361878,9.229999967,-0.002866399,-0.000537879,0.25,-1.22E-06,-0.000264747,-3.18E-06,50.16235352,50.16235352,24408.59961,24434.42188,44.41525898,17.52047963,4.434031487,0,0,0,40,49.84382248,1,6,1,1.942901611,60.11730194,,,,,,,,,,,,,,,,
3773003243,50.16225815,23128.80566,-0.000296643,1.03E-06,1,0.999253354,40.02988815,1.996528233,9.229999967,-0.003214313,-0.000594075,0.25,-5.58E-07,-0.000296715,-2.75E-06,50.16225815,50.16225815,23115.79688,23141.81445,43.99630609,17.51461206,4.433743477,0,0,0,40,49.84495163,1,6,1,1.954040527,60.60606384,,,,,,,,,,,,,,,,
3773003295,50.16093254,21830.52148,-0.000303651,1.16E-06,1,0.999253354,40.02988815,1.996147681,9.229999967,-0.003289148,-0.000609432,0.25,-7.06E-07,-0.000303702,-2.95E-06,50.16086197,50.16086197,21818.80859,21842.23438,43.83685387,17.52128132,4.4338274,0,0,0,40,49.84539032,1,6,1,1.960601807,60.11730194,,,,,,,,,,,,,,,,
3773003347,50.16067314,20534.79883,-0.000320055,1.09E-06,1,0.999253354,40.02988815,1.996277801,9.229999967,-0.003465516,-0.000649389,0.25,-1.39E-06,-0.000320081,-3.76E-06,50.16067886,50.16067886,20521.80859,20547.78906,44.32380844,17.5174042,4.433642387,0,0,0,40,49.84618759,1,6,1,1.959228516,61.58358002,,,,,,,,,,,,,,,,
3773003399,50.15994453,19241.09961,-0.000345785,1.25E-06,1,0.999253354,40.02988815,1.996258779,9.229999967,-0.003745389,-0.000692979,0.25,-7.11E-07,-0.000345795,-3.28E-06,50.16001129,50.16001129,19226.7793,19255.41992,44.44730575,17.52503948,4.434015751,0,0,0,40,49.84649658,1,6,1,1.952667236,61.09482193,,,,,,,,,,,,,,,,
3773003451,50.15960503,17945.62598,-0.000363685,1.14E-06,1,0.999253354,40.02988815,1.9962215,9.229999967,-0.003936673,-0.000741095,0.25,-1.88E-06,-0.000363661,-4.58E-06,50.15949631,50.15949631,17932.83203,17958.41992,44.44417923,17.52369633,4.433699608,0,0,0,40,49.84778976,1,6,1,1.947784424,60.60606384,,,,,,,,,,,,,,,,
3773003503,50.15909576,16652.57227,-0.0003854,1.06E-06,1,0.999253354,40.02988815,1.996081816,9.220000356,-0.004170281,-0.000790014,0.25,-2.43E-06,-0.000385344,-5.30E-06,50.15903091,50.15903091,16639.6543,16665.49023,44.35976335,17.52733965,4.433846951,0,0,0,40,49.84856415,1,6,1,1.958465576,62.0723381,,,,,,,,,,,,,,,,
3773003578,50.15970612,14780.9707,-0.00041856,1.14E-06,1,0.999253354,40.02988815,1.996155094,9.239999577,-0.00452944,-0.000854388,0.25,-2.31E-06,-0.000418459,-5.42E-06,50.15964127,50.15964127,14768.25977,14793.68164,43.73289728,17.52668255,4.434244156,0,0,0,40,49.85269928,1,6,1,1.964569092,60.11730194,,,,,,,,,,,,,,,,
3773003630,50.15919876,13486.03906,-0.000450738,7.74E-07,1,0.999253354,40.02988815,1.996201285,9.239999577,-0.004876825,-0.000923263,0.25,-2.79E-06,-0.000450596,-6.14E-06,50.15921021,50.15921021,13472.9248,13499.15332,44.09557291,17.52251785,4.434332848,0,0,0,40,49.85110474,1,6,1,1.945343018,60.60606384,,,,,,,,,,,,,,,,
3773003682,50.15778732,12191.74902,-0.000476485,8.09E-07,1,0.999253354,40.02988815,1.996070956,9.239999577,-0.005154664,-0.000976261,0.25,-2.98E-06,-0.000476302,-6.52E-06,50.15776443,50.15776443,12178.9668,12204.53125,44.31599215,17.5260458,4.434546947,0,0,0,40,49.8510704,1,6,1,1.952209473,61.58358002,,,,,,,,,,,,,,,,
3773003734,50.15786934,10899.19678,-0.000503586,9.46E-07,1,0.999253354,40.02988815,1.995725108,9.239999577,-0.005446162,-0.001033796,0.25,-3.36E-06,-0.000503356,-7.10E-06,50.15764236,50.15764236,10887.99512,10910.39844,43.95566141,17.51868546,4.434473991,0,0,0,40,49.85277176,1,6,1,1.953887939,61.58358002,,,,,,,,,,,,,,,,
3773003786,50.15726662,9603.949219,-0.000532397,9.32E-07,1,0.999253354,40.02988815,1.995742086,9.229999967,-0.005758495,-0.001086931,0.25,-3.00E-06,-0.000532123,-6.96E-06,50.15726089,50.15726089,9592.636719,9615.261719,44.1033892,17.52086615,4.434920788,0,0,0,40,49.85325623,1,6,1,1.950531006,61.09482193,,,,,,,,,,,,,,,,
3773003838,50.15745735,8311.087402,-0.000558655,1.09E-06,1,0.999253354,40.02988815,1.995818128,9.239999577,-0.00604099,-0.001147866,0.25,-3.83E-06,-0.000558326,-7.98E-06,50.15755844,50.15755844,8296.577148,8325.597656,43.71960959,17.5167426,4.434764385,0,0,0,40,49.85293579,1,6,1,1.952667236,61.58358002,,,,,,,,,,,,,,,,
3773003890,50.1564827,7015.367188,-0.000583066,8.13E-07,1,0.999253354,40.02988815,1.995692302,9.239999577,-0.006304502,-0.001196052,0.25,-3.83E-06,-0.000582686,-8.16E-06,50.15632629,50.15632629,7006.246094,7024.488281,44.47309949,17.52443264,4.434427738,0,0,0,40,49.85380554,1,6,1,1.934814453,61.58358002,,,,,,,,,,,,,,,,
3773003942,50.15696144,5716.534424,-0.000603236,6.48E-07,1,0.999253354,40.02988815,1.995549088,9.239999577,-0.006521434,-0.001238957,0.25,-4.12E-06,-0.000602804,-8.60E-06,50.15711594,50.15711594,5703.611816,5729.457031,44.62239053,17.52518728,4.434596539,0,0,0,40,49.85218811,1,6,1,1.963043213,62.56109619,,,,,,,,,,,,,,,,
3773003994,50.15551567,4423.396484,-0.000618684,4.80E-07,1,0.999253354,40.02988815,1.995796124,9.250000119,-0.006689877,-0.001265003,0.25,-3.69E-06,-0.000618208,-8.29E-06,50.15556335,50.15556335,4410.588867,4436.204102,44.37774081,17.52649536,4.43456316,0,0,0,40,49.85477829,1,6,1,1.949005127,62.0723381,,,,,,,,,,,,,,,,
3773004046,50.15693855,3128.715454,-0.000616797,5.81E-07,1,0.999253354,40.02988815,1.995398177,9.239999577,-0.006667881,-0.001260569,0.25,-3.66E-06,-0.000616288,-8.24E-06,50.15698624,50.15698624,3115.612793,3141.818115,44.61379262,17.53104989,4.435119629,0,0,0,40,49.85427856,1,6,1,1.93939209,61.58358002,,,,,,,,,,,,,,,,
3773004098,50.15591621,1836.577759,-0.000563997,5.08E-07,1,0.999253354,40.02988815,1.995478649,9.239999577,-0.006095549,-0.001160545,0.25,-4.07E-06,-0.000563496,-8.26E-06,50.15593338,50.15593338,1823.595093,1849.560425,43.88531484,17.53290986,4.434793472,0,0,0,40,49.8553009,1,6,1,1.940917969,61.58358002,,,,,,,,,,,,,,,,
3773004150,50.15625,541.4932251,-0.00016975,1.14E-06,1,0.999253354,40.02988815,1.995468649,9.239999577,-0.001835631,-0.00034326,0.25,-6.70E-07,-0.000169596,-1.93E-06,50.15647125,50.15647125,524.9785767,558.0078735,44.61926402,17.52778495,4.435108185,0,0,0,40,49.85395813,1,6,1,1.953125,60.60606384,,,,,,,,,,,,,,,,
3773004226,50.15645981,-1350.613831,0.003086387,1.98E-06,1,0.999253354,40.02988815,1.99574336,9.229999967,0.033366693,0.006318011,0.25,1.92E-05,0.003083613,4.21E-05,50.15652084,50.15652084,-1363.608032,-1337.619629,43.89078624,17.52557404,4.435233593,0,0,0,40,49.85386276,1,6,1,1.95022583,60.60606384,,,,,,,,,,,,,,,,
3773004278,50.15542984,-2648.050659,0.002237971,9.26E-07,1,0.999253354,40.02988815,1.995743403,9.229999967,0.024194991,0.004585658,0.25,1.43E-05,0.002236069,3.09E-05,50.15526199,50.15526199,-2661.063232,-2635.038086,43.88531484,17.51068363,4.43497467,0,0,0,40,49.85406494,1,6,1,1.944274902,60.60606384,,,,,,,,,,,,,,,,
3773004330,50.15539932,-3943.199707,0.001895372,7.11E-07,1,0.999253354,40.02988815,1.995958065,9.229999967,0.020499217,0.003857567,0.25,9.64E-06,0.001893885,2.37E-05,50.15526199,50.15526199,-3956.306885,-3930.092529,44.12214828,17.53208973,4.434877872,0,0,0,40,49.85483932,1,6,1,1.947021484,61.09482193,,,,,,,,,,,,,,,,
3773004382,50.15589142,-5239.30249,0.001702168,6.04E-07,1,0.999253354,40.02988815,1.995939895,9.229999967,0.018409182,0.003472124,0.25,9.36E-06,0.001700928,2.20E-05,50.15593338,50.15593338,-5248.707031,-5229.897949,43.93221255,17.52354124,4.434873104,0,0,0,40,49.85406494,1,6,1,1.945800781,61.09482193,,,,,,,,,,,,,,,,
3773004434,50.15530014,-6532.763184,0.001574835,8.69E-07,1,0.999253354,40.02988815,1.99610099,9.229999967,0.017035512,0.003206761,0.25,8.09E-06,0.001573788,1.98E-05,50.15522766,50.15522766,-6545.485352,-6520.041016,44.12683805,17.5260032,4.435146332,0,0,0,40,49.85357666,1,6,1,1.94519043,61.09482193,,,,,,,,,,,,,,,,
3773004485,50.15595818,-7825.665527,0.001485595,8.14E-07,1,0.999253354,40.02988815,1.995908717,9.229999967,0.016068104,0.003033873,0.25,8.46E-06,0.001484696,1.95E-05,50.15589905,50.15589905,-7838.475098,-7812.855957,44.14794202,17.52667324,4.434961319,0,0,0,40,49.85264969,1,6,1,1.945800781,61.58358002,,,,,,,,,,,,,,,,
3773004537,50.15614319,-9122.611816,0.001413305,8.14E-07,1,0.999253354,40.02988815,1.996082934,9.229999967,0.015288281,0.002887778,0.25,8.15E-06,0.001412542,1.87E-05,50.1560173,50.1560173,-9137.013672,-9108.209961,44.20500091,17.52688455,4.43573904,0,0,0,40,49.8533783,1,6,1,1.945495605,60.11730194,,,,,,,,,,,,,,,,
3773004589,50.15627861,-10420.12695,0.001354835,1.10E-06,1,0.999253354,40.02988815,1.996201218,9.229999967,0.01465825,0.002764973,0.25,7.47E-06,0.001354195,1.76E-05,50.15642166,50.15642166,-10433.1377,-10407.11621,44.23626605,17.52768179,4.435512066,0,0,0,40,49.85284042,1,6,1,1.943817139,61.58358002,,,,,,,,,,,,,,,,
3773004641,50.1566143,-11712.38477,0.001314467,9.83E-07,1,0.999253354,40.02988815,1.995953553,9.229999967,0.014220308,0.002685101,0.25,7.50E-06,0.001313933,1.73E-05,50.1566391,50.1566391,-11723.69043,-11701.0791,44.19952951,17.5263852,4.435754776,0,0,0,40,49.85173798,1,6,1,1.947784424,61.09482193,,,,,,,,,,,,,,,,
3773004693,50.15726662,-13006.2085,0.001273696,1.11E-06,1,0.999253354,40.02988815,1.995647252,9.229999967,0.013776077,0.002613098,0.25,8.33E-06,0.001273258,1.78E-05,50.15759659,50.15759659,-13019.21387,-12993.20313,44.14403388,17.52831536,4.43585062,0,0,0,40,49.85095215,1,6,1,1.937103271,61.58358002,,,,,,,,,,,,,,,,
3773004745,50.1573143,-14299.11865,0.001243791,1.09E-06,1,0.999253354,40.02988815,1.995626875,9.229999967,0.013453522,0.00255137,0.25,8.09E-06,0.00124345,1.73E-05,50.15746307,50.15746307,-14308.52344,-14289.71387,44.28238213,17.5222119,4.435843468,0,0,0,40,49.85096359,1,6,1,1.938476563,61.58358002,,,,,,,,,,,,,,,,
3773004821,50.15865326,-16190.02588,0.001204942,1.40E-06,1,0.999253354,40.02988815,1.995701406,9.229999967,0.013033742,0.00247946,0.25,8.53E-06,0.001204729,1.75E-05,50.1586113,50.1586113,-16204.39551,-16175.65625,44.15185017,17.51822375,4.435890675,0,0,0,40,49.85100937,1,6,1,1.934356689,59.13978577,,,,,,,,,,,,,,,,
3773004873,50.15812111,-17484.65527,0.001180507,1.15E-06,1,0.999253354,40.02988815,1.995811569,9.229999967,0.012773363,0.002416488,0.25,7.16E-06,0.00118039,1.59E-05,50.15809631,50.15809631,-17497.55469,-17471.75586,44.54031954,17.51606636,4.436369419,0,0,0,40,49.84891891,1,6,1,1.959228516,59.62854385,,,,,,,,,,,,,,,,
3773004925,50.1574707,-18778.19629,0.001158266,9.72E-07,1,0.999253354,40.02988815,1.995935982,9.229999967,0.012533726,0.002374587,0.25,7.34E-06,0.00115823,1.59E-05,50.15752411,50.15752411,-18791.50586,-18764.88672,43.54217992,17.51891161,4.436185837,0,0,0,40,49.84876633,1,6,1,1.94519043,61.09482193,,,,,,,,,,,,,,,,
3773004977,50.15797806,-20070.76563,0.001128351,1.19E-06,1,0.999253354,40.02988815,1.995720978,9.229999967,0.01220865,0.002318517,0.25,7.65E-06,0.001128392,1.60E-05,50.15773773,50.15773773,-20083.58203,-20057.94922,44.16201134,17.52558495,4.43571949,0,0,0,40,49.84952545,1,6,1,1.949310303,60.60606384,,,,,,,,,,,,,,,,
3773005029,50.15802002,-21371.07324,0.00111228,1.19E-06,1,0.999253354,40.02988815,1.995666216,9.229999967,0.012039503,0.002262682,0.25,5.43E-06,0.001112416,1.37E-05,50.1579895,50.1579895,-21382.48438,-21359.66211,44.27222096,17.53545825,4.4361763,0,0,0,40,49.84761047,1,6,1,1.93572998,62.0723381,,,,,,,,,,,,,,,,
3773005081,50.1593647,-22661.44824,0.001091938,1.03E-06,1,0.999253354,40.02988815,1.996061837,9.229999967,0.011816649,0.002253198,0.25,8.23E-06,0.001092127,1.63E-05,50.15949631,50.15949631,-22675.85742,-22647.03906,44.57314794,17.5213075,4.436436176,0,0,0,40,49.84731674,1,6,1,1.944122314,61.09482193,,,,,,,,,,,,,,,,
3773005133,50.15864754,-23955.01563,0.001078044,8.28E-07,1,0.999253354,40.02988815,1.995869301,9.229999967,0.011670192,0.002201821,0.25,6.04E-06,0.001078322,1.40E-05,50.15859985,50.15859985,-23967.89258,-23942.13867,43.75165636,17.52687447,4.436528683,0,0,0,40,49.84495163,1,6,1,1.947937012,61.09482193,,,,,,,,,,,,,,,,
3773005185,50.15926933,-25249.62793,0.00104821,1.40E-06,1,0.999253354,40.02988815,1.995857653,9.229999967,0.011346768,0.002147618,0.25,6.49E-06,0.001048551,1.42E-05,50.15910339,50.15910339,-25261.13477,-25238.12109,43.98067352,17.52407677,4.436362743,0,0,0,40,49.84452057,1,6,1,1.95022583,61.09482193,,,,,,,,,,,,,,,,
3773005237,50.1585331,-26542.83203,0.001027385,1.18E-06,1,0.999253354,40.02988815,1.995851328,9.229999967,0.011123573,0.002096939,0.25,5.62E-06,0.001027796,1.32E-05,50.15855026,50.15855026,-26555.60938,-26530.05469,43.67193025,17.52117162,4.436740398,0,0,0,40,49.84468842,1,6,1,1.948547363,61.58358002,,,,,,,,,,,,,,,,
3773005289,50.16001701,-27837.3125,0.001002363,1.36E-06,1,0.999253354,40.02988815,1.996112864,9.229999967,0.010855561,0.002041969,0.25,5.10E-06,0.001002838,1.25E-05,50.16005707,50.16005707,-27848.83008,-27825.79492,43.68834445,17.5224006,4.436040401,0,0,0,40,49.84329987,1,6,1,1.946258545,61.58358002,,,,,,,,,,,,,,,,
3773005341,50.16024399,-29131.58496,0.000982409,8.51E-07,1,0.999253354,40.02988815,1.995935749,9.229999967,0.010639067,0.002002637,0.25,5.13E-06,0.000982943,1.24E-05,50.16014099,50.16014099,-29144.06055,-29119.10938,43.70788517,17.52357344,4.436436176,0,0,0,40,49.8420372,1,6,1,1.945953369,62.56109619,,,,,,,,,,,,,,,,
3773005424,50.1607933,-29024.86133,0.000219429,1.08E-06,1,0.999253354,40.02988815,1.995945891,9.239999577,0.002375933,0.000449445,0.25,1.34E-06,0.000219546,2.96E-06,50.16067886,50.16067886,-29037.57227,-29012.15039,44.43010992,17.52041511,4.437120438,0,0,0,40,49.84329987,1,6,1,1.946105957,59.13978577,,,,,,,,,,,,,,,,
3773005476,50.15959358,-27730.05859,0.000224281,1.06E-06,1,0.999253354,40.02988815,1.996079711,9.239999577,0.002428592,0.000458574,0.25,1.30E-06,0.000224385,2.95E-06,50.15964127,50.15964127,-27739.40234,-27720.71484,43.95175326,17.52272796,4.436702251,0,0,0,40,49.84235764,1,6,1,1.953277588,61.09482193,,,,,,,,,,,,,,,,
3773005528,50.15953445,-26432.7334,0.000250596,8.88E-07,1,0.999253354,40.02988815,1.99577457,9.239999577,0.002714948,0.000501377,0.25,4.41E-07,0.000250702,2.29E-06,50.15953445,50.15953445,-26445.44141,-26420.02539,44.30192284,17.52893387,4.436536312,0,0,0,40,49.8445816,1,6,1,1.945953369,60.60606384,,,,,,,,,,,,,,,,
3773005580,50.15897179,-25136.80273,0.000255248,1.37E-06,1,0.999253354,40.02988815,1.995914404,9.239999577,0.00276444,0.000515619,0.25,9.02E-07,0.000255335,2.79E-06,50.15900803,50.15900803,-25149.60938,-25123.99609,44.18546019,17.53116681,4.436863899,0,0,0,40,49.84373856,1,6,1,1.955718994,61.58358002,,,,,,,,,,,,,,,,
3773005632,50.15875053,-23840.25977,0.000268452,8.64E-07,1,0.999253354,40.02988815,1.995798145,9.239999577,0.002906377,0.000546003,0.25,1.30E-06,0.000268521,3.28E-06,50.15856552,50.15856552,-23851.70508,-23828.81445,43.99630609,17.53303047,4.436769009,0,0,0,40,49.84550858,1,6,1,1.947784424,61.58358002,,,,,,,,,,,,,,,,
3773005684,50.15864754,-22548.17578,0.000292146,1.29E-06,1,0.999253354,40.02988815,1.995915908,9.239999577,0.003160565,0.000606741,0.25,2.57E-06,0.000292192,4.73E-06,50.15859985,50.15859985,-22561.1582,-22535.19336,44.2816005,17.52508825,4.436985016,0,0,0,40,49.84564972,1,6,1,1.959533691,61.09482193,,,,,,,,,,,,,,,,
3773005736,50.15821838,-21252.47949,0.000307594,1.09E-06,1,0.999253354,40.02988815,1.995919617,9.239999577,0.003328908,0.000630844,0.25,1.97E-06,0.000307626,4.25E-06,50.15821838,50.15821838,-21265.5918,-21239.36719,44.01115703,17.52512998,4.43682766,0,0,0,40,49.8465538,1,6,1,1.947479248,61.09482193,,,,,,,,,,,,,,,,
3773005788,50.1576786,-19959.22949,0.000328013,1.09E-06,1,0.999253354,40.02988815,1.996025073,9.239999577,0.003551212,0.000665072,0.25,1.39E-06,0.000328029,3.82E-06,50.1578331,50.1578331,-19970.5332,-19947.92578,44.09166477,17.52536366,4.436741829,0,0,0,40,49.84693527,1,6,1,1.94732666,59.62854385,,,,,,,,,,,,,,,,
3773005840,50.15784645,-18663.50098,0.000348652,7.20E-07,1,0.999253354,40.02988815,1.995917553,9.239999577,0.003774151,0.000707082,0.25,1.50E-06,0.000348644,4.09E-06,50.15809631,50.15809631,-18676.83008,-18650.17188,43.70944842,17.52976017,4.436472416,0,0,0,40,49.84725571,1,6,1,1.935119629,63.04985428,,,,,,,,,,,,,,,,
3773005892,50.15703964,-17370.0791,0.000379114,1.16E-06,1,0.999253354,40.02988815,1.995893068,9.239999577,0.004102254,0.000775961,0.25,2.29E-06,0.000379074,5.11E-06,50.15698624,50.15698624,-17379.46484,-17360.69336,43.56015738,17.52259124,4.436497211,0,0,0,40,49.84856415,1,6,1,1.958312988,62.0723381,,,,,,,,,,,,,,,,
3773005943,50.15699768,-16075.65039,0.000399444,9.72E-07,1,0.999253354,40.02988815,1.995828982,9.239999577,0.004322825,0.000811915,0.25,1.90E-06,0.000399378,4.86E-06,50.15702057,50.15702057,-16088.35449,-16062.94629,44.05180172,17.52656173,4.436759949,0,0,0,40,49.84863281,1,6,1,1.949005127,62.0723381,,,,,,,,,,,,,,,,
3773005995,50.1558857,-14782.60254,0.000421556,8.98E-07,1,0.999253354,40.02988815,1.995766544,9.239999577,0.004562184,0.000853971,0.25,1.74E-06,0.000421459,4.87E-06,50.15582657,50.15582657,-14795.18945,-14770.01563,44.23704767,17.52581786,4.437129974,0,0,0,40,49.85165405,1,6,1,1.951293945,61.58358002,,,,,,,,,,,,,,,,
3773006071,50.15589714,-12891.43652,0.000465721,1.22E-06,1,0.999253354,40.02988815,1.996012078,9.229999967,0.005039988,0.000944734,0.25,2.04E-06,0.000465565,5.50E-06,50.15594482,50.15594482,-12904.44727,-12878.42578,44.43479969,17.52517105,4.437438488,0,0,0,40,49.8510704,1,6,1,1.953582764,60.11730194,,,,,,,,,,,,,,,,
3773006123,50.15443802,-11602.08105,0.000496742,9.59E-07,1,0.999253354,40.02988815,1.995826117,9.229999967,0.005374889,0.001007328,0.25,2.16E-06,0.000496542,5.85E-06,50.1545105,50.1545105,-11614.88867,-11589.27344,44.10964223,17.52775587,4.437206268,0,0,0,40,49.85269928,1,6,1,1.943359375,61.58358002,,,,,,,,,,,,,,,,
3773006175,50.15546799,-10304.11182,0.000525633,7.74E-07,1,0.999253354,40.02988815,1.995933744,9.229999967,0.005688611,0.0010593,0.25,1.67E-06,0.000525391,5.58E-06,50.15546799,50.15546799,-10316.91211,-10291.31152,44.30035958,17.530175,4.43747139,0,0,0,40,49.85301971,1,6,1,1.961364746,61.58358002,,,,,,,,,,,,,,,,
3773006227,50.15586281,-9013.363281,0.000544293,7.91E-07,1,0.999253354,40.02988815,1.995992658,9.229999967,0.005889017,0.001104078,0.25,2.40E-06,0.000544002,6.45E-06,50.15582657,50.15582657,-9024.958984,-9001.767578,44.06274451,17.53016653,4.437270641,0,0,0,40,49.85281754,1,6,1,1.944580078,60.60606384,,,,,,,,,,,,,,,,
3773006279,50.15541267,-7717.981934,0.000572436,6.11E-07,1,0.999253354,40.02988815,1.995730648,9.229999967,0.006192363,0.001160791,0.25,2.51E-06,0.000572092,6.77E-06,50.15564728,50.15564728,-7732.595703,-7703.368164,44.55595211,17.53359961,4.437105179,0,0,0,40,49.85255814,1,6,1,1.938476563,61.09482193,,,,,,,,,,,,,,,,
3773006331,50.15605164,-6423.321533,0.000601155,7.15E-07,1,0.999253354,40.02988815,1.995975198,9.229999967,0.006505786,0.001205906,0.25,1.42E-06,0.000600765,5.89E-06,50.15615845,50.15615845,-6434.620117,-6412.022949,44.22063348,17.52962506,4.437520504,0,0,0,40,49.85369873,1,6,1,1.945495605,61.58358002,,,,,,,,,,,,,,,,
3773006383,50.15437889,-5129.874756,0.000617998,6.43E-07,1,0.999253354,40.02988815,1.99600929,9.229999967,0.00668559,0.001251488,0.25,2.55E-06,0.000617551,7.15E-06,50.15427017,50.15427017,-5141.182617,-5118.566895,44.05492823,17.52537216,4.437260151,0,0,0,40,49.85412598,1,6,1,1.944885254,61.58358002,,,,,,,,,,,,,,,,
3773006435,50.15416336,-3832.56897,0.000627642,5.92E-07,1,0.999253354,40.02988815,1.996159379,9.229999967,0.006789341,0.001274653,0.25,2.93E-06,0.000627148,7.59E-06,50.1542244,50.1542244,-3841.971191,-3823.166748,43.45698241,17.52360629,4.437138081,0,0,0,40,49.85322189,1,6,1,1.946716309,61.58358002,,,,,,,,,,,,,,,,
3773006487,50.15547752,-2541.749268,0.000610573,5.18E-07,1,0.999253354,40.02988815,1.996146984,9.229999967,0.006603896,0.001242136,0.25,3.05E-06,0.000610058,7.59E-06,50.15559769,50.15559769,-2551.050293,-2532.448242,43.85483133,17.52280902,4.437959194,0,0,0,40,49.85406494,1,6,1,1.961517334,61.09482193,,,,,,,,,,,,,,,,
3773006539,50.15350533,-1247.519348,0.000488265,2.36E-06,1,0.999253354,40.02988815,1.995969665,9.229999967,0.005278789,0.001001489,0.25,3.21E-06,0.000487822,6.84E-06,50.15353012,50.15353012,-1258.82019,-1236.218506,44.05805474,17.52499749,4.43775177,0,0,0,40,49.85520554,1,6,1,1.947937012,63.04985428,,,,,,,,,,,,,,,,
3773006591,50.15449715,48.78623009,-0.001984733,1.09E-05,1,0.999253354,40.02988815,1.996017517,9.229999967,-0.021460065,-0.004055837,0.25,-1.17E-05,-0.001982873,-2.64E-05,50.15446091,50.15446091,35.64915848,61.9233017,44.28785353,17.52719948,4.438016891,0,0,0,40,49.85325623,1,6,1,1.943359375,62.56109619,,,,,,,,,,,,,,,,
3773006666,50.15556335,1916.174255,-0.002608161,3.32E-06,1,0.999253354,40.02988815,1.996054365,9.239999577,-0.028203654,-0.005327517,0.25,-1.51E-05,-0.00260588,-3.44E-05,50.15563583,50.15563583,1904.569336,1927.779175,43.68834445,17.51570575,4.43802166,0,0,0,40,49.85506439,1,6,1,1.947479248,60.60606384,,,,,,,,,,,,,,,,
3773006718,50.15351868,3210.738037,-0.002069853,7.13E-07,1,0.999253354,40.02988815,1.9959178,9.239999577,-0.022386904,-0.004202854,0.25,-9.64E-06,-0.002068168,-2.50E-05,50.15335083,50.15335083,3199.494873,3221.981201,44.3253717,17.5232714,4.437177181,0,0,0,40,49.85490799,1,6,1,1.953125,60.60606384,,,,,,,,,,,,,,,,
3773006770,50.15397263,4507.769043,-0.001808041,6.83E-07,1,0.999253354,40.02988815,1.995996252,9.239999577,-0.019555482,-0.003680322,0.25,-9.22E-06,-0.001806668,-2.27E-05,50.15399551,50.15399551,4494.599609,4520.938477,44.07994034,17.52141384,4.43778944,0,0,0,40,49.85424423,1,6,1,1.93145752,60.60606384,,,,,,,,,,,,,,,,
3773006822,50.15474892,5800.704102,-0.001646183,8.15E-07,1,0.999253354,40.02988815,1.996043802,9.239999577,-0.017806496,-0.003350217,0.25,-8.31E-06,-0.001645032,-2.06E-05,50.15467834,50.15467834,5787.788086,5813.620117,43.76103591,17.50926379,4.437858105,0,0,0,40,49.85316086,1,6,1,1.931915283,62.56109619,,,,,,,,,,,,,,,,
3773006874,50.15425301,7092.427246,-0.001536781,9.28E-07,1,0.999253354,40.02988815,1.995988052,9.239999577,-0.016624282,-0.003124548,0.25,-7.47E-06,-0.001535805,-1.89E-05,50.15419769,50.15419769,7079.617676,7105.236816,43.18888383,17.52307784,4.437224388,0,0,0,40,49.8533783,1,6,1,1.962585449,61.58358002,,,,,,,,,,,,,,,,
3773006926,50.15461731,8390.096191,-0.001461652,7.63E-07,1,0.999253354,40.02988815,1.996023189,9.239999577,-0.01581371,-0.002967302,0.25,-6.67E-06,-0.00146082,-1.75E-05,50.15472412,50.15472412,8377.085938,8403.106445,43.89625764,17.53035082,4.4375844,0,0,0,40,49.85223389,1,6,1,1.941680908,61.09482193,,,,,,,,,,,,,,,,
3773006978,50.15493584,9688.130371,-0.001394008,8.67E-07,1,0.999253354,40.02988815,1.995948689,9.239999577,-0.015081069,-0.002836949,0.25,-7.00E-06,-0.001393302,-1.74E-05,50.15484619,50.15484619,9678.126953,9698.133789,44.02288146,17.52440891,4.437808514,0,0,0,40,49.85180664,1,6,1,1.950073242,61.58358002,,,,,,,,,,,,,,,,
3773007030,50.15527534,10981.06299,-0.001343761,1.04E-06,1,0.999253354,40.02988815,1.995865326,9.239999577,-0.014539294,-0.002726988,0.25,-6.03E-06,-0.001343176,-1.60E-05,50.15537262,50.15537262,10968.44434,10993.68164,44.26987607,17.5312171,4.437742233,0,0,0,40,49.85177231,1,6,1,1.949462891,61.58358002,,,,,,,,,,,,,,,,
3773007082,50.15480804,12274.76709,-0.001297093,9.87E-07,1,0.999253354,40.02988815,1.996054604,9.239999577,-0.014035312,-0.002639525,0.25,-6.45E-06,-0.001296611,-1.61E-05,50.15505981,50.15505981,12261.95508,12287.5791,44.2433007,17.52119542,4.438480854,0,0,0,40,49.85148621,1,6,1,1.946411133,61.09482193,,,,,,,,,,,,,,,,
3773007134,50.15543175,13568.60498,-0.001269256,1.01E-06,1,0.999253354,40.02988815,1.99559986,9.239999577,-0.013731911,-0.002583414,0.25,-6.40E-06,-0.001268871,-1.58E-05,50.15537262,50.15537262,13554.08691,13583.12305,43.20607966,17.51767429,4.438443184,0,0,0,40,49.85157013,1,6,1,1.943206787,61.58358002,,,,,,,,,,,,,,,,
3773007186,50.15547943,14861.76318,-0.001234234,9.07E-07,1,0.999253354,40.02988815,1.995638174,9.239999577,-0.013354419,-0.002511033,0.25,-6.11E-06,-0.001233946,-1.53E-05,50.15546799,50.15546799,14848.67676,14874.84961,43.49137407,17.52706967,4.438977242,0,0,0,40,49.85040665,1,6,1,1.941375732,62.0723381,,,,,,,,,,,,,,,,
3773007237,50.15549088,16152.55713,-0.001203966,9.86E-07,1,0.999253354,40.02988815,1.995829196,9.239999577,-0.013028417,-0.00245311,0.25,-6.26E-06,-0.001203767,-1.52E-05,50.15546799,50.15546799,16139.83203,16165.28223,44.16044808,17.52178491,4.438428879,0,0,0,40,49.8494072,1,6,1,1.935577393,61.09482193,,,,,,,,,,,,,,,,
3773007313,50.15626717,18048.19141,-0.001174596,1.65E-06,1,0.999253354,40.02988815,1.983389516,9.239999577,-0.012634527,-0.00239188,0.25,-7.28E-06,-0.001174514,-1.60E-05,50.15642166,50.15642166,18035.27539,18061.10742,44.54500931,17.52550261,4.438336849,0,0,0,40,49.84775543,1,6,1,1.932220459,60.11730194,,,,,,,,,,,,,,,,
3773007365,50.15681267,19342.21387,-0.001152115,8.94E-07,1,0.999253354,40.02988815,1.983026255,9.239999577,-0.012392882,-0.002337982,0.25,-6.41E-06,-0.001152122,-1.50E-05,50.15698624,50.15698624,19331.00586,19353.42188,44.05649149,17.53530443,4.438155174,0,0,0,40,49.84611511,1,6,1,1.92565918,60.60606384,,,,,,,,,,,,,,,,
3773007417,50.15745926,20635.54883,-0.001130665,9.95E-07,1,0.999253354,40.02988815,1.983189492,9.250000119,-0.012162814,-0.002301059,0.25,-6.88E-06,-0.001130747,-1.53E-05,50.15750122,50.15750122,20622.53906,20648.55859,43.53123712,17.53400932,4.438597679,0,0,0,40,49.84638977,1,6,1,1.945037842,60.60606384,,,,,,,,,,,,,,,,
3773007469,50.1570816,21931.46191,-0.001107995,1.05E-06,1,0.999253354,40.02988815,1.983229653,9.239999577,-0.011921277,-0.00224823,0.25,-6.11E-06,-0.001108158,-1.43E-05,50.15718842,50.15718842,21919.9375,21942.98633,44.08541174,17.51908787,4.438485622,0,0,0,40,49.8454628,1,6,1,1.93572998,61.58358002,,,,,,,,,,,,,,,,
3773007521,50.15725517,23225.65039,-0.00107897,1.21E-06,1,0.999253354,40.02988815,1.983428699,9.239999577,-0.011612148,-0.002182986,0.25,-5.34E-06,-0.00107921,-1.33E-05,50.15718842,50.15718842,23214.33789,23236.96289,43.46089055,17.51671132,4.438628197,0,0,0,40,49.84500885,1,6,1,1.918792725,60.60606384,,,,,,,,,,,,,,,,
3773007573,50.15807343,24520.23633,-0.001066238,1.10E-06,1,0.999253354,40.02988815,1.983336858,9.239999577,-0.01147356,-0.002167514,0.25,-6.23E-06,-0.001066544,-1.41E-05,50.15809631,50.15809631,24508.625,24531.84766,44.18233368,17.52905635,4.43844986,0,0,0,40,49.84257507,1,6,1,1.930999756,61.58358002,,,,,,,,,,,,,,,,
3773007625,50.15874863,25814.62402,-0.00104944,8.04E-07,1,0.999253354,40.02988815,1.983111674,9.239999577,-0.011292062,-0.002135032,0.25,-6.31E-06,-0.001049814,-1.41E-05,50.1588974,50.1588974,25801.60742,25827.64063,44.47778926,17.52145867,4.43888855,0,0,0,40,49.8419075,1,6,1,1.936035156,61.09482193,,,,,,,,,,,,,,,,
3773007677,50.15916252,27108.66309,-0.001012628,1.58E-06,1,0.999253354,40.02988815,1.983092703,9.239999577,-0.0108955,-0.002066451,0.25,-6.67E-06,-0.001013056,-1.41E-05,50.15937805,50.15937805,27099.26172,27118.06445,44.19327648,17.5244128,4.439109802,0,0,0,40,49.84135056,1,6,1,1.937255859,61.09482193,,,,,,,,,,,,,,,,
3773007729,50.15903091,28402.42285,-0.000999943,2.03E-06,1,0.999253354,40.02988815,1.983032018,9.239999577,-0.010758101,-0.002048126,0.25,-7.29E-06,-0.001000432,-1.47E-05,50.15900803,50.15900803,28389.60938,28415.23633,44.11745851,17.52599768,4.439082146,0,0,0,40,49.84140778,1,6,1,1.93572998,61.58358002,,,,,,,,,,,,,,,,
3773007781,50.15949631,29699.52539,-0.000976427,1.20E-06,1,0.999253354,40.02988815,1.982902512,9.239999577,-0.010506539,-0.001992564,0.25,-6.44E-06,-0.000976978,-1.36E-05,50.15940094,50.15940094,29687.83789,29711.21289,43.588296,17.52747382,4.439140797,0,0,0,40,49.84038544,1,6,1,1.938171387,61.58358002,,,,,,,,,,,,,,,,
3773007842,50.1601963,29052.4541,-0.00023003,1.20E-06,1,0.999253354,40.02988815,1.982872003,9.239999577,-0.002477599,-0.00045541,0.25,-2.18E-07,-0.000230161,-1.91E-06,50.16034698,50.16034698,29041.17773,29063.73047,43.58595112,17.52965775,4.439366341,0,0,0,40,49.83976746,1,6,1,1.929779053,61.58358002,,,,,,,,,,,,,,,,
3773007918,50.1599865,27158.74219,-0.000250507,1.66E-06,1,0.999253354,40.02988815,1.995188289,9.239999577,-0.002712841,-0.000503816,0.25,-6.95E-07,-0.000250621,-2.54E-06,50.16009521,50.16009521,27147.13086,27170.35352,43.8212213,17.53259669,4.438867092,0,0,0,40,49.84024429,1,6,1,1.948242188,60.11730194,,,,,,,,,,,,,,,,
3773007970,50.15906525,25864.52637,-0.000255584,1.23E-06,1,0.999253354,40.02988815,1.995017833,9.239999577,-0.002765556,-0.000524014,0.25,-1.64E-06,-0.000255675,-3.52E-06,50.1590538,50.1590538,25851.52734,25877.52539,43.52107595,17.52732874,4.439211845,0,0,0,40,49.84257507,1,6,1,1.937103271,61.09482193,,,,,,,,,,,,,,,,
3773008022,50.15880394,24571.55566,-0.000265444,1.03E-06,1,0.999253354,40.02988815,1.995271504,9.239999577,-0.002874865,-0.000530738,0.25,-4.49E-07,-0.000265529,-2.41E-06,50.1587677,50.1587677,24558.92578,24584.18555,44.60832122,17.53014912,4.43951416,0,0,0,40,49.84323883,1,6,1,1.94732666,61.58358002,,,,,,,,,,,,,,,,
3773008074,50.15789413,23273.74707,-0.000289086,1.26E-06,1,0.999253354,40.02988815,1.995174562,9.239999577,-0.003127764,-0.000593204,0.25,-1.90E-06,-0.000289148,-4.03E-06,50.15805054,50.15805054,23260.74805,23286.74609,44.12918294,17.52643861,4.439404488,0,0,0,40,49.84396362,1,6,1,1.946868896,61.58358002,,,,,,,,,,,,,,,,
3773008126,50.15784073,21979.62012,-0.000306221,1.79E-06,1,0.999253354,40.02988815,1.995205675,9.239999577,-0.003314917,-0.000617657,0.25,-1.02E-06,-0.000306272,-3.29E-06,50.15794373,50.15794373,21967.08203,21992.1582,43.83294573,17.52843787,4.439144611,0,0,0,40,49.84461594,1,6,1,1.953125,61.09482193,,,,,,,,,,,,,,,,
3773008178,50.15834808,20683.97461,-0.000325845,1.30E-06,1,0.999253354,40.02988815,1.995274564,9.239999577,-0.003525361,-0.000667344,0.25,-2.02E-06,-0.000325869,-4.43E-06,50.1582756,50.1582756,20672.75391,20695.19531,43.68756283,17.52907491,4.439042568,0,0,0,40,49.84571075,1,6,1,1.940460205,61.09482193,,,,,,,,,,,,,,,,
3773008230,50.1574688,19388.45996,-0.0003368,1.22E-06,1,0.999253354,40.02988815,1.995119428,9.239999577,-0.003644259,-0.000684758,0.25,-1.63E-06,-0.000336804,-4.13E-06,50.15746307,50.15746307,19375.65039,19401.26953,44.07994034,17.53876846,4.439101219,0,0,0,40,49.84638977,1,6,1,1.959991455,61.09482193,,,,,,,,,,,,,,,,
3773008282,50.15699768,18091.19727,-0.000365501,9.32E-07,1,0.999253354,40.02988815,1.995033623,9.239999577,-0.003953334,-0.000748684,0.25,-2.29E-06,-0.000365476,-5.00E-06,50.15714264,50.15714264,18078.08789,18104.30664,44.1033892,17.53066274,4.439326286,0,0,0,40,49.84635162,1,6,1,1.939697266,61.58358002,,,,,,,,,,,,,,,,
3773008334,50.15715218,16798.53223,-0.000378547,8.98E-07,1,0.999253354,40.02988815,1.995170267,9.239999577,-0.004096185,-0.000765771,0.25,-1.48E-06,-0.000378501,-4.29E-06,50.15722275,50.15722275,16783.91797,16813.14648,44.30973913,17.54036608,4.439921856,0,0,0,40,49.84856415,1,6,1,1.937408447,61.58358002,,,,,,,,,,,,,,,,
3773008385,50.15561104,15502.71045,-0.000411081,1.16E-06,1,0.999253354,40.02988815,1.995125106,9.239999577,-0.004448949,-0.000825351,0.25,-1.04E-06,-0.000411007,-4.09E-06,50.1557312,50.1557312,15489.48633,15515.93457,44.59034377,17.54146536,4.439902782,0,0,0,40,49.84882355,1,6,1,1.953582764,61.58358002,,,,,,,,,,,,,,,,
3773008438,50.15565872,14208.42236,-0.000440568,1.55E-06,1,0.999253354,40.02988815,1.99518317,9.239999577,-0.004767796,-0.000884931,0.25,-1.15E-06,-0.000440457,-4.42E-06,50.15563583,50.15563583,14195.50879,14221.33594,44.32615333,17.53872131,4.439631939,0,0,0,40,49.84946442,1,6,1,1.935424805,61.09482193,,,,,,,,,,,,,,,,
3773008513,50.15598106,12310.90723,-0.000477255,7.28E-07,1,0.999253354,40.02988815,1.995529422,9.250000119,-0.0051637,-0.000966589,0.25,-1.97E-06,-0.000477081,-5.52E-06,50.15593338,50.15593338,12299.69922,12322.11523,43.98458166,17.52659314,4.439481258,0,0,0,40,49.85299683,1,6,1,1.933746338,63.04985428,,,,,,,,,,,,,,,,
3773008565,50.15501213,11017.14014,-0.00050908,1.15E-06,1,0.999253354,40.02988815,1.995382246,9.239999577,-0.005510146,-0.001015248,0.25,-6.55E-07,-0.000508872,-4.44E-06,50.15491486,50.15491486,11004.16406,11030.11621,43.54608806,17.53414697,4.439274311,0,0,0,40,49.85095215,1,6,1,1.962280273,60.11730194,,,,,,,,,,,,,,,,
3773008617,50.1540432,9722.005371,-0.00054298,9.67E-07,1,0.999253354,40.02988815,1.995693226,9.239999577,-0.00587554,-0.001093851,0.25,-1.71E-06,-0.000542713,-5.74E-06,50.1540184,50.1540184,9708.801758,9735.208984,43.94706349,17.52897162,4.439342976,0,0,0,40,49.85227203,1,6,1,1.946105957,61.58358002,,,,,,,,,,,,,,,,
3773008669,50.15501213,8429.440918,-0.000567022,9.06E-07,1,0.999253354,40.02988815,1.995625987,9.239999577,-0.006134368,-0.001146209,0.25,-2.15E-06,-0.000566704,-6.37E-06,50.15484619,50.15484619,8416.732422,8442.149414,43.42728053,17.52732554,4.439723492,0,0,0,40,49.85277176,1,6,1,1.956634521,60.60606384,,,,,,,,,,,,,,,,
3773008721,50.15437889,7127.838623,-0.000588757,6.66E-07,1,0.999253354,40.02988815,1.995385777,9.239999577,-0.006366906,-0.001197907,0.25,-2.97E-06,-0.000588383,-7.35E-06,50.15440369,50.15440369,7111.618652,7144.058594,43.86342924,17.53444519,4.439819813,0,0,0,40,49.85145187,1,6,1,1.945037842,62.56109619,,,,,,,,,,,,,,,,
3773008773,50.15410995,5836.373779,-0.000610303,6.48E-07,1,0.999253354,40.02988815,1.995591439,9.239999577,-0.00660052,-0.001239728,0.25,-2.89E-06,-0.000609879,-7.43E-06,50.15427017,50.15427017,5823.794434,5848.953125,44.19796625,17.52909428,4.439753532,0,0,0,40,49.8536377,1,6,1,1.933135986,60.60606384,,,,,,,,,,,,,,,,
3773008825,50.15318298,4542.805176,-0.00062472,7.30E-07,1,0.999253354,40.02988815,1.995521226,9.239999577,-0.00675561,-0.001269992,0.25,-3.06E-06,-0.000624248,-7.71E-06,50.15318298,50.15318298,4530.094238,4555.516113,44.1198034,17.52747328,4.440195084,0,0,0,40,49.85351944,1,6,1,1.948547363,62.0723381,,,,,,,,,,,,,,,,
3773008877,50.15384102,3247.216309,-0.0006236,6.44E-07,1,0.999253354,40.02988815,1.995598509,9.239999577,-0.006743346,-0.001267714,0.25,-3.06E-06,-0.000623092,-7.69E-06,50.15394974,50.15394974,3236.118164,3258.314453,44.63098845,17.53238439,4.439475536,0,0,0,40,49.8539238,1,6,1,1.948242188,61.58358002,,,,,,,,,,,,,,,,
3773008929,50.15387726,1956.219055,-0.000578743,6.12E-07,1,0.999253354,40.02988815,1.99547289,9.239999577,-0.006257235,-0.00117828,0.25,-3.01E-06,-0.00057824,-7.31E-06,50.15378189,50.15378189,1943.496704,1968.941406,44.3034861,17.53354541,4.440199375,0,0,0,40,49.85466003,1,6,1,1.947784424,61.58358002,,,,,,,,,,,,,,,,
3773008981,50.15396118,661.2014465,-0.000261736,9.16E-07,1,0.999253354,40.02988815,1.995313114,9.239999577,-0.002830233,-0.000528693,0.25,-9.83E-07,-0.000261499,-2.93E-06,50.15397263,50.15397263,651.7553101,670.647583,43.82200293,17.53436314,4.440155029,0,0,0,40,49.85515976,1,6,1,1.956939697,61.58358002,,,,,,,,,,,,,,,,
3773009033,50.15211868,-637.7398682,0.004418556,2.67E-06,1,0.999253354,40.02988815,1.995615162,9.239999577,0.047774785,0.008988269,0.25,2.23E-05,0.00441451,5.51E-05,50.15222549,50.15222549,-652.1602173,-623.319519,44.22063348,17.54482335,4.440023899,0,0,0,40,49.8560524,1,6,1,1.933898926,61.09482193,,,,,,,,,,,,,,,,
3773009085,50.15395355,-1929.557373,0.002599215,7.66E-07,1,0.999253354,40.02988815,1.995538373,9.239999577,0.028103711,0.005287868,0.25,1.32E-05,0.002596956,3.25E-05,50.15391159,50.15391159,-1940.749878,-1918.364868,44.7638653,17.53890466,4.440443516,0,0,0,40,49.85570526,1,6,1,1.936340332,61.09482193,,,,,,,,,,,,,,,,
3773009161,50.15393066,-3825.184814,0.001926662,1.41E-06,1,0.999253354,40.02988815,1.995568104,9.239999577,0.020833153,0.003923256,0.25,1.01E-05,0.001925137,2.44E-05,50.15386581,50.15386581,-3834.584961,-3815.784668,43.66098746,17.5323479,4.439988613,0,0,0,40,49.85322189,1,6,1,1.932220459,60.60606384,,,,,,,,,,,,,,,,
3773009213,50.15284157,-5119.679688,0.001723177,7.92E-07,1,0.999253354,40.02988815,1.99552759,9.239999577,0.018634021,0.00350669,0.25,8.77E-06,0.001721916,2.16E-05,50.15272903,50.15272903,-5130.980469,-5108.378906,43.88844135,17.5362439,4.440001965,0,0,0,40,49.85407639,1,6,1,1.937561035,61.09482193,,,,,,,,,,,,,,,,
3773009265,50.15343857,-6410.39624,0.001590603,7.32E-07,1,0.999253354,40.02988815,1.99549062,9.239999577,0.017200842,0.003238732,0.25,8.25E-06,0.001589536,2.01E-05,50.15339661,50.15339661,-6421.810059,-6398.982422,43.83372736,17.53277076,4.44017601,0,0,0,40,49.8548851,1,6,1,1.95098877,60.60606384,,,,,,,,,,,,,,,,
3773009317,50.15347672,-7704.5979,0.001498468,6.87E-07,1,0.999253354,40.02988815,1.995295838,9.250000119,0.016202639,0.003058586,0.25,8.47E-06,0.001497552,1.96E-05,50.15333939,50.15333939,-7717.504883,-7691.690918,44.32380844,17.53841682,4.440448284,0,0,0,40,49.85357666,1,6,1,1.937713623,60.60606384,,,,,,,,,,,,,,,,
3773009369,50.15338707,-9001.592285,0.00142102,7.85E-07,1,0.999253354,40.02988815,1.995568408,9.239999577,0.015370084,0.002890712,0.25,7.08E-06,0.00142025,1.76E-05,50.15342331,50.15342331,-9014.305664,-8988.878906,43.87828018,17.53052352,4.440635204,0,0,0,40,49.85348511,1,6,1,1.946411133,61.58358002,,,,,,,,,,,,,,,,
3773009421,50.1544323,-10295.67725,0.001373349,8.85E-07,1,0.999253354,40.02988815,1.9953125,9.239999577,0.014854271,0.002790189,0.25,6.53E-06,0.001372699,1.67E-05,50.1542244,50.1542244,-10308.59082,-10282.76367,44.28003724,17.53980572,4.440847874,0,0,0,40,49.85281754,1,6,1,1.954345703,61.58358002,,,,,,,,,,,,,,,,
3773009473,50.15490341,-11589.53613,0.001324442,1.21E-06,1,0.999253354,40.02988815,1.995462312,9.239999577,0.014328163,0.002686363,0.25,5.85E-06,0.001323908,1.57E-05,50.15498734,50.15498734,-11600.94531,-11578.12695,44.32927984,17.54689479,4.440500736,0,0,0,40,49.85154724,1,6,1,1.94732666,61.09482193,,,,,,,,,,,,,,,,
3773009525,50.15415192,-12881.62354,0.001283806,1.03E-06,1,0.999253354,40.02988815,1.995401589,9.239999577,0.013886497,0.00261823,0.25,6.98E-06,0.001283366,1.65E-05,50.15415192,50.15415192,-12894.63086,-12868.61621,44.31755541,17.5342461,4.440720081,0,0,0,40,49.85148621,1,6,1,1.95098877,60.60606384,,,,,,,,,,,,,,,,
3773009577,50.15459442,-14175.00049,0.001255122,9.85E-07,1,0.999253354,40.02988815,1.995226557,9.239999577,0.013576114,0.002559305,0.25,6.79E-06,0.001254779,1.61E-05,50.15458298,50.15458298,-14188.01758,-14161.9834,44.2323579,17.53780159,4.440960884,0,0,0,40,49.85074997,1,6,1,1.950378418,61.58358002,,,,,,,,,,,,,,,,
3773009629,50.15463448,-15471.97705,0.001223753,1.03E-06,1,0.999253354,40.02988815,1.995426865,9.239999577,0.013238841,0.002496553,0.25,6.70E-06,0.001223503,1.58E-05,50.15473557,50.15473557,-15484.88867,-15459.06543,44.17686228,17.54057531,4.44071722,0,0,0,40,49.85040665,1,6,1,1.936645508,61.58358002,,,,,,,,,,,,,,,,
3773009681,50.15502548,-16765.72852,0.001192624,1.07E-06,1,0.999253354,40.02988815,1.995381896,9.239999577,0.012903542,0.002428588,0.25,6.11E-06,0.001192466,1.50E-05,50.15502548,50.15502548,-16776.85352,-16754.60352,44.26674956,17.53754612,4.441198826,0,0,0,40,49.84909821,1,6,1,1.948242188,62.0723381,,,,,,,,,,,,,,,,
3773009756,50.15707397,-18633.09277,0.001156186,1.52E-06,1,0.999253354,40.02988815,1.99555104,9.239999577,0.012513944,0.002341954,0.25,4.75E-06,0.001156161,1.33E-05,50.15703201,50.15703201,-18646.10742,-18620.07813,44.10964223,17.54292854,4.441289425,0,0,0,40,49.85022736,1,6,1,1.951141357,60.11730194,,,,,,,,,,,,,,,,
3773009807,50.15597534,-19926.01563,0.001133961,1.01E-06,1,0.999253354,40.02988815,1.995702578,9.239999577,0.01227061,0.002322006,0.25,6.95E-06,0.001133999,1.54E-05,50.1560173,50.1560173,-19939.02344,-19913.00781,44.33240635,17.51605622,4.441170692,0,0,0,40,49.84771729,1,6,1,1.936187744,60.11730194,,,,,,,,,,,,,,,,
3773009859,50.15616035,-21221.2832,0.001114039,1.21E-06,1,0.999253354,40.02988815,1.995767443,9.239999577,0.012055458,0.002285802,0.25,7.24E-06,0.001114152,1.55E-05,50.15606308,50.15606308,-21237.27734,-21205.28906,43.97129398,17.5235469,4.441099644,0,0,0,40,49.84693527,1,6,1,1.949462891,60.11730194,,,,,,,,,,,,,,,,
3773009911,50.15668678,-22519.85938,0.001095208,1.14E-06,1,0.999253354,40.02988815,1.995768433,9.239999577,0.011850334,0.002259346,0.25,8.23E-06,0.001095389,1.63E-05,50.15685272,50.15685272,-22531.02734,-22508.69141,44.48404229,17.5148943,4.441268921,0,0,0,40,49.84484482,1,6,1,1.949615479,63.53861237,,,,,,,,,,,,,,,,
3773009963,50.15637398,-23814.81055,0.001074455,1.20E-06,1,0.999253354,40.02988815,1.995456322,9.239999577,0.011625981,0.00221037,0.25,7.53E-06,0.001074713,1.55E-05,50.15642166,50.15642166,-23827.63477,-23801.98633,43.97911026,17.52491386,4.441559315,0,0,0,40,49.84556961,1,6,1,1.952972412,60.60606384,,,,,,,,,,,,,,,,
3773010015,50.1567955,-25104.56934,0.001042121,1.49E-06,1,0.999253354,40.02988815,1.995229106,9.239999577,0.011276988,0.002136665,0.25,6.66E-06,0.001042449,1.44E-05,50.15670013,50.15670013,-25117.18359,-25091.95508,43.91892487,17.5219969,4.440999031,0,0,0,40,49.84606552,1,6,1,1.94732666,60.60606384,,,,,,,,,,,,,,,,
3773010067,50.15678024,-26403.0498,0.001021503,1.21E-06,1,0.999253354,40.02988815,1.995253779,9.239999577,0.011052457,0.002107345,0.25,7.71E-06,0.001021888,1.53E-05,50.15678024,50.15678024,-26416.06641,-26390.0332,44.26831282,17.5290606,4.440695763,0,0,0,40,49.84350204,1,6,1,1.958770752,61.58358002,,,,,,,,,,,,,,,,
3773010119,50.15727806,-27697.59375,0.001002351,1.18E-06,1,0.999253354,40.02988815,1.995004877,9.239999577,0.010846464,0.002058211,0.25,6.70E-06,0.001002806,1.41E-05,50.15703201,50.15703201,-27710.41016,-27684.77734,43.59767555,17.52894702,4.441277027,0,0,0,40,49.84378433,1,6,1,1.940765381,61.09482193,,,,,,,,,,,,,,,,
3773010171,50.15760803,-28991.00781,0.000989495,9.83E-07,1,0.999253354,40.02988815,1.995192335,9.239999577,0.010706674,0.00204511,0.25,7.82E-06,0.000990005,1.51E-05,50.15750122,50.15750122,-29000.31445,-28981.70117,44.26987607,17.53708895,4.441802502,0,0,0,40,49.84213257,1,6,1,1.950073242,61.09482193,,,,,,,,,,,,,,,,
3773010214,50.15871811,-30000.23926,0.000828454,1.17E-06,1,0.999253354,40.02988815,1.995453437,9.239999577,0.008970457,0.001686877,0.25,4.19E-06,0.000828944,1.03E-05,50.15871811,50.15871811,-30000.32422,-30000.1543,44.73885318,17.53623107,4.44124651,0,0,0,40,49.84038544,1,4,1,1.948242188,62.0723381,,,,,,,,,,,,,,,,