File: Data/DyBCO_MVT_2000Oe_50-120K_Continuous.csv
Time Stamp (sec),Temperature (K),Magnetic Field (Oe),Moment (emu),M. Std. Err. (emu),Transport Action,Averaging Time (sec),Frequency (Hz),Peak Amplitude (mm),Center Position (mm),Coil Signal' (mV),"Coil Signal"" (mV)",Range (mV),M. Quad. Signal (emu),M. Raw' (emu),"M. Raw"" (emu)",Min. Temperature (K),Max. Temperature (K),Min. Field (Oe),Max. Field (Oe),Mass (grams),Motor Lag (deg),Pressure (Torr),VSM Status (code),Motor Status (code),Measure Status (code),Measure Count,System Temp. (K),Temp. Status (code),Field Status (code),Chamber Status (code),Motor Current (amps),Motor Heatsink Temp. (C),Map 01,Map 02,Map 03,Map 04,Map 05,Map 06,Map 07,Map 08,Map 09,Map 10,Map 11,Map 12,Map 13,Map 14,Map 15,Map 16
3772649310,49.53345108,1999.997681,,,2,,,,10.29200012,,,,,,,49.53345108,49.53345108,1999.997681,1999.997681,,,44.8299408,,,,40,48.67600632,0,0,0,0.036010742,41.54447937,,,,,,,,,,,,,,,,
3772649532,51.01409721,2000.018494,0.001582727,4.72E-06,1,0.999253354,40.02988815,1.975034587,10.28000005,0.016930316,0.003302054,0.25,1.85E-05,0.001581701,3.03E-05,51.00515747,51.00515747,2000.016113,2000.020874,43.84935993,17.50574991,45.03211594,0,0,0,40,51.17068481,2,4,1,1.922302246,52.29716492,,,,,,,,,,,,,,,,
3772649653,53.0103035,2000.006958,0.001454989,3.73E-06,1,0.999253354,40.02988815,1.975081706,10.28000005,0.01556966,0.003060349,0.25,1.92E-05,0.001454925,3.00E-05,53.00035095,53.00035095,2000.006958,2000.006958,43.93533907,17.50809459,45.65372467,0,0,0,40,53.2469902,2,4,1,1.935577393,54.25220108,,,,,,,,,,,,,,,,
3772649774,55.01331711,1999.974731,0.001298913,3.49E-06,1,0.999253354,40.02988815,1.975075688,10.28000005,0.013923355,0.002648414,0.25,9.29E-06,0.001299689,1.88E-05,55.00585556,55.00585556,1999.942505,2000.006958,44.14637877,17.50982859,46.21808243,0,0,0,40,55.28418732,2,4,1,1.922454834,55.71847534,,,,,,,,,,,,,,,,
3772649894,57.0163784,1999.988464,0.001131595,6.02E-06,1,0.999253354,40.02988815,1.974927206,10.28000005,0.012129288,0.002344218,0.25,1.16E-05,0.001132888,1.98E-05,57.00780106,57.00780106,1999.960815,2000.016113,43.7883929,17.5101178,46.63818741,0,0,0,40,57.3254509,2,4,1,1.923675537,56.20723343,,,,,,,,,,,,,,,,
3772649984,58.50585556,1999.990784,0.001058874,5.15E-06,1,0.999253354,40.02988815,1.988729359,10.28000005,0.011423418,0.002242523,0.25,1.41E-05,0.001060482,2.16E-05,58.49512863,58.49512863,1999.965454,2000.016113,43.74071356,17.51149901,46.79641724,0,0,0,40,58.83010101,2,4,1,1.946868896,55.71847534,,,,,,,,,,,,,,,,
3772650105,60.51534271,2000.009216,0.000887928,3.93E-06,1,0.999253354,40.02988815,1.988589697,10.27000044,0.009608263,0.001744671,0.25,-6.69E-07,0.000889808,5.47E-06,60.50814438,60.50814438,2000.006958,2000.011475,43.66880374,17.50856201,46.96619034,0,0,0,40,60.85452652,2,4,1,1.954498291,56.69599533,,,,,,,,,,,,,,,,
3772650225,62.50450516,2000.016174,0.000692882,4.16E-06,1,0.999253354,40.02988815,1.988741453,10.27000044,0.007516986,0.001277471,0.25,-8.20E-06,0.000694711,-3.57E-06,62.49714279,62.49714279,2000.006958,2000.025391,44.18546019,17.51195269,47.140625,0,0,0,40,62.86420441,2,4,1,1.943817139,57.18475342,,,,,,,,,,,,,,,,
3772650346,64.51555634,2000.011536,0.00055587,4.54E-06,1,0.999253354,40.02988815,1.988650271,10.28000005,0.006046737,0.000948245,0.25,-1.36E-05,0.000557609,-1.00E-05,64.50697327,64.50697327,2000.006958,2000.016113,44.07212406,17.51218736,47.33591843,0,0,0,40,64.89338684,2,4,1,1.939849854,54.74095917,,,,,,,,,,,,,,,,
3772650466,66.51435471,1999.990784,0.000405796,4.73E-06,1,0.999253354,40.02988815,1.988702377,10.28000005,0.004386497,0.000854429,0.25,5.15E-06,0.000407117,7.69E-06,66.50559998,66.50559998,1999.965454,2000.016113,44.14325225,17.51282471,47.48438644,0,0,0,40,66.91316986,2,4,1,1.944274902,57.67351151,,,,,,,,,,,,,,,,
3772650556,68.015728,1999.983826,0.000329165,3.23E-06,1,0.999253354,40.02988815,1.988822904,10.28000005,0.003551332,0.00073676,0.25,8.25E-06,0.000330293,1.03E-05,68.00894928,68.00894928,1999.951538,2000.016113,43.93377581,17.51280402,47.55739975,0,0,0,40,68.40939331,2,4,1,1.951751709,56.20723343,,,,,,,,,,,,,,,,
3772650676,70.01164246,2000.011536,0.000173112,3.62E-06,1,0.999253354,40.02988815,1.988682675,10.27000044,0.001924335,7.73E-05,0.25,-2.42E-05,0.000173922,-2.33E-05,70.00222778,70.00222778,2000.006958,2000.016113,44.17373576,17.50942761,47.69121933,0,0,0,40,70.43700409,2,4,1,1.94519043,58.16226959,,,,,,,,,,,,,,,,
3772650796,72.01176071,2000.011536,9.85E-05,4.89E-06,1,0.999253354,40.02988815,1.98866969,10.27000044,0.001040776,0.000344949,0.25,1.40E-05,9.88E-05,1.46E-05,72.00391388,72.00391388,2000.006958,2000.016113,44.05727311,17.51238538,47.83857727,0,0,0,40,72.46481323,2,4,1,1.950378418,58.65102768,,,,,,,,,,,,,,,,
3772650917,74.01327896,2000.004578,3.59E-05,3.15E-06,1,0.999253354,40.02988815,1.988768786,10.28000005,0.000405805,-2.33E-05,0.25,-8.63E-06,3.61E-05,-8.48E-06,74.00480652,74.00480652,2000.002197,2000.006958,44.08463011,17.51387761,48.0008049,0,0,0,40,74.48579407,2,4,1,1.944732666,58.65102768,,,,,,,,,,,,,,,,
3772651037,76.00737381,1999.983887,9.34E-06,2.92E-06,1,0.999253354,40.02988815,1.988763234,10.28000005,9.68E-05,4.34E-05,0.25,2.31E-06,9.37E-06,2.37E-06,75.99687958,75.99687958,1999.956299,2000.011475,44.18780508,17.51474019,48.15726089,0,0,0,40,76.51167297,2,4,1,1.953277588,58.16226959,,,,,,,,,,,,,,,,
3772651159,78.05165863,2000.006958,,,2,,,,10.27199997,,,,,,,78.05165863,78.05165863,2000.006958,2000.006958,,,48.27887726,,,,40,78.56642914,0,0,0,0.042114258,55.22971725,,,,,,,,,,,,,,,,
3772651246,79.50187302,2000.007019,-1.25E-06,1.14E-05,1,0.999253354,40.02988815,2.000861408,10.25999989,-8.19E-06,-3.30E-05,0.25,-2.80E-06,-1.25E-06,-2.82E-06,79.49353027,79.49353027,1999.993164,2000.020874,44.16748274,17.50633167,48.33946228,0,0,0,40,80.04312134,2,4,1,1.965789795,58.16226959,,,,,,,,,,,,,,,,
3772651367,81.51037979,2000.009216,1.99E-05,7.03E-07,1,0.999253354,40.02988815,2.000864673,10.27000044,0.000215743,4.96E-05,0.25,9.58E-07,2.00E-05,1.05E-06,81.50080109,81.50080109,2000.006958,2000.011475,44.02991612,17.50802388,48.46706772,0,0,0,40,82.0645752,2,4,1,1.968231201,59.13978577,,,,,,,,,,,,,,,,
3772651487,83.50603485,1999.983826,2.05E-05,4.12E-07,1,0.999253354,40.02988815,2.000697993,10.25999989,0.00022349,3.99E-05,0.25,-2.64E-08,2.06E-05,6.28E-08,83.49590302,83.49590302,1999.951538,2000.016113,44.20500091,17.50705426,48.61553574,0,0,0,40,84.08763123,2,4,1,1.956787109,58.65102768,,,,,,,,,,,,,,,,
3772651608,85.51473999,1999.986206,2.06E-05,4.69E-07,1,0.999253354,40.02988815,2.00077267,10.27000044,0.000224684,4.46E-05,0.25,3.74E-07,2.07E-05,4.62E-07,85.50485229,85.50485229,1999.951538,2000.020874,44.15497668,17.51456994,48.75601578,0,0,0,40,86.11541748,2,4,1,1.955413818,58.65102768,,,,,,,,,,,,,,,,
3772651728,87.50915146,2000.004578,2.04E-05,4.32E-07,1,0.999253354,40.02988815,2.000813776,10.27000044,0.000222397,4.11E-05,0.25,1.08E-07,2.05E-05,1.91E-07,87.50249481,87.50249481,2000.002197,2000.006958,44.12761968,17.51183413,48.86475754,0,0,0,40,88.13153076,2,4,1,1.954193115,60.11730194,,,,,,,,,,,,,,,,
3772651818,89.00452805,1999.981506,2.03E-05,4.31E-07,1,0.999253354,40.02988815,1.98865604,10.25999989,0.000219871,4.09E-05,0.25,1.34E-07,2.04E-05,2.14E-07,88.9969101,88.9969101,1999.951538,2000.011475,44.01975495,17.50761149,48.97261429,0,0,0,40,89.64579773,2,4,1,1.947937012,58.65102768,,,,,,,,,,,,,,,,
3772651939,91.01766205,2000.002319,2.03E-05,3.24E-07,1,0.999253354,40.02988815,1.988607397,10.25000028,0.000219724,4.47E-05,0.25,4.78E-07,2.04E-05,5.57E-07,91.00980377,91.00980377,1999.997681,2000.006958,44.23470279,17.50718743,49.10421753,0,0,0,40,91.66794586,2,4,1,1.946563721,58.65102768,,,,,,,,,,,,,,,,
3772652059,93.00948715,1999.999939,2.06E-05,3.54E-07,1,0.999253354,40.02988815,1.988527478,10.25999989,0.000223383,4.25E-05,0.25,2.29E-07,2.07E-05,3.05E-07,92.99977112,92.99977112,1999.997681,2000.002197,44.20421928,17.51002617,49.23404312,0,0,0,40,93.69334412,2,4,1,1.956787109,57.67351151,,,,,,,,,,,,,,,,
3772652179,95.00008774,1999.990784,2.09E-05,4.01E-07,1,0.999253354,40.02988815,1.988644576,10.25000028,0.00022618,4.31E-05,0.25,2.34E-07,2.10E-05,3.08E-07,94.99266052,94.99266052,1999.965454,2000.016113,44.33318798,17.51205545,49.33146667,0,0,0,40,95.70944214,2,4,1,1.954345703,59.13978577,,,,,,,,,,,,,,,,
3772652300,97.01576233,2000.009216,2.00E-05,3.51E-07,1,0.999253354,40.02988815,1.988444039,10.25000028,0.000217054,3.96E-05,0.25,7.64E-08,2.01E-05,1.44E-07,97.00609589,97.00609589,2000.006958,2000.011475,44.08541174,17.50419702,49.42356491,0,0,0,40,97.74291229,2,4,1,1.95602417,58.16226959,,,,,,,,,,,,,,,,
3772652390,98.51560974,1999.981628,2.10E-05,4.29E-07,1,0.999253354,40.02988815,2.000827738,10.23999974,0.000227875,4.74E-05,0.25,5.95E-07,2.11E-05,6.67E-07,98.28726196,98.28726196,1999.956299,2000.006958,43.71023005,17.50666801,49.53386307,0,0,0,40,99.47183228,2,4,1,1.956634521,57.67351151,,,,,,,,,,,,,,,,
3772652509,100.5072594,2000.004578,2.09E-05,4.72E-07,1,0.999253354,40.02988815,2.000744812,10.25000028,0.000227524,4.47E-05,0.25,3.62E-07,2.10E-05,4.29E-07,100.4996872,100.4996872,2000.002197,2000.006958,44.25737002,17.51097527,49.62485123,0,0,0,40,101.262085,2,4,1,1.966094971,58.16226959,,,,,,,,,,,,,,,,
3772652630,102.5154228,2000.006958,2.04E-05,3.01E-07,1,0.999253354,40.02988815,2.000808293,10.23999974,0.000222893,4.07E-05,0.25,8.64E-08,2.05E-05,1.49E-07,102.5089951,102.5089951,2000.006958,2000.006958,44.3034861,17.50948714,49.70074844,0,0,0,40,103.2967224,2,4,1,1.967163086,58.65102768,,,,,,,,,,,,,,,,
3772652750,104.512188,2000.009155,2.10E-05,3.23E-07,1,0.999253354,40.02988815,2.000820781,10.23999974,0.000228415,4.54E-05,0.25,4.17E-07,2.11E-05,4.81E-07,104.5022964,104.5022964,2000.002197,2000.016113,44.18077042,17.51426224,49.82081223,0,0,0,40,105.310463,2,4,1,1.958465576,59.13978577,,,,,,,,,,,,,,,,
3772652870,106.5056343,2000.006836,2.04E-05,2.91E-07,1,0.999253354,40.02988815,2.000642495,10.23999974,0.00022278,3.98E-05,0.25,1.30E-08,2.05E-05,7.12E-08,106.4961624,106.4961624,2000.002197,2000.011475,44.11511363,17.50872264,49.98614502,0,0,0,40,107.312027,2,4,1,1.958465576,59.13978577,,,,,,,,,,,,,,,,
3772652990,108.5010109,1999.97467,2.08E-05,4.63E-07,1,0.999253354,40.02988815,2.000779906,10.23999974,0.000226097,4.49E-05,0.25,4.12E-07,2.09E-05,4.71E-07,108.493042,108.493042,1999.937866,2000.011475,44.12683805,17.51189138,50.09688568,0,0,0,40,109.327179,2,4,1,1.962127686,59.13978577,,,,,,,,,,,,,,,,
3772653081,110.0137024,1999.990723,2.07E-05,3.21E-07,1,0.999253354,40.02988815,1.988552131,10.21999959,0.000223619,4.90E-05,0.25,8.22E-07,2.08E-05,8.83E-07,110.0048904,110.0048904,1999.983765,1999.997681,44.14794202,17.51309939,50.14459991,0,0,0,40,110.8538742,2,4,1,1.945648193,58.16226959,,,,,,,,,,,,,,,,
3772653201,112.0060463,2000.002319,2.07E-05,3.80E-07,1,0.999253354,40.02988815,1.988549653,10.21999959,0.000223724,4.62E-05,0.25,5.67E-07,2.08E-05,6.24E-07,111.99897,111.99897,1999.997681,2000.006958,44.0103754,17.51250784,50.20718384,0,0,0,40,112.8641968,2,4,1,1.942749023,58.65102768,,,,,,,,,,,,,,,,
3772653321,114.0029602,2000.000061,2.11E-05,3.33E-07,1,0.999253354,40.02988815,1.988719315,10.21999959,0.000228582,4.28E-05,0.25,1.91E-07,2.12E-05,2.45E-07,113.9934769,113.9934769,1999.993164,2000.006958,43.75634614,17.51747504,50.20851517,0,0,0,40,114.8767471,2,4,1,1.945037842,59.62854385,,,,,,,,,,,,,,,,
3772653442,116.0150375,2000.002197,2.08E-05,3.23E-07,1,0.999253354,40.02988815,1.98856427,10.21999959,0.000225597,4.19E-05,0.25,1.59E-07,2.09E-05,2.11E-07,116.0049133,116.0049133,2000.002197,2000.002197,43.93924721,17.50852301,50.28108215,0,0,0,40,116.9027634,2,4,1,1.945648193,60.11730194,,,,,,,,,,,,,,,,
3772653562,118.0095749,2000.002319,2.08E-05,3.45E-07,1,0.999253354,40.02988815,1.988590978,10.21999959,0.000225488,4.30E-05,0.25,2.59E-07,2.09E-05,3.10E-07,118.0040054,118.0040054,1999.997681,2000.006958,44.35663684,17.51165852,50.35476303,0,0,0,40,118.9138184,2,4,1,1.941070557,59.13978577,,,,,,,,,,,,,,,,
3772653652,119.5041008,2000.006958,2.11E-05,3.25E-07,1,0.999253354,40.02988815,1.988546643,10.21999959,0.00022718,4.91E-05,0.25,7.79E-07,2.12E-05,8.33E-07,119.4975204,119.4975204,2000.006958,2000.006958,44.00881215,17.51340862,50.39870453,0,0,0,40,120.422348,2,4,1,1.947479248,57.18475342,,,,,,,,,,,,,,,,
3772654058,119.4878349,1999.995422,2.07E-05,7.39E-07,1,0.999253354,40.02988815,1.988486473,10.20999998,0.000224168,4.30E-05,0.25,2.80E-07,2.08E-05,3.30E-07,119.4977493,119.4977493,1999.993164,1999.997681,43.79230105,17.51418082,50.48214722,0,0,0,40,117.8481293,6,4,1,1.945343018,58.65102768,,,,,,,,,,,,,,,,
3772654179,117.4852829,1999.995422,2.11E-05,4.71E-07,1,0.999253354,40.02988815,1.988481777,10.20999998,0.000228309,4.69E-05,0.25,5.61E-07,2.12E-05,6.15E-07,117.4916687,117.4916687,1999.993164,1999.997681,43.74384008,17.50848946,50.44619751,0,0,0,40,115.6007614,2,4,1,1.947479248,59.13978577,,,,,,,,,,,,,,,,
3772654269,115.9915276,1999.995422,2.10E-05,4.83E-07,1,0.999253354,40.02988815,2.000619479,10.21999959,0.000229616,4.19E-05,0.25,9.81E-08,2.11E-05,1.50E-07,116.0006561,116.0006561,1999.993164,1999.997681,43.85639459,17.504556,50.38938141,0,0,0,40,114.0767212,2,4,1,1.958465576,57.18475342,,,,,,,,,,,,,,,,
3772654389,113.9876595,2000.006958,2.10E-05,6.27E-07,1,0.999253354,40.02988815,2.000693688,10.21999959,0.000228929,4.50E-05,0.25,3.77E-07,2.11E-05,4.32E-07,113.9957047,113.9957047,2000.006958,2000.006958,44.3199003,17.51231425,50.3272438,0,0,0,40,112.03582,2,4,1,1.960296631,58.16226959,,,,,,,,,,,,,,,,
3772654509,111.9878349,1999.999939,2.10E-05,5.34E-07,1,0.999253354,40.02988815,2.000655257,10.21999959,0.000229945,3.97E-05,0.25,-1.04E-07,2.11E-05,-4.93E-08,111.9941101,111.9941101,1999.997681,2000.002197,43.71960959,17.50925708,50.24690628,0,0,0,40,110.0313797,2,4,1,1.962432861,58.65102768,,,,,,,,,,,,,,,,
3772654629,109.9910965,2000.006958,2.08E-05,6.43E-07,1,0.999253354,40.02988815,2.000676416,10.23000013,0.000226555,4.28E-05,0.25,2.21E-07,2.09E-05,2.78E-07,109.9990692,109.9990692,2000.006958,2000.006958,43.90094741,17.50957783,50.18010712,0,0,0,40,108.0260162,2,4,1,1.956939697,59.13978577,,,,,,,,,,,,,,,,
3772654749,107.9955521,1999.995422,2.07E-05,5.29E-07,1,0.999253354,40.02988815,2.000544125,10.21999959,0.000224097,4.94E-05,0.25,8.38E-07,2.08E-05,9.00E-07,108.0032501,108.0032501,1999.993164,1999.997681,44.41682223,17.51254707,50.12906647,0,0,0,40,106.0332794,2,4,1,1.956481934,58.65102768,,,,,,,,,,,,,,,,
3772654858,106.1705399,2000.002197,,,2,,,,10.23200013,,,,,,,106.1705399,106.1705399,2000.002197,2000.002197,,,50.08024216,,,,40,104.2246094,0,0,0,0.040893555,56.20723343,,,,,,,,,,,,,,,,
3772654959,104.4942474,1999.967773,2.11E-05,5.72E-07,1,0.999253354,40.02988815,2.000674047,10.21999959,0.000230823,4.17E-05,0.25,5.11E-08,2.13E-05,1.14E-07,104.5033875,104.5033875,1999.937866,1999.997681,43.94002884,17.51217671,50.03341675,0,0,0,40,102.5488892,2,4,1,1.959381104,58.65102768,,,,,,,,,,,,,,,,
3772655078,102.495285,1999.993164,2.08E-05,4.62E-07,1,0.999253354,40.02988815,2.000498338,10.21999959,0.000226447,4.41E-05,0.25,3.31E-07,2.09E-05,3.96E-07,102.5010757,102.5010757,1999.993164,1999.993164,44.13465434,17.50976378,49.9437561,0,0,0,40,100.5680008,2,4,1,1.948547363,61.58358002,,,,,,,,,,,,,,,,
3772655198,100.4926186,1999.995361,2.06E-05,3.95E-07,1,0.999253354,40.02988815,2.000536262,10.21999959,0.00022449,4.61E-05,0.25,5.34E-07,2.08E-05,6.02E-07,100.5026093,100.5026093,1999.988525,2000.002197,44.06196289,17.51120936,49.85520935,0,0,0,40,98.57183075,2,4,1,1.950683594,58.65102768,,,,,,,,,,,,,,,,
3772655318,98.49374008,1999.999939,2.02E-05,5.02E-07,1,0.999253354,40.02988815,2.00048861,10.21999959,0.000220801,4.14E-05,0.25,1.79E-07,2.04E-05,2.46E-07,98.50074005,98.50074005,1999.997681,2000.002197,43.98223678,17.50913029,49.76133728,0,0,0,40,96.59809875,2,4,1,1.958007813,58.65102768,,,,,,,,,,,,,,,,
3772655438,96.48937988,1999.997681,2.08E-05,4.16E-07,1,0.999253354,40.02988815,2.000460853,10.23000013,0.000225827,5.14E-05,0.25,9.79E-07,2.10E-05,1.05E-06,96.49667358,96.49667358,1999.997681,1999.997681,43.84701504,17.51061626,49.67367554,0,0,0,40,94.61483002,2,4,1,1.967926025,59.62854385,,,,,,,,,,,,,,,,
3772655528,94.98924255,2000.018433,2.14E-05,4.72E-07,1,0.999253354,40.02988815,2.000619924,10.23999974,0.000232589,4.54E-05,0.25,3.34E-07,2.15E-05,4.10E-07,94.99981689,94.99981689,1999.988525,2000.04834,44.00412238,17.51234718,49.59311676,0,0,0,40,93.12762451,2,4,1,1.955718994,58.65102768,,,,,,,,,,,,,,,,
3772655647,92.998909,1999.995422,2.05E-05,4.21E-07,1,0.999253354,40.02988815,2.000764359,10.23999974,0.000222569,4.56E-05,0.25,5.15E-07,2.06E-05,5.91E-07,93.00837708,93.00837708,1999.993164,1999.997681,43.78761128,17.50957262,49.4734993,0,0,0,40,91.16699219,2,4,1,1.946868896,59.13978577,,,,,,,,,,,,,,,,
3772655767,90.99552917,2000.006958,2.09E-05,5.63E-07,1,0.999253354,40.02988815,2.000685177,10.23999974,0.000226018,5.43E-05,0.25,1.22E-06,2.10E-05,1.31E-06,91.00411987,91.00411987,2000.006958,2000.006958,44.3144289,17.51360653,49.35343933,0,0,0,40,89.18774414,2,4,1,1.955718994,58.65102768,,,,,,,,,,,,,,,,
3772655887,88.99003601,1999.995361,2.04E-05,3.58E-07,1,0.999253354,40.02988815,2.000844811,10.25000028,0.00022277,3.83E-05,0.25,-1.49E-07,2.05E-05,-7.03E-08,88.99661255,88.99661255,1999.983765,2000.006958,44.22610488,17.51679424,49.24536133,0,0,0,40,87.22022247,2,4,1,1.954193115,58.16226959,,,,,,,,,,,,,,,,
3772656007,86.9905777,1999.997681,2.06E-05,4.55E-07,1,0.999253354,40.02988815,2.000692365,10.25000028,0.000223245,4.91E-05,0.25,8.02E-07,2.07E-05,8.90E-07,86.99912262,86.99912262,1999.993164,2000.002197,44.2706577,17.50974338,49.14638138,0,0,0,40,85.24589539,2,4,1,1.963195801,59.13978577,,,,,,,,,,,,,,,,
3772656099,85.44770813,2000.004578,2.08E-05,4.37E-07,1,0.999253354,40.02988815,1.975080724,10.23000013,0.000223082,4.49E-05,0.25,4.35E-07,2.09E-05,5.25E-07,85.45907593,85.45907593,2000.002197,2000.006958,44.1033892,17.51532523,49.09112167,0,0,0,40,83.74115753,2,4,1,1.923065186,57.18475342,,,,,,,,,,,,,,,,
3772656216,83.49440765,2000.004578,2.08E-05,4.52E-07,1,0.999253354,40.02988815,1.974830214,10.23000013,0.000223833,4.10E-05,0.25,7.12E-08,2.09E-05,1.62E-07,83.50430298,83.50430298,2000.002197,2000.006958,44.06899754,17.50921041,49.01721954,0,0,0,40,81.80909729,2,4,1,1.938781738,59.13978577,,,,,,,,,,,,,,,,
3772656336,81.48667526,1999.997681,2.03E-05,5.20E-07,1,0.999253354,40.02988815,1.974855999,10.23000013,0.00021776,4.68E-05,0.25,6.88E-07,2.04E-05,7.84E-07,81.49454498,81.49454498,1999.997681,1999.997681,43.62972231,17.51758053,48.9315567,0,0,0,40,79.83911133,2,4,1,1.922607422,58.65102768,,,,,,,,,,,,,,,,
3772656455,79.48438263,2000.009216,2.11E-05,1.99E-06,1,0.999253354,40.02988815,1.974859549,10.23000013,0.000216152,0.000103823,0.25,5.83E-06,2.12E-05,5.96E-06,79.49645233,79.49645233,2000.006958,2000.011475,44.21203556,17.51249419,48.80461884,0,0,0,40,77.87013245,2,4,1,1.922607422,58.65102768,,,,,,,,,,,,,,,,
3772656574,77.49033737,2000.018433,-6.32E-06,9.74E-07,1,0.999253354,40.02988815,1.974724714,10.23000013,-0.000116283,0.000255078,0.25,2.48E-05,-6.47E-06,2.49E-05,77.49741364,77.49741364,1999.988525,2000.04834,44.48326066,17.51776183,48.65859222,0,0,0,40,75.92045593,2,4,1,1.924285889,59.13978577,,,,,,,,,,,,,,,,
3772656701,75.37462616,2000.006958,,,2,,,,10.26199989,,,,,,,75.37462616,75.37462616,2000.006958,2000.006958,,,48.5343132,,,,40,73.85604095,0,0,0,0.043945313,56.20723343,,,,,,,,,,,,,,,,
3772656783,73.98979568,1999.999939,-5.44E-06,1.28E-06,1,0.999253354,40.02988815,2.000553444,10.25999989,-0.000131712,0.000389778,0.25,3.67E-05,-5.66E-06,3.68E-05,73.99856567,73.99856567,1999.997681,2000.002197,44.1198034,17.51287099,48.4439888,0,0,0,40,72.49733734,2,4,1,1.960296631,58.16226959,,,,,,,,,,,,,,,,
3772656902,71.99698257,2000.011475,-6.19E-05,5.61E-06,1,0.999253354,40.02988815,2.000458207,10.25000028,-0.000714924,9.94E-05,0.25,2.03E-05,-6.23E-05,2.01E-05,72.00460052,72.00460052,2000.011475,2000.011475,44.3089575,17.51371202,48.29441071,0,0,0,40,70.56037903,2,4,1,1.9581604,58.16226959,,,,,,,,,,,,,,,,
3772657022,69.98361969,2000.004578,-0.000101925,5.94E-06,1,0.999253354,40.02988815,2.000419812,10.25000028,-0.001100843,-0.000258171,0.25,-5.21E-06,-0.000102288,-5.82E-06,69.99524689,69.99524689,2000.002197,2000.006958,43.86968227,17.5124282,48.09135056,0,0,0,40,68.59924316,2,4,1,1.960754395,59.13978577,,,,,,,,,,,,,,,,
3772657141,67.99030304,2000.009155,-7.71E-05,6.03E-06,1,0.999253354,40.02988815,2.00053141,10.25000028,-0.000927763,0.000326585,0.25,4.40E-05,-7.77E-05,4.37E-05,67.99876404,67.99876404,2000.002197,2000.016113,44.63255171,17.51269778,47.90959549,0,0,0,40,66.6566925,2,4,1,1.959838867,59.13978577,,,,,,,,,,,,,,,,
3772657260,65.99012375,1999.999939,-0.000127605,5.50E-06,1,0.999253354,40.02988815,2.000375742,10.25999989,-0.001454924,0.00010421,0.25,3.28E-05,-0.000128225,3.21E-05,65.99987793,65.99987793,1999.997681,2000.002197,44.37148778,17.51685807,47.7160759,0,0,0,40,64.71730804,2,4,1,1.961364746,59.13978577,,,,,,,,,,,,,,,,
3772657350,64.485569,1999.999939,-0.000163094,4.87E-06,1,0.999253354,40.02988815,2.000432557,10.25999989,-0.001861242,0.000144417,0.25,4.29E-05,-0.000163856,4.20E-05,64.49611664,64.49611664,1999.997681,2000.002197,44.086975,17.51302907,47.55651093,0,0,0,40,63.23781967,2,4,1,1.954956055,57.18475342,,,,,,,,,,,,,,,,
3772657469,62.48413849,2000.011536,-0.000175763,8.14E-06,1,0.999253354,40.02988815,2.000358612,10.25999989,-0.001915793,-0.00033453,0.25,1.28E-06,-0.000176221,1.07E-07,62.49177933,62.49177933,2000.006958,2000.016113,44.32068193,17.50983414,47.35100937,0,0,0,40,61.30549622,2,4,1,1.958312988,59.13978577,,,,,,,,,,,,,,,,
3772657588,60.48725891,2000.009216,-0.000205915,7.21E-06,1,0.999253354,40.02988815,2.000432556,10.27000044,-0.002268202,-0.000256361,0.25,1.40E-05,-0.000206445,1.26E-05,60.4965477,60.4965477,2000.006958,2000.011475,44.02366309,17.51814542,47.14173508,0,0,0,40,59.37185669,2,4,1,1.95602417,60.11730194,,,,,,,,,,,,,,,,
3772657707,58.48716736,2000.002319,-0.000185615,6.38E-06,1,0.999253354,40.02988815,2.000455545,10.27000044,-0.002047687,-0.00020876,0.25,1.47E-05,-0.000186018,1.34E-05,58.49518585,58.49518585,1999.997681,2000.006958,44.12292991,17.51288039,46.91137695,0,0,0,40,57.429142,2,4,1,1.955566406,59.13978577,,,,,,,,,,,,,,,,
3772657825,56.49001122,2000.006836,-0.00021503,7.63E-06,1,0.999253354,40.02988815,2.000303026,10.25999989,-0.002371953,-0.000235278,0.25,1.76E-05,-0.000215388,1.61E-05,56.49882126,56.49882126,2000.002197,2000.011475,44.24642722,17.51673668,46.66992188,0,0,0,40,55.48680496,2,4,1,1.959228516,59.13978577,,,,,,,,,,,,,,,,
3772657920,54.88571739,2000.002197,-0.000206072,7.82E-06,1,0.999253354,40.02988815,2.000417554,10.25999989,-0.002307092,-3.48E-05,0.25,3.45E-05,-0.000206452,3.30E-05,55.11449432,55.11449432,2000.002197,2000.002197,44.51139928,17.51205298,46.40072632,0,0,0,40,53.7443428,2,4,1,1.965942383,57.18475342,,,,,,,,,,,,,,,,
3772658033,52.9894104,2000.013794,-0.000281807,7.37E-06,1,0.999253354,40.02988815,2.000372637,10.25999989,-0.003029737,-0.000722444,0.25,-1.50E-05,-0.000281709,-1.71E-05,52.99735641,52.99735641,2000.011475,2000.016113,44.18155205,17.51580484,46.06983566,0,0,0,40,52.10503769,2,4,1,1.967315674,59.13978577,,,,,,,,,,,,,,,,
3772658152,50.98638535,2000.002319,-0.00022059,7.62E-06,1,0.999253354,40.02988815,2.000475382,10.25999989,-0.002473316,-1.69E-06,0.25,4.02E-05,-0.000220764,3.85E-05,50.9930954,50.9930954,1999.997681,2000.006958,43.92048812,17.51317191,45.49394226,0,0,0,40,50.17810822,2,4,1,1.970672607,60.60606384,,,,,,,,,,,,,,,,
3772658503,50.20280647,2000.004578,-0.000315635,6.63E-06,1,0.999253354,40.02988815,2.000313594,10.25999989,-0.003435986,-0.000559295,0.25,6.17E-06,-0.000315425,3.82E-06,50.20268631,50.20268631,2000.002197,2000.006958,43.93533907,17.51537004,44.78688812,0,0,0,40,49.89891052,6,4,1,1.958465576,59.13978577,,,,,,,,,,,,,,,,
3772658598,51.50156212,1999.999939,-0.000246851,8.69E-06,1,0.999253354,40.02988815,1.988223725,10.28999966,-0.002780524,0.000153303,0.25,5.94E-05,-0.000247191,5.75E-05,51.49342728,51.49342728,1999.997681,2000.002197,44.01350192,17.51726371,45.07583237,0,0,0,40,51.67199707,2,4,1,1.947937012,57.67351151,,,,,,,,,,,,,,,,
3772658720,53.51096916,1999.999939,-0.000270189,5.70E-06,1,0.999253354,40.02988815,1.988195733,10.28000005,-0.002972726,-0.000228441,0.25,2.83E-05,-0.000270454,2.63E-05,53.50141907,53.50141907,1999.997681,2000.002197,44.114332,17.51097463,45.71497726,0,0,0,40,53.75178528,2,4,1,1.948547363,59.13978577,,,,,,,,,,,,,,,,
3772658841,55.51170731,1999.970032,-0.0002809,4.88E-06,1,0.999253354,40.02988815,1.988239834,10.28000005,-0.003039683,-0.000526191,0.25,2.63E-06,-0.000281142,5.82E-07,55.50334167,55.50334167,1999.937866,2000.002197,44.25189862,17.51572129,46.27267456,0,0,0,40,55.79661942,2,4,1,1.947937012,59.13978577,,,,,,,,,,,,,,,,
3772658962,57.51736069,2000.002197,-0.000241397,6.60E-06,1,0.999253354,40.02988815,1.988198061,10.28999966,-0.002636527,-0.000326971,0.25,1.38E-05,-0.000241823,1.21E-05,57.51014709,57.51014709,2000.002197,2000.002197,43.88531484,17.51799069,46.65815735,0,0,0,40,57.83007431,2,4,1,1.947937012,59.13978577,,,,,,,,,,,,,,,,
3772659082,59.5054512,1999.999939,-0.000182003,7.86E-06,1,0.999253354,40.02988815,1.98836484,10.28000005,-0.002006206,-0.000152255,0.25,1.91E-05,-0.000182477,1.79E-05,59.49559021,59.49559021,1999.997681,2000.002197,43.75009311,17.51493386,46.95642471,0,0,0,40,59.83677673,2,4,1,1.942596436,59.13978577,,,,,,,,,,,,,,,,
3772659172,61.01542282,2000.002319,-0.000226681,6.66E-06,1,0.999253354,40.02988815,2.000470429,10.28999966,-0.002415188,-0.000732633,0.25,-2.60E-05,-0.000227008,-2.76E-05,61.00761032,61.00761032,1999.997681,2000.006958,43.99474283,17.51225717,47.13241196,0,0,0,40,61.3500061,2,4,1,1.958618164,57.18475342,,,,,,,,,,,,,,,,
3772659292,63.00810242,1999.993164,-0.000223779,5.90E-06,1,0.999253354,40.02988815,2.000401414,10.3000002,-0.002430716,-0.000474082,0.25,-2.80E-06,-0.000224358,-4.30E-06,63.00128174,63.00128174,1999.993164,1999.993164,44.09635454,17.51703238,47.35655594,0,0,0,40,63.37130356,2,4,1,1.956634521,59.13978577,,,,,,,,,,,,,,,,
3772659412,65.00173569,1999.988464,-0.000169034,6.94E-06,1,0.999253354,40.02988815,2.000243859,10.28999966,-0.001895363,-3.54E-05,0.25,2.75E-05,-0.000169728,2.65E-05,64.99053192,64.99053192,1999.983765,1999.993164,43.95566141,17.52000014,47.58536148,0,0,0,40,65.37656403,2,4,1,1.958770752,59.13978577,,,,,,,,,,,,,,,,
3772659533,67.01399231,1999.995422,-0.000174747,4.81E-06,1,0.999253354,40.02988815,2.000347996,10.3000002,-0.001940961,-0.000142148,0.25,1.87E-05,-0.00017546,1.77E-05,67.00819397,67.00819397,1999.993164,1999.997681,43.90172904,17.51877565,47.79019928,0,0,0,40,67.41161346,2,4,1,1.968231201,58.16226959,,,,,,,,,,,,,,,,
3772659653,69.01351166,1999.997742,-0.000149597,3.67E-06,1,0.999253354,40.02988815,2.000279511,10.3000002,-0.001629695,-0.00029997,0.25,-3.94E-07,-0.000150152,-1.28E-06,69.00533295,69.00533295,1999.988525,2000.006958,43.82981922,17.51999107,47.98615646,0,0,0,40,69.43263245,2,4,1,1.956176758,58.65102768,,,,,,,,,,,,,,,,
3772659773,71.00701904,2000.011475,,,2,,,,10.27199997,,,,,,,71.00701904,71.00701904,2000.011475,2000.011475,,,48.20120239,,,,40,71.43761444,0,0,0,0.042114258,55.71847534,,,,,,,,,,,,,,,,
3772659863,72.51026535,2000.009216,-0.000117539,3.40E-06,1,0.999253354,40.02988815,1.988039876,10.25999989,-0.001290033,-0.000143645,0.25,8.01E-06,-0.000118074,7.40E-06,72.49951172,72.49951172,2000.006958,2000.011475,43.86030273,17.51420758,48.32459259,0,0,0,40,72.96482849,2,4,1,1.956176758,58.16226959,,,,,,,,,,,,,,,,
3772659984,74.51200867,1999.997681,-5.36E-05,3.61E-06,1,0.999253354,40.02988815,1.988193893,10.25999989,-0.000653867,0.000295264,0.25,3.69E-05,-5.41E-05,3.68E-05,74.50323486,74.50323486,1999.997681,1999.997681,44.53015837,17.5174504,48.5076828,0,0,0,40,75.00289917,2,4,1,1.946563721,58.65102768,,,,,,,,,,,,,,,,
3772660104,76.51105499,1999.997681,-3.08E-05,2.33E-06,1,0.999253354,40.02988815,1.988294945,10.25999989,-0.000389318,0.000248629,0.25,2.85E-05,-3.10E-05,2.84E-05,76.50306702,76.50306702,1999.997681,1999.997681,44.01662843,17.51279762,48.68788528,0,0,0,40,77.01269531,2,4,1,1.946105957,58.16226959,,,,,,,,,,,,,,,,
3772660224,78.50699997,2000.004578,-2.19E-06,6.69E-07,1,0.999253354,40.02988815,1.988331598,10.25999989,-6.07E-05,0.000200317,0.25,1.89E-05,-2.30E-06,1.89E-05,78.4997406,78.4997406,2000.002197,2000.006958,43.89000461,17.51857539,48.88428879,0,0,0,40,79.02666473,2,4,1,1.95602417,58.65102768,,,,,,,,,,,,,,,,
3772660343,80.500103,1999.990723,1.37E-05,3.85E-06,1,0.999253354,40.02988815,1.988165803,10.25999989,0.000121364,0.000175848,0.25,1.37E-05,1.37E-05,1.39E-05,80.49365234,80.49365234,1999.983765,1999.997681,43.98848981,17.51891456,49.05406189,0,0,0,40,81.04563141,2,4,1,1.9480896,59.13978577,,,,,,,,,,,,,,,,
3772660434,82.00986862,1999.979248,2.05E-05,6.61E-07,1,0.999253354,40.02988815,1.988329066,10.25000028,0.000220271,5.07E-05,0.25,9.86E-07,2.06E-05,1.08E-06,82.00245667,82.00245667,1999.979248,1999.979248,44.17764391,17.50811627,49.17034912,0,0,0,40,82.56096649,2,4,1,1.949615479,56.20723343,,,,,,,,,,,,,,,,
3772660554,84.00489807,1999.997681,2.07E-05,4.26E-07,1,0.999253354,40.02988815,1.988223955,10.25000028,0.000224145,4.60E-05,0.25,5.10E-07,2.08E-05,6.03E-07,83.99634552,83.99634552,1999.997681,1999.997681,44.09400966,17.50895113,49.28553009,0,0,0,40,84.59420013,2,4,1,1.9581604,58.16226959,,,,,,,,,,,,,,,,
3772660674,86.0001297,1999.993103,2.03E-05,3.66E-07,1,0.999253354,40.02988815,1.988192834,10.25000028,0.000219136,4.74E-05,0.25,7.22E-07,2.04E-05,8.10E-07,85.99059296,85.99059296,1999.988525,1999.997681,44.17842554,17.51059572,49.36497879,0,0,0,40,86.61301422,2,4,1,1.945343018,58.65102768,,,,,,,,,,,,,,,,
3772660795,88.00841904,2000.004578,2.05E-05,3.27E-07,1,0.999253354,40.02988815,1.988175377,10.25000028,0.000221138,4.99E-05,0.25,9.12E-07,2.06E-05,9.99E-07,87.99887085,87.99887085,1999.997681,2000.011475,44.2925433,17.51617064,49.4561882,0,0,0,40,88.64056396,2,4,1,1.946258545,58.65102768,,,,,,,,,,,,,,,,
3772660915,90.00391006,1999.990845,2.07E-05,2.97E-07,1,0.999253354,40.02988815,1.988253391,10.25000028,0.000223918,4.75E-05,0.25,6.59E-07,2.08E-05,7.42E-07,89.99708557,89.99708557,1999.988525,1999.993164,44.32615333,17.5109547,49.57780457,0,0,0,40,90.65369415,2,4,1,1.944732666,58.65102768,,,,,,,,,,,,,,,,
3772661017,91.70276642,1999.999939,2.05E-05,4.28E-07,1,0.999253354,40.02988815,2.000465991,10.23999974,0.000223685,4.07E-05,0.25,6.20E-08,2.06E-05,1.38E-07,91.6964035,91.6964035,1999.997681,2000.002197,44.16591948,17.50949398,49.66368866,0,0,0,40,92.36528015,2,4,1,1.960601807,57.67351151,,,,,,,,,,,,,,,,
3772661126,93.50843048,2000.000061,2.07E-05,3.27E-07,1,0.999253354,40.02988815,2.000392142,10.23999974,0.000225847,4.26E-05,0.25,1.98E-07,2.08E-05,2.73E-07,93.50147247,93.50147247,1999.993164,2000.006958,44.29723307,17.51161848,49.74646759,0,0,0,40,94.19680786,2,4,1,1.958618164,57.67351151,,,,,,,,,,,,,,,,
3772661246,95.50372696,1999.997681,2.10E-05,2.91E-07,1,0.999253354,40.02988815,2.000381853,10.25000028,0.000228307,4.76E-05,0.25,6.04E-07,2.11E-05,6.79E-07,95.49700928,95.49700928,1999.993164,2000.002197,43.93612069,17.51543867,49.85676193,0,0,0,40,96.20552826,2,4,1,1.958465576,58.16226959,,,,,,,,,,,,,,,,
3772661367,97.51527023,1999.990845,2.07E-05,3.86E-07,1,0.999253354,40.02988815,2.000379073,10.25000028,0.000224628,4.61E-05,0.25,5.29E-07,2.08E-05,6.01E-07,97.5075531,97.5075531,1999.988525,1999.993164,44.25189862,17.51189592,49.96483994,0,0,0,40,98.23356628,2,4,1,1.953887939,58.16226959,,,,,,,,,,,,,,,,
3772661487,99.50665283,1999.997681,2.06E-05,3.74E-07,1,0.999253354,40.02988815,2.000373242,10.25000028,0.000222706,5.26E-05,0.25,1.14E-06,2.07E-05,1.21E-06,99.49707031,99.49707031,1999.993164,2000.002197,44.1252748,17.51086734,50.08623505,0,0,0,40,100.251564,2,4,1,1.967315674,58.65102768,,,,,,,,,,,,,,,,
3772661622,101.7686005,1999.997681,,,2,,,,10.26199989,,,,,,,101.7686005,101.7686005,1999.997681,1999.997681,,,50.24513245,,,,40,102.5267334,0,0,0,0.041351318,55.71847534,,,,,,,,,,,,,,,,
3772661697,103.0148735,1999.997681,2.09E-05,3.07E-07,1,0.999253354,40.02988815,1.988156469,10.25000028,0.000225113,4.97E-05,0.25,8.51E-07,2.10E-05,9.19E-07,103.0086365,103.0086365,1999.997681,1999.997681,43.7993357,17.50827864,50.31215286,0,0,0,40,103.7886734,2,4,1,1.935577393,57.18475342,,,,,,,,,,,,,,,,
3772661817,105.0122299,1999.997681,2.07E-05,3.78E-07,1,0.999253354,40.02988815,1.988097302,10.25000028,0.000223856,4.58E-05,0.25,5.27E-07,2.08E-05,5.90E-07,105.0028915,105.0028915,1999.997681,1999.997681,44.26284142,17.51092399,50.39648438,0,0,0,40,105.8080215,2,4,1,1.95022583,58.16226959,,,,,,,,,,,,,,,,
3772661937,107.0027122,1999.997681,2.10E-05,4.68E-07,1,0.999253354,40.02988815,1.988146381,10.25000028,0.000228071,3.90E-05,0.25,-1.44E-07,2.11E-05,-8.53E-08,106.9949799,106.9949799,1999.993164,2000.002197,44.53406651,17.51083978,50.47127533,0,0,0,40,107.8196564,2,4,1,1.958465576,58.16226959,,,,,,,,,,,,,,,,
3772662057,109.0011368,2000.002319,2.11E-05,3.02E-07,1,0.999253354,40.02988815,1.988154358,10.25000028,0.000228287,4.35E-05,0.25,2.51E-07,2.12E-05,3.10E-07,108.993576,108.993576,1999.997681,2000.006958,44.39102849,17.51197944,50.58223724,0,0,0,40,109.8353806,2,4,1,1.941986084,58.16226959,,,,,,,,,,,,,,,,
3772662178,111.0155258,2000.013916,2.01E-05,3.80E-07,1,0.999253354,40.02988815,1.988015882,10.25999989,0.000218207,4.17E-05,0.25,2.60E-07,2.02E-05,3.15E-07,111.0086975,111.0086975,2000.006958,2000.020874,44.3363145,17.51207325,50.690979,0,0,0,40,111.8558273,2,4,1,1.946716309,58.16226959,,,,,,,,,,,,,,,,
3772662268,112.5070381,1999.995422,2.06E-05,4.60E-07,1,0.999253354,40.02988815,1.988237625,10.20999998,0.000223446,4.44E-05,0.25,4.15E-07,2.08E-05,4.71E-07,112.4975967,112.4975967,1999.993164,1999.997681,43.93299418,17.51322518,50.74712753,0,0,0,40,113.3701401,2,4,1,1.957092285,56.20723343,,,,,,,,,,,,,,,,
3772662388,114.5031128,1999.990845,2.07E-05,3.70E-07,1,0.999253354,40.02988815,1.988029349,10.20999998,0.000223202,4.74E-05,0.25,6.86E-07,2.08E-05,7.42E-07,114.4926834,114.4926834,1999.988525,1999.993164,44.421512,17.50825633,50.84188843,0,0,0,40,115.3882446,2,4,1,1.946563721,58.16226959,,,,,,,,,,,,,,,,
3772662509,116.510849,2000.025391,2.12E-05,4.82E-07,1,0.999253354,40.02988815,1.988178674,10.20999998,0.000228699,4.84E-05,0.25,6.88E-07,2.13E-05,7.44E-07,116.5010986,116.5010986,1999.993164,2000.057617,43.93143092,17.50744097,50.93642807,0,0,0,40,117.408165,2,4,1,1.946411133,57.18475342,,,,,,,,,,,,,,,,
3772662629,118.5068207,1999.993164,2.08E-05,4.11E-07,1,0.999253354,40.02988815,1.988064503,10.20999998,0.000225482,4.33E-05,0.25,2.90E-07,2.09E-05,3.41E-07,118.498909,118.498909,1999.993164,1999.993164,43.92752278,17.50910394,50.9930191,0,0,0,40,119.4162979,2,4,1,1.947631836,57.67351151,,,,,,,,,,,,,,,,
3772662856,118.6821289,1999.979248,,,2,,,,10.21199998,,,,,,,118.6821289,118.6821289,1999.979248,1999.979248,,,50.99146652,,,,40,116.3606949,0,0,0,0.040435791,55.71847534,,,,,,,,,,,,,,,,
3772663172,118.9845428,2000.000061,2.16E-05,4.69E-07,1,0.999253354,40.02988815,1.988408294,10.20999998,0.000233739,4.65E-05,0.25,4.42E-07,2.17E-05,4.95E-07,118.9937897,118.9937897,1999.993164,2000.006958,44.10964223,17.50263273,50.87917328,0,0,0,40,117.2597351,2,4,1,1.955871582,58.16226959,,,,,,,,,,,,,,,,
3772663293,116.985157,1999.997681,2.09E-05,5.27E-07,1,0.999253354,40.02988815,1.988316811,10.20000037,0.000226361,4.47E-05,0.25,3.95E-07,2.10E-05,4.48E-07,116.9923248,116.9923248,1999.997681,1999.997681,44.04007729,17.50289675,50.79106903,0,0,0,40,115.0824509,2,4,1,1.946716309,57.18475342,,,,,,,,,,,,,,,,
3772663413,114.988163,2000.018494,2.07E-05,5.99E-07,1,0.999253354,40.02988815,1.988403442,10.20000037,0.000224304,4.29E-05,0.25,2.68E-07,2.08E-05,3.21E-07,114.9933701,114.9933701,1999.993164,2000.043823,44.27534747,17.50488472,50.7417984,0,0,0,40,113.0377884,2,4,1,1.947631836,58.65102768,,,,,,,,,,,,,,,,
3772663503,113.4921646,1999.999939,2.07E-05,4.64E-07,1,0.999253354,40.02988815,2.0005762,10.20999998,0.000224931,4.96E-05,0.25,8.49E-07,2.08E-05,9.06E-07,113.501091,113.501091,1999.997681,2000.002197,44.02444472,17.50226024,50.67832947,0,0,0,40,111.5351944,2,4,1,1.9581604,56.20723343,,,,,,,,,,,,,,,,
3772663623,111.4920464,1999.999939,2.09E-05,6.12E-07,1,0.999253354,40.02988815,2.000399032,10.20999998,0.000226637,4.99E-05,0.25,8.48E-07,2.10E-05,9.07E-07,111.5010071,111.5010071,1999.997681,2000.002197,44.36523475,17.50449234,50.61175156,0,0,0,40,109.5262909,2,4,1,1.960601807,57.67351151,,,,,,,,,,,,,,,,
3772663743,109.4919319,1999.993164,2.07E-05,5.80E-07,1,0.999253354,40.02988815,2.000428101,10.20999998,0.000225513,4.52E-05,0.25,4.52E-07,2.08E-05,5.11E-07,109.5000763,109.5000763,1999.993164,1999.993164,44.10026268,17.50001419,50.54850388,0,0,0,40,107.5292053,2,4,1,1.955413818,58.65102768,,,,,,,,,,,,,,,,
3772663863,107.4932213,2000.023132,2.08E-05,6.63E-07,1,0.999253354,40.02988815,2.000505973,10.21999959,0.000226215,4.62E-05,0.25,5.24E-07,2.09E-05,5.85E-07,107.5001907,107.5001907,1999.993164,2000.053101,44.12996457,17.50735878,50.48858261,0,0,0,40,105.5304871,2,4,1,1.966705322,58.65102768,,,,,,,,,,,,,,,,
3772663983,105.494442,2000.004578,2.09E-05,4.99E-07,1,0.999253354,40.02988815,2.000572763,10.21999959,0.000227285,4.60E-05,0.25,4.83E-07,2.10E-05,5.47E-07,105.5012589,105.5012589,2000.002197,2000.006958,44.07525057,17.50462714,50.40469742,0,0,0,40,103.5413742,2,4,1,1.96182251,58.16226959,,,,,,,,,,,,,,,,
3772664086,103.7727165,1999.997681,2.13E-05,5.59E-07,1,0.999253354,40.02988815,2.00040191,10.20999998,0.00023052,5.09E-05,0.25,8.70E-07,2.14E-05,9.38E-07,103.9999161,103.9999161,1999.993164,2000.002197,44.35898172,17.50068928,50.32635498,0,0,0,40,101.6196365,2,4,1,1.956787109,55.71847534,,,,,,,,,,,,,,,,
3772664192,101.9954529,1999.999939,2.09E-05,5.72E-07,1,0.999253354,40.02988815,2.000480562,10.20999998,0.000226676,4.98E-05,0.25,8.29E-07,2.10E-05,8.97E-07,102.0055923,102.0055923,1999.997681,2000.002197,44.1198034,17.50642483,50.2912941,0,0,0,40,100.0666885,2,4,1,1.95602417,56.20723343,,,,,,,,,,,,,,,,
3772664312,99.99054337,1999.983765,2.13E-05,5.43E-07,1,0.999253354,40.02988815,2.000433969,10.21999959,0.000231818,4.80E-05,0.25,5.91E-07,2.14E-05,6.62E-07,99.998909,99.998909,1999.983765,1999.983765,44.448869,17.50727896,50.23115158,0,0,0,40,98.07958221,2,4,1,1.955871582,57.67351151,,,,,,,,,,,,,,,,
3772664432,97.98952484,2000.002319,2.16E-05,3.59E-07,1,0.999253354,40.02988815,2.000353352,10.21999959,0.000235544,4.69E-05,0.25,4.25E-07,2.18E-05,4.99E-07,97.99627686,97.99627686,1999.997681,2000.006958,43.93768395,17.50809685,50.14326859,0,0,0,40,96.09590912,2,4,1,1.960144043,58.65102768,,,,,,,,,,,,,,,,
3772664552,95.98496628,1999.997742,2.11E-05,5.62E-07,1,0.999253354,40.02988815,2.00036636,10.20999998,0.00022884,4.93E-05,0.25,7.43E-07,2.12E-05,8.19E-07,95.99359131,95.99359131,1999.988525,2000.006958,43.91267184,17.50443125,50.04074097,0,0,0,40,94.12236786,2,4,1,1.96685791,58.65102768,,,,,,,,,,,,,,,,
3772664672,93.98307037,1999.995361,2.13E-05,5.08E-07,1,0.999253354,40.02988815,2.000401763,10.21999959,0.000231632,4.80E-05,0.25,5.81E-07,2.14E-05,6.60E-07,93.99292755,93.99292755,1999.988525,2000.002197,44.15497668,17.50526248,49.97238541,0,0,0,40,92.14115143,2,4,1,1.969909668,58.16226959,,,,,,,,,,,,,,,,
3772664762,92.48246002,1999.990845,2.06E-05,5.00E-07,1,0.999253354,40.02988815,2.000334943,10.23999974,0.000225045,4.14E-05,0.25,9.96E-08,2.07E-05,1.75E-07,92.49207306,92.49207306,1999.988525,1999.993164,43.89625764,17.50312182,49.9275589,0,0,0,40,90.65827942,2,4,1,1.955108643,57.67351151,,,,,,,,,,,,,,,,
3772664881,90.49422073,1999.990845,2.08E-05,4.07E-07,1,0.999253354,40.02988815,2.000276122,10.23999974,0.000225019,5.45E-05,0.25,1.26E-06,2.09E-05,1.34E-06,90.50200653,90.50200653,1999.988525,1999.993164,44.14872365,17.50515872,49.84300232,0,0,0,40,88.69514465,2,4,1,1.966705322,58.16226959,,,,,,,,,,,,,,,,
3772665001,88.48901749,2000.009277,2.03E-05,3.92E-07,1,0.999253354,40.02988815,2.000308611,10.23000013,0.000220478,4.33E-05,0.25,3.31E-07,2.04E-05,4.12E-07,88.49591827,88.49591827,1999.993164,2000.025391,43.83998039,17.50504423,49.73648071,0,0,0,40,86.72129059,2,4,1,1.958465576,59.62854385,,,,,,,,,,,,,,,,
3772665120,86.49860764,1999.995422,2.04E-05,4.67E-07,1,0.999253354,40.02988815,2.000283442,10.23000013,0.000221132,4.78E-05,0.25,7.22E-07,2.05E-05,8.10E-07,86.50595093,86.50595093,1999.993164,1999.997681,44.03382426,17.5059143,49.67256546,0,0,0,40,84.77009583,2,4,1,1.970062256,57.67351151,,,,,,,,,,,,,,,,
3772665240,84.49219131,2000.002319,2.08E-05,4.13E-07,1,0.999253354,40.02988815,2.000244782,10.23000013,0.000225904,4.70E-05,0.25,5.68E-07,2.09E-05,6.60E-07,84.49950409,84.49950409,1999.997681,2000.006958,43.89860253,17.50580887,49.57536316,0,0,0,40,82.78729248,2,4,1,1.967773438,57.67351151,,,,,,,,,,,,,,,,
3772665330,82.98746109,1999.995422,2.10E-05,4.83E-07,1,0.999253354,40.02988815,2.000302082,10.23999974,0.00022899,4.28E-05,0.25,1.43E-07,2.11E-05,2.36E-07,82.99638367,82.99638367,1999.993164,1999.997681,43.70085051,17.50292994,49.49413681,0,0,0,40,81.32738495,2,4,1,1.961669922,54.25220108,,,,,,,,,,,,,,,,
3772665450,80.98573303,1999.986145,2.08E-05,4.54E-07,1,0.999253354,40.02988815,2.000300928,10.25000028,0.000227561,3.53E-05,0.25,-5.04E-07,2.09E-05,-4.11E-07,80.99355316,80.99355316,1999.983765,1999.988525,43.88844135,17.50466431,49.37340927,0,0,0,40,79.34792328,2,4,1,1.963806152,57.67351151,,,,,,,,,,,,,,,,
3772665569,78.99431992,1999.995422,1.68E-05,3.73E-06,1,0.999253354,40.02988815,2.000257474,10.23999974,0.000151259,0.000210645,0.25,1.63E-05,1.68E-05,1.64E-05,79.00398254,79.00398254,1999.993164,1999.997681,44.44652412,17.50559931,49.2400322,0,0,0,40,77.39666748,2,4,1,1.959228516,57.67351151,,,,,,,,,,,,,,,,
3772665689,76.9837265,1999.993164,-8.83E-06,9.47E-07,1,0.999253354,40.02988815,2.000119201,10.25000028,-0.000165051,0.000363789,0.25,3.49E-05,-9.04E-06,3.51E-05,76.99069977,76.99069977,1999.993164,1999.993164,44.01350192,17.50673227,49.1190834,0,0,0,40,75.43099976,2,4,1,1.966094971,58.16226959,,,,,,,,,,,,,,,,
3772665807,74.99550247,1999.997681,-2.20E-05,2.41E-06,1,0.999253354,40.02988815,2.000165094,10.23999974,-0.000297807,0.00027603,0.25,2.93E-05,-2.23E-05,2.93E-05,75.00572968,75.00572968,1999.997681,1999.997681,43.9939612,17.50305564,48.97571945,0,0,0,40,73.48133087,2,4,1,1.957855225,57.67351151,,,,,,,,,,,,,,,,
3772665931,72.92851257,1999.997681,,,2,,,,10.26199989,,,,,,,72.92851257,72.92851257,1999.997681,1999.997681,,,48.78575516,,,,40,71.46726227,0,0,0,0.035858154,54.74095917,,,,,,,,,,,,,,,,
3772666016,71.49033356,1999.995422,-3.71E-05,3.50E-06,1,0.999253354,40.02988815,2.000232192,10.25000028,-0.000472373,0.000302839,0.25,3.45E-05,-3.74E-05,3.44E-05,71.49718475,71.49718475,1999.993164,1999.997681,44.26205979,17.50400704,48.67101669,0,0,0,40,70.06280518,2,4,1,1.95526123,58.16226959,,,,,,,,,,,,,,,,
3772666135,69.49586105,2000.018433,-5.19E-05,4.26E-06,1,0.999253354,40.02988815,2.000213322,10.25000028,-0.000676121,0.000506463,0.25,5.59E-05,-5.24E-05,5.58E-05,69.5063324,69.5063324,1999.988525,2000.04834,44.0705608,17.50803736,48.49525452,0,0,0,40,68.12004852,2,4,1,1.958618164,57.18475342,,,,,,,,,,,,,,,,
3772666255,67.48561859,1999.990845,-7.77E-05,4.76E-06,1,0.999253354,40.02988815,2.000113219,10.25000028,-0.000891534,9.36E-05,0.25,2.27E-05,-7.81E-05,2.23E-05,67.49446869,67.49446869,1999.988525,1999.993164,44.35585521,17.50660907,48.33413696,0,0,0,40,66.16732788,2,4,1,1.956329346,57.67351151,,,,,,,,,,,,,,,,
3772666374,65.48737335,2000.029968,-4.68E-05,3.62E-06,1,0.999253354,40.02988815,2.000194238,10.25000028,-0.000632716,0.000586057,0.25,6.23E-05,-4.73E-05,6.22E-05,65.4964447,65.4964447,1999.997681,2000.062256,44.0760322,17.51162756,48.20298004,0,0,0,40,64.22724152,2,4,1,1.96105957,58.16226959,,,,,,,,,,,,,,,,
3772666493,63.49041367,2000.025269,-9.19E-05,5.66E-06,1,0.999253354,40.02988815,2.000173398,10.25000028,-0.001062479,0.000158067,0.25,3.12E-05,-9.24E-05,3.07E-05,63.4983139,63.4983139,2000.002197,2000.04834,43.87906181,17.50860043,48.01190186,0,0,0,40,62.28446198,2,4,1,1.958770752,58.65102768,,,,,,,,,,,,,,,,
3772666582,61.99442482,2000.020752,-9.22E-05,8.47E-06,1,0.999253354,40.02988815,2.000252134,10.25999989,-0.001088985,0.000289112,0.25,4.34E-05,-9.27E-05,4.28E-05,62.00180054,62.00180054,1999.993164,2000.04834,44.22375999,17.50490998,47.85499954,0,0,0,40,60.83363724,2,4,1,1.966552734,56.69599533,,,,,,,,,,,,,,,,
3772666701,59.99888802,1999.993103,-0.000114927,6.62E-06,1,0.999253354,40.02988815,2.000064195,10.27000044,-0.001309686,9.87E-05,0.25,3.00E-05,-0.000115365,2.93E-05,60.0080719,60.0080719,1999.988525,1999.997681,44.39024686,17.50466543,47.60977173,0,0,0,40,58.89316559,2,4,1,1.956939697,58.16226959,,,,,,,,,,,,,,,,
3772666820,57.99841881,1999.995361,-0.000108766,7.25E-06,1,0.999253354,40.02988815,2.000023861,10.27000044,-0.001276495,0.000299382,0.25,4.74E-05,-0.000109265,4.67E-05,58.00544357,58.00544357,1999.988525,2000.002197,43.89313113,17.50795008,47.33747101,0,0,0,40,56.94843292,2,4,1,1.95602417,58.16226959,,,,,,,,,,,,,,,,
3772666938,55.99692154,1999.997681,-0.000146509,6.03E-06,1,0.999253354,40.02988815,2.000149461,10.25999989,-0.001645633,3.10E-06,0.25,2.71E-05,-0.000146843,2.60E-05,56.00455856,56.00455856,1999.993164,2000.002197,44.08775663,17.50632457,47.07360077,0,0,0,40,55.02563477,2,4,1,1.959228516,58.16226959,,,,,,,,,,,,,,,,
3772667057,53.9940567,1999.986145,-0.000181398,5.35E-06,1,0.999253354,40.02988815,2.000083737,10.25999989,-0.002041088,3.00E-05,0.25,3.59E-05,-0.000181727,3.46E-05,54.0022316,54.0022316,1999.983765,1999.988525,44.64193125,17.50927821,46.71696854,0,0,0,40,53.08604431,2,4,1,1.957244873,58.16226959,,,,,,,,,,,,,,,,
3772667150,52.42915154,1999.983765,-0.000182255,7.66E-06,1,0.999253354,40.02988815,1.974184812,10.25999989,-0.002065461,0.000253063,0.25,5.69E-05,-0.000182655,5.56E-05,52.65774536,52.65774536,1999.983765,1999.983765,43.75790939,17.5090013,46.20609665,0,0,0,40,51.37493134,2,4,1,1.936187744,56.20723343,,,,,,,,,,,,,,,,
3772667265,50.49379349,2000.025391,-0.000172594,9.13E-06,1,0.999253354,40.02988815,1.974291239,10.25999989,-0.001966474,0.000302726,0.25,5.98E-05,-0.000172914,5.85E-05,50.50074005,50.50074005,1999.988525,2000.062256,43.96738584,17.51206451,45.60046387,0,0,0,40,49.70043564,2,4,1,1.923522949,57.67351151,,,,,,,,,,,,,,,,
3772667400,50.2112999,2000.000061,-0.000233598,5.48E-06,1,0.999253354,40.02988815,1.97439407,10.25999989,-0.002532892,-0.000292959,0.25,1.54E-05,-0.000233522,1.36E-05,50.21140289,50.21140289,1999.993164,2000.006958,43.9197065,17.50850754,45.32794189,0,0,0,40,49.90330887,1,4,1,1.923065186,57.18475342,,,,,,,,,,,,,,,,