File: Data/DyBCO_MVF_70K_-5000-5000Oe_Continuous.csv
Time Stamp (sec),Temperature (K),Magnetic Field (Oe),Moment (emu),M. Std. Err. (emu),Transport Action,Averaging Time (sec),Frequency (Hz),Peak Amplitude (mm),Center Position (mm),Coil Signal' (mV),"Coil Signal"" (mV)",Range (mV),M. Quad. Signal (emu),M. Raw' (emu),"M. Raw"" (emu)",Min. Temperature (K),Max. Temperature (K),Min. Field (Oe),Max. Field (Oe),Mass (grams),Motor Lag (deg),Pressure (Torr),VSM Status (code),Motor Status (code),Measure Status (code),Measure Count,System Temp. (K),Temp. Status (code),Field Status (code),Chamber Status (code),Motor Current (amps),Motor Heatsink Temp. (C),Map 01,Map 02,Map 03,Map 04,Map 05,Map 06,Map 07,Map 08,Map 09,Map 10,Map 11,Map 12,Map 13,Map 14,Map 15,Map 16
3772710505,70.18809509,-0.007556926,,,2,,,,10.26199989,,,,,,,70.18809509,70.18809509,-0.007556926,-0.007556926,,,49.13706207,,,,40,69.72349548,0,0,0,0.04486084,48.38709641,,,,,,,,,,,,,,,,
3772710527,70.18798065,64.32308578,0.000326094,4.32E-06,1,0.999253354,40.02988815,1.988348478,10.25000028,0.00351226,0.000764147,0.25,1.14E-05,0.000327291,1.33E-05,70.18772888,70.18772888,54.91378784,73.73238373,43.31003625,17.54540774,49.13683701,0,0,0,40,69.72658539,1,6,1,1.947631836,50.83089066,,,,,,,,,,,,,,,,
3772710532,70.18891907,190.0606918,0.000505464,1.81E-06,1,0.999253354,40.02988815,1.988430689,10.25000028,0.005445957,0.001176058,0.25,1.69E-05,0.000507325,1.99E-05,70.18900299,70.18900299,177.1470947,202.9742889,43.62503254,17.54208658,49.13683701,0,0,0,40,69.72734833,1,6,1,1.941833496,51.80840683,,,,,,,,,,,,,,,,
3772710537,70.18864822,312.6695099,0.000529073,1.78E-06,1,0.999253354,40.02988815,1.988324151,10.25000028,0.005697338,0.001245833,0.25,1.91E-05,0.000531013,2.22E-05,70.18843079,70.18843079,300.0623474,325.2766724,43.63050394,17.54022712,49.13661575,0,0,0,40,69.7259903,1,6,1,1.956787109,51.31964874,,,,,,,,,,,,,,,,
3772710542,70.18972015,439.0107269,0.000527665,1.52E-06,1,0.999253354,40.02988815,1.988320599,10.25999989,0.00567478,0.0012833,0.25,2.28E-05,0.000529578,2.59E-05,70.18963623,70.18963623,425.8990173,452.1224365,43.5937674,17.54229679,49.12773895,0,0,0,40,69.7255249,1,6,1,1.949005127,52.29716492,,,,,,,,,,,,,,,,
3772710547,70.18975449,565.7528381,0.000506714,2.34E-06,1,0.999253354,40.02988815,1.988491507,10.25000028,0.005442286,0.001274508,0.25,2.58E-05,0.000508529,2.88E-05,70.1897049,70.1897049,552.9567261,578.5489502,43.60783672,17.54690025,49.13351059,0,0,0,40,69.72412872,1,6,1,1.949310303,52.29716492,,,,,,,,,,,,,,,,
3772710552,70.18986893,685.2306519,0.000503512,2.81E-06,1,0.999253354,40.02988815,1.988457542,10.25000028,0.005413645,0.001234257,0.25,2.26E-05,0.000505333,2.56E-05,70.18973541,70.18973541,675.9227295,694.5385742,43.75634614,17.54598124,49.13550568,0,0,0,40,69.7233963,1,6,1,1.960754395,53.76344299,,,,,,,,,,,,,,,,
3772710557,70.189888,810.8230591,0.000465431,3.01E-06,1,0.999253354,40.02988815,1.988404291,10.25000028,0.004996226,0.001184282,0.25,2.49E-05,0.000467092,2.77E-05,70.18973541,70.18973541,798.0039673,823.6421509,43.47730475,17.54667716,49.13550568,0,0,0,40,69.72273254,1,6,1,1.960449219,53.27468491,,,,,,,,,,,,,,,,
3772710562,70.18931961,935.4594116,0.000447499,4.00E-06,1,0.999253354,40.02988815,1.988431209,10.25999989,0.004810927,0.001099295,0.25,2.03E-05,0.000449117,2.30E-05,70.18933868,70.18933868,924.0479736,946.8708496,44.30739424,17.54853763,49.13883591,0,0,0,40,69.72273254,1,6,1,1.960144043,53.76344299,,,,,,,,,,,,,,,,
3772710567,70.18985367,1062.929504,0.000439934,2.56E-06,1,0.999253354,40.02988815,1.988359101,10.25999989,0.004733629,0.001057573,0.25,1.78E-05,0.000441538,2.05E-05,70.1897049,70.1897049,1048.317871,1077.541138,43.39679702,17.54514524,49.13683701,0,0,0,40,69.72266388,1,6,1,1.949462891,53.76344299,,,,,,,,,,,,,,,,
3772710572,70.19060898,1184.658264,0.000397393,7.38E-06,1,0.999253354,40.02988815,1.988291355,10.25000028,0.004276151,0.000953111,0.25,1.59E-05,0.000398843,1.83E-05,70.19084167,70.19084167,1171.744629,1197.571899,43.89078624,17.53910637,49.13373184,0,0,0,40,69.72232819,1,6,1,1.949768066,54.25220108,,,,,,,,,,,,,,,,
3772710577,70.19034195,1313.510864,0.000344792,5.94E-06,1,0.999253354,40.02988815,1.988316021,10.25000028,0.003727014,0.000734116,0.25,5.25E-06,0.000346101,7.27E-06,70.19054413,70.19054413,1298.857788,1328.16394,43.64222837,17.54438665,49.13462067,0,0,0,40,69.72193146,1,6,1,1.958465576,54.25220108,,,,,,,,,,,,,,,,
3772710582,70.1903038,1434.131287,0.000380341,4.54E-06,1,0.999253354,40.02988815,1.988327999,10.25000028,0.004093527,0.000907923,0.25,1.48E-05,0.000381733,1.71E-05,70.19026947,70.19026947,1422.524048,1445.738525,44.36288987,17.54496564,49.13506317,0,0,0,40,69.72200012,1,6,1,1.961517334,53.76344299,,,,,,,,,,,,,,,,
3772710587,70.1906929,1558.385254,0.00028125,9.80E-06,1,0.999253354,40.02988815,1.988316328,10.25000028,0.003034672,0.000629169,0.25,7.08E-06,0.000282302,8.74E-06,70.19054413,70.19054413,1543.960327,1572.810181,43.90954532,17.54455138,49.13506317,0,0,0,40,69.72077179,1,6,1,1.948699951,55.22971725,,,,,,,,,,,,,,,,
3772710592,70.18898392,1682.832581,0.000334482,5.57E-06,1,0.999253354,40.02988815,1.988380017,10.25000028,0.003578377,0.000918095,0.25,2.41E-05,0.000335642,2.61E-05,70.18946838,70.18946838,1673.017822,1692.647339,44.01272029,17.54922747,49.13217926,0,0,0,40,69.72119904,1,6,1,1.950531006,55.22971725,,,,,,,,,,,,,,,,
3772710597,70.18899918,1808.5448,0.000303631,1.08E-05,1,0.999253354,40.02988815,1.988408815,10.25000028,0.003281578,0.000650171,0.25,4.96E-06,0.000304783,6.74E-06,70.18862915,70.18862915,1796.928345,1820.161255,43.8485783,17.55018816,49.13994598,0,0,0,40,69.72283173,1,6,1,1.95892334,54.74095917,,,,,,,,,,,,,,,,
3772710602,70.18960571,1932.863098,0.00026163,1.30E-05,1,0.999253354,40.02988815,1.988304522,10.25000028,0.002796826,0.000729537,0.25,1.99E-05,0.000262533,2.15E-05,70.18987274,70.18987274,1916.346191,1949.380005,44.02053657,17.54950293,49.13817215,0,0,0,40,69.72379303,1,6,1,1.949462891,54.74095917,,,,,,,,,,,,,,,,
3772710607,70.19091034,2056.538696,0.000316309,3.56E-06,1,0.999253354,40.02988815,1.988448347,10.25000028,0.003389302,0.000839441,0.25,2.01E-05,0.000317423,2.20E-05,70.19057465,70.19057465,2043.73584,2069.341553,44.03069775,17.54695485,49.13484192,0,0,0,40,69.7233963,1,6,1,1.9480896,55.22971725,,,,,,,,,,,,,,,,
3772710612,70.19089127,2182.393799,0.000270539,7.76E-06,1,0.999253354,40.02988815,1.988472893,10.25000028,0.002927057,0.000562618,0.25,2.88E-06,0.000271575,4.46E-06,70.1911087,70.1911087,2172.387695,2192.399902,44.16044808,17.5485649,49.13040161,0,0,0,40,69.72290039,1,6,1,1.959838867,55.22971725,,,,,,,,,,,,,,,,
3772710617,70.19033813,2305.217041,0.000197412,6.44E-06,1,0.999253354,40.02988815,1.988450053,10.25000028,0.002189849,0.000112529,0.25,-2.54E-05,0.000198328,-2.43E-05,70.19050598,70.19050598,2290.879639,2319.554443,44.02835286,17.54515064,49.13217926,0,0,0,40,69.72259521,1,6,1,1.949157715,55.71847534,,,,,,,,,,,,,,,,
3772710622,70.19037247,2428.245239,0.000327649,5.62E-06,1,0.999253354,40.02988815,1.988482267,10.25999989,0.003503046,0.000912766,0.25,2.48E-05,0.000328781,2.68E-05,70.19023895,70.19023895,2422.158203,2434.332275,44.05023846,17.54764189,49.12263489,0,0,0,40,69.72239685,1,6,1,1.961517334,55.71847534,,,,,,,,,,,,,,,,
3772710627,70.19017029,2556.19458,0.00024309,6.99E-06,1,0.999253354,40.02988815,1.988495871,10.25000028,0.002591406,0.000719171,0.25,2.23E-05,0.000243908,2.38E-05,70.19010162,70.19010162,2546.782959,2565.606201,43.98770818,17.55046481,49.13573074,0,0,0,40,69.72259521,1,6,1,1.951751709,55.71847534,,,,,,,,,,,,,,,,
3772710632,70.19039154,2678.082275,0.000223902,6.26E-06,1,0.999253354,40.02988815,1.988425198,10.25000028,0.002287777,0.00120876,0.25,7.09E-05,0.000224363,7.25E-05,70.19057465,70.19057465,2666.675537,2689.489014,43.96504095,17.5522275,49.1363945,0,0,0,40,69.72273254,1,6,1,1.947937012,55.71847534,,,,,,,,,,,,,,,,
3772710637,70.18965149,2803.981079,0.000210068,7.94E-06,1,0.999253354,40.02988815,1.988538806,10.25999989,0.002152248,0.001102689,0.25,6.37E-05,0.000210518,6.51E-05,70.18963623,70.18963623,2792.572021,2815.390137,44.54266443,17.55100479,49.13462067,0,0,0,40,69.72290039,1,6,1,1.947021484,60.60606384,,,,,,,,,,,,,,,,
3772710642,70.19018936,2927.106079,0.000114589,4.97E-06,1,0.999253354,40.02988815,1.988397108,10.25000028,0.001239416,0.000240115,0.25,1.39E-06,0.000115028,2.06E-06,70.19004059,70.19004059,2915.5979,2938.614258,44.15966645,17.54994178,49.13972473,0,0,0,40,69.72290039,1,6,1,1.960754395,56.69599533,,,,,,,,,,,,,,,,
3772710647,70.1901741,3056.006836,0.000229692,8.33E-06,1,0.999253354,40.02988815,1.988425113,10.25000028,0.002404479,0.00092251,0.25,4.35E-05,0.000230336,4.50E-05,70.19013977,70.19013977,3042.890625,3069.123047,43.98536329,17.55027201,49.13972473,0,0,0,40,69.72349548,1,6,1,1.956939697,57.18475342,,,,,,,,,,,,,,,,
3772710652,70.19022369,3176.254272,0.000175763,9.81E-06,1,0.999253354,40.02988815,1.988429544,10.25000028,0.001827772,0.000773117,0.25,3.95E-05,0.000176221,4.06E-05,70.19020844,70.19020844,3163.38208,3189.126465,44.18155205,17.54662,49.1448288,0,0,0,40,69.72372437,1,6,1,1.963348389,56.69599533,,,,,,,,,,,,,,,,
3772710657,70.19017029,3304.431641,0.000151165,8.53E-06,1,0.999253354,40.02988815,1.9883791,10.25999989,0.001542608,0.000826768,0.25,4.89E-05,0.000151472,4.99E-05,70.19017029,70.19017029,3290.421387,3318.441895,44.10807897,17.54784518,49.14438248,0,0,0,40,69.72379303,1,6,1,1.960449219,53.76344299,,,,,,,,,,,,,,,,
3772710661,70.19009018,3423.807861,0.000226549,9.63E-06,1,0.999253354,40.02988815,1.988499662,10.25000028,0.002322939,0.001178892,0.25,6.77E-05,0.000227042,6.93E-05,70.19023895,70.19023895,3412.60376,3435.011963,44.21125393,17.55074188,49.14016724,0,0,0,40,69.72366333,1,6,1,1.947631836,56.69599533,,,,,,,,,,,,,,,,
3772710667,70.1906929,3551.139771,5.50E-05,9.19E-06,1,0.999253354,40.02988815,1.988395313,10.25000028,0.000563406,0.000286495,0.25,1.65E-05,5.51E-05,1.69E-05,70.19074249,70.19074249,3541.223633,3561.055908,43.91110858,17.54731737,49.13106918,0,0,0,40,69.72322845,1,6,1,1.963043213,56.20723343,,,,,,,,,,,,,,,,
3772710672,70.1906929,3673.914673,0.00017276,9.36E-06,1,0.999253354,40.02988815,1.988414207,10.25000028,0.001726427,0.001146888,0.25,7.45E-05,0.000173004,7.58E-05,70.19081116,70.19081116,3660.715576,3687.11377,44.19874788,17.55110094,49.13018036,0,0,0,40,69.72325897,1,6,1,1.9480896,56.20723343,,,,,,,,,,,,,,,,
3772710677,70.19166183,3796.813843,0.000114504,2.76E-05,1,0.999253354,40.02988815,1.988424748,10.25999989,0.001081602,0.001106064,0.25,8.13E-05,0.000114482,8.23E-05,70.1914444,70.1914444,3783.80127,3809.826416,43.92439627,17.54898559,49.12596512,0,0,0,40,69.72239685,1,6,1,1.961975098,57.18475342,,,,,,,,,,,,,,,,
3772710681,70.1904068,3921.648071,0.000112052,1.03E-05,1,0.999253354,40.02988815,1.988375122,10.25000028,0.001143636,0.000612001,0.25,3.62E-05,0.000112282,3.69E-05,70.19047546,70.19047546,3908.444336,3934.851807,44.30583098,17.55157244,49.12662888,0,0,0,40,69.72259521,1,6,1,1.948547363,57.18475342,,,,,,,,,,,,,,,,
3772710686,70.19032288,4047.323364,0.000101968,9.96E-06,1,0.999253354,40.02988815,1.988508976,10.25000028,0.000970599,0.000944286,0.25,6.86E-05,0.00010197,6.95E-05,70.19020844,70.19020844,4035.916504,4058.730225,43.96113281,17.55394794,49.12463379,0,0,0,40,69.72273254,1,6,1,1.95098877,57.18475342,,,,,,,,,,,,,,,,
3772710692,70.19105911,4171.789307,7.20E-05,1.61E-05,1,0.999253354,40.02988815,1.988344647,10.25000028,0.000672412,0.000740898,0.25,5.53E-05,7.20E-05,5.59E-05,70.1911087,70.1911087,4155.804688,4187.773926,44.04476706,17.5476223,49.12396622,0,0,0,40,69.72306061,1,6,1,1.949462891,57.67351151,,,,,,,,,,,,,,,,
3772710696,70.19065475,4290.838623,-7.04E-05,6.92E-06,1,0.999253354,40.02988815,1.988352631,10.25000028,-0.000785312,-1.59E-05,0.25,1.13E-05,-7.07E-05,1.09E-05,70.19087219,70.19087219,4278.033203,4303.644043,44.14637877,17.54340464,49.1255188,0,0,0,40,69.72290039,1,6,1,1.943664551,57.18475342,,,,,,,,,,,,,,,,
3772710701,70.19032288,4417.232666,4.26E-05,9.87E-06,1,0.999253354,40.02988815,1.988399299,10.25000028,0.000438495,0.000210058,0.25,1.17E-05,4.27E-05,1.20E-05,70.19043732,70.19043732,4407.523926,4426.941406,43.92908604,17.54874013,49.12130356,0,0,0,40,69.72299957,1,6,1,1.949157715,57.18475342,,,,,,,,,,,,,,,,
3772710707,70.19142532,4546.981445,8.97E-05,1.45E-05,1,0.999253354,40.02988815,1.988315932,10.25000028,0.000838499,0.000914435,0.25,6.81E-05,8.97E-05,6.89E-05,70.19137573,70.19137573,4533.76123,4560.20166,44.06743429,17.54868559,49.12596512,0,0,0,40,69.72332764,1,6,1,1.958618164,57.67351151,,,,,,,,,,,,,,,,
3772710712,70.19213104,4671.316162,5.81E-05,5.28E-05,1,0.999253354,40.02988815,1.98834944,10.25000028,0.000467297,0.001013867,0.25,8.30E-05,5.79E-05,8.37E-05,70.19228363,70.19228363,4658.285156,4684.347168,44.19171322,17.55137417,49.1270752,0,0,0,40,69.7233963,1,6,1,1.960449219,57.67351151,,,,,,,,,,,,,,,,
3772710717,70.19181442,4796.008057,-1.46E-05,2.18E-06,1,0.999253354,40.02988815,1.988299588,10.25000028,-0.000291118,0.000706743,0.25,6.78E-05,-1.50E-05,6.80E-05,70.19184875,70.19184875,4781.61084,4810.405273,44.61379262,17.55449832,49.12174606,0,0,0,40,69.72212982,1,6,1,1.953125,55.22971725,,,,,,,,,,,,,,,,
3772710721,70.1922493,4917.268799,2.32E-06,2.09E-06,1,0.999253354,40.02988815,1.988395025,10.25999989,-4.07E-05,0.000367589,0.25,3.35E-05,2.13E-06,3.36E-05,70.19261932,70.19261932,4907.871094,4926.666504,43.9142351,17.54631125,49.12330246,0,0,0,40,69.72156525,1,6,1,1.946411133,57.67351151,,,,,,,,,,,,,,,,
3772710735,70.1916275,4982.541748,4.10E-05,0.000175372,1,0.999253354,40.02988815,1.988367147,10.25000028,0.000305719,0.000844375,0.25,7.05E-05,4.07E-05,7.10E-05,70.19151306,70.19151306,4979.334473,4985.749023,44.11355037,17.55308985,49.12219238,0,0,0,40,69.72183228,1,6,1,1.960449219,57.67351151,,,,,,,,,,,,,,,,
3772710739,70.19156265,4863.199951,-7.02E-05,1.08E-05,1,0.999253354,40.02988815,1.988324079,10.25999989,-0.000847153,0.000337623,0.25,4.39E-05,-7.07E-05,4.36E-05,70.19158173,70.19158173,4850.162109,4876.237793,43.88922298,17.55025964,49.1206398,0,0,0,40,69.72090149,1,6,1,1.957397461,57.67351151,,,,,,,,,,,,,,,,
3772710745,70.1911087,4737.201904,-9.31E-05,6.92E-06,1,0.999253354,40.02988815,1.98839668,10.25000028,-0.001149555,0.000590338,0.25,7.13E-05,-9.39E-05,7.11E-05,70.19094086,70.19094086,4724.187012,4750.216797,43.83607224,17.5501078,49.12907028,0,0,0,40,69.722229,1,6,1,1.947937012,58.16226959,,,,,,,,,,,,,,,,
3772710749,70.19226456,4613.636963,-0.000104465,1.42E-05,1,0.999253354,40.02988815,1.988493593,10.25999989,-0.001227761,0.000320795,0.25,4.85E-05,-0.000105154,4.81E-05,70.19238281,70.19238281,4604.225586,4623.04834,44.26362304,17.55176087,49.1270752,0,0,0,40,69.7213974,1,6,1,1.948699951,57.67351151,,,,,,,,,,,,,,,,
3772710755,70.19264984,4487.371582,-0.000133558,6.61E-06,1,0.999253354,40.02988815,1.988403078,10.25000028,-0.001614606,0.000658426,0.25,8.49E-05,-0.000134571,8.45E-05,70.19261932,70.19261932,4474.384277,4500.358887,44.46059343,17.55786574,49.12773895,0,0,0,40,69.72216797,1,6,1,1.950378418,58.16226959,,,,,,,,,,,,,,,,
3772710759,70.19331741,4365.504639,-0.000125657,7.19E-06,1,0.999253354,40.02988815,1.988413023,10.25000028,-0.001493763,0.000479653,0.25,6.70E-05,-0.000126536,6.66E-05,70.19328308,70.19328308,4353.888184,4377.121094,44.13230945,17.55074246,49.11708832,0,0,0,40,69.72156525,1,6,1,1.963653564,57.67351151,,,,,,,,,,,,,,,,
3772710764,70.19248199,4237.628906,-0.000126832,8.37E-06,1,0.999253354,40.02988815,1.988427772,10.25000028,-0.001492404,0.000399491,0.25,5.98E-05,-0.000127674,5.93E-05,70.19238281,70.19238281,4226.028809,4249.229004,43.86577413,17.55376041,49.111763,0,0,0,40,69.72083282,1,6,1,1.947937012,58.16226959,,,,,,,,,,,,,,,,
3772710769,70.19283295,4113.584717,-0.000177308,8.07E-06,1,0.999253354,40.02988815,1.988397333,10.25000028,-0.001946937,-0.000210848,0.25,1.27E-05,-0.000178075,1.17E-05,70.19268036,70.19268036,4103.975098,4123.194336,44.08384848,17.55209237,49.10221863,0,0,0,40,69.71977234,1,6,1,1.953277588,58.16226959,,,,,,,,,,,,,,,,
3772710774,70.19353485,3991.365234,-0.000206239,8.14E-06,1,0.999253354,40.02988815,1.98844744,10.25000028,-0.002293241,-8.75E-05,0.25,2.93E-05,-0.000207215,2.82E-05,70.1931839,70.1931839,3975.018799,4007.71167,44.36054498,17.55208963,49.10421753,0,0,0,40,69.71990204,1,6,1,1.950836182,58.16226959,,,,,,,,,,,,,,,,
3772710780,70.19316864,3865.328247,-0.000102336,1.43E-05,1,0.999253354,40.02988815,1.988444326,10.25000028,-0.001173174,0.000151218,0.25,3.25E-05,-0.000102924,3.20E-05,70.19308472,70.19308472,3852.421631,3878.234863,43.81184176,17.55191986,49.09534073,0,0,0,40,69.71967316,1,6,1,1.9480896,57.18475342,,,,,,,,,,,,,,,,
3772710784,70.19264984,3746.196045,-0.000163037,6.87E-06,1,0.999253354,40.02988815,1.988392322,10.25000028,-0.001856452,0.000171692,0.25,4.54E-05,-0.000163937,4.46E-05,70.19274902,70.19274902,3732.989746,3759.402344,44.40275292,17.55152196,49.10177612,0,0,0,40,69.71930695,1,6,1,1.949615479,60.60606384,,,,,,,,,,,,,,,,
3772710789,70.19227982,3620.002319,-0.000263583,6.22E-06,1,0.999253354,40.02988815,1.988318727,10.25000028,-0.002815612,-0.000746897,0.25,-2.11E-05,-0.00026449,-2.28E-05,70.19217682,70.19217682,3606.890625,3633.114014,44.3363145,17.54559053,49.10621262,0,0,0,40,69.71930695,1,6,1,1.954040527,58.65102768,,,,,,,,,,,,,,,,
3772710795,70.19160843,3490.836548,-0.000243546,6.27E-06,1,0.999253354,40.02988815,1.988464691,10.25999989,-0.002614322,-0.000620778,0.25,-1.31E-05,-0.000244421,-1.46E-05,70.19147491,70.19147491,3479.459717,3502.213379,43.95097164,17.54776061,49.111763,0,0,0,40,69.72036743,1,6,1,1.951904297,58.16226959,,,,,,,,,,,,,,,,
3772710799,70.19102478,3374.176514,-0.000263596,6.14E-06,1,0.999253354,40.02988815,1.988400973,10.25000028,-0.002877162,-0.000408587,0.25,1.01E-05,-0.000264683,8.58E-06,70.19074249,70.19074249,3361.170898,3387.182129,44.46762809,17.54541765,49.10821152,0,0,0,40,69.72106934,1,6,1,1.951599121,59.13978577,,,,,,,,,,,,,,,,
3772710804,70.19223022,3247.082031,-0.000232419,8.59E-06,1,0.999253354,40.02988815,1.988432541,10.25000028,-0.002555963,-0.000255051,0.25,1.86E-05,-0.000233433,1.73E-05,70.19217682,70.19217682,3234.15918,3260.004883,44.38868361,17.5492172,49.11619949,0,0,0,40,69.72283173,1,6,1,1.951904297,58.16226959,,,,,,,,,,,,,,,,
3772710809,70.19246292,3121.067871,-0.000296953,7.10E-06,1,0.999253354,40.02988815,1.98853047,10.25999989,-0.00322964,-0.000525535,0.25,5.33E-06,-0.000298143,3.63E-06,70.19241333,70.19241333,3106.350342,3135.7854,44.31755541,17.55122486,49.10599136,0,0,0,40,69.72325897,1,6,1,1.948394775,57.67351151,,,,,,,,,,,,,,,,
3772710814,70.19308472,2995.371826,-0.000267772,7.50E-06,1,0.999253354,40.02988815,1.98840252,10.25000028,-0.002906234,-0.000506166,0.25,1.82E-06,-0.000268827,2.80E-07,70.19298553,70.19298553,2982.26001,3008.483643,43.53905341,17.55092464,49.10488129,0,0,0,40,69.72315979,1,6,1,1.957855225,58.65102768,,,,,,,,,,,,,,,,
3772710819,70.19291687,2868.307129,-0.000251644,7.28E-06,1,0.999253354,40.02988815,1.988416368,10.25999989,-0.002752812,-0.00035639,0.25,1.27E-05,-0.000252698,1.13E-05,70.19294739,70.19294739,2852.391602,2884.222656,44.11042385,17.54830179,49.10488129,0,0,0,40,69.72216797,1,6,1,1.949462891,58.65102768,,,,,,,,,,,,,,,,
3772710824,70.19251633,2749.154175,-0.000308895,4.81E-06,1,0.999253354,40.02988815,1.988471246,10.25999989,-0.003384529,-0.00040798,0.25,1.83E-05,-0.000310205,1.66E-05,70.19241333,70.19241333,2736.34668,2761.96167,43.92595952,17.54892755,49.10754395,0,0,0,40,69.72183228,1,6,1,1.946411133,58.16226959,,,,,,,,,,,,,,,,
3772710829,70.19291687,2622.045776,-0.000264151,6.24E-06,1,0.999253354,40.02988815,1.988451174,10.25000028,-0.002938918,-0.000102318,0.25,3.84E-05,-0.000265402,3.70E-05,70.19277954,70.19277954,2609.224365,2634.867188,44.06899754,17.55561866,49.10554886,0,0,0,40,69.72156525,1,6,1,1.950683594,57.67351151,,,,,,,,,,,,,,,,
3772710834,70.19384003,2496.515625,-0.000312957,7.20E-06,1,0.999253354,40.02988815,1.988433082,10.25999989,-0.003433322,-0.000389339,0.25,2.08E-05,-0.000314297,1.91E-05,70.19392395,70.19392395,2483.613525,2509.417725,44.08775663,17.54856019,49.10998535,0,0,0,40,69.72156525,1,6,1,1.945800781,59.62854385,,,,,,,,,,,,,,,,
3772710839,70.19306564,2373.137207,-0.000282941,5.76E-06,1,0.999253354,40.02988815,1.98848613,10.25000028,-0.003136524,-0.000173037,0.25,3.53E-05,-0.000284247,3.38E-05,70.1931839,70.1931839,2360.149902,2386.124512,44.2323579,17.55080756,49.09511566,0,0,0,40,69.72143555,1,6,1,1.959686279,58.65102768,,,,,,,,,,,,,,,,
3772710844,70.19316864,2248.265747,-0.000342859,5.02E-06,1,0.999253354,40.02988815,1.988289608,10.25000028,-0.003659326,-0.000988171,0.25,-2.90E-05,-0.000344026,-3.11E-05,70.19315338,70.19315338,2237.063965,2259.467529,43.84388853,17.54698173,49.10443878,0,0,0,40,69.72060394,1,6,1,1.952667236,58.65102768,,,,,,,,,,,,,,,,
3772710849,70.19300079,2128.115356,-0.000368114,5.66E-06,1,0.999253354,40.02988815,1.988352471,10.25000028,-0.003932466,-0.001041808,0.25,-2.94E-05,-0.000369377,-3.17E-05,70.19308472,70.19308472,2115.194824,2141.035889,44.2925433,17.54793651,49.10932159,0,0,0,40,69.72083282,1,6,1,1.954345703,58.16226959,,,,,,,,,,,,,,,,
3772710855,70.19216156,1998.594543,-0.000382157,3.65E-06,1,0.999253354,40.02988815,1.988438467,10.25000028,-0.004081054,-0.001090356,0.25,-3.13E-05,-0.000383462,-3.37E-05,70.19258118,70.19258118,1985.657959,2011.531128,44.09088314,17.54902809,49.0944519,0,0,0,40,69.7213974,1,6,1,1.962432861,59.13978577,,,,,,,,,,,,,,,,
3772710860,70.19236755,1872.1521,-0.000398676,4.36E-06,1,0.999253354,40.02988815,1.98839868,10.25000028,-0.004304662,-0.000876507,0.25,-8.62E-06,-0.000400177,-1.10E-05,70.19245148,70.19245148,1859.337646,1884.966553,44.3034861,17.54901417,49.10021973,0,0,0,40,69.72193146,1,6,1,1.949615479,59.13978577,,,,,,,,,,,,,,,,
3772710864,70.19253159,1751.713562,-0.000400201,4.63E-06,1,0.999253354,40.02988815,1.988347102,10.25000028,-0.00434548,-0.000744827,0.25,3.80E-06,-0.00040178,1.50E-06,70.19255066,70.19255066,1743.52771,1759.899414,44.26284142,17.54859791,49.1013298,0,0,0,40,69.72259521,1,6,1,1.950073242,58.65102768,,,,,,,,,,,,,,,,
3772710869,70.19333649,1624.245728,-0.000405532,5.73E-06,1,0.999253354,40.02988815,1.988402217,10.25999989,-0.00440791,-0.000730283,0.25,6.11E-06,-0.000407144,3.78E-06,70.1931839,70.1931839,1611.230713,1637.260742,44.13543597,17.55258286,49.10688019,0,0,0,40,69.72232819,1,6,1,1.948394775,59.13978577,,,,,,,,,,,,,,,,
3772710874,70.19514084,1501.590698,-0.000446088,4.73E-06,1,0.999253354,40.02988815,1.988414903,10.25000028,-0.004832871,-0.000890956,0.25,-1.36E-06,-0.000447813,-3.95E-06,70.19519043,70.19519043,1488.81311,1514.368286,43.79855408,17.55043531,49.10887527,0,0,0,40,69.72156525,1,6,1,1.948394775,59.62854385,,,,,,,,,,,,,,,,
3772710879,70.19457626,1380.216797,-0.000411101,4.94E-06,1,0.999253354,40.02988815,1.988446563,10.25000028,-0.004487623,-0.000634907,0.25,1.59E-05,-0.00041279,1.36E-05,70.19452667,70.19452667,1367.307861,1393.125732,44.33787775,17.55330812,49.10221863,0,0,0,40,69.72109985,1,6,1,1.936340332,58.65102768,,,,,,,,,,,,,,,,
3772710885,70.19310379,1251.03717,-0.000459621,3.80E-06,1,0.999253354,40.02988815,1.988274293,10.25000028,-0.004981998,-0.000902193,0.25,4.97E-08,-0.000461407,-2.62E-06,70.1930542,70.1930542,1238.019897,1264.054443,44.3417859,17.54664569,49.10021973,0,0,0,40,69.72003937,1,6,1,1.950683594,59.62854385,,,,,,,,,,,,,,,,
3772710889,70.19305038,1130.105469,-0.000438149,3.66E-06,1,0.999253354,40.02988815,1.988417806,10.25999989,-0.00475224,-0.000845403,0.25,1.40E-06,-0.000439859,-1.13E-06,70.19325256,70.19325256,1115.777222,1144.433716,44.14403388,17.55487984,49.09733582,0,0,0,40,69.72053528,1,6,1,1.949157715,59.13978577,,,,,,,,,,,,,,,,
3772710894,70.19182968,1002.623871,-0.000463654,4.10E-06,1,0.999253354,40.02988815,1.988356791,10.25000028,-0.005025354,-0.000913131,0.25,-2.25E-07,-0.000465452,-2.92E-06,70.19181061,70.19181061,986.7243652,1018.523376,44.4433976,17.55310318,49.09556198,0,0,0,40,69.721138,1,6,1,1.96182251,59.13978577,,,,,,,,,,,,,,,,
3772710899,70.19280243,881.2591553,-0.000483008,4.34E-06,1,0.999253354,40.02988815,1.988367796,10.25999989,-0.005224201,-0.00101169,0.25,-5.81E-06,-0.000484849,-8.64E-06,70.19298553,70.19298553,870.057373,892.4609375,44.46137506,17.54853543,49.09289932,0,0,0,40,69.72229767,1,6,1,1.959991455,59.13978577,,,,,,,,,,,,,,,,
3772710904,70.19301987,756.6988525,-0.000517227,2.89E-06,1,0.999253354,40.02988815,1.988360297,10.25000028,-0.005589379,-0.001110403,0.25,-8.72E-06,-0.000519183,-1.18E-05,70.1930542,70.1930542,747.5982666,765.7994385,44.34100427,17.55377559,49.09289932,0,0,0,40,69.72259521,1,6,1,1.949157715,59.62854385,,,,,,,,,,,,,,,,
3772710909,70.19380569,632.9427185,-0.000509626,2.70E-06,1,0.999253354,40.02988815,1.98830066,10.25999989,-0.005512586,-0.00106368,0.25,-5.79E-06,-0.000511569,-8.77E-06,70.19392395,70.19392395,621.4299316,644.4555054,44.16044808,17.55242045,49.09223175,0,0,0,40,69.72273254,1,6,1,1.950073242,59.13978577,,,,,,,,,,,,,,,,
3772710914,70.1937027,505.3181458,-0.000530181,2.12E-06,1,0.999253354,40.02988815,1.988482123,10.25000028,-0.005743384,-0.001062708,0.25,-1.96E-06,-0.000532226,-5.05E-06,70.19381714,70.19381714,495.5425415,515.09375,44.33944101,17.55488441,49.0900116,0,0,0,40,69.72206879,1,6,1,1.950378418,59.62854385,,,,,,,,,,,,,,,,
3772710919,70.19367218,385.0938873,-0.00054111,2.04E-06,1,0.999253354,40.02988815,1.988304802,10.25999989,-0.005849169,-0.001151353,0.25,-8.17E-06,-0.000543161,-1.13E-05,70.1937561,70.1937561,372.2724609,397.9153137,44.2268865,17.55394818,49.09467316,0,0,0,40,69.72156525,1,6,1,1.948394775,59.13978577,,,,,,,,,,,,,,,,
3772710924,70.19419098,256.2367706,-0.000557734,1.29E-06,1,0.999253354,40.02988815,1.988220745,10.25000028,-0.006012853,-0.001273681,0.25,-1.64E-05,-0.000559801,-1.97E-05,70.19402313,70.19402313,244.8322754,267.6412659,44.2433007,17.54358832,49.10044479,0,0,0,40,69.72070313,1,6,1,1.952209473,57.67351151,,,,,,,,,,,,,,,,
3772710929,70.19323349,136.0171356,-0.000566196,1.49E-06,1,0.999253354,40.02988815,1.988346701,10.25000028,-0.006100409,-0.001315362,0.25,-1.88E-05,-0.000568282,-2.21E-05,70.19335175,70.19335175,119.5808105,152.4534607,44.37852244,17.55064615,49.11286926,0,0,0,40,69.72067261,1,6,1,1.961212158,59.13978577,,,,,,,,,,,,,,,,
3772710934,70.19321823,11.5006293,-0.00056343,1.95E-06,1,0.999253354,40.02988815,1.988269712,10.25999989,-0.00608735,-0.001215191,0.25,-1.00E-05,-0.000565555,-1.33E-05,70.1931839,70.1931839,0.093816504,22.90744209,44.14090737,17.55061462,49.11442566,0,0,0,40,69.72100067,1,6,1,1.958312988,59.62854385,,,,,,,,,,,,,,,,
3772710939,70.19285202,-112.8062096,-0.00055601,1.05E-06,1,0.999253354,40.02988815,1.98839329,10.25000028,-0.005997101,-0.001256923,0.25,-1.52E-05,-0.000558077,-1.85E-05,70.19255066,70.19255066,-124.2084122,-101.404007,44.67241476,17.55727043,49.10909653,0,0,0,40,69.72109985,1,6,1,1.95892334,59.62854385,,,,,,,,,,,,,,,,
3772710944,70.19345093,-239.8570404,-0.000542508,1.77E-06,1,0.999253354,40.02988815,1.988377053,10.25000028,-0.005857201,-0.001194518,0.25,-1.19E-05,-0.000544542,-1.51E-05,70.19345093,70.19345093,-251.2615509,-228.4525299,44.33318798,17.55261406,49.10243988,0,0,0,40,69.72170258,1,6,1,1.957397461,57.67351151,,,,,,,,,,,,,,,,
3772710949,70.19490814,-364.1085815,-0.000528008,2.00E-06,1,0.999253354,40.02988815,1.988414447,10.25999989,-0.005694482,-0.001197207,0.25,-1.48E-05,-0.000529969,-1.79E-05,70.19482422,70.19482422,-378.5128174,-349.7043457,44.36992452,17.55403859,49.10665512,0,0,0,40,69.7213974,1,6,1,1.95526123,59.62854385,,,,,,,,,,,,,,,,
3772710954,70.19525909,-486.9777527,-0.000515125,2.54E-06,1,0.999253354,40.02988815,1.9884179,10.25000028,-0.005547516,-0.001212392,0.25,-1.85E-05,-0.000517015,-2.16E-05,70.19519043,70.19519043,-496.1889038,-477.7666016,44.13309108,17.55269031,49.09999847,0,0,0,40,69.721138,1,6,1,1.951446533,59.13978577,,,,,,,,,,,,,,,,
3772710959,70.19534302,-607.6974182,-0.00049264,2.63E-06,1,0.999253354,40.02988815,1.988273947,10.25999989,-0.005307548,-0.001145394,0.25,-1.64E-05,-0.000494456,-1.93E-05,70.19532776,70.19532776,-619.0213013,-596.3735352,44.2706577,17.55133084,49.10688019,0,0,0,40,69.71950531,1,6,1,1.951293945,59.13978577,,,,,,,,,,,,,,,,
3772710964,70.19525909,-734.973999,-0.000494539,2.99E-06,1,0.999253354,40.02988815,1.988369799,10.25000028,-0.005342979,-0.001068631,0.25,-8.97E-06,-0.000496406,-1.19E-05,70.19535828,70.19535828,-747.7838745,-722.1641235,43.98067352,17.55165699,49.10577011,0,0,0,40,69.71874237,1,6,1,1.963500977,59.62854385,,,,,,,,,,,,,,,,
3772710969,70.19425583,-858.7854309,-0.000471032,3.16E-06,1,0.999253354,40.02988815,1.988365905,10.25999989,-0.005084227,-0.0010442,0.25,-1.10E-05,-0.000472797,-1.38E-05,70.19452667,70.19452667,-871.8049927,-845.7658691,44.42073038,17.54766818,49.09667206,0,0,0,40,69.71837616,1,6,1,1.960296631,59.62854385,,,,,,,,,,,,,,,,
3772710974,70.19380188,-983.4794006,-0.000437905,5.06E-06,1,0.999253354,40.02988815,1.988358658,10.25999989,-0.004722122,-0.000995741,0.25,-1.25E-05,-0.000439533,-1.51E-05,70.19381714,70.19381714,-996.2824097,-970.6763916,44.32068193,17.54708753,49.10243988,0,0,0,40,69.71930695,1,6,1,1.95098877,59.62854385,,,,,,,,,,,,,,,,
3772710979,70.19368744,-1108.426697,-0.000429362,2.97E-06,1,0.999253354,40.02988815,1.988469768,10.25000028,-0.004625256,-0.001003925,0.25,-1.48E-05,-0.000430944,-1.74E-05,70.19368744,70.19368744,-1121.529175,-1095.324219,44.29566981,17.55168619,49.10066605,0,0,0,40,69.71990204,1,6,1,1.954345703,58.65102768,,,,,,,,,,,,,,,,
3772710984,70.19388962,-1227.25946,-0.00037646,3.20E-06,1,0.999253354,40.02988815,1.988290625,10.25000028,-0.00407351,-0.000778189,0.25,-3.58E-06,-0.000377902,-5.78E-06,70.19358826,70.19358826,-1239.772095,-1214.746826,43.86342924,17.54607175,49.10710144,0,0,0,40,69.71990204,1,6,1,1.960449219,59.13978577,,,,,,,,,,,,,,,,
3772710989,70.19298172,-1354.324097,-0.000414847,4.48E-06,1,0.999253354,40.02988815,1.988394391,10.25000028,-0.004416496,-0.00125827,0.25,-4.09E-05,-0.000416221,-4.35E-05,70.19328308,70.19328308,-1365.608765,-1343.039429,44.1252748,17.55598138,49.10821152,0,0,0,40,69.72040558,1,6,1,1.953887939,61.58358002,,,,,,,,,,,,,,,,
3772710994,70.19316864,-1477.787659,-0.000394918,4.59E-06,1,0.999253354,40.02988815,1.988339401,10.25000028,-0.00422734,-0.001070232,0.25,-2.72E-05,-0.000396295,-2.96E-05,70.1931839,70.1931839,-1487.49646,-1468.078857,44.27300259,17.54626684,49.10532379,0,0,0,40,69.72156525,1,6,1,1.949310303,59.62854385,,,,,,,,,,,,,,,,
3772710999,70.19358826,-1601.322632,-0.000357517,4.36E-06,1,0.999253354,40.02988815,1.988403473,10.25999989,-0.00378883,-0.001180128,0.25,-4.41E-05,-0.000358651,-4.63E-05,70.19368744,70.19368744,-1614.314453,-1588.330811,44.21281719,17.55252638,49.1008873,0,0,0,40,69.72216797,1,6,1,1.959686279,60.11730194,,,,,,,,,,,,,,,,
3772711004,70.19348526,-1724.67572,-0.000327442,6.42E-06,1,0.999253354,40.02988815,1.988313812,10.25999989,-0.003514376,-0.000835729,0.25,-1.78E-05,-0.000328612,-1.97E-05,70.19345093,70.19345093,-1733.985962,-1715.365479,44.32459007,17.54726197,49.10266113,0,0,0,40,69.72232819,1,6,1,1.951141357,60.11730194,,,,,,,,,,,,,,,,
3772711009,70.19331741,-1851.638916,-0.000342508,5.52E-06,1,0.999253354,40.02988815,1.988430381,10.25999989,-0.003670174,-0.000907971,0.25,-2.17E-05,-0.000343715,-2.38E-05,70.19345093,70.19345093,-1864.619385,-1838.658447,44.19014996,17.55198211,49.09511566,0,0,0,40,69.72249603,1,6,1,1.948852539,60.11730194,,,,,,,,,,,,,,,,
3772711014,70.1939888,-1975.977905,-0.000329373,5.80E-06,1,0.999253354,40.02988815,1.988476429,10.25999989,-0.003475851,-0.001169252,0.25,-4.82E-05,-0.000330375,-5.03E-05,70.19402313,70.19402313,-1985.682129,-1966.273682,44.51296254,17.55697362,49.09090042,0,0,0,40,69.72239685,1,6,1,1.962127686,59.62854385,,,,,,,,,,,,,,,,
3772711019,70.1939888,-2099.941528,-0.000265274,8.38E-06,1,0.999253354,40.02988815,1.988428619,10.25000028,-0.002843306,-0.000699142,0.25,-1.64E-05,-0.000266211,-1.80E-05,70.1938858,70.1938858,-2112.841309,-2087.041748,44.37774081,17.54774343,49.0920105,0,0,0,40,69.72216797,1,6,1,1.943511963,59.62854385,,,,,,,,,,,,,,,,
3772711024,70.19405746,-2227.275635,-0.000254182,1.07E-05,1,0.999253354,40.02988815,1.988285292,10.25000028,-0.002798285,-0.000261233,0.25,2.20E-05,-0.000255299,2.06E-05,70.19419098,70.19419098,-2240.48877,-2214.0625,44.64036799,17.54680488,49.09600449,0,0,0,40,69.72249603,1,6,1,1.959686279,59.62854385,,,,,,,,,,,,,,,,
3772711029,70.19470596,-2346.23999,-0.000288287,7.45E-06,1,0.999253354,40.02988815,1.988354369,10.25000028,-0.003114168,-0.000625685,0.25,-5.49E-06,-0.000289378,-7.18E-06,70.19448853,70.19448853,-2359.137451,-2333.342529,43.8321641,17.55090052,49.09467316,0,0,0,40,69.72206879,1,6,1,1.943817139,60.11730194,,,,,,,,,,,,,,,,
3772711034,70.19495773,-2473.403564,-0.000240593,6.94E-06,1,0.999253354,40.02988815,1.988318478,10.25000028,-0.002571624,-0.000672817,0.25,-1.85E-05,-0.000241423,-1.99E-05,70.19485474,70.19485474,-2483.213867,-2463.593262,44.45512203,17.55135552,49.10510254,0,0,0,40,69.72156525,1,6,1,1.951141357,60.60606384,,,,,,,,,,,,,,,,
3772711039,70.19500732,-2599.030518,-0.000234193,4.76E-06,1,0.999253354,40.02988815,1.988301759,10.25000028,-0.002492247,-0.000715353,0.25,-2.36E-05,-0.000234969,-2.50E-05,70.19519043,70.19519043,-2610.833496,-2587.227539,44.43636295,17.55195106,49.11375809,0,0,0,40,69.72060394,1,6,1,1.962280273,57.18475342,,,,,,,,,,,,,,,,
3772711044,70.19502258,-2721.512695,-0.000171459,1.41E-05,1,0.999253354,40.02988815,1.988265508,10.25000028,-0.001822777,-0.000533842,0.25,-1.82E-05,-0.000172022,-1.92E-05,70.19485474,70.19485474,-2734.338867,-2708.686523,44.37148778,17.54994675,49.12507629,0,0,0,40,69.71877289,1,6,1,1.949920654,60.11730194,,,,,,,,,,,,,,,,
3772711049,70.19556046,-2841.552612,-0.0001639,1.04E-05,1,0.999253354,40.02988815,1.98828848,10.25999989,-0.001676447,-0.000874512,0.25,-5.10E-05,-0.000164244,-5.21E-05,70.19559479,70.19559479,-2854.341797,-2828.763428,44.48560554,17.54894116,49.12485504,0,0,0,40,69.71960449,1,6,1,1.964416504,59.13978577,,,,,,,,,,,,,,,,
3772711054,70.19574356,-2973.53833,-0.000207197,1.04E-05,1,0.999253354,40.02988815,1.988299529,10.25000028,-0.002177735,-0.000783199,0.25,-3.47E-05,-0.000207805,-3.60E-05,70.19579315,70.19579315,-2982.85083,-2964.22583,44.44965063,17.55521045,49.12019348,0,0,0,40,69.71847534,1,6,1,1.954040527,59.62854385,,,,,,,,,,,,,,,,
3772711059,70.1952095,-3095.871094,-0.000124602,8.37E-06,1,0.999253354,40.02988815,1.988308516,10.25000028,-0.001320822,-0.00040924,0.25,-1.52E-05,-0.000125001,-1.60E-05,70.19512939,70.19512939,-3111.876465,-3079.865723,44.23392116,17.55320454,49.11198425,0,0,0,40,69.7178421,1,6,1,1.962280273,59.62854385,,,,,,,,,,,,,,,,
3772711064,70.19537735,-3220.901245,-0.00014714,7.91E-06,1,0.999253354,40.02988815,1.988357025,10.25000028,-0.001486248,-0.00088901,0.25,-5.54E-05,-0.000147394,-5.64E-05,70.19519043,70.19519043,-3232.52002,-3209.282471,44.55438885,17.55953586,49.11464691,0,0,0,40,69.7178421,1,6,1,1.948852539,60.11730194,,,,,,,,,,,,,,,,
3772711069,70.19500732,-3343.526123,-9.86E-05,1.16E-05,1,0.999253354,40.02988815,1.988215112,10.25000028,-0.001005902,-0.000542451,0.25,-3.22E-05,-9.88E-05,-3.29E-05,70.19519043,70.19519043,-3356.674561,-3330.377686,44.62942519,17.54637968,49.11997223,0,0,0,40,69.71788025,1,6,1,1.960601807,59.62854385,,,,,,,,,,,,,,,,
3772711074,70.19387054,-3467.540405,-7.37E-05,7.36E-06,1,0.999253354,40.02988815,1.988180333,10.25000028,-0.000803055,-0.000119736,0.25,2.30E-06,-7.40E-05,1.88E-06,70.19378662,70.19378662,-3484.15625,-3450.924561,44.13309108,17.55182379,49.111763,0,0,0,40,69.71864319,1,6,1,1.944580078,60.11730194,,,,,,,,,,,,,,,,
3772711079,70.19433975,-3593.174438,-0.000128613,1.13E-05,1,0.999253354,40.02988815,1.988165076,10.25999989,-0.001317938,-0.000672468,0.25,-3.87E-05,-0.000128891,-3.96E-05,70.19429016,70.19429016,-3605.975098,-3580.373779,43.9087637,17.5485651,49.11375809,0,0,0,40,69.71903992,1,6,1,1.951446533,60.60606384,,,,,,,,,,,,,,,,
3772711084,70.19408798,-3720.5177,-3.91E-05,1.06E-05,1,0.999253354,40.02988815,1.988314752,10.25000028,-0.000434325,-1.97E-05,0.25,5.27E-06,-3.93E-05,5.07E-06,70.19419098,70.19419098,-3733.631836,-3707.403564,44.05258334,17.55183624,49.10754395,0,0,0,40,69.72010803,1,6,1,1.952667236,60.11730194,,,,,,,,,,,,,,,,
3772711089,70.19406891,-3842.562012,-8.74E-05,1.35E-05,1,0.999253354,40.02988815,1.988212502,10.25000028,-0.000825127,-0.000848602,0.25,-6.24E-05,-8.74E-05,-6.32E-05,70.19398499,70.19398499,-3853.837402,-3831.286621,44.45043226,17.54934352,49.1077652,0,0,0,40,69.72040558,1,6,1,1.958618164,60.11730194,,,,,,,,,,,,,,,,
3772711094,70.1944046,-3966.322998,-6.53E-05,1.96E-05,1,0.999253354,40.02988815,1.988312071,10.25000028,-0.000582365,-0.000819099,0.25,-6.37E-05,-6.52E-05,-6.44E-05,70.19455719,70.19455719,-3980.932373,-3951.713623,44.54031954,17.55530509,49.11575699,0,0,0,40,69.72109985,1,6,1,1.960601807,60.11730194,,,,,,,,,,,,,,,,
3772711099,70.19396973,-4094.484131,-3.31E-05,1.21E-05,1,0.999253354,40.02988815,1.988291393,10.25000028,-0.000362693,-4.11E-05,0.25,2.20E-06,-3.32E-05,2.02E-06,70.19398499,70.19398499,-4107.376953,-4081.591309,44.15419505,17.54973067,49.11642075,0,0,0,40,69.7213974,1,6,1,1.946411133,60.11730194,,,,,,,,,,,,,,,,
3772711104,70.19510651,-4216.860352,-6.03E-05,8.75E-06,1,0.999253354,40.02988815,1.988263951,10.25999989,-0.00065344,-0.000116531,0.25,1.66E-07,-6.05E-05,-1.82E-07,70.19502258,70.19502258,-4229.928223,-4203.79248,44.09635454,17.5502834,49.13040161,0,0,0,40,69.72246552,1,6,1,1.95022583,60.60606384,,,,,,,,,,,,,,,,
3772711134,70.19535828,-4962.220215,-4.11E-05,1.39E-05,1,0.999253354,40.02988815,1.988451731,10.25999989,-0.000384353,-0.000420658,0.25,-3.14E-05,-4.11E-05,-3.17E-05,70.19542694,70.19542694,-4973.626953,-4950.813477,44.19014996,17.54581623,49.1448288,0,0,0,40,69.71887207,1,6,1,1.961975098,58.65102768,,,,,,,,,,,,,,,,
3772711148,70.19488907,-4936.485107,-5.62E-07,1.10E-07,1,0.999253354,40.02988815,1.988409963,10.25000028,0.000183669,-0.001048504,0.25,-9.66E-05,-6.40E-09,-9.70E-05,70.19485474,70.19485474,-4950.988281,-4921.981934,44.56064188,17.54625981,49.15836716,0,0,0,40,69.72133636,1,6,1,1.956787109,59.13978577,,,,,,,,,,,,,,,,
3772711153,70.19537354,-4815.560547,2.04E-05,2.85E-06,1,0.999253354,40.02988815,1.988384428,10.25999989,0.000432575,-0.001129327,0.25,-0.000107869,2.11E-05,-0.000108174,70.19545746,70.19545746,-4824.972168,-4806.148926,43.55937575,17.55059774,49.14127731,0,0,0,40,69.7212677,1,6,1,1.947937012,57.18475342,,,,,,,,,,,,,,,,
3772711158,70.19713593,-4689.527832,0.00020175,7.24E-06,1,0.999253354,40.02988815,1.988325927,10.25000028,0.00220065,0.000320513,0.25,-6.98E-06,0.000202581,-5.85E-06,70.19676971,70.19676971,-4702.480469,-4676.575195,44.18858671,17.54527815,49.13195801,0,0,0,40,69.72143555,1,6,1,1.959686279,59.62854385,,,,,,,,,,,,,,,,
3772711163,70.19688416,-4563.71875,0.000148873,1.04E-05,1,0.999253354,40.02988815,1.988310946,10.25000028,0.001669024,-1.28E-05,0.25,-2.81E-05,0.000149619,-2.74E-05,70.1968689,70.1968689,-4576.538086,-4550.899414,44.08541174,17.54722864,49.14616013,0,0,0,40,69.72097015,1,6,1,1.948394775,59.62854385,,,,,,,,,,,,,,,,
3772711168,70.19656372,-4437.58252,0.00012669,7.24E-06,1,0.999253354,40.02988815,1.988385489,10.25000028,0.001492094,-0.000406707,0.25,-6.05E-05,0.000127535,-6.00E-05,70.19632721,70.19632721,-4447.480469,-4427.68457,44.59894168,17.55108166,49.1452713,0,0,0,40,69.71994019,1,6,1,1.948547363,58.65102768,,,,,,,,,,,,,,,,
3772711173,70.19619751,-4316.335205,0.000161507,8.45E-06,1,0.999253354,40.02988815,1.988338183,10.25000028,0.001762684,0.000251125,0.25,-6.09E-06,0.000162175,-5.19E-06,70.19602966,70.19602966,-4329.444824,-4303.225586,44.23313953,17.54916375,49.14971161,0,0,0,40,69.71953583,1,6,1,1.937408447,59.13978577,,,,,,,,,,,,,,,,
3772711178,70.1955452,-4188.491943,0.000210222,8.44E-06,1,0.999253354,40.02988815,1.988370109,10.25999989,0.002229922,0.000682671,0.25,2.49E-05,0.000210901,2.62E-05,70.19559479,70.19559479,-4201.364258,-4175.619629,44.13778085,17.5475272,49.1517067,0,0,0,40,69.71910858,1,6,1,1.960601807,59.62854385,,,,,,,,,,,,,,,,
3772711183,70.19551086,-4066.332397,0.000238844,6.47E-06,1,0.999253354,40.02988815,1.988361392,10.25000028,0.002570152,0.0005734,0.25,9.62E-06,0.000239723,1.10E-05,70.19542694,70.19542694,-4079.158447,-4053.506348,44.06274451,17.54656185,49.14993286,0,0,0,40,69.71907043,1,6,1,1.953582764,59.13978577,,,,,,,,,,,,,,,,
3772711188,70.19589615,-3940.378296,8.20E-05,7.07E-06,1,0.999253354,40.02988815,1.988270805,10.25999989,0.00111119,-0.001065163,0.25,-0.000113127,8.30E-05,-0.000113095,70.19586182,70.19586182,-3955.08667,-3925.669922,44.07994034,17.55453012,49.14660263,0,0,0,40,69.71974182,1,6,1,1.94442749,59.62854385,,,,,,,,,,,,,,,,
3772711193,70.19465637,-3814.640503,0.000211947,7.30E-06,1,0.999253354,40.02988815,1.988408706,10.25000028,0.002370699,1.24E-05,0.25,-3.73E-05,0.00021299,-3.62E-05,70.19475555,70.19475555,-3827.448242,-3801.832764,44.45277715,17.54968838,49.14882278,0,0,0,40,69.72026825,1,6,1,1.954345703,60.11730194,,,,,,,,,,,,,,,,
3772711198,70.19472504,-3691.386719,0.000220885,6.61E-06,1,0.999253354,40.02988815,1.988443841,10.25000028,0.002413235,0.000330246,0.25,-9.56E-06,0.000221804,-8.32E-06,70.19469452,70.19469452,-3704.168945,-3678.604492,44.37852244,17.55226293,49.1517067,0,0,0,40,69.72046661,1,6,1,1.955566406,59.62854385,,,,,,,,,,,,,,,,
3772711203,70.1942215,-3564.72998,0.000206848,1.25E-05,1,0.999253354,40.02988815,1.988412661,10.25000028,0.002291912,0.000132242,0.25,-2.53E-05,0.000207803,-2.42E-05,70.19405365,70.19405365,-3577.742676,-3551.717285,43.94628187,17.5531812,49.14704895,0,0,0,40,69.7213974,1,6,1,1.945037842,59.13978577,,,,,,,,,,,,,,,,
3772711208,70.19475937,-3443.090942,0.000267839,7.68E-06,1,0.999253354,40.02988815,1.988307872,10.25000028,0.002818077,0.0009962,0.25,4.34E-05,0.000268634,4.51E-05,70.19469452,70.19469452,-3455.900879,-3430.281006,44.32068193,17.54775745,49.14216614,0,0,0,40,69.72239685,1,6,1,1.959991455,59.62854385,,,,,,,,,,,,,,,,
3772711213,70.19504166,-3319.424805,0.000264773,8.34E-06,1,0.999253354,40.02988815,1.988413566,10.25000028,0.002799305,0.00091112,0.25,3.61E-05,0.000265598,3.78E-05,70.19525909,70.19525909,-3332.543457,-3306.306152,44.26987607,17.55103113,49.14971161,0,0,0,40,69.72232819,1,6,1,1.95098877,60.11730194,,,,,,,,,,,,,,,,
3772711218,70.19494247,-3196.200684,0.000273238,6.21E-06,1,0.999253354,40.02988815,1.988337592,10.25999989,0.00295735,0.000561269,0.25,2.27E-06,0.000274291,3.86E-06,70.19509125,70.19509125,-3209.180908,-3183.220459,44.00334075,17.54703629,49.15392685,0,0,0,40,69.72249603,1,6,1,1.942749023,60.11730194,,,,,,,,,,,,,,,,
3772711223,70.19496155,-3072.128906,0.000283177,6.68E-06,1,0.999253354,40.02988815,1.98834548,10.25999989,0.003123204,0.000260109,0.25,-2.73E-05,0.00028444,-2.58E-05,70.19512939,70.19512939,-3083.233887,-3061.023926,44.39649989,17.55021593,49.15991974,0,0,0,40,69.7225647,1,6,1,1.954345703,59.62854385,,,,,,,,,,,,,,,,
3772711228,70.19438934,-2952.87207,0.000274094,5.03E-06,1,0.999253354,40.02988815,1.988397823,10.25000028,0.002990525,0.000431545,0.25,-9.85E-06,0.00027522,-8.30E-06,70.19429016,70.19429016,-2965.77417,-2939.969971,44.63098845,17.549312,49.17212677,0,0,0,40,69.72216797,1,6,1,1.960601807,59.62854385,,,,,,,,,,,,,,,,
3772711233,70.19497299,-2823.158081,0.000259474,7.73E-06,1,0.999253354,40.02988815,1.988359855,10.25000028,0.002865926,0.000215518,0.25,-2.71E-05,0.000260643,-2.57E-05,70.19475555,70.19475555,-2836.163818,-2810.152344,44.09010151,17.55382645,49.16901779,0,0,0,40,69.72229767,1,6,1,1.959838867,58.65102768,,,,,,,,,,,,,,,,
3772711238,70.19663239,-2695.462036,0.000304125,6.23E-06,1,0.999253354,40.02988815,1.988297314,10.25000028,0.003288686,0.000640636,0.25,4.00E-06,0.000305287,5.77E-06,70.19670105,70.19670105,-2706.668457,-2684.255615,44.50045649,17.54790049,49.17234802,0,0,0,40,69.72216797,1,6,1,1.949005127,60.60606384,,,,,,,,,,,,,,,,
3772711243,70.19617844,-2574.887695,0.000305214,5.74E-06,1,0.999253354,40.02988815,1.98832649,10.25000028,0.003347102,0.000385789,0.25,-1.97E-05,0.000306518,-1.80E-05,70.19622803,70.19622803,-2589.208984,-2560.566406,44.30426773,17.54720951,49.17057037,0,0,0,40,69.72097015,1,6,1,1.961669922,60.11730194,,,,,,,,,,,,,,,,
3772711248,70.19681549,-2449.956421,0.000314777,4.66E-06,1,0.999253354,40.02988815,1.98834523,10.25000028,0.003430635,0.000515771,0.25,-9.45E-06,0.000316058,-7.67E-06,70.19663239,70.19663239,-2462.971436,-2436.941406,44.51765231,17.55473799,49.16391373,0,0,0,40,69.72026825,1,6,1,1.948547363,60.11730194,,,,,,,,,,,,,,,,
3772711253,70.19734955,-2324.013794,0.000331968,4.40E-06,1,0.999253354,40.02988815,1.988244046,10.25000028,0.003635765,0.000444877,0.25,-1.91E-05,0.000333372,-1.73E-05,70.19736481,70.19736481,-2336.918213,-2311.109375,43.69850562,17.54947219,49.16812897,0,0,0,40,69.71930695,1,6,1,1.959991455,60.11730194,,,,,,,,,,,,,,,,
3772711258,70.19639587,-2201.121338,0.000277104,5.87E-06,1,0.999253354,40.02988815,1.988213512,10.25000028,0.00302416,0.000430278,0.25,-1.05E-05,0.000278244,-8.95E-06,70.19656372,70.19656372,-2214.233154,-2188.009521,44.02444472,17.55273922,49.18210983,0,0,0,40,69.71810913,1,6,1,1.954193115,60.11730194,,,,,,,,,,,,,,,,
3772711263,70.19557953,-2074.100586,0.000346386,4.82E-06,1,0.999253354,40.02988815,1.988257159,10.25000028,0.003728409,0.000824489,0.25,1.33E-05,0.000347657,1.54E-05,70.19566345,70.19566345,-2087.217041,-2060.984131,44.24173745,17.54937971,49.18632889,0,0,0,40,69.71847534,1,6,1,1.959838867,60.11730194,,,,,,,,,,,,,,,,
3772711268,70.19457626,-1949.344482,0.000360223,3.33E-06,1,0.999253354,40.02988815,1.988240271,10.25000028,0.003903257,0.000714219,0.25,6.22E-07,0.000361621,2.71E-06,70.1947937,70.1947937,-1959.242188,-1939.446777,44.51296254,17.5486725,49.19409561,0,0,0,40,69.71857452,1,6,1,1.954040527,59.13978577,,,,,,,,,,,,,,,,
3772711273,70.19393539,-1826.929138,0.000398203,3.65E-06,1,0.999253354,40.02988815,1.988300093,10.25999989,0.004284073,0.000959697,0.25,1.64E-05,0.000399656,1.88E-05,70.19381714,70.19381714,-1838.22998,-1815.628296,44.57627445,17.54813097,49.1823349,0,0,0,40,69.72006989,1,6,1,1.959991455,60.11730194,,,,,,,,,,,,,,,,
3772711278,70.19529343,-1700.431213,0.000426835,4.22E-06,1,0.999253354,40.02988815,1.988343648,10.25000028,0.004550579,0.00125846,0.25,3.88E-05,0.00042827,4.14E-05,70.19539642,70.19539642,-1708.13562,-1692.726807,44.31521053,17.55053886,49.18810272,0,0,0,40,69.72119904,1,6,1,1.953277588,61.58358002,,,,,,,,,,,,,,,,
3772711283,70.19527435,-1578.990601,0.000416159,4.80E-06,1,0.999253354,40.02988815,1.988353246,10.25000028,0.004478863,0.000994704,0.25,1.64E-05,0.000417682,1.88E-05,70.19519043,70.19519043,-1591.901855,-1566.079346,43.77823173,17.54772229,49.18699265,0,0,0,40,69.72150421,1,6,1,1.945648193,60.60606384,,,,,,,,,,,,,,,,
3772711288,70.19594574,-1452.441956,0.000437121,3.96E-06,1,0.999253354,40.02988815,1.988262699,10.25999989,0.004696546,0.001087295,0.25,2.11E-05,0.000438697,2.37E-05,70.19579315,70.19579315,-1465.452271,-1439.431641,44.3089575,17.5431845,49.17767334,0,0,0,40,69.72119904,1,6,1,1.957550049,60.11730194,,,,,,,,,,,,,,,,
3772711293,70.19593048,-1328.909363,0.000450287,4.27E-06,1,0.999253354,40.02988815,1.988319108,10.25000028,0.004834999,0.001137369,0.25,2.33E-05,0.000451901,2.60E-05,70.19602966,70.19602966,-1342.021118,-1315.797607,44.28629027,17.54775594,49.18899155,0,0,0,40,69.72003937,1,6,1,1.947937012,60.11730194,,,,,,,,,,,,,,,,
3772711298,70.19681549,-1200.317139,0.000450087,3.65E-06,1,0.999253354,40.02988815,1.988272796,10.25000028,0.004861044,0.000980608,0.25,8.91E-06,0.000451783,1.16E-05,70.19673157,70.19673157,-1213.129395,-1187.504883,44.25737002,17.54834369,49.18122482,0,0,0,40,69.72020721,1,6,1,1.950836182,60.11730194,,,,,,,,,,,,,,,,
3772711303,70.19670105,-1083.530273,0.000490565,3.02E-06,1,0.999253354,40.02988815,1.988356572,10.25000028,0.005269423,0.00122889,0.25,2.45E-05,0.000492328,2.74E-05,70.19663239,70.19663239,-1096.683472,-1070.377075,44.07837708,17.5528782,49.18943405,0,0,0,40,69.71923828,1,6,1,1.951446533,59.62854385,,,,,,,,,,,,,,,,
3772711308,70.19720078,-953.3139038,0.000491024,3.39E-06,1,0.999253354,40.02988815,1.988345773,10.25000028,0.005317456,0.000992029,0.25,2.54E-06,0.000492916,5.40E-06,70.1969986,70.1969986,-966.4371338,-940.1906738,44.20656416,17.55598325,49.20408249,0,0,0,40,69.71864319,1,6,1,1.944732666,60.11730194,,,,,,,,,,,,,,,,
3772711313,70.19599533,-833.0619812,0.000492965,2.41E-06,1,0.999253354,40.02988815,1.988322562,10.25000028,0.005268849,0.001379772,0.25,3.80E-05,0.000494657,4.10E-05,70.19629669,70.19629669,-845.9225464,-820.201416,44.47309949,17.5487999,49.20851898,0,0,0,40,69.7183075,1,6,1,1.952362061,61.09482193,,,,,,,,,,,,,,,,
3772711318,70.1949234,-705.0066528,0.000506614,2.34E-06,1,0.999253354,40.02988815,1.988266793,10.25000028,0.005461329,0.001159948,0.25,1.52E-05,0.000508491,1.82E-05,70.19499207,70.19499207,-716.3120728,-693.7012329,44.63645985,17.55145369,49.21562195,0,0,0,40,69.71810913,1,6,1,1.95098877,59.62854385,,,,,,,,,,,,,,,,
3772711323,70.19499207,-582.5821228,0.000522157,2.03E-06,1,0.999253354,40.02988815,1.988243968,10.25000028,0.005625904,0.00121165,0.25,1.72E-05,0.000524083,2.03E-05,70.19509125,70.19509125,-595.7606812,-569.4035645,44.11042385,17.54491879,49.20363998,0,0,0,40,69.71903992,1,6,1,1.960906982,61.09482193,,,,,,,,,,,,,,,,
3772711328,70.19388962,-459.3397064,0.000534606,2.12E-06,1,0.999253354,40.02988815,1.988267741,10.25000028,0.005773348,0.001167392,0.25,1.08E-05,0.000536617,1.40E-05,70.19402313,70.19402313,-472.3477478,-446.331665,44.30192284,17.54922743,49.20630264,0,0,0,40,69.71987152,1,6,1,1.948852539,60.11730194,,,,,,,,,,,,,,,,
3772711333,70.19384003,-334.7609863,0.000546065,1.75E-06,1,0.999253354,40.02988815,1.988358668,10.25000028,0.005897363,0.001192355,0.25,1.10E-05,0.000548118,1.43E-05,70.1937561,70.1937561,-349.4508972,-320.0710754,44.65678219,17.55439031,49.20230484,0,0,0,40,69.72249603,1,6,1,1.952209473,60.11730194,,,,,,,,,,,,,,,,
3772711338,70.19405365,-206.2770996,0.000548279,1.65E-06,1,0.999253354,40.02988815,1.988102893,10.25000028,0.005912204,0.00124307,0.25,1.53E-05,0.000550315,1.86E-05,70.19405365,70.19405365,-219.1999054,-193.3542938,44.15185017,17.55380166,49.20164108,0,0,0,40,69.72232819,1,6,1,1.953125,60.60606384,,,,,,,,,,,,,,,,
3772711343,70.19420242,-84.17053604,0.000553856,1.16E-06,1,0.999253354,40.02988815,1.98818519,10.25000028,0.005969789,0.001271161,0.25,1.69E-05,0.000555905,2.02E-05,70.19415283,70.19415283,-95.5980835,-72.74298859,44.22063348,17.55356488,49.20075226,0,0,0,40,69.72332764,1,6,1,1.964111328,60.60606384,,,,,,,,,,,,,,,,
3772711348,70.19452667,0.23435691,0.000508934,1.37E-06,1,0.999253354,40.02988815,1.988243835,10.25999989,0.005490519,0.001141754,0.25,1.31E-05,0.000510831,1.61E-05,70.19435883,70.19435883,0.070777088,0.397936732,44.21985185,17.55282492,49.20630264,0,0,0,40,69.72349548,1,4,1,1.950073242,60.60606384,,,,,,,,,,,,,,,,