File: Data/DyBCO_MVF_50K_-30000-30000Oe_Continuous.csv
Time Stamp (sec),Temperature (K),Magnetic Field (Oe),Moment (emu),M. Std. Err. (emu),Transport Action,Averaging Time (sec),Frequency (Hz),Peak Amplitude (mm),Center Position (mm),Coil Signal' (mV),"Coil Signal"" (mV)",Range (mV),M. Quad. Signal (emu),M. Raw' (emu),"M. Raw"" (emu)",Min. Temperature (K),Max. Temperature (K),Min. Field (Oe),Max. Field (Oe),Mass (grams),Motor Lag (deg),Pressure (Torr),VSM Status (code),Motor Status (code),Measure Status (code),Measure Count,System Temp. (K),Temp. Status (code),Field Status (code),Chamber Status (code),Motor Current (amps),Motor Heatsink Temp. (C),Map 01,Map 02,Map 03,Map 04,Map 05,Map 06,Map 07,Map 08,Map 09,Map 10,Map 11,Map 12,Map 13,Map 14,Map 15,Map 16
3772703570,50.18635178,0.015482487,,,2,,,,10.27199997,,,,,,,50.18635178,50.18635178,0.015482487,0.015482487,,,44.81351852,,,,40,49.88381577,0,0,0,0.041046143,47.89833832,,,,,,,,,,,,,,,,
3772703607,50.17789268,459.916687,0.00140758,4.82E-06,1,0.999253354,40.02988815,2.000884235,10.25999989,0.015167161,0.003363098,0.25,5.25E-05,0.001405957,6.29E-05,50.17794037,50.17794037,446.6851501,473.1482239,43.52029432,17.55149245,44.77579117,0,0,0,40,49.88306427,1,6,1,1.959075928,52.29716492,,,,,,,,,,,,,,,,
3772703628,50.17698288,985.3834839,0.001966731,4.06E-06,1,0.999253354,40.02988815,2.000789234,10.25999989,0.021176547,0.004781257,0.25,8.10E-05,0.00196444,9.55E-05,50.17698288,50.17698288,972.711792,998.0551758,43.99239795,17.55238871,44.76491547,0,0,0,40,49.88364792,1,6,1,1.958618164,53.27468491,,,,,,,,,,,,,,,,
3772703649,50.17710304,1506.862122,0.002089394,4.42E-06,1,0.999253354,40.02988815,2.000809878,10.27000044,0.022483889,0.005156422,0.25,9.31E-05,0.002086946,0.000108539,50.17712784,50.17712784,1495.374634,1518.349609,43.82981922,17.55361241,44.77223969,0,0,0,40,49.88449097,1,6,1,1.9480896,54.25220108,,,,,,,,,,,,,,,,
3772703670,50.17560196,2033.139832,0.002005063,1.08E-05,1,0.999253354,40.02988815,2.000762654,10.27000044,0.021582696,0.004913558,0.25,8.61E-05,0.002002777,0.000100961,50.17578888,50.17578888,2018.733276,2047.546387,43.88531484,17.55460055,44.7593689,0,0,0,40,49.88408661,1,6,1,1.9581604,57.18475342,,,,,,,,,,,,,,,,
3772703691,50.17612267,2555.618652,0.001882406,1.00E-05,1,0.999253354,40.02988815,2.000668405,10.25999989,0.020262248,0.004611115,0.25,8.07E-05,0.0018803,9.46E-05,50.17617035,50.17617035,2544.009033,2567.228271,44.10260757,17.55430859,44.74805069,0,0,0,40,49.88238525,1,6,1,1.962738037,55.71847534,,,,,,,,,,,,,,,,
3772703712,50.17552376,3075.318481,0.001956904,6.78E-06,1,0.999253354,40.02988815,2.00083901,10.25999989,0.021033746,0.004972057,0.25,0.000100289,0.001954635,0.000114762,50.17531967,50.17531967,3060.70459,3089.932373,43.94393698,17.55665682,44.74117279,0,0,0,40,49.88361359,1,6,1,1.959686279,56.20723343,,,,,,,,,,,,,,,,
3772703733,50.17448807,3601.900269,0.001721777,1.02E-05,1,0.999253354,40.02988815,2.000766004,10.25999989,0.018482722,0.004503332,0.25,0.000100103,0.001719732,0.000112831,50.17454147,50.17454147,3588.887695,3614.912842,44.1033892,17.55689577,44.72364044,0,0,0,40,49.8834343,1,6,1,1.959381104,55.71847534,,,,,,,,,,,,,,,,
3772703754,50.17425537,4121.08667,0.001617505,1.55E-05,1,0.999253354,40.02988815,2.000662096,10.25999989,0.01744157,0.00380062,0.25,5.44E-05,0.001615915,6.64E-05,50.17435074,50.17435074,4107.979492,4134.193848,44.05883637,17.55201681,44.72408295,0,0,0,40,49.88175583,1,6,1,1.969909668,57.18475342,,,,,,,,,,,,,,,,
3772703775,50.17351913,4644.964111,0.00133838,2.31E-05,1,0.999253354,40.02988815,2.00083532,10.25999989,0.014465066,0.002971333,0.25,2.90E-05,0.001337214,3.89E-05,50.17338181,50.17338181,4626.841309,4663.086914,44.04554869,17.55706978,44.70033646,0,0,0,40,49.88318253,1,6,1,1.967468262,57.67351151,,,,,,,,,,,,,,,,
3772703796,50.17345619,5171.14917,0.001404191,2.37E-05,1,0.999253354,40.02988815,2.000799802,10.25999989,0.015054908,0.003781968,0.25,9.17E-05,0.001402547,0.000102061,50.17332458,50.17332458,5158.272461,5184.025879,44.49420346,17.55658239,44.69878387,0,0,0,40,49.88127899,1,6,1,1.948547363,58.16226959,,,,,,,,,,,,,,,,
3772703817,50.17386055,5692.565674,0.001538251,1.38E-05,1,0.999253354,40.02988815,2.000839962,10.25999989,0.016377979,0.004771697,0.25,0.000158347,0.001536057,0.000169686,50.17381287,50.17381287,5679.755859,5705.375488,44.06118126,17.55702593,44.69634247,0,0,0,40,49.88273239,1,6,1,1.968536377,57.67351151,,,,,,,,,,,,,,,,
3772703838,50.17288017,6214.383057,0.001418987,1.63E-05,1,0.999253354,40.02988815,2.000807964,10.25999989,0.015154354,0.004149992,0.25,0.000122867,0.00141717,0.000133345,50.17290497,50.17290497,6199.755371,6229.010742,44.23392116,17.55936928,44.67082214,0,0,0,40,49.8809967,1,6,1,1.954040527,58.16226959,,,,,,,,,,,,,,,,
3772703859,50.17323303,6737.691406,0.000945573,2.54E-05,1,0.999253354,40.02988815,2.000655938,10.25999989,0.010035561,0.003106453,0.25,0.000113314,0.000944152,0.000120279,50.17308426,50.17308426,6724.666992,6750.71582,44.49185857,17.56243717,44.64197159,0,0,0,40,49.88085175,1,6,1,1.962738037,58.65102768,,,,,,,,,,,,,,,,
3772703880,50.17312622,7258.09375,0.001240355,2.11E-05,1,0.999253354,40.02988815,2.000858066,10.25999989,0.013123114,0.004308367,0.25,0.000170108,0.001238363,0.000179237,50.17320251,50.17320251,7244.989258,7271.198242,44.40900595,17.5624546,44.63753128,0,0,0,40,49.87999725,1,6,1,1.967315674,59.13978577,,,,,,,,,,,,,,,,
3772703901,50.17295837,7777.80542,0.000940687,2.79E-05,1,0.999253354,40.02988815,2.000624341,10.27000044,0.009850452,0.003820949,0.25,0.00018004,0.000938821,0.000186939,50.17300034,50.17300034,7764.993164,7790.617676,44.68335756,17.55876308,44.63753128,0,0,0,40,49.87907028,1,6,1,1.961517334,59.62854385,,,,,,,,,,,,,,,,
3772703922,50.17250252,8305.529785,0.001069462,2.72E-05,1,0.999253354,40.02988815,2.000792915,10.25999989,0.011247925,0.004083079,0.25,0.000180601,0.001067547,0.000188462,50.17258072,50.17258072,8292.507813,8318.551758,44.10807897,17.56044018,44.61312103,0,0,0,40,49.87889099,1,6,1,1.961669922,59.13978577,,,,,,,,,,,,,,,,
3772703943,50.17095947,8830.547363,0.000270879,5.54E-05,1,0.999253354,40.02988815,2.000698114,10.27000044,0.002754256,0.001551464,0.25,9.34E-05,0.000270047,9.54E-05,50.17108536,50.17108536,8819.18457,8841.910156,43.98458166,17.55860482,44.60512924,0,0,0,40,49.8787117,1,6,1,1.970214844,59.13978577,,,,,,,,,,,,,,,,
3772703963,50.17167282,9348.354004,0.000816039,2.54E-05,1,0.999253354,40.02988815,2.000688433,10.25999989,0.008514845,0.003485984,0.25,0.000171939,0.000814367,0.000177928,50.17152786,50.17152786,9335.258789,9361.449219,44.00099586,17.56329567,44.60468674,0,0,0,40,49.87746429,1,6,1,1.970672607,58.65102768,,,,,,,,,,,,,,,,
3772703985,50.17068481,9876.138184,0.000343625,3.74E-05,1,0.999253354,40.02988815,2.000804501,10.25999989,0.003525994,0.001795003,0.25,0.000102528,0.000342706,0.000105038,50.17079926,50.17079926,9863.132813,9889.143555,44.53484814,17.56137535,44.59869385,0,0,0,40,49.8784256,1,6,1,1.962127686,59.62854385,,,,,,,,,,,,,,,,
3772704005,50.17158318,10396.37549,0.0005192,4.53E-05,1,0.999253354,40.02988815,2.000863357,10.25999989,0.005309041,0.002815346,0.25,0.000164407,0.000517755,0.0001682,50.1717453,50.1717453,10384.95703,10407.79395,44.35429195,17.55981079,44.59603119,0,0,0,40,49.87752151,1,6,1,1.971588135,59.62854385,,,,,,,,,,,,,,,,
3772704027,50.17099762,10916.92969,0.00069991,5.46E-05,1,0.999253354,40.02988815,2.000784716,10.25999989,0.006899524,0.005201704,0.25,0.000351214,0.000697017,0.00035628,50.17113495,50.17113495,10903.92871,10929.93066,44.69039222,17.56679141,44.59137344,0,0,0,40,49.87717819,1,6,1,1.972198486,60.11730194,,,,,,,,,,,,,,,,
3772704048,50.17023659,11441.68701,0.000424615,3.04E-05,1,0.999253354,40.02988815,2.000760604,10.25999989,0.004281615,0.002631997,0.25,0.000164816,0.00042323,0.000167913,50.1701889,50.1701889,11423.58301,11459.79102,44.91940937,17.56029974,44.58493423,0,0,0,40,49.87691498,1,6,1,1.960601807,61.09482193,,,,,,,,,,,,,,,,
3772704072,50.16969299,12062.47656,0.000296273,4.71E-05,1,0.999253354,40.02988815,2.000790295,10.27000044,0.002914588,0.00223579,0.25,0.00015178,0.000295043,0.000153932,50.16950607,50.16950607,12053.16602,12071.78711,44.032261,17.55782683,44.58293915,0,0,0,40,49.87615585,1,6,1,1.966094971,61.09482193,,,,,,,,,,,,,,,,
3772704098,50.16969299,12688.15137,0.000697235,5.26E-05,1,0.999253354,40.02988815,2.000786282,10.25999989,0.007120652,0.003832803,0.25,0.000225553,0.000695342,0.000230669,50.16984177,50.16984177,12680.22559,12696.07715,44.0158468,17.55909312,44.58094025,0,0,0,40,49.87653732,1,6,1,1.961975098,60.60606384,,,,,,,,,,,,,,,,
3772704119,50.16960335,13214.30762,0.000164339,0.000108122,1,0.999253354,40.02988815,2.000759146,10.25999989,0.001352503,0.002684917,0.25,0.000217279,0.000162677,0.00021844,50.16928101,50.16928101,13201.18848,13227.42676,44.38399384,17.56176312,44.57006836,0,0,0,40,49.88134003,1,6,1,1.971435547,61.09482193,,,,,,,,,,,,,,,,
3772704139,50.17216873,13734.68213,0.000408138,5.78E-05,1,0.999253354,40.02988815,2.000637458,10.25999989,0.004042859,0.002928434,0.25,0.000195125,0.000406584,0.000198111,50.17209244,50.17209244,13721.57031,13747.79395,44.17060925,17.56631991,44.57317352,0,0,0,40,49.87659454,1,6,1,1.972351074,61.09482193,,,,,,,,,,,,,,,,
3772704164,50.16995049,14357.79443,0.000306836,0.000127049,1,0.999253354,40.02988815,2.000552658,10.25999989,0.002781201,0.003613045,0.25,0.000276727,0.000304711,0.000278948,50.16999817,50.16999817,14341.89258,14373.69629,44.33787775,17.56712099,44.57406235,0,0,0,40,49.87408447,1,6,1,1.961669922,61.09482193,,,,,,,,,,,,,,,,
3772704210,50.17060661,15500.44336,5.82E-05,4.56E-05,1,0.999253354,40.02988815,2.000695707,10.25999989,0.000201309,0.002468174,0.25,0.000216709,5.66E-05,0.000217107,50.17074966,50.17074966,15487.3291,15513.55762,44.35038381,17.56113674,44.56917953,0,0,0,40,49.87420654,1,6,1,1.961669922,60.11730194,,,,,,,,,,,,,,,,
3772704239,50.16760635,16225.24219,4.20E-05,0.000259866,1,0.999253354,40.02988815,2.00072809,10.25999989,0.000316659,0.000847171,0.25,7.03E-05,4.15E-05,7.06E-05,50.16753387,50.16753387,16213.81641,16236.66797,44.37930406,17.55842091,44.57051086,0,0,0,40,49.87306213,1,6,1,1.960296631,58.16226959,,,,,,,,,,,,,,,,
3772704264,50.16783333,16846.08105,0.000195655,4.13E-05,1,0.999253354,40.02988815,2.000644973,10.25999989,0.00193412,0.001427629,0.25,9.57E-05,0.000194928,9.72E-05,50.16771317,50.16771317,16833.00586,16859.15625,44.16670111,17.56005321,44.57983017,0,0,0,40,49.8721962,1,6,1,1.970825195,60.11730194,,,,,,,,,,,,,,,,
3772704293,50.16694832,17564.9082,7.30E-05,0.000177118,1,0.999253354,40.02988815,2.000755564,10.25999989,0.000444279,0.002049223,0.25,0.000175383,7.17E-05,0.000175916,50.16675568,50.16675568,17552.14844,17577.66797,44.37070615,17.55393614,44.5831604,0,0,0,40,49.87171936,1,6,1,1.959991455,60.11730194,,,,,,,,,,,,,,,,
3772704336,50.16684151,18638.88965,-5.52E-05,1.23E-05,1,0.999253354,40.02988815,2.000761542,10.25999989,-0.001114544,0.002705283,2.5,0.00025931,-5.72E-05,0.000258903,50.16662598,50.16662598,18601.25391,18676.52539,44.71149619,17.55992065,44.58493423,0,0,0,40,49.87036514,1,6,1,1.964111328,61.09482193,,,,,,,,,,,,,,,,
3772704386,50.16703606,19887.27539,-7.11E-06,1.37E-06,1,0.999253354,40.02988815,2.000944763,10.27000044,-0.000638425,0.003054772,2.5,0.000282656,-9.20E-06,0.000282626,50.16677856,50.16677856,19846.66406,19927.88672,44.65756382,17.5556361,44.57916641,0,0,0,40,49.87157822,1,6,1,1.966094971,62.0723381,,,,,,,,,,,,,,,,
3772704445,50.16580582,21355.65918,-0.000361115,2.81E-05,1,0.999253354,40.02988815,2.000959873,10.27000044,-0.004308734,0.001402588,2.5,0.000195215,-0.000362619,0.000192571,50.16584778,50.16584778,21318.52148,21392.79688,44.80216509,17.55674335,44.5851593,0,0,0,40,49.86980438,1,6,1,1.960906982,60.11730194,,,,,,,,,,,,,,,,
3772704507,50.16651726,22898.31543,0.000107394,5.97E-05,1,0.999253354,40.02988815,2.001189749,10.27000044,0.000442014,0.004175712,0.25,0.000364752,0.00010472,0.000365635,50.16649246,50.16649246,22858.00586,22938.625,43.86577413,17.55884226,44.5915947,1,0,0,40,49.86695099,1,6,1,1.970062256,61.09482193,,,,,,,,,,,,,,,,
3772704568,50.16536903,24415.32031,-0.000134266,4.18E-05,1,0.999253354,40.02988815,2.000927951,10.25999989,-0.001498294,-4.69E-05,2.5,2.02E-05,-0.000134459,1.92E-05,50.16553497,50.16553497,24376.58008,24454.06055,44.24408233,17.54636001,44.59469986,0,0,0,40,49.86663055,1,6,1,1.968078613,61.58358002,,,,,,,,,,,,,,,,
3772704630,50.16571426,25959.61035,-0.000178295,4.09E-05,1,0.999253354,40.02988815,2.000920677,10.27000044,-0.001970666,-0.000169705,0.25,1.70E-05,-0.000178494,1.57E-05,50.16571426,50.16571426,25921.17383,25998.04688,44.43167318,17.54823741,44.62865448,0,0,0,40,49.86548996,1,6,1,1.959075928,62.0723381,,,,,,,,,,,,,,,,
3772704692,50.16499138,27489.19824,-8.65E-05,1.80E-05,1,0.999253354,40.02988815,2.00102102,10.27000044,-0.001459554,0.002671739,2.5,0.000261782,-8.85E-05,0.000261273,50.16509247,50.16509247,27450.35938,27528.03711,44.09322803,17.55281697,44.63775253,0,0,0,40,49.8646698,1,6,1,1.952362061,63.53861237,,,,,,,,,,,,,,,,
3772704755,50.16505814,29081.67969,6.91E-05,8.45E-05,1,0.999253354,40.02988815,2.001054163,10.25999989,0.000370444,0.002217318,2.5,0.000191474,6.77E-05,0.000192094,50.16520309,50.16520309,29043.14258,29120.2168,44.77871624,17.55337241,44.65684128,0,0,0,40,49.86255264,1,6,1,1.968383789,62.0723381,,,,,,,,,,,,,,,,
3772704855,50.16524887,29301.78613,0.000199266,0.000372217,1,0.999253354,40.02988815,1.988574185,10.28000005,0.001502335,0.0039497,0.25,0.000329208,0.000196962,0.000330869,50.16558456,50.16558456,29263.25781,29340.31445,43.77041545,17.55730194,44.65040207,1,0,0,40,49.86156845,1,6,1,1.949920654,62.0723381,,,,,,,,,,,,,,,,
3772704920,50.16392136,27666.74121,8.79E-05,0.000115828,1,0.999253354,40.02988815,1.988670062,10.27000044,0.000494964,0.00265752,2.5,0.000230022,8.62E-05,0.000230786,50.16403961,50.16403961,27627.50586,27705.97656,44.25346187,17.56506298,44.63375854,0,0,0,40,49.86245728,1,6,1,1.951293945,62.56109619,,,,,,,,,,,,,,,,
3772704986,50.16325188,26030.01172,0.00018235,0.00081208,1,0.999253354,40.02988815,1.988630307,10.28000005,0.001327849,0.003868981,0.25,0.00032488,0.000180027,0.00032636,50.1634903,50.1634903,25991.14063,26068.88281,43.88062507,17.55860957,44.6271019,1,0,0,40,49.86277771,1,6,1,1.951446533,62.0723381,,,,,,,,,,,,,,,,
3772705052,50.16223526,24397.24414,-0.000240766,3.84E-05,1,0.999253354,40.02988815,1.988500039,10.27000044,-0.002905323,0.001198041,2.5,0.000154999,-0.00024199,0.000153269,50.1622963,50.1622963,24358.72461,24435.76367,44.30817587,17.55972701,44.61090088,0,0,0,40,49.8641243,1,6,1,1.953582764,62.0723381,,,,,,,,,,,,,,,,
3772705115,50.1617794,22820.91992,7.83E-05,4.16E-05,1,0.999253354,40.02988815,1.988654698,10.27000044,0.000199804,0.003684801,2.5,0.000326995,7.59E-05,0.000327653,50.16235352,50.16235352,22780.68164,22861.1582,44.58487237,17.5597147,44.6004715,0,0,0,40,49.86494446,1,6,1,1.946411133,63.04985428,,,,,,,,,,,,,,,,
3772705181,50.16017914,21170.58887,-0.000385301,3.31E-05,1,0.999253354,40.02988815,1.988542705,10.28000005,-0.004235329,-0.000349632,0.25,3.81E-05,-0.00038564,3.52E-05,50.16034698,50.16034698,21128.97266,21212.20508,44.49342183,17.56231379,44.5915947,1,0,0,40,49.86551285,1,6,1,1.954193115,62.56109619,,,,,,,,,,,,,,,,
3772705240,50.16024399,19701.49414,-0.000208892,3.11E-05,1,0.999253354,40.02988815,1.98851744,10.27000044,-0.002436853,0.000580641,0.25,9.20E-05,-0.000209589,9.04E-05,50.1599617,50.1599617,19662.47266,19740.51563,44.69742687,17.56153903,44.58826447,1,0,0,40,49.8670578,1,6,1,1.949157715,63.04985428,,,,,,,,,,,,,,,,
3772705294,50.16003418,18361.55762,-0.000364135,4.42E-05,1,0.999253354,40.02988815,1.988616736,10.27000044,-0.004099443,0.000201272,0.25,8.52E-05,-0.000364765,8.25E-05,50.15977097,50.15977097,18324.25195,18398.86328,44.61066611,17.56355528,44.57738876,1,0,0,40,49.86733246,1,6,1,1.952972412,63.04985428,,,,,,,,,,,,,,,,
3772705340,50.15901184,17229.35938,-0.000418144,3.94E-05,1,0.999253354,40.02988815,1.988502019,10.27000044,-0.00471633,0.000282461,0.25,0.000102648,-0.000418878,9.95E-05,50.15888596,50.15888596,17190.7207,17267.99805,44.4981116,17.56057901,44.58737564,0,0,0,40,49.86854553,1,6,1,1.951293945,63.04985428,,,,,,,,,,,,,,,,
3772705386,50.1593895,16080.32666,-0.000545387,3.33E-05,1,0.999253354,40.02988815,1.988624652,10.27000044,-0.006016326,-0.000370706,0.25,6.54E-05,-0.000545803,6.14E-05,50.15937805,50.15937805,16067.52637,16093.12695,44.38399384,17.56867988,44.56274414,0,0,0,40,49.86750031,1,6,1,1.950836182,63.53861237,,,,,,,,,,,,,,,,
3772705444,50.15916252,14628.18311,-0.000519732,2.67E-05,1,0.999253354,40.02988815,2.000989002,10.28000005,-0.005964926,0.000728804,0.25,0.000162193,-0.00052083,0.000158295,50.15918732,50.15918732,14618.37012,14637.99609,44.58018259,17.56323715,44.58382797,0,0,0,40,49.87070847,1,6,1,1.960296631,61.58358002,,,,,,,,,,,,,,,,
3772705472,50.15754128,13917.52051,-0.00050849,2.49E-05,1,0.999253354,40.02988815,2.000970148,10.28000005,-0.00600811,0.001656008,0.25,0.000245545,-0.00051019,0.000241703,50.15755844,50.15755844,13904.60938,13930.43164,44.37617755,17.5644159,44.58582306,0,0,0,40,49.87000656,1,6,1,1.968994141,61.58358002,,,,,,,,,,,,,,,,
3772705497,50.1579895,13294.06934,-0.000535901,3.45E-05,1,0.999253354,40.02988815,2.000911172,10.28000005,-0.006086099,0.000402992,0.25,0.000135147,-0.000536756,0.000131124,50.15792847,50.15792847,13281.14844,13306.99023,44.27847399,17.56170478,44.57783508,0,0,0,40,49.86875916,1,6,1,1.957702637,62.56109619,,,,,,,,,,,,,,,,
3772705518,50.1567688,12776.24316,-0.000886283,2.87E-05,1,0.999253354,40.02988815,2.000836936,10.28000005,-0.009498894,-0.002426658,0.25,-6.14E-05,-0.000885554,-6.80E-05,50.15675735,50.15675735,12763.43945,12789.04688,44.31364727,17.55863054,44.5915947,0,0,0,40,49.86936569,1,6,1,1.967315674,62.56109619,,,,,,,,,,,,,,,,
3772705543,50.15633392,12150.73633,-0.000809229,2.85E-05,1,0.999253354,40.02988815,2.000874145,10.27000044,-0.00871983,-0.001959187,0.25,-3.25E-05,-0.000808712,-3.85E-05,50.15630341,50.15630341,12141.3291,12160.14355,44.49498509,17.55835427,44.59625244,0,0,0,40,49.86959076,1,6,1,1.959228516,63.04985428,,,,,,,,,,,,,,,,
3772705564,50.156147,11622.97754,-0.000995067,1.79E-05,1,0.999253354,40.02988815,2.000889289,10.27000044,-0.010718796,-0.002427125,0.25,-4.16E-05,-0.000994391,-4.90E-05,50.15613556,50.15613556,11613.16992,11632.78516,44.48638717,17.56418207,44.59869385,0,0,0,40,49.87029266,1,6,1,1.97052002,63.04985428,,,,,,,,,,,,,,,,
3772705585,50.15599823,11103.41553,-0.000984686,2.57E-05,1,0.999253354,40.02988815,2.000793612,10.27000044,-0.010308976,-0.004026565,0.25,-0.000190852,-0.000982877,-0.000198101,50.15597916,50.15597916,11088.70508,11118.12598,44.60206819,17.55733489,44.61156845,0,0,0,40,49.8706131,1,6,1,1.963500977,63.04985428,,,,,,,,,,,,,,,,
3772705606,50.15575409,10580.32178,-0.000605354,4.06E-05,1,0.999253354,40.02988815,2.00082344,10.27000044,-0.006806533,8.85E-05,0.25,0.000118886,-0.000605982,0.000114332,50.15594482,50.15594482,10567.11133,10593.53223,44.27456584,17.56365462,44.60779572,0,0,0,40,49.87020874,1,6,1,1.960601807,59.13978577,,,,,,,,,,,,,,,,
3772705627,50.15550423,10055.90332,-0.001199842,2.35E-05,1,0.999253354,40.02988815,2.000764617,10.27000044,-0.012934681,-0.002861297,0.25,-4.42E-05,-0.001198974,-5.31E-05,50.15563583,50.15563583,10043.00098,10068.80566,44.05570986,17.55875056,44.5984726,0,0,0,40,49.87123108,1,6,1,1.962585449,62.56109619,,,,,,,,,,,,,,,,
3772705648,50.15526199,9533.470703,-0.00089361,1.76E-05,1,0.999253354,40.02988815,2.000898445,10.28000005,-0.009922002,-0.00055528,0.25,0.000112301,-0.00089402,0.000105599,50.15526199,50.15526199,9525.166992,9541.774414,43.95097164,17.56579086,44.59825134,0,0,0,40,49.87065125,1,6,1,1.970214844,62.56109619,,,,,,,,,,,,,,,,
3772705669,50.15531158,9010.475586,-0.000993895,2.71E-05,1,0.999253354,40.02988815,2.000864951,10.27000044,-0.011134233,-7.52E-05,0.25,0.000174874,-0.000994696,0.000167391,50.15513229,50.15513229,8997.47168,9023.479492,44.2323579,17.56496661,44.59580994,0,0,0,40,49.87205124,1,6,1,1.968688965,63.53861237,,,,,,,,,,,,,,,,
3772705690,50.15665054,8489.481445,-0.001079556,3.09E-05,1,0.999253354,40.02988815,2.000752282,10.27000044,-0.011803471,-0.001663954,0.25,4.42E-05,-0.001079313,3.61E-05,50.15652084,50.15652084,8476.46875,8502.494141,44.63724148,17.56194529,44.58870697,0,0,0,40,49.87107849,1,6,1,1.969909668,63.04985428,,,,,,,,,,,,,,,,
3772705711,50.15537643,7964.811523,-0.0010789,2.65E-05,1,0.999253354,40.02988815,2.000728178,10.27000044,-0.011748841,-0.001919855,0.25,2.04E-05,-0.001078452,1.24E-05,50.15544128,50.15544128,7946.488281,7983.134766,44.89127074,17.56175555,44.59314728,0,0,0,40,49.87087631,1,6,1,1.962280273,65.00489044,,,,,,,,,,,,,,,,
3772705732,50.15543747,7442.512695,-0.000991213,3.86E-05,1,0.999253354,40.02988815,2.000534147,10.27000044,-0.011003839,-0.000609337,0.25,0.00012516,-0.000991568,0.000117712,50.15556335,50.15556335,7432.598633,7452.426758,44.96474383,17.56615897,44.60868073,0,0,0,40,49.87183762,1,6,1,1.968383789,63.53861237,,,,,,,,,,,,,,,,
3772705753,50.1554184,6920.2854,-0.001365627,2.26E-05,1,0.999253354,40.02988815,2.000857008,10.28000005,-0.014988274,-0.00179085,0.25,8.48E-05,-0.001365428,7.46E-05,50.15530014,50.15530014,6907.378906,6933.191895,45.01085991,17.56700793,44.6206665,0,0,0,40,49.8728981,1,6,1,1.952514648,63.53861237,,,,,,,,,,,,,,,,
3772705774,50.15597916,6397.69165,-0.001281257,2.34E-05,1,0.999253354,40.02988815,2.00066372,10.27000044,-0.01395173,-0.002275403,0.25,2.47E-05,-0.00128063,1.51E-05,50.15615845,50.15615845,6385.084473,6410.298828,44.51608906,17.56734948,44.61778259,0,0,0,40,49.8707695,1,6,1,1.971893311,63.04985428,,,,,,,,,,,,,,,,
3772705795,50.15449905,5874.934082,-0.00140024,2.23E-05,1,0.999253354,40.02988815,2.000733973,10.27000044,-0.015287875,-0.002265805,0.25,4.73E-05,-0.00139967,3.69E-05,50.15430832,50.15430832,5865.024902,5884.843262,44.65834545,17.5624156,44.61423111,0,0,0,40,49.87231445,1,6,1,1.960906982,63.53861237,,,,,,,,,,,,,,,,
3772705816,50.15458107,5353.43042,-0.001709565,1.36E-05,1,0.999253354,40.02988815,2.000834455,10.28000005,-0.018418707,-0.004115745,0.25,-6.66E-05,-0.001707903,-7.92E-05,50.15460587,50.15460587,5341.72168,5365.13916,44.60519471,17.56467372,44.61312103,0,0,0,40,49.87167358,1,6,1,1.972808838,63.04985428,,,,,,,,,,,,,,,,
3772705837,50.15443802,4831.393799,-0.001656746,2.63E-05,1,0.999253354,40.02988815,2.000833028,10.27000044,-0.018087061,-0.002688083,0.25,5.53E-05,-0.001655986,4.30E-05,50.15436554,50.15436554,4818.616211,4844.171387,44.63098845,17.56861642,44.600914,0,0,0,40,49.87123108,1,6,1,1.963195801,63.53861237,,,,,,,,,,,,,,,,
3772705858,50.15477371,4307.323242,-0.001873761,1.38E-05,1,0.999253354,40.02988815,2.000899124,10.28000005,-0.020378515,-0.003466094,0.25,2.33E-05,-0.001872565,9.37E-06,50.15467834,50.15467834,4299.418457,4315.228027,44.11824014,17.56564865,44.59692001,0,0,0,40,49.87380219,1,6,1,1.96685791,63.53861237,,,,,,,,,,,,,,,,
3772705879,50.15466499,3787.64856,-0.00193102,1.65E-05,1,0.999253354,40.02988815,2.00080356,10.27000044,-0.020966387,-0.003754519,0.25,7.19E-06,-0.001929618,-7.17E-06,50.15460587,50.15460587,3778.335938,3796.961182,44.01741006,17.57076888,44.58649063,0,0,0,40,49.87199402,1,6,1,1.960906982,62.56109619,,,,,,,,,,,,,,,,
3772705900,50.15415192,3263.967407,-0.001978905,1.38E-05,1,0.999253354,40.02988815,2.000819065,10.27000044,-0.021474873,-0.003908191,0.25,1.78E-06,-0.001977381,-1.29E-05,50.15405655,50.15405655,3251.291016,3276.643799,44.92409914,17.56436743,44.59758377,0,0,0,40,49.87225342,1,6,1,1.961517334,63.53861237,,,,,,,,,,,,,,,,
3772705921,50.1544857,2741.666382,-0.002046005,1.38E-05,1,0.999253354,40.02988815,2.000731229,10.27000044,-0.022120002,-0.004486697,0.25,-3.93E-05,-0.002044079,-5.45E-05,50.15453339,50.15453339,2731.863281,2751.469482,44.7255655,17.57195119,44.60646439,0,0,0,40,49.87295532,1,6,1,1.961212158,63.53861237,,,,,,,,,,,,,,,,
3772705942,50.15450478,2219.44812,-0.002169652,6.85E-06,1,0.999253354,40.02988815,2.000740478,10.27000044,-0.023449126,-0.004797478,0.25,-4.53E-05,-0.002167536,-6.14E-05,50.15440369,50.15440369,2209.734619,2229.161621,44.40040803,17.56678247,44.5827179,0,0,0,40,49.87295532,1,6,1,1.959533691,63.53861237,,,,,,,,,,,,,,,,
3772705963,50.15410995,1696.660828,-0.00219531,7.71E-06,1,0.999253354,40.02988815,2.00084925,10.27000044,-0.023730054,-0.004838603,0.25,-4.44E-05,-0.002193135,-6.07E-05,50.1542244,50.1542244,1683.744873,1709.576782,44.43401806,17.56563886,44.59314728,0,0,0,40,49.8728981,1,6,1,1.970062256,63.04985428,,,,,,,,,,,,,,,,
3772705984,50.15378189,1173.763,-0.002277627,7.67E-06,1,0.999253354,40.02988815,2.000948854,10.28000005,-0.024599744,-0.005133818,0.25,-5.66E-05,-0.002275248,-7.34E-05,50.15394974,50.15394974,1159.137573,1188.388428,44.49498509,17.56849547,44.6093483,0,0,0,40,49.87242126,1,6,1,1.969146729,63.04985428,,,,,,,,,,,,,,,,
3772706005,50.15382957,656.3829651,-0.002316824,5.09E-06,1,0.999253354,40.02988815,2.00081366,10.27000044,-0.025014052,-0.005260104,0.25,-6.11E-05,-0.002314338,-7.82E-05,50.15368652,50.15368652,643.5292969,669.2366333,44.50045649,17.56322229,44.60579681,0,0,0,40,49.87300491,1,6,1,1.97052002,64.02737427,,,,,,,,,,,,,,,,
3772706051,50.15511894,-488.6366119,-0.002287528,2.39E-05,1,0.999253354,40.02988815,1.98870066,10.25999989,-0.024534587,-0.005280863,0.25,-7.11E-05,-0.002284982,-8.81E-05,50.15497589,50.15497589,-504.9393005,-472.3339233,43.91189021,17.55977838,44.60557556,0,0,0,40,49.87679672,1,6,1,1.955718994,61.58358002,,,,,,,,,,,,,,,,
3772706072,50.15547943,-1012.932953,-0.002216958,1.36E-05,1,0.999253354,40.02988815,1.988635502,10.25999989,-0.023787488,-0.005062535,0.25,-6.38E-05,-0.002214566,-8.02E-05,50.15546799,50.15546799,-1026.040039,-999.8258667,44.70289827,17.565969,44.61644745,0,0,0,40,49.87260056,1,6,1,1.964416504,61.58358002,,,,,,,,,,,,,,,,
3772706093,50.15428352,-1539.34436,-0.002147718,7.46E-06,1,0.999253354,40.02988815,1.988702243,10.25999989,-0.022978681,-0.005271159,0.25,-9.58E-05,-0.002145188,-0.00011168,50.15434265,50.15434265,-1552.264893,-1526.423828,44.43401806,17.56674004,44.61067963,0,0,0,40,49.87308884,1,6,1,1.957244873,62.0723381,,,,,,,,,,,,,,,,
3772706114,50.15406799,-2058.781616,-0.002132948,5.55E-06,1,0.999253354,40.02988815,1.988740185,10.25999989,-0.022749908,-0.005626595,0.25,-0.000131428,-0.002130208,-0.000147175,50.15394974,50.15394974,-2070.20459,-2047.358643,44.25893327,17.56689292,44.62443924,0,0,0,40,49.87300491,1,6,1,1.953277588,62.56109619,,,,,,,,,,,,,,,,
3772706135,50.15360832,-2582.757813,-0.00200462,6.98E-06,1,0.999253354,40.02988815,1.988655186,10.27000044,-0.021410389,-0.005125954,0.25,-0.0001085,-0.002002199,-0.000123316,50.15353012,50.15353012,-2592.623291,-2572.892334,44.75448575,17.56317403,44.62110901,0,0,0,40,49.87260056,1,6,1,1.93572998,63.04985428,,,,,,,,,,,,,,,,
3772706156,50.1522274,-3102.670044,-0.001703396,1.45E-05,1,0.999253354,40.02988815,1.988383478,10.27000044,-0.01823094,-0.00413793,0.25,-7.20E-05,-0.001701525,-8.47E-05,50.15234756,50.15234756,-3113.871826,-3091.468262,44.76464692,17.56601963,44.62266159,0,0,0,40,49.87251663,1,6,1,1.950683594,62.56109619,,,,,,,,,,,,,,,,
3772706177,50.15385246,-3626.779541,-0.001627621,2.23E-05,1,0.999253354,40.02988815,1.988640252,10.25999989,-0.017334063,-0.004437774,0.25,-0.000113647,-0.001625537,-0.000125664,50.15394974,50.15394974,-3639.782959,-3613.776123,44.63333333,17.56368127,44.63109589,0,0,0,40,49.8717308,1,6,1,1.959381104,62.56109619,,,,,,,,,,,,,,,,
3772706198,50.15318871,-4149.513672,-0.001575729,1.95E-05,1,0.999253354,40.02988815,1.988625994,10.25999989,-0.01674894,-0.0044754,0.25,-0.00012662,-0.001573625,-0.000138245,50.15303802,50.15303802,-4166.233398,-4132.793945,44.46450157,17.56494431,44.63953018,0,0,0,40,49.87193298,1,6,1,1.959838867,62.0723381,,,,,,,,,,,,,,,,
3772706219,50.15334511,-4669.916748,-0.001255655,1.44E-05,1,0.999253354,40.02988815,1.988503331,10.25999989,-0.013395966,-0.003294672,0.25,-7.57E-05,-0.001254194,-8.50E-05,50.15333939,50.15333939,-4679.224609,-4660.608887,44.64974753,17.56541098,44.64130402,0,0,0,40,49.87237549,1,6,1,1.964569092,63.04985428,,,,,,,,,,,,,,,,
3772706240,50.15284729,-5194.51709,-0.001345468,1.05E-05,1,0.999253354,40.02988815,1.988615788,10.25999989,-0.014335576,-0.003638167,0.25,-9.11E-05,-0.001343861,-0.00010106,50.15284729,50.15284729,-5207.495117,-5181.539063,44.68492082,17.56495994,44.65195847,0,0,0,40,49.87231445,1,6,1,1.956787109,62.0723381,,,,,,,,,,,,,,,,
3772706261,50.15289688,-5719.066895,-0.001132674,2.63E-05,1,0.999253354,40.02988815,1.988452357,10.27000044,-0.011891303,-0.004026791,0.25,-0.000166082,-0.001130684,-0.000174397,50.15280151,50.15280151,-5728.98291,-5709.150879,44.31286564,17.56544898,44.6517334,0,0,0,40,49.87276459,1,6,1,1.958465576,63.53861237,,,,,,,,,,,,,,,,
3772706282,50.15402031,-6237.025391,-0.000882995,1.91E-05,1,0.999253354,40.02988815,1.98843946,10.25999989,-0.009319908,-0.002867709,0.25,-0.000104304,-0.000881654,-0.000110806,50.15406799,50.15406799,-6248.62793,-6225.422852,44.12605642,17.56696098,44.6537323,0,0,0,40,49.87195587,1,6,1,1.951293945,62.56109619,,,,,,,,,,,,,,,,
3772706303,50.15366745,-6760.335205,-0.001246233,2.05E-05,1,0.999253354,40.02988815,1.988693135,10.25999989,-0.013116289,-0.004263754,0.25,-0.00016721,-0.001244222,-0.000176378,50.15381622,50.15381622,-6771.833984,-6748.836426,43.96347769,17.56545596,44.67836761,0,0,0,40,49.87113571,1,6,1,1.962127686,63.53861237,,,,,,,,,,,,,,,,
3772706324,50.15338707,-7278.203613,-0.001146467,1.92E-05,1,0.999253354,40.02988815,1.988564564,10.25999989,-0.012037388,-0.004077859,0.25,-0.000168243,-0.001144539,-0.000176674,50.15342331,50.15342331,-7291.211426,-7265.195801,44.53406651,17.56454266,44.68369293,0,0,0,40,49.87203979,1,6,1,1.946105957,63.53861237,,,,,,,,,,,,,,,,
3772706345,50.15315247,-7800.11499,-0.000944446,2.92E-05,1,0.999253354,40.02988815,1.988539063,10.27000044,-0.009811185,-0.00393449,0.25,-0.000191904,-0.000942485,-0.000198823,50.1531105,50.1531105,-7809.524414,-7790.705566,44.52781348,17.56739987,44.70566177,0,0,0,40,49.87093353,1,6,1,1.963500977,64.02737427,,,,,,,,,,,,,,,,
3772706366,50.15364265,-8325.727051,-0.000749203,2.93E-05,1,0.999253354,40.02988815,1.988677102,10.25999989,-0.007907713,-0.002443237,0.25,-8.94E-05,-0.000748135,-9.49E-05,50.15375519,50.15375519,-8338.9375,-8312.516602,44.52859511,17.56450883,44.69612122,0,0,0,40,49.87069702,1,6,1,1.96182251,63.04985428,,,,,,,,,,,,,,,,
3772706387,50.15379333,-8852.099121,-0.000691704,2.95E-05,1,0.999253354,40.02988815,1.988631435,10.25999989,-0.007241477,-0.00258036,0.25,-0.000112607,-0.000690513,-0.000117696,50.15390015,50.15390015,-8860.379883,-8843.818359,44.43010992,17.56553055,44.71365356,0,0,0,40,49.87085342,1,6,1,1.960144043,63.04985428,,,,,,,,,,,,,,,,
3772706408,50.15434265,-9371.968262,-0.000694008,4.16E-05,1,0.999253354,40.02988815,1.98857632,10.25999989,-0.007177276,-0.00307181,0.25,-0.000157731,-0.000692498,-0.000162818,50.15446091,50.15446091,-9386.582031,-9357.354492,44.7255655,17.56698976,44.72119904,0,0,0,40,49.87107849,1,6,1,1.938171387,63.04985428,,,,,,,,,,,,,,,,
3772706429,50.15401268,-9897.326172,-0.000437381,2.91E-05,1,0.999253354,40.02988815,1.988430185,10.25999989,-0.004499102,-0.002067075,0.25,-0.000111568,-0.000436351,-0.000114771,50.15391159,50.15391159,-9905.526367,-9889.125977,44.45043226,17.56445505,44.73606491,0,0,0,40,49.87133789,1,6,1,1.950531006,62.56109619,,,,,,,,,,,,,,,,
3772706450,50.15446281,-10417.13232,-0.000670427,3.41E-05,1,0.999253354,40.02988815,1.988500995,10.25999989,-0.006866924,-0.003331619,0.25,-0.000186117,-0.000668753,-0.000191025,50.15448761,50.15448761,-10428.64063,-10405.62402,44.63098845,17.56863524,44.71831131,0,0,0,40,49.870327,1,6,1,1.952362061,60.11730194,,,,,,,,,,,,,,,,
3772706471,50.15315247,-10938.43604,-0.000461915,4.68E-05,1,0.999253354,40.02988815,1.98869805,10.25999989,-0.004698069,-0.00248006,0.25,-0.000145314,-0.000460647,-0.000148692,50.15328979,50.15328979,-10949.81934,-10927.05273,44.69508199,17.56432139,44.7509346,0,0,0,40,49.87023544,1,6,1,1.961517334,63.04985428,,,,,,,,,,,,,,,,
3772706492,50.15386391,-11462.32471,-0.000202217,7.11E-05,1,0.999253354,40.02988815,1.988421399,10.25999989,-0.001813888,-0.002411953,0.25,-0.000186531,-0.000200753,-0.000187965,50.15391159,50.15391159,-11471.73145,-11452.91797,44.60675796,17.56843543,44.73495865,0,0,0,40,49.8700676,1,6,1,1.948242188,64.02737427,,,,,,,,,,,,,,,,
3772706513,50.15414429,-11988.61572,-0.000142754,0.000170301,1,0.999253354,40.02988815,1.988601312,10.25999989,-0.001141126,-0.002465641,0.25,-0.000202358,-0.000141199,-0.000203349,50.15418625,50.15418625,-11998.52734,-11978.7041,44.96318057,17.5689,44.76669312,0,0,0,40,49.86959076,1,6,1,1.951751709,62.56109619,,,,,,,,,,,,,,,,
3772706534,50.15477371,-12509.72168,-0.000262805,0.000125375,1,0.999253354,40.02988815,1.98856621,10.25999989,-0.002350938,-0.003171728,0.25,-0.000245822,-0.000260892,-0.000247698,50.15494156,50.15494156,-12521.14941,-12498.29395,44.5473542,17.57023441,44.74782944,0,0,0,40,49.86882019,1,6,1,1.947937012,63.53861237,,,,,,,,,,,,,,,,
3772706555,50.15403175,-13033.8584,-0.000493796,3.55E-05,1,0.999253354,40.02988815,1.98849716,10.25999989,-0.004954202,-0.003024082,0.25,-0.00018989,-0.000492238,-0.000193507,50.15411377,50.15411377,-13045.35547,-13022.36133,44.74979598,17.56721646,44.76403046,0,0,0,40,49.86886597,1,6,1,1.948547363,63.04985428,,,,,,,,,,,,,,,,
3772706579,50.15340996,-13650.99951,0.000116876,2.45E-05,1,0.999253354,40.02988815,1.988282511,10.25999989,0.001718722,-0.002270328,0.25,-0.000231764,0.000118569,-0.000230834,50.15353012,50.15353012,-13664.00488,-13637.99414,44.26049653,17.56559308,44.76735687,0,0,0,40,49.86882019,1,6,1,1.947479248,63.53861237,,,,,,,,,,,,,,,,
3772706601,50.15423393,-14174.79102,-4.88E-05,5.58E-05,1,0.999253354,40.02988815,1.988488949,10.25999989,-0.000196645,-0.001903109,0.25,-0.0001674,-4.76E-05,-0.000167724,50.15411377,50.15411377,-14187.89844,-14161.68359,44.43870783,17.57144194,44.76491547,0,0,0,40,49.86855698,1,6,1,1.954803467,63.53861237,,,,,,,,,,,,,,,,
3772706634,50.15356636,-15009.47461,-7.05E-05,5.92E-05,1,0.999253354,40.02988815,1.988532748,10.27000044,-0.000319498,-0.002555143,0.25,-0.00022383,-6.89E-05,-0.000224312,50.15335083,50.15335083,-15018.12793,-15000.82129,44.60050494,17.57304913,44.76758194,1,0,0,40,49.86898422,1,6,1,1.962738037,61.58358002,,,,,,,,,,,,,,,,
3772706700,50.15443802,-16660.30273,-0.00016708,0.000403957,1,0.999253354,40.02988815,1.988683369,10.25999989,-0.00126879,-0.003254106,0.25,-0.000270882,-0.000165051,-0.000272097,50.15443802,50.15443802,-16671.81836,-16648.78711,44.71227781,17.5646354,44.76602554,0,0,0,40,49.86661911,1,6,1,1.959686279,62.56109619,,,,,,,,,,,,,,,,
3772706759,50.15525246,-18107.08691,0.000273912,3.57E-05,1,0.999253354,40.02988815,1.988573884,10.27000044,0.003403639,-0.001901199,0.25,-0.000226211,0.000275585,-0.000224173,50.15513229,50.15513229,-18143.68945,-18070.48438,44.41213246,17.56882776,44.77135468,1,0,0,40,49.86575317,1,6,1,1.950683594,62.0723381,,,,,,,,,,,,,,,,
3772706824,50.15525818,-19747.72363,-2.91E-05,1.54E-05,1,0.999253354,40.02988815,1.988491471,10.25999989,0.000190188,-0.00281241,2.5,-0.000255258,-2.72E-05,-0.000255491,50.15531158,50.15531158,-19789.54492,-19705.90234,44.25737002,17.56656219,44.77667999,0,0,0,40,49.86421585,1,6,1,1.952362061,62.56109619,,,,,,,,,,,,,,,,
3772706881,50.15565872,-21165.59375,-0.000182179,0.000371187,1,0.999253354,40.02988815,1.988450105,10.27000044,-0.001393257,-0.003496402,0.25,-0.000290525,-0.000180053,-0.000291917,50.15582657,50.15582657,-21204.32617,-21126.86133,44.38477546,17.57067223,44.79021835,1,0,0,40,49.86408615,1,6,1,1.960754395,62.56109619,,,,,,,,,,,,,,,,
3772706945,50.15571785,-22737.07031,-7.23E-05,8.02E-05,1,0.999253354,40.02988815,1.988272701,10.25999989,-0.000288503,-0.002832259,0.25,-0.00024911,-7.05E-05,-0.000249703,50.15589905,50.15589905,-22773.97656,-22700.16406,44.32146355,17.56517811,44.81684875,1,0,0,40,49.86292267,1,6,1,1.955871582,62.56109619,,,,,,,,,,,,,,,,
3772707011,50.15546036,-24380.87598,-0.000189013,0.000251406,1,0.999253354,40.02988815,1.988393847,10.25999989,-0.001209729,-0.00491607,2.5,-0.000420819,-0.000185963,-0.000422352,50.15522766,50.15522766,-24416.28516,-24345.4668,44.44105272,17.56820398,44.81951141,0,0,0,40,49.86310196,1,6,1,1.953125,63.04985428,,,,,,,,,,,,,,,,
3772707076,50.15655518,-26007.7832,-7.26E-05,2.86E-05,1,0.999253354,40.02988815,1.988316367,10.27000044,-9.29E-06,-0.004379533,0.25,-0.000392283,-6.97E-05,-0.00039298,50.15652084,50.15652084,-26044.70703,-25970.85938,44.45043226,17.56813978,44.83637619,1,0,0,40,49.86114883,1,6,1,1.951141357,63.04985428,,,,,,,,,,,,,,,,
3772707141,50.1572361,-27638.4502,-0.000215672,0.000530982,1,0.999253354,40.02988815,1.988371841,10.27000044,-0.001630601,-0.004243684,2.5,-0.000353598,-0.000213174,-0.000355364,50.15709305,50.15709305,-27678.47461,-27598.42578,44.13230945,17.57019551,44.84037018,0,0,0,40,49.86054611,1,6,1,1.953735352,63.04985428,,,,,,,,,,,,,,,,
3772707207,50.15743446,-29286.86133,-0.000180032,0.001270392,1,0.999253354,40.02988815,1.988314964,10.25999989,-0.001247233,-0.004169231,0.25,-0.000353096,-0.00017754,-0.000354629,50.15727234,50.15727234,-29325.87891,-29247.84375,44.68648407,17.56564475,44.84614182,1,0,0,40,49.85832214,1,6,1,1.946716309,63.04985428,,,,,,,,,,,,,,,,
3772707310,50.15821075,-28571.73438,-0.000180156,0.001340017,1,0.999253354,40.02988815,1.988528659,10.27000044,-0.001249695,-0.004163918,0.25,-0.000352557,-0.00017766,-0.000354077,50.15805054,50.15805054,-28610.72656,-28532.74219,44.9366052,17.56371005,44.83105087,1,0,0,40,49.85894012,1,6,1,1.957550049,61.58358002,,,,,,,,,,,,,,,,
3772707376,50.15675354,-26934.52441,-0.000294139,7.77E-05,1,0.999253354,40.02988815,1.988450468,10.27000044,-0.002670041,-0.003347282,2.5,-0.000256229,-0.000292385,-0.000258516,50.15670013,50.15670013,-26974.74414,-26894.30469,44.36054498,17.56926014,44.81773376,0,0,0,40,49.8608284,1,6,1,1.960601807,60.11730194,,,,,,,,,,,,,,,,
3772707442,50.15553284,-25298.65332,-0.000185957,0.000221665,1,0.999253354,40.02988815,1.988382834,10.28000005,-0.001503092,-0.003128931,0.25,-0.000255745,-0.000184137,-0.000257214,50.15537262,50.15537262,-25340.37109,-25256.93555,44.50592789,17.5673154,44.81484985,1,0,0,40,49.86173248,1,6,1,1.961364746,62.56109619,,,,,,,,,,,,,,,,
3772707508,50.15611839,-23657.93262,-8.19E-05,5.54E-05,1,0.999253354,40.02988815,1.988377119,10.27000044,-0.000381201,-0.002909257,2.5,-0.000254532,-8.00E-05,-0.00025521,50.15630341,50.15630341,-23699.95898,-23615.90625,44.04398543,17.56631724,44.81551743,0,0,0,40,49.86179352,1,6,1,1.951904297,63.04985428,,,,,,,,,,,,,,,,
3772707571,50.15559769,-22079.39355,8.00E-05,2.14E-05,1,0.999253354,40.02988815,1.988310831,10.27000044,0.001117237,-0.001227485,2.5,-0.00012836,8.10E-05,-0.000127792,50.15551376,50.15551376,-22114.52344,-22044.26367,44.41604061,17.56072634,44.81063461,0,0,0,40,49.86249542,1,6,1,1.954345703,63.04985428,,,,,,,,,,,,,,,,
3772707632,50.15473557,-20556.68457,-7.42E-05,6.61E-05,1,0.999253354,40.02988815,1.988098445,10.27000044,-0.000250316,-0.003155126,0.25,-0.000278728,-7.21E-05,-0.000279309,50.15473557,50.15473557,-20595.18164,-20518.1875,44.64974753,17.56793719,44.80442047,1,0,0,40,49.86408615,1,6,1,1.948242188,63.04985428,,,,,,,,,,,,,,,,
3772707693,50.15492249,-19029.70117,0.000181857,4.33E-05,1,0.999253354,40.02988815,1.98846286,10.27000044,0.002270135,-0.001321909,2.5,-0.000155744,0.000183018,-0.000154399,50.15468979,50.15468979,-19072.61914,-18986.7832,44.47388112,17.56379854,44.80863571,0,0,0,40,49.86424255,1,6,1,1.952209473,63.04985428,,,,,,,,,,,,,,,,
3772707750,50.15418625,-17618.82813,0.000153499,2.65E-05,1,0.999253354,40.02988815,1.988411576,10.27000044,0.002136523,-0.002319151,0.25,-0.000242926,0.000155296,-0.000241774,50.15418625,50.15418625,-17657.21875,-17580.4375,44.34413078,17.56514,44.79576492,0,0,0,40,49.86540604,1,6,1,1.947174072,63.53861237,,,,,,,,,,,,,,,,
3772707806,50.15412712,-16228.31006,3.96E-05,1.06E-05,1,0.999253354,40.02988815,1.988486301,10.27000044,0.000863833,-0.002305207,0.25,-0.000220818,4.13E-05,-0.000220496,50.15419769,50.15419769,-16239.8252,-16216.79492,44.26909444,17.56578429,44.81951141,1,0,0,40,49.86753464,1,6,1,1.949768066,63.04985428,,,,,,,,,,,,,,,,
3772707852,50.15314674,-15077.5791,0.000125067,2.74E-05,1,0.999253354,40.02988815,1.98845599,10.27000044,0.001916611,-0.002851649,0.25,-0.000287089,0.000127178,-0.000286106,50.15333939,50.15333939,-15086.8916,-15068.2666,44.46919134,17.56420888,44.80442047,0,0,0,40,49.86619186,1,6,1,1.952514648,63.04985428,,,,,,,,,,,,,,,,
3772707911,50.15554428,-13615.2168,0.000521773,2.78E-05,1,0.999253354,40.02988815,2.00051347,10.28000005,0.005731781,0.000662035,0.25,-3.44E-05,0.000521892,-3.06E-05,50.15544128,50.15544128,-13624.90332,-13605.53027,44.9530194,17.56182163,44.8255043,0,0,0,40,49.86900711,1,6,1,1.965637207,62.0723381,,,,,,,,,,,,,,,,
3772707932,50.15395927,-13093.41748,0.000652005,3.38E-05,1,0.999253354,40.02988815,2.000692856,10.27000044,0.007282446,0.000173312,0.25,-0.000103297,0.000652584,-9.84E-05,50.15390015,50.15390015,-13103.31348,-13083.52148,44.99757222,17.56012058,44.82416916,0,0,0,40,49.86765289,1,6,1,1.964874268,62.0723381,,,,,,,,,,,,,,,,
3772707957,50.15369034,-12467.9873,0.000901968,2.85E-05,1,0.999253354,40.02988815,2.000695901,10.27000044,0.00984438,0.001495241,0.25,-2.72E-05,0.000901878,-2.05E-05,50.15356445,50.15356445,-12477.99121,-12457.9834,44.71696759,17.56364334,44.82683563,0,0,0,40,49.86834335,1,6,1,1.971740723,62.56109619,,,,,,,,,,,,,,,,
3772707978,50.15279961,-11946.58008,0.000542443,2.89E-05,1,0.999253354,40.02988815,2.000780551,10.27000044,0.006376799,-0.001595372,0.25,-0.000246201,0.000544084,-0.00024208,50.15256119,50.15256119,-11961.38281,-11931.77734,44.90612169,17.56504597,44.83526611,0,0,0,40,49.86855698,1,6,1,1.961975098,62.56109619,,,,,,,,,,,,,,,,
3772708003,50.15289497,-11324.07666,0.000844291,5.08E-05,1,0.999253354,40.02988815,2.000738763,10.27000044,0.009123047,0.001899594,0.25,2.06E-05,0.000843813,2.68E-05,50.15275192,50.15275192,-11335.49023,-11312.66309,44.62786193,17.56464775,44.84170151,0,0,0,40,49.86770248,1,6,1,1.961212158,62.56109619,,,,,,,,,,,,,,,,
3772708024,50.1531353,-10805.09326,0.00066249,3.79E-05,1,0.999253354,40.02988815,2.00054271,10.27000044,0.007099966,0.001806148,0.25,4.52E-05,0.000661881,5.02E-05,50.15327835,50.15327835,-10817.90039,-10792.28613,44.48873206,17.55785918,44.85590744,0,0,0,40,49.86878204,1,6,1,1.964569092,62.0723381,,,,,,,,,,,,,,,,
3772708044,50.15210152,-10285.0498,0.00092281,2.24E-05,1,0.999253354,40.02988815,2.000689919,10.28000005,0.009979313,0.002029114,0.25,1.82E-05,0.00092227,2.50E-05,50.15209579,50.15209579,-10298.04395,-10272.05566,44.24955373,17.5598661,44.86855698,0,0,0,40,49.86956787,1,6,1,1.962738037,62.56109619,,,,,,,,,,,,,,,,
3772708066,50.15297318,-9756.351074,0.000875217,2.53E-05,1,0.999253354,40.02988815,2.000732937,10.27000044,0.009697127,0.000653109,0.25,-9.99E-05,0.000875552,-9.34E-05,50.15284729,50.15284729,-9767.750977,-9744.951172,44.0815036,17.56496912,44.87277222,0,0,0,40,49.86875916,1,6,1,1.971435547,62.0723381,,,,,,,,,,,,,,,,
3772708086,50.15257263,-9235.558594,0.000756172,3.02E-05,1,0.999253354,40.02988815,2.00084746,10.28000005,0.008536879,-0.000302164,0.25,-0.000166162,0.000757036,-0.000160454,50.15277481,50.15277481,-9246.764648,-9224.352539,44.26909444,17.56845155,44.8852005,0,0,0,40,49.86904526,1,6,1,1.970367432,63.04985428,,,,,,,,,,,,,,,,
3772708107,50.15240479,-8711.961914,0.0008531,2.34E-05,1,0.999253354,40.02988815,2.000703346,10.27000044,0.009488761,0.000432577,0.25,-0.000116191,0.000853522,-0.000109783,50.15241623,50.15241623,-8727.976563,-8695.947266,44.2542435,17.56421504,44.87654495,0,0,0,40,49.86919785,1,6,1,1.969604492,62.56109619,,,,,,,,,,,,,,,,
3772708128,50.15244102,-8193.082764,0.00111391,2.03E-05,1,0.999253354,40.02988815,2.00057716,10.27000044,0.01205591,0.002383553,0.25,1.59E-05,0.001113185,2.42E-05,50.15222549,50.15222549,-8206.083984,-8180.081543,44.46137506,17.56243682,44.88409042,0,0,0,40,49.87017441,1,6,1,1.963043213,63.53861237,,,,,,,,,,,,,,,,
3772708150,50.15197563,-7667.461426,0.00120135,2.30E-05,1,0.999253354,40.02988815,2.000613644,10.27000044,0.013192285,0.001531236,0.25,-7.86E-05,0.001201248,-6.97E-05,50.15213013,50.15213013,-7681.872559,-7653.050293,44.61144774,17.56879189,44.89585114,0,0,0,40,49.86910248,1,6,1,1.970214844,63.53861237,,,,,,,,,,,,,,,,
3772708170,50.1529007,-7149.484619,0.001589886,1.88E-05,1,0.999253354,40.02988815,2.000641701,10.27000044,0.016908633,0.0050334,0.25,0.000173032,0.00158765,0.000184757,50.15294266,50.15294266,-7162.58252,-7136.386719,44.7638653,17.56731456,44.88409042,0,0,0,40,49.86907959,1,6,1,1.962890625,63.53861237,,,,,,,,,,,,,,,,
3772708191,50.15177345,-6626.94165,0.001159975,1.96E-05,1,0.999253354,40.02988815,2.000577507,10.27000044,0.01278996,0.001189245,0.25,-0.000102583,0.001160016,-9.39E-05,50.15172577,50.15172577,-6636.344238,-6617.539063,44.33162473,17.56426717,44.8871994,0,0,0,40,49.87125778,1,6,1,1.962432861,63.53861237,,,,,,,,,,,,,,,,
3772708212,50.15172577,-6100.150146,0.001641417,1.82E-05,1,0.999253354,40.02988815,2.000723769,10.28000005,0.017658034,0.004094465,0.25,7.71E-05,0.001639779,8.92E-05,50.15172577,50.15172577,-6113.354004,-6086.946289,44.3417859,17.56175254,44.89385605,0,0,0,40,49.87081528,1,6,1,1.963500977,63.04985428,,,,,,,,,,,,,,,,
3772708233,50.15188026,-5575.204346,0.001578757,1.45E-05,1,0.999253354,40.02988815,2.00064067,10.27000044,0.01707662,0.00342534,0.25,2.69E-05,0.001577494,3.86E-05,50.15172577,50.15172577,-5588.170898,-5562.237793,44.62004565,17.56481185,44.89296722,0,0,0,40,49.8706131,1,6,1,1.963195801,63.53861237,,,,,,,,,,,,,,,,
3772708254,50.15213585,-5056.391357,0.001656062,2.23E-05,1,0.999253354,40.02988815,2.00052319,10.28000005,0.017788536,0.004264234,0.25,9.01E-05,0.001654237,0.000102362,50.15223694,50.15223694,-5064.803223,-5047.979492,44.67710453,17.56680802,44.89429855,0,0,0,40,49.86956787,1,6,1,1.964416504,63.04985428,,,,,,,,,,,,,,,,
3772708275,50.15172958,-4534.504639,0.00183198,1.82E-05,1,0.999253354,40.02988815,2.000555738,10.28000005,0.019765515,0.00423869,0.25,5.56E-05,0.001830246,6.92E-05,50.15174866,50.15174866,-4546.17627,-4522.833008,44.41682223,17.5617429,44.89119339,0,0,0,40,49.87038803,1,6,1,1.961517334,63.53861237,,,,,,,,,,,,,,,,
3772708296,50.15135384,-4011.454712,0.001835661,1.42E-05,1,0.999253354,40.02988815,2.000589398,10.27000044,0.0197415,0.004594704,0.25,8.77E-05,0.001833641,0.000101309,50.15155792,50.15155792,-4024.439697,-3998.469727,44.32224518,17.56562581,44.88697433,0,0,0,40,49.87000656,1,6,1,1.971130371,63.04985428,,,,,,,,,,,,,,,,
3772708317,50.15171242,-3490.356201,0.001925232,1.21E-05,1,0.999253354,40.02988815,2.000611332,10.27000044,0.020748371,0.004579202,0.25,6.99E-05,0.001923234,8.42E-05,50.15177155,50.15177155,-3503.265137,-3477.447266,44.70602479,17.56731596,44.87987518,0,0,0,40,49.87151718,1,6,1,1.972961426,63.04985428,,,,,,,,,,,,,,,,
3772708338,50.15197372,-2971.510986,0.002021366,8.27E-06,1,0.999253354,40.02988815,2.000513913,10.28000005,0.021764383,0.00490892,0.25,8.28E-05,0.002019155,9.77E-05,50.15205765,50.15205765,-2984.523682,-2958.498291,44.54891745,17.56642121,44.87854385,0,0,0,40,49.870327,1,6,1,1.971588135,63.04985428,,,,,,,,,,,,,,,,
3772708359,50.15173149,-2442.850952,0.002032775,1.29E-05,1,0.999253354,40.02988815,2.000625965,10.27000044,0.022082431,0.003873325,0.25,-1.48E-05,0.002031235,3.21E-07,50.15155792,50.15155792,-2455.856689,-2429.845215,44.44965063,17.56955574,44.89496613,0,0,0,40,49.870327,1,6,1,1.971435547,62.56109619,,,,,,,,,,,,,,,,
3772708380,50.15155029,-1920.215698,0.002164282,1.03E-05,1,0.999253354,40.02988815,2.000738859,10.27000044,0.023383224,0.004826838,0.25,4.90E-05,0.002162116,6.51E-05,50.15148544,50.15148544,-1933.129272,-1907.302124,44.74979598,17.5631179,44.88142776,0,0,0,40,49.87139893,1,6,1,1.963348389,63.04985428,,,,,,,,,,,,,,,,
3772708401,50.15159225,-1396.2005,0.002226027,5.80E-06,1,0.999253354,40.02988815,2.000794375,10.28000005,0.024057196,0.004927841,0.25,4.70E-05,0.00222378,6.35E-05,50.15141296,50.15141296,-1410.710693,-1381.690308,44.53562977,17.56663582,44.87366104,0,0,0,40,49.8710289,1,6,1,1.961517334,62.0723381,,,,,,,,,,,,,,,,
3772708422,50.15102577,-874.2288208,0.0022745,7.07E-06,1,0.999253354,40.02988815,2.000681165,10.28000005,0.024542924,0.005233609,0.25,6.64E-05,0.002272026,8.32E-05,50.15110397,50.15110397,-888.6192627,-859.8383789,44.28316376,17.56065802,44.86811066,0,0,0,40,49.8706131,1,6,1,1.973571777,63.04985428,,,,,,,,,,,,,,,,
3772708443,50.15218925,-357.8326416,0.002298842,3.88E-06,1,0.999253354,40.02988815,2.000829409,10.27000044,0.024796615,0.005346332,0.25,7.23E-05,0.002296267,8.93E-05,50.15232086,50.15232086,-369.144989,-346.5202942,44.33787775,17.56583483,44.86966705,0,0,0,40,49.87044907,1,6,1,1.971130371,63.53861237,,,,,,,,,,,,,,,,
3772708457,50.15094757,-9.223322868,0.002307841,3.87E-06,1,0.999253354,40.02988815,2.000880463,10.27000044,0.024897797,0.005346946,0.25,7.07E-05,0.00230525,8.78E-05,50.15095901,50.15095901,-18.98742676,0.540781021,44.61691913,17.56564594,44.87033081,0,0,0,40,49.87117386,1,4,1,1.960754395,63.53861237,,,,,,,,,,,,,,,,