File: Data/DyBCO_MVF_50K_-5000-5000Oe_Continuous.csv
Time Stamp (sec),Temperature (K),Magnetic Field (Oe),Moment (emu),M. Std. Err. (emu),Transport Action,Averaging Time (sec),Frequency (Hz),Peak Amplitude (mm),Center Position (mm),Coil Signal' (mV),"Coil Signal"" (mV)",Range (mV),M. Quad. Signal (emu),M. Raw' (emu),"M. Raw"" (emu)",Min. Temperature (K),Max. Temperature (K),Min. Field (Oe),Max. Field (Oe),Mass (grams),Motor Lag (deg),Pressure (Torr),VSM Status (code),Motor Status (code),Measure Status (code),Measure Count,System Temp. (K),Temp. Status (code),Field Status (code),Chamber Status (code),Motor Current (amps),Motor Heatsink Temp. (C),Map 01,Map 02,Map 03,Map 04,Map 05,Map 06,Map 07,Map 08,Map 09,Map 10,Map 11,Map 12,Map 13,Map 14,Map 15,Map 16
3772686324,50.16915894,0.006266713,,,2,,,,10.32199988,,,,,,,50.16915894,50.16915894,0.006266713,0.006266713,,,43.59514999,,,,40,49.88694,0,0,0,0.025177002,43.49951172,,,,,,,,,,,,,,,,
3772686362,50.15638161,200.8362198,0.00060842,4.66E-06,1,0.999253354,40.02988815,2.000742044,10.30999981,0.006565532,0.001398178,0.25,1.76E-05,0.000607748,2.21E-05,50.15670013,50.15670013,196.2651978,205.4072418,43.588296,17.50419894,43.56696701,0,0,0,40,49.86942673,1,6,1,1.958007813,48.38709641,,,,,,,,,,,,,,,,
3772686384,50.14772606,417.9619293,0.001251863,4.13E-06,1,0.999253354,40.02988815,2.000714381,10.30999981,0.013504545,0.002900445,0.25,3.84E-05,0.001250468,4.76E-05,50.14791107,50.14791107,413.4254761,422.4983826,43.55937575,17.50547794,43.56363678,0,0,0,40,49.86513138,1,6,1,1.957702637,49.85337448,,,,,,,,,,,,,,,,
3772686406,50.14464569,636.7165527,0.001574005,2.89E-06,1,0.999253354,40.02988815,2.00067469,10.30999981,0.016997912,0.003545841,0.25,3.89E-05,0.001572329,5.06E-05,50.1446228,50.1446228,631.5534058,641.8796997,43.7141382,17.50406449,43.57562256,0,0,0,40,49.86695099,1,6,1,1.957855225,50.83089066,,,,,,,,,,,,,,,,
3772686428,50.14401245,855.4112549,0.001739941,3.46E-06,1,0.999253354,40.02988815,2.000737293,10.30999981,0.018805813,0.003836478,0.25,3.54E-05,0.001738158,4.83E-05,50.14390564,50.14390564,850.2573242,860.5651855,43.51873107,17.50569697,43.56962967,0,0,0,40,49.86671448,1,6,1,1.958312988,51.31964874,,,,,,,,,,,,,,,,
3772686450,50.14372635,1075.458313,0.001855889,3.66E-06,1,0.999253354,40.02988815,2.000770125,10.32000035,0.020042009,0.004187666,0.25,4.65E-05,0.001853935,6.03E-05,50.14365387,50.14365387,1071.721313,1079.195313,43.85639459,17.51041365,43.57429123,0,0,0,40,49.8665123,1,6,1,1.957244873,52.78592682,,,,,,,,,,,,,,,,
3772686472,50.14388084,1293.593262,0.001904091,3.47E-06,1,0.999253354,40.02988815,2.000782215,10.32000035,0.020565968,0.004279307,0.25,4.62E-05,0.001902113,6.03E-05,50.14397812,50.14397812,1289.817139,1297.369385,43.68365468,17.5070631,43.57828522,0,0,0,40,49.86654663,1,6,1,1.95602417,52.78592682,,,,,,,,,,,,,,,,
3772686494,50.14362907,1513.624207,0.001947838,3.92E-06,1,0.999253354,40.02988815,2.000808428,10.32000035,0.021068989,0.004213253,0.25,3.21E-05,0.001945943,4.65E-05,50.14360428,50.14360428,1508.590088,1518.658325,43.54765132,17.5159203,43.57917023,0,0,0,40,49.86727142,1,6,1,1.96395874,54.25220108,,,,,,,,,,,,,,,,
3772686516,50.14416122,1732.187622,0.001895448,4.39E-06,1,0.999253354,40.02988815,2.000758491,10.30999981,0.020441844,0.004428751,0.25,6.15E-05,0.001893395,7.55E-05,50.14427567,50.14427567,1726.971558,1737.403687,43.92752278,17.51078724,43.58427811,0,0,0,40,49.86657333,1,6,1,1.959381104,54.25220108,,,,,,,,,,,,,,,,
3772686538,50.14431763,1950.684204,0.001860252,5.05E-06,1,0.999253354,40.02988815,2.000811977,10.30999981,0.020116413,0.004054337,0.25,3.34E-05,0.001858453,4.72E-05,50.14434814,50.14434814,1944.910522,1956.457886,44.22375999,17.51476779,43.59648132,0,0,0,40,49.86834335,1,6,1,1.956787109,55.22971725,,,,,,,,,,,,,,,,
3772686560,50.14370155,2169.79126,0.001844933,8.06E-06,1,0.999253354,40.02988815,2.000751413,10.30999981,0.019961744,0.003958591,0.25,2.74E-05,0.001843207,4.11E-05,50.14365387,50.14365387,2164.618896,2174.963623,43.91501672,17.51459201,43.60691071,0,0,0,40,49.86750031,1,6,1,1.956634521,55.22971725,,,,,,,,,,,,,,,,
3772686582,50.14459229,2389.456055,0.00174157,5.51E-06,1,0.999253354,40.02988815,2.000754907,10.32000035,0.018800218,0.003973927,0.25,4.77E-05,0.001739794,6.06E-05,50.14466858,50.14466858,2383.5625,2395.349609,43.82747433,17.51296924,43.61579132,0,0,0,40,49.86689377,1,6,1,1.960906982,54.74095917,,,,,,,,,,,,,,,,
3772686604,50.14539909,2608.798096,0.001598376,1.20E-05,1,0.999253354,40.02988815,2.000632388,10.30999981,0.01742467,0.002711764,0.25,-4.24E-05,0.001597401,-3.05E-05,50.1450882,50.1450882,2604.164795,2613.431396,44.1198034,17.50956394,43.62688446,0,0,0,40,49.8667984,1,6,1,1.956481934,57.67351151,,,,,,,,,,,,,,,,
3772686626,50.14398193,2828.255493,0.001764768,7.55E-06,1,0.999253354,40.02988815,2.000852162,10.30999981,0.019072041,0.003916744,0.25,3.82E-05,0.001763075,5.13E-05,50.14411926,50.14411926,2822.504883,2834.006104,44.07915871,17.51619086,43.63531876,0,0,0,40,49.86671448,1,6,1,1.956634521,56.69599533,,,,,,,,,,,,,,,,
3772686648,50.14529228,3045.422485,0.001589262,1.31E-05,1,0.999253354,40.02988815,2.000754369,10.30999981,0.017159934,0.003607844,0.25,4.18E-05,0.001587698,5.36E-05,50.1450882,50.1450882,3039.6604,3051.18457,44.03929566,17.51211497,43.63420868,0,0,0,40,49.86738205,1,6,1,1.967315674,56.20723343,,,,,,,,,,,,,,,,
3772686670,50.1454277,3263.529785,0.001672908,1.22E-05,1,0.999253354,40.02988815,2.000796071,10.30999981,0.018083172,0.003690934,0.25,3.42E-05,0.00167135,4.66E-05,50.14529037,50.14529037,3258.880615,3268.178955,43.96504095,17.51627361,43.64109039,0,0,0,40,49.86647797,1,6,1,1.967163086,56.20723343,,,,,,,,,,,,,,,,
3772686692,50.14463425,3481.74292,0.001694127,8.60E-06,1,0.999253354,40.02988815,2.000875576,10.30999981,0.018273187,0.003957758,0.25,5.49E-05,0.001692414,6.74E-05,50.14444351,50.14444351,3476.510742,3486.975098,44.32693495,17.51794087,43.63975906,0,0,0,40,49.86791611,1,6,1,1.969604492,56.69599533,,,,,,,,,,,,,,,,
3772686714,50.14377975,3702.898193,0.001603248,1.39E-05,1,0.999253354,40.02988815,2.000911843,10.30999981,0.017362363,0.003368572,0.25,1.72E-05,0.001601901,2.91E-05,50.1435585,50.1435585,3697.693604,3708.102783,44.31521053,17.51818043,43.64109039,0,0,0,40,49.86846161,1,6,1,1.960296631,56.20723343,,,,,,,,,,,,,,,,
3772686736,50.14466286,3919.708252,0.001619521,8.54E-06,1,0.999253354,40.02988815,2.000914984,10.32000035,0.017439707,0.003944475,0.25,6.73E-05,0.001617805,7.93E-05,50.14494324,50.14494324,3913.185791,3926.230713,43.82591107,17.51974674,43.6419754,0,0,0,40,49.8665123,1,6,1,1.96395874,56.69599533,,,,,,,,,,,,,,,,
3772686758,50.14534569,4139.193115,0.00157577,1.21E-05,1,0.999253354,40.02988815,2.000867282,10.32000035,0.017077482,0.003241294,0.25,1.05E-05,0.001574524,2.22E-05,50.14529037,50.14529037,4135.225586,4143.160645,43.92595952,17.5197627,43.64242172,0,0,0,40,49.86654663,1,6,1,1.954193115,57.67351151,,,,,,,,,,,,,,,,
3772686779,50.14500618,4357.885498,0.00153699,1.61E-05,1,0.999253354,40.02988815,2.000968906,10.32000035,0.016688705,0.002994804,0.25,-5.16E-06,0.001535905,6.27E-06,50.14513779,50.14513779,4353.164551,4362.606445,43.8212213,17.51747139,43.63665009,0,0,0,40,49.86743927,1,6,1,1.9581604,57.67351151,,,,,,,,,,,,,,,,
3772686801,50.14536285,4577.453613,0.001424014,2.43E-05,1,0.999253354,40.02988815,2.000912502,10.30999981,0.015412904,0.003041638,0.25,1.98E-05,0.00142284,3.04E-05,50.14519501,50.14519501,4572.900879,4582.006348,43.90485555,17.51956693,43.6330986,0,0,0,40,49.86743927,1,6,1,1.95602417,58.16226959,,,,,,,,,,,,,,,,
3772686824,50.14533806,4798.346436,0.001286937,1.52E-05,1,0.999253354,40.02988815,2.000848483,10.30999981,0.01401088,0.002300944,0.25,-2.34E-05,0.001286195,-1.38E-05,50.14529037,50.14529037,4793.171875,4803.520996,44.13934411,17.51987178,43.63531876,0,0,0,40,49.86797333,1,6,1,1.969451904,58.16226959,,,,,,,,,,,,,,,,
3772686854,50.14564514,4995.236328,0.001204473,1.25E-05,1,0.999253354,40.02988815,2.000918164,10.32000035,0.012978356,0.002893238,0.25,4.63E-05,0.001203283,5.52E-05,50.14596176,50.14596176,4995.236328,4995.236328,44.21359882,17.52344795,43.64286423,0,0,0,40,49.86645126,1,6,1,1.957550049,57.67351151,,,,,,,,,,,,,,,,
3772686875,50.14510536,4783.686279,0.000133865,1.27E-05,1,0.999253354,40.02988815,2.000822761,10.30999981,0.001589129,-0.000480991,0.25,-6.88E-05,0.000134281,-6.78E-05,50.14520645,50.14520645,4779.04834,4788.324219,44.30192284,17.51739088,43.64619446,0,0,0,40,49.86590576,1,6,1,1.959381104,59.13978577,,,,,,,,,,,,,,,,
3772686897,50.14470673,4564.576904,-0.000543659,1.52E-05,1,0.999253354,40.02988815,2.000788952,10.32000035,-0.00562053,-0.002601416,0.25,-0.000140303,-0.000542223,-0.000144245,50.14470673,50.14470673,4559.381348,4569.772461,44.18858671,17.51521929,43.64619446,0,0,0,40,49.8667984,1,6,1,1.968688965,58.65102768,,,,,,,,,,,,,,,,
3772686919,50.14495659,4346.153809,-0.000983538,1.87E-05,1,0.999253354,40.02988815,2.000978991,10.30999981,-0.010609106,-0.002300352,0.25,-3.21E-05,-0.000982579,-3.94E-05,50.14511108,50.14511108,4340.949219,4351.358398,44.32380844,17.51936147,43.64974594,0,0,0,40,49.86829376,1,6,1,1.968688965,61.58358002,,,,,,,,,,,,,,,,
3772686966,50.14634323,3878.043823,-0.001489359,1.59E-05,1,0.999253354,40.02988815,2.000849304,10.3000002,-0.016063414,-0.00348592,0.25,-4.88E-05,-0.001487876,-5.99E-05,50.14616394,50.14616394,3872.212646,3883.875,43.78213988,17.51954935,43.65440369,0,0,0,40,49.86817551,1,6,1,1.957855225,58.16226959,,,,,,,,,,,,,,,,
3772686988,50.14572144,3658.644043,-0.001650502,9.47E-06,1,0.999253354,40.02988815,2.000925975,10.28999966,-0.017791554,-0.003919617,0.25,-5.93E-05,-0.001648802,-7.15E-05,50.14573288,50.14573288,3652.831055,3664.457031,44.08463011,17.51809028,43.65307236,0,0,0,40,49.8672142,1,6,1,1.969299316,58.16226959,,,,,,,,,,,,,,,,
3772687011,50.14539337,3439.087646,-0.001597127,1.13E-05,1,0.999253354,40.02988815,2.000844102,10.28999966,-0.017244941,-0.003631006,0.25,-4.25E-05,-0.001595578,-5.43E-05,50.14558029,50.14558029,3434.574219,3443.601074,44.07759546,17.52039286,43.65418243,0,0,0,40,49.86661911,1,6,1,1.95602417,57.18475342,,,,,,,,,,,,,,,,
3772687032,50.14490891,3219.450562,-0.001832863,1.11E-05,1,0.999253354,40.02988815,2.00096511,10.28999966,-0.019800613,-0.004115902,0.25,-4.41E-05,-0.001831103,-5.76E-05,50.14496994,50.14496994,3214.805908,3224.095215,44.19952951,17.52143597,43.65418243,0,0,0,40,49.86683273,1,6,1,1.967010498,58.65102768,,,,,,,,,,,,,,,,
3772687054,50.14459229,3001.613037,-0.001864596,1.33E-05,1,0.999253354,40.02988815,2.00080834,10.28999966,-0.020042866,-0.004727414,0.25,-9.46E-05,-0.001862418,-0.000108428,50.14438248,50.14438248,2997.111084,3006.11499,44.18155205,17.51671758,43.65817642,0,0,0,40,49.86693954,1,6,1,1.965942383,60.11730194,,,,,,,,,,,,,,,,
3772687076,50.14459801,2781.911621,-0.001841879,1.52E-05,1,0.999253354,40.02988815,2.000925443,10.3000002,-0.019910105,-0.004065837,0.25,-3.78E-05,-0.001840124,-5.15E-05,50.14432144,50.14432144,2777.296875,2786.526367,44.23939256,17.52154579,43.65729141,0,0,0,40,49.86886597,1,6,1,1.954956055,59.13978577,,,,,,,,,,,,,,,,
3772687098,50.14538765,2563.037231,-0.001861044,1.43E-05,1,0.999253354,40.02988815,2.000902082,10.3000002,-0.020086478,-0.004274217,0.25,-5.35E-05,-0.001859141,-6.73E-05,50.14544678,50.14544678,2558.477783,2567.59668,44.46215669,17.52074216,43.66661072,0,0,0,40,49.86846161,1,6,1,1.959075928,59.13978577,,,,,,,,,,,,,,,,
3772687120,50.14481354,2344.522461,-0.001966843,1.06E-05,1,0.999253354,40.02988815,2.000978345,10.28999966,-0.021231625,-0.00450272,0.25,-5.52E-05,-0.001964824,-6.98E-05,50.1447525,50.1447525,2339.391602,2349.65332,43.96191444,17.52106039,43.6592865,0,0,0,40,49.86671448,1,6,1,1.966247559,59.62854385,,,,,,,,,,,,,,,,
3772687142,50.14963722,2125.433472,-0.002022634,9.55E-06,1,0.999253354,40.02988815,2.000987403,10.28999966,-0.021839666,-0.004598413,0.25,-5.38E-05,-0.002020564,-6.88E-05,50.14966583,50.14966583,2121.696533,2129.17041,44.05883637,17.51931943,43.66860962,0,0,0,40,49.87350464,1,6,1,1.957855225,60.11730194,,,,,,,,,,,,,,,,
3772687164,50.14633751,1905.275818,-0.002026158,1.31E-05,1,0.999253354,40.02988815,2.000931316,10.3000002,-0.021858501,-0.004706984,0.25,-6.32E-05,-0.002023996,-7.82E-05,50.14629745,50.14629745,1900.11731,1910.434326,43.73055239,17.51868812,43.65884399,0,0,0,40,49.86673737,1,6,1,1.967163086,59.62854385,,,,,,,,,,,,,,,,
3772687186,50.14543533,1687.7146,-0.002048743,8.58E-06,1,0.999253354,40.02988815,2.001039307,10.28999966,-0.022104124,-0.004753994,0.25,-6.34E-05,-0.002046543,-7.86E-05,50.14542389,50.14542389,1682.629883,1692.799316,44.13230945,17.52292721,43.66061783,0,0,0,40,49.86770248,1,6,1,1.967010498,59.62854385,,,,,,,,,,,,,,,,
3772687208,50.14543533,1467.635193,-0.002118816,8.09E-06,1,0.999253354,40.02988815,2.000940966,10.28999966,-0.02282308,-0.005112134,0.25,-8.36E-05,-0.00211639,-9.93E-05,50.14546967,50.14546967,1463.036499,1472.233887,44.44027109,17.52285161,43.66217041,0,0,0,40,49.86645126,1,6,1,1.95892334,60.11730194,,,,,,,,,,,,,,,,
3772687230,50.14501762,1248.136536,-0.002137527,6.82E-06,1,0.999253354,40.02988815,2.000964202,10.28999966,-0.023054619,-0.00499373,0.25,-6.93E-05,-0.002135174,-8.51E-05,50.14496994,50.14496994,1243.014893,1253.258179,44.16748274,17.52745251,43.6701622,0,0,0,40,49.86779785,1,6,1,1.948852539,59.62854385,,,,,,,,,,,,,,,,
3772687252,50.14388084,1030.61676,-0.002178999,3.38E-06,1,0.999253354,40.02988815,2.000933186,10.28999966,-0.023508681,-0.005050604,0.25,-6.69E-05,-0.00217661,-8.31E-05,50.14397812,50.14397812,1024.81311,1036.42041,44.24095582,17.52498024,43.66194916,0,0,0,40,49.86673737,1,6,1,1.966552734,59.13978577,,,,,,,,,,,,,,,,
3772687274,50.14497375,810.2655334,-0.002177317,5.46E-06,1,0.999253354,40.02988815,2.000984119,10.28999966,-0.023550217,-0.004722717,0.25,-3.70E-05,-0.002175137,-5.32E-05,50.14494324,50.14494324,805.6990967,814.8319702,44.51765231,17.52522309,43.66949463,0,0,0,40,49.86711884,1,6,1,1.957397461,60.11730194,,,,,,,,,,,,,,,,
3772687296,50.14455032,591.9279175,-0.002217307,4.29E-06,1,0.999253354,40.02988815,2.000958482,10.28999966,-0.023897203,-0.005274552,0.25,-8.06E-05,-0.002214752,-9.70E-05,50.14458466,50.14458466,587.3684082,596.4874268,44.49498509,17.52586835,43.66683197,0,0,0,40,49.86796188,1,6,1,1.958618164,61.09482193,,,,,,,,,,,,,,,,
3772687318,50.14437866,371.3416748,-0.002243806,4.28E-06,1,0.999253354,40.02988815,2.001018989,10.3000002,-0.024193323,-0.005283108,0.25,-7.65E-05,-0.002241244,-9.31E-05,50.1443367,50.1443367,366.2131042,376.4702454,44.43401806,17.52798798,43.66705322,0,0,0,40,49.8682251,1,6,1,1.968994141,60.11730194,,,,,,,,,,,,,,,,
3772687340,50.14523125,154.4993591,-0.002243777,4.51E-06,1,0.999253354,40.02988815,2.000978136,10.3000002,-0.024180108,-0.005350133,0.25,-8.27E-05,-0.002241156,-9.93E-05,50.1450386,50.1450386,149.352356,159.6463623,44.25815164,17.52608617,43.67038345,0,0,0,40,49.86802292,1,6,1,1.966705322,60.11730194,,,,,,,,,,,,,,,,
3772687362,50.14441872,-64.02947617,-0.002212083,5.00E-06,1,0.999253354,40.02988815,2.001019631,10.28999966,-0.02391565,-0.004855456,0.25,-4.29E-05,-0.002209781,-5.93E-05,50.14451599,50.14451599,-69.23638153,-58.8225708,44.16357459,17.5290095,43.67060471,0,0,0,40,49.86817551,1,6,1,1.956939697,60.60606384,,,,,,,,,,,,,,,,
3772687384,50.14599609,-281.740387,-0.00221429,3.76E-06,1,0.999253354,40.02988815,2.000961331,10.28999966,-0.023886973,-0.005144594,0.25,-6.91E-05,-0.002211805,-8.55E-05,50.14616394,50.14616394,-286.8298035,-276.6509705,44.18233368,17.52314536,43.67082596,0,0,0,40,49.8674736,1,6,1,1.967010498,60.11730194,,,,,,,,,,,,,,,,
3772687406,50.14472961,-500.0710754,-0.002150092,4.98E-06,1,0.999253354,40.02988815,2.001120593,10.28999966,-0.023276746,-0.004556089,0.25,-2.66E-05,-0.002147992,-4.26E-05,50.14472961,50.14472961,-505.2618408,-494.8803101,44.50827277,17.53106736,43.67237854,0,0,0,40,49.8682251,1,6,1,1.96762085,61.09482193,,,,,,,,,,,,,,,,
3772687428,50.14548874,-722.1157227,-0.002178454,3.23E-06,1,0.999253354,40.02988815,2.001003432,10.28999966,-0.023455706,-0.005309955,0.25,-9.09E-05,-0.002175866,-0.000107033,50.1455307,50.1455307,-727.1959229,-717.0355225,44.2706577,17.52592008,43.66350174,0,0,0,40,49.86695099,1,6,1,1.964874268,61.09482193,,,,,,,,,,,,,,,,
3772687450,50.14490318,-940.8610229,-0.002125064,4.16E-06,1,0.999253354,40.02988815,2.001105629,10.28999966,-0.022945399,-0.004834147,0.25,-5.68E-05,-0.002122792,-7.26E-05,50.14484787,50.14484787,-944.8629761,-936.8590698,44.15966645,17.52856645,43.67548752,0,0,0,40,49.86904526,1,6,1,1.958770752,60.11730194,,,,,,,,,,,,,,,,
3772687472,50.14532661,-1160.500427,-0.002094922,3.23E-06,1,0.999253354,40.02988815,2.001007794,10.28999966,-0.02256382,-0.005067434,0.25,-8.38E-05,-0.002092491,-9.93E-05,50.1450882,50.1450882,-1165.663574,-1155.33728,44.18546019,17.5271997,43.67215729,0,0,0,40,49.86872482,1,6,1,1.956939697,61.09482193,,,,,,,,,,,,,,,,
3772687494,50.1452446,-1379.501526,-0.00206571,5.28E-06,1,0.999253354,40.02988815,2.000954222,10.28999966,-0.02228721,-0.004786668,0.25,-6.33E-05,-0.002063473,-7.86E-05,50.14532852,50.14532852,-1384.118652,-1374.884399,44.42385689,17.52545942,43.66705322,0,0,0,40,49.86759567,1,6,1,1.958007813,61.09482193,,,,,,,,,,,,,,,,
3772687516,50.14533806,-1597.405945,-0.002027411,4.05E-06,1,0.999253354,40.02988815,2.001089023,10.28999966,-0.021832393,-0.004934292,0.25,-8.39E-05,-0.00202507,-9.89E-05,50.14529037,50.14529037,-1601.956177,-1592.855713,44.08853826,17.52962223,43.67082596,0,0,0,40,49.86814117,1,6,1,1.961669922,61.09482193,,,,,,,,,,,,,,,,
3772687538,50.14532852,-1816.116699,-0.001953611,6.74E-06,1,0.999253354,40.02988815,2.000882012,10.3000002,-0.021012353,-0.004882362,0.25,-9.26E-05,-0.001951284,-0.00010709,50.14525604,50.14525604,-1821.36499,-1810.868408,44.17060925,17.53131207,43.66394806,0,0,0,40,49.86677551,1,6,1,1.957244873,61.58358002,,,,,,,,,,,,,,,,
3772687585,50.14541626,-2284.461914,-0.001937855,9.83E-06,1,0.999253354,40.02988815,1.98877042,10.28000005,-0.020742072,-0.004715221,0.25,-8.26E-05,-0.001935651,-9.70E-05,50.14544678,50.14544678,-2288.171387,-2280.752441,44.38868361,17.52400975,43.67459869,0,0,0,40,49.86953354,1,6,1,1.954193115,59.62854385,,,,,,,,,,,,,,,,
3772687607,50.14569283,-2502.076294,-0.001924685,8.47E-06,1,0.999253354,40.02988815,1.988761834,10.28000005,-0.020631545,-0.004517354,0.25,-6.67E-05,-0.001922628,-8.09E-05,50.14575958,50.14575958,-2505.843262,-2498.309326,44.31286564,17.52474334,43.68303299,0,0,0,40,49.86683273,1,6,1,1.94732666,61.09482193,,,,,,,,,,,,,,,,
3772687629,50.14608192,-2723.606934,-0.001880598,8.45E-06,1,0.999253354,40.02988815,1.988721109,10.28000005,-0.020120792,-0.004621359,0.25,-8.44E-05,-0.001878462,-9.83E-05,50.14611816,50.14611816,-2728.7771,-2718.436768,44.31364727,17.52752875,43.68125916,0,0,0,40,49.86765289,1,6,1,1.946258545,60.60606384,,,,,,,,,,,,,,,,
3772687651,50.14503479,-2941.603516,-0.001845529,1.01E-05,1,0.999253354,40.02988815,1.988693422,10.28000005,-0.019830431,-0.004070792,0.25,-3.98E-05,-0.001843769,-5.35E-05,50.14506531,50.14506531,-2946.287354,-2936.919678,44.44183435,17.52263027,43.68880463,0,0,0,40,49.86843872,1,6,1,1.956176758,61.09482193,,,,,,,,,,,,,,,,
3772687673,50.14519501,-3161.535522,-0.001787743,1.08E-05,1,0.999253354,40.02988815,1.988703084,10.28000005,-0.019118962,-0.0044399,0.25,-8.46E-05,-0.001785713,-9.78E-05,50.14519501,50.14519501,-3166.659424,-3156.411621,44.45903017,17.52832487,43.6943512,0,0,0,40,49.8674736,1,6,1,1.951293945,60.60606384,,,,,,,,,,,,,,,,
3772687695,50.14409447,-3379.651978,-0.001617517,1.22E-05,1,0.999253354,40.02988815,1.988685199,10.28999966,-0.017462589,-0.003120052,0.25,6.66E-06,-0.001616313,-5.38E-06,50.14404678,50.14404678,-3385.547607,-3373.756348,44.53875628,17.5238648,43.69346237,0,0,0,40,49.86764145,1,6,1,1.947631836,61.09482193,,,,,,,,,,,,,,,,
3772687717,50.14577103,-3600.897095,-0.001659643,1.48E-05,1,0.999253354,40.02988815,1.988762276,10.28999966,-0.017718692,-0.00429227,0.25,-9.43E-05,-0.001657673,-0.00010655,50.14578247,50.14578247,-3603.620361,-3598.173828,44.09869943,17.52949343,43.69213104,0,0,0,40,49.86785507,1,6,1,1.945495605,60.60606384,,,,,,,,,,,,,,,,
3772687739,50.14506912,-3819.317627,-0.00160628,9.55E-06,1,0.999253354,40.02988815,1.988864741,10.28000005,-0.017162001,-0.004088725,0.25,-8.52E-05,-0.001604433,-9.70E-05,50.14484787,50.14484787,-3824.572998,-3814.062256,44.31521053,17.53326279,43.69745636,0,0,0,40,49.86878204,1,6,1,1.951141357,61.09482193,,,,,,,,,,,,,,,,
3772687761,50.14484406,-4038.208008,-0.001594777,1.03E-05,1,0.999253354,40.02988815,1.98877772,10.28000005,-0.017094449,-0.003753758,0.25,-5.62E-05,-0.001593169,-6.80E-05,50.14490891,50.14490891,-4042.737549,-4033.678467,44.22454162,17.52783481,43.70012283,0,0,0,40,49.86854553,1,6,1,1.949615479,61.58358002,,,,,,,,,,,,,,,,
3772687783,50.14529037,-4257.663086,-0.001611801,1.55E-05,1,0.999253354,40.02988815,1.98883281,10.28000005,-0.017103824,-0.004743764,0.25,-0.000144853,-0.001609538,-0.000156734,50.14538574,50.14538574,-4261.704102,-4253.62207,44.59581516,17.52689598,43.71144104,0,0,0,40,49.86741638,1,6,1,1.948394775,61.09482193,,,,,,,,,,,,,,,,
3772687805,50.14539337,-4476.461426,-0.001381182,1.32E-05,1,0.999253354,40.02988815,1.988777839,10.28999966,-0.015009737,-0.002133,0.25,5.49E-05,-0.001380588,4.46E-05,50.14558029,50.14558029,-4480.334473,-4472.588379,44.61770076,17.52457253,43.70455933,0,0,0,40,49.86743927,1,6,1,1.961212158,61.58358002,,,,,,,,,,,,,,,,
3772687827,50.14486694,-4693.469971,-0.001326608,1.15E-05,1,0.999253354,40.02988815,1.988694644,10.28000005,-0.014082593,-0.003872588,0.25,-0.000116291,-0.001324793,-0.000126074,50.14519501,50.14519501,-4699.310547,-4687.629395,44.25189862,17.53127228,43.7056694,0,0,0,40,49.86689377,1,6,1,1.949462891,61.09482193,,,,,,,,,,,,,,,,
3772687849,50.14539909,-4912.236084,-0.001257542,1.27E-05,1,0.999253354,40.02988815,1.988825346,10.28999966,-0.013253963,-0.004198414,0.25,-0.000159097,-0.001255471,-0.000168338,50.14546967,50.14546967,-4917.438477,-4907.033691,44.25189862,17.53249766,43.70189667,0,0,0,40,49.86733246,1,6,1,1.95602417,61.58358002,,,,,,,,,,,,,,,,
3772687880,50.14616394,-4874.942139,-0.000427774,1.20E-05,1,0.999253354,40.02988815,1.988880371,10.28999966,-0.004480533,-0.001582003,0.25,-6.84E-05,-0.000426963,-7.15E-05,50.14616394,50.14616394,-4878.349609,-4871.534668,44.38243058,17.53246507,43.6963501,0,0,0,40,49.86828232,1,6,1,1.948242188,59.13978577,,,,,,,,,,,,,,,,
3772687902,50.14566231,-4656.29834,0.000295132,2.55E-05,1,0.999253354,40.02988815,1.988860372,10.28000005,0.003263838,0.000147524,0.25,-4.03E-05,0.00029522,-3.81E-05,50.14563751,50.14563751,-4661.470703,-4651.125977,44.37148778,17.53304684,43.69035721,0,0,0,40,49.8674736,1,6,1,1.958770752,61.09482193,,,,,,,,,,,,,,,,
3772687924,50.14605141,-4437.435059,0.000850134,1.38E-05,1,0.999253354,40.02988815,1.988763417,10.28999966,0.009264604,0.001170662,0.25,-4.70E-05,0.000849865,-4.06E-05,50.14614105,50.14614105,-4443.277832,-4431.592285,44.27378421,17.5326075,43.68480682,0,0,0,40,49.86727142,1,6,1,1.948547363,61.58358002,,,,,,,,,,,,,,,,
3772687946,50.14546013,-4219.05835,0.001113502,1.22E-05,1,0.999253354,40.02988815,1.988848204,10.28999966,0.012139466,0.001509595,0.25,-6.38E-05,0.001113155,-5.54E-05,50.14542389,50.14542389,-4224.219238,-4213.897461,44.36445312,17.53182322,43.68680573,0,0,0,40,49.86790466,1,6,1,1.944580078,61.58358002,,,,,,,,,,,,,,,,
3772687968,50.14570999,-4000.446777,0.001366215,1.45E-05,1,0.999253354,40.02988815,1.988837331,10.28999966,0.014802085,0.00235648,0.25,-3.15E-05,0.001365428,-2.13E-05,50.14563751,50.14563751,-4005.736572,-3995.156982,44.4871688,17.53412634,43.68924713,0,0,0,40,49.86782074,1,6,1,1.955108643,61.58358002,,,,,,,,,,,,,,,,
3772687990,50.14592552,-3779.378906,0.00162005,1.26E-05,1,0.999253354,40.02988815,1.988844182,10.28000005,0.017442071,0.003395878,0.25,1.84E-05,0.001618687,3.05E-05,50.14580536,50.14580536,-3784.57666,-3774.181152,44.6982085,17.53428368,43.68835831,0,0,0,40,49.86886597,1,6,1,1.956787109,62.56109619,,,,,,,,,,,,,,,,
3772688012,50.14543533,-3560.979004,0.001727774,1.10E-05,1,0.999253354,40.02988815,1.988828678,10.28999966,0.018600739,0.003626081,0.25,2.01E-05,0.001726301,3.29E-05,50.14544678,50.14544678,-3566.130615,-3555.827393,44.07837708,17.53492183,43.67615128,0,0,0,40,49.86823654,1,6,1,1.957244873,62.0723381,,,,,,,,,,,,,,,,
3772688034,50.14490318,-3343.473267,0.001735169,1.29E-05,1,0.999253354,40.02988815,1.988818273,10.28000005,0.01869766,0.003545403,0.25,1.12E-05,0.001733738,2.41E-05,50.14484787,50.14484787,-3348.067383,-3338.87915,44.35194707,17.53229731,43.67637634,0,0,0,40,49.8682251,1,6,1,1.94442749,61.58358002,,,,,,,,,,,,,,,,
3772688056,50.14537621,-3122.209595,0.001830246,1.19E-05,1,0.999253354,40.02988815,1.988772319,10.28000005,0.019768305,0.003484022,0.25,-1.18E-05,0.001828896,1.78E-06,50.14532852,50.14532852,-3127.405029,-3117.01416,44.29332493,17.5310822,43.67082596,0,0,0,40,49.86758041,1,6,1,1.958465576,62.56109619,,,,,,,,,,,,,,,,
3772688078,50.1455307,-2904.104492,0.001927593,1.01E-05,1,0.999253354,40.02988815,1.988880892,10.28999966,0.020737439,0.004124289,0.25,2.97E-05,0.001925841,4.40E-05,50.1455307,50.1455307,-2908.101807,-2900.107178,44.17217251,17.53510023,43.66261673,0,0,0,40,49.86791611,1,6,1,1.946716309,62.0723381,,,,,,,,,,,,,,,,
3772688100,50.1449337,-2686.03894,0.001943196,1.22E-05,1,0.999253354,40.02988815,1.988798374,10.28999966,0.020886686,0.00425368,0.25,3.88E-05,0.001941345,5.33E-05,50.14480209,50.14480209,-2691.840332,-2680.237549,44.4379262,17.53369758,43.66172791,0,0,0,40,49.86829376,1,6,1,1.942901611,62.0723381,,,,,,,,,,,,,,,,
3772688121,50.14626503,-2467.602173,0.001938231,9.72E-06,1,0.999253354,40.02988815,1.988778519,10.28000005,0.020887274,0.003945729,0.25,1.12E-05,0.001936573,2.56E-05,50.14624786,50.14624786,-2472.772217,-2462.432129,44.10417083,17.53519293,43.65151978,0,0,0,40,49.86703491,1,6,1,1.957244873,60.60606384,,,,,,,,,,,,,,,,
3772688144,50.14571571,-2247.748535,0.001950838,1.28E-05,1,0.999253354,40.02988815,1.988761784,10.28000005,0.020987028,0.004166735,0.25,2.94E-05,0.001949017,4.39E-05,50.14556503,50.14556503,-2252.897949,-2242.599121,44.05492823,17.53518319,43.65218353,0,0,0,40,49.8670578,1,6,1,1.949157715,61.58358002,,,,,,,,,,,,,,,,
3772688190,50.14704323,-1779.078613,0.00207482,1.28E-05,1,0.999253354,40.02988815,1.988750125,10.28000005,0.022247791,0.004827793,0.25,6.80E-05,0.002072572,8.34E-05,50.14691925,50.14691925,-1782.990723,-1775.166504,43.65629768,17.52971926,43.63931274,0,0,0,40,49.87139893,1,6,1,1.947021484,60.60606384,,,,,,,,,,,,,,,,
3772688213,50.14722252,-1559.621338,0.00209781,1.13E-05,1,0.999253354,40.02988815,1.988801632,10.28000005,0.022624784,0.004170096,0.25,2.84E-06,0.002096011,1.84E-05,50.14691925,50.14691925,-1564.885864,-1554.356812,43.98770818,17.53439366,43.63909149,0,0,0,40,49.86765289,1,6,1,1.948394775,61.09482193,,,,,,,,,,,,,,,,
3772688235,50.145895,-1339.843811,0.002119722,9.57E-06,1,0.999253354,40.02988815,1.988868659,10.28999966,0.022832729,0.004371794,0.25,1.75E-05,0.002117777,3.33E-05,50.14578247,50.14578247,-1345.030029,-1334.657593,44.36679801,17.5354781,43.63420868,0,0,0,40,49.86849594,1,6,1,1.954193115,61.58358002,,,,,,,,,,,,,,,,
3772688257,50.14596558,-1120.890991,0.002158727,6.60E-06,1,0.999253354,40.02988815,1.988906228,10.28999966,0.023235225,0.004550051,0.25,2.69E-05,0.002156662,4.29E-05,50.14592361,50.14592361,-1126.008057,-1115.773926,44.42932829,17.53354607,43.62755203,0,0,0,40,49.86802292,1,6,1,1.960754395,61.58358002,,,,,,,,,,,,,,,,
3772688278,50.14515495,-903.7353821,0.002183333,7.19E-06,1,0.999253354,40.02988815,1.988788524,10.28000005,0.023498319,0.004602963,0.25,2.73E-05,0.002181226,4.35E-05,50.14506531,50.14506531,-908.9445801,-898.5261841,44.46919134,17.53444094,43.63243484,0,0,0,40,49.86849594,1,6,1,1.947631836,62.0723381,,,,,,,,,,,,,,,,
3772688301,50.14550209,-683.6352844,0.002199933,7.01E-06,1,0.999253354,40.02988815,1.988794702,10.28000005,0.023641086,0.004833632,0.25,4.57E-05,0.00219766,6.20E-05,50.14542389,50.14542389,-688.6832275,-678.5873413,44.76855507,17.53697614,43.63354492,0,0,0,40,49.86854553,1,6,1,1.960754395,61.58358002,,,,,,,,,,,,,,,,
3772688322,50.1450634,-465.6455994,0.002232641,6.06E-06,1,0.999253354,40.02988815,1.988866497,10.28000005,0.023948612,0.005149571,0.25,6.90E-05,0.002230151,8.55E-05,50.1450386,50.1450386,-470.2097168,-461.0814819,44.25268024,17.53512141,43.63620758,0,0,0,40,49.8670578,1,6,1,1.957244873,62.0723381,,,,,,,,,,,,,,,,
3772688344,50.14556694,-247.8701477,0.002226703,5.39E-06,1,0.999253354,40.02988815,1.988934966,10.28000005,0.023940264,0.004836931,0.25,4.11E-05,0.002224412,5.76E-05,50.14573288,50.14573288,-253.0401917,-242.7001038,44.503583,17.53511764,43.63198853,0,0,0,40,49.86743927,1,6,1,1.945800781,62.0723381,,,,,,,,,,,,,,,,
3772688366,50.14498138,-27.99583626,0.002244141,4.80E-06,1,0.999253354,40.02988815,1.988755746,10.28999966,0.024092059,0.005057566,0.25,5.84E-05,0.002241695,7.50E-05,50.14500427,50.14500427,-33.20735168,-22.78432083,44.23470279,17.5359207,43.63354492,0,0,0,40,49.86823654,1,6,1,1.946411133,62.0723381,,,,,,,,,,,,,,,,
3772688388,50.14535713,192.7655106,0.002239478,3.85E-06,1,0.999253354,40.02988815,1.988938449,10.28999966,0.023998552,0.005296944,0.25,8.14E-05,0.002236873,9.79E-05,50.14538574,50.14538574,188.118454,197.4125671,44.27143933,17.53619878,43.64175415,0,0,0,40,49.86900711,1,6,1,1.943817139,62.0723381,,,,,,,,,,,,,,,,
3772688410,50.14483643,409.7529907,0.002205464,4.95E-06,1,0.999253354,40.02988815,1.988817089,10.28999966,0.023648194,0.005132199,0.25,7.23E-05,0.00220297,8.87E-05,50.14494324,50.14494324,405.1635132,414.3424683,44.01506517,17.53771777,43.63731766,0,0,0,40,49.86834335,1,6,1,1.946258545,62.56109619,,,,,,,,,,,,,,,,
3772688432,50.14638519,627.8624878,0.002176168,4.88E-06,1,0.999253354,40.02988815,1.988797974,10.28999966,0.023387276,0.00477286,0.25,4.44E-05,0.002173923,6.05E-05,50.14652252,50.14652252,623.2592163,632.4657593,44.38712035,17.53602071,43.63398743,0,0,0,40,49.8677597,1,6,1,1.960906982,62.56109619,,,,,,,,,,,,,,,,
3772688454,50.14517212,846.4512329,0.00216639,3.59E-06,1,0.999253354,40.02988815,1.98879249,10.28000005,0.023202017,0.005190254,0.25,8.49E-05,0.002163867,0.000100902,50.14525604,50.14525604,841.2904053,851.6120605,44.46215669,17.53321809,43.63420868,0,0,0,40,49.86828232,1,6,1,1.958312988,62.0723381,,,,,,,,,,,,,,,,
3772688476,50.14544106,1065.761047,0.0021483,3.48E-06,1,0.999253354,40.02988815,1.988869093,10.28000005,0.02299966,0.005199761,0.25,8.90E-05,0.002145778,0.000104934,50.14538574,50.14538574,1061.206177,1070.315918,44.40822432,17.53485648,43.62444305,0,0,0,40,49.86855698,1,6,1,1.948699951,62.0723381,,,,,,,,,,,,,,,,
3772688498,50.1464138,1286.133057,0.002095237,5.26E-06,1,0.999253354,40.02988815,1.988791174,10.28999966,0.02241235,0.005172668,0.25,9.63E-05,0.002092724,0.000111743,50.1462822,50.1462822,1280.960693,1291.30542,44.14012574,17.53639236,43.61911774,0,0,0,40,49.86750031,1,6,1,1.956481934,62.0723381,,,,,,,,,,,,,,,,
3772688520,50.14562607,1505.030457,0.002069317,4.40E-06,1,0.999253354,40.02988815,1.988962516,10.28000005,0.02214375,0.005072581,0.25,9.17E-05,0.002066876,0.000106976,50.14556503,50.14556503,1499.904175,1510.156738,44.24408233,17.53756073,43.62777328,0,0,0,40,49.86882019,1,6,1,1.96105957,62.56109619,,,,,,,,,,,,,,,,
3772688542,50.14597893,1724.135376,0.001978827,7.12E-06,1,0.999253354,40.02988815,1.988866291,10.28000005,0.021181067,0.004815348,0.25,8.44E-05,0.001976533,9.90E-05,50.14596176,50.14596176,1720.363892,1727.90686,44.46371994,17.53456685,43.61268234,0,0,0,40,49.86875916,1,6,1,1.967926025,62.0723381,,,,,,,,,,,,,,,,
3772688564,50.14565086,1943.194092,0.001957292,5.95E-06,1,0.999253354,40.02988815,1.988843115,10.28000005,0.020876124,0.0051696,0.25,0.000121175,0.00195476,0.000135624,50.14549637,50.14549637,1940.703491,1945.684692,44.31833704,17.53599875,43.6064682,0,0,0,40,49.86940002,1,6,1,1.949615479,63.04985428,,,,,,,,,,,,,,,,
3772688586,50.14547729,2163.704346,0.001918785,7.50E-06,1,0.999253354,40.02988815,1.988887868,10.28000005,0.020522758,0.004757885,0.25,9.00E-05,0.001916533,0.000104231,50.1455307,50.1455307,2158.578125,2168.830566,44.23939256,17.5393262,43.59848022,0,0,0,40,49.86861801,1,6,1,1.940155029,63.04985428,,,,,,,,,,,,,,,,
3772688608,50.14580536,2382.659424,0.001920213,8.10E-06,1,0.999253354,40.02988815,1.988988174,10.28999966,0.020465751,0.005163189,0.25,0.000127321,0.001917699,0.000141492,50.14578247,50.14578247,2377.540039,2387.778809,44.63489659,17.53724432,43.5971489,0,0,0,40,49.86828232,1,6,1,1.955413818,62.0723381,,,,,,,,,,,,,,,,
3772688630,50.14548874,2601.522217,0.001864765,7.22E-06,1,0.999253354,40.02988815,1.988920384,10.28000005,0.019902298,0.004861058,0.25,0.00010947,0.001862446,0.000123245,50.14544678,50.14544678,2596.359131,2606.685303,44.70680641,17.53579419,43.59936523,0,0,0,40,49.86933136,1,6,1,1.948242188,62.0723381,,,,,,,,,,,,,,,,
3772688652,50.14622498,2821.619873,0.001736854,8.54E-06,1,0.999253354,40.02988815,1.989057906,10.28000005,0.018502682,0.004723848,0.25,0.000120116,0.001734575,0.000132933,50.14604568,50.14604568,2815.772461,2827.467285,44.37226941,17.54029548,43.60070038,0,0,0,40,49.86817551,1,6,1,1.94732666,63.04985428,,,,,,,,,,,,,,,,
3772688674,50.14597893,3041.185669,0.001723944,8.28E-06,1,0.999253354,40.02988815,1.988968363,10.28000005,0.018380865,0.004599288,0.25,0.000110946,0.001721759,0.000123677,50.14609146,50.14609146,3036.024902,3046.346436,44.40431618,17.54130706,43.5971489,0,0,0,40,49.86869812,1,6,1,1.960144043,62.56109619,,,,,,,,,,,,,,,,
3772688696,50.14669037,3258.403198,0.001733277,9.94E-06,1,0.999253354,40.02988815,1.988997952,10.28000005,0.01854002,0.004300603,0.25,8.15E-05,0.00173132,9.44E-05,50.14666748,50.14666748,3252.594971,3264.211426,44.47857089,17.53975372,43.59470749,0,0,0,40,49.86695099,1,6,1,1.956787109,62.0723381,,,,,,,,,,,,,,,,
3772688718,50.14579391,3477.897583,0.001611346,1.92E-05,1,0.999253354,40.02988815,1.988900983,10.28999966,0.017210473,0.004132804,0.25,8.83E-05,0.001609448,0.000100225,50.14578247,50.14578247,3471.257568,3484.537598,43.95566141,17.53400257,43.58827209,0,0,0,40,49.86797333,1,6,1,1.955871582,62.0723381,,,,,,,,,,,,,,,,
3772688740,50.14621162,3697.988403,0.001546914,2.67E-05,1,0.999253354,40.02988815,1.98891854,10.28999966,0.016409277,0.00458707,0.25,0.000142193,0.00154468,0.000153588,50.1462822,50.1462822,3692.786133,3703.190674,44.31755541,17.53748387,43.58982468,0,0,0,40,49.86811829,1,6,1,1.94229126,62.56109619,,,,,,,,,,,,,,,,
3772688762,50.14524841,3915.233765,0.001670705,8.82E-06,1,0.999253354,40.02988815,1.988997472,10.28999966,0.017760672,0.004749829,0.25,0.000134614,0.001668449,0.000146937,50.14520645,50.14520645,3911.476074,3918.991455,44.41682223,17.53723711,43.5891571,0,0,0,40,49.86823654,1,6,1,1.947174072,65.00489044,,,,,,,,,,,,,,,,
3772688809,50.14775467,4385.256348,0.001546107,1.55E-05,1,0.999253354,40.02988815,1.989010502,10.28000005,0.016404733,0.004569799,0.25,0.000140707,0.001543933,0.000152103,50.14759827,50.14759827,4380.129883,4390.382813,43.77745011,17.53532504,43.58893585,0,0,0,40,49.87151718,1,6,1,1.949920654,60.60606384,,,,,,,,,,,,,,,,
3772688831,50.14756393,4604.911865,0.001554084,1.49E-05,1,0.999253354,40.02988815,1.988954422,10.28000005,0.016503684,0.004513501,0.25,0.000134037,0.001551969,0.000145499,50.14758682,50.14758682,4599.750977,4610.072754,44.28863516,17.53490814,43.58316803,0,0,0,40,49.86846161,1,6,1,1.956481934,61.58358002,,,,,,,,,,,,,,,,
3772688853,50.1474781,4823.316406,0.0014591,1.31E-05,1,0.999253354,40.02988815,1.988952792,10.28000005,0.01538061,0.004863789,0.25,0.000183872,0.001456697,0.000194594,50.14752579,50.14752579,4818.704102,4827.928711,44.19171322,17.53554601,43.58338928,0,0,0,40,49.86866379,1,6,1,1.95602417,61.58358002,,,,,,,,,,,,,,,,
3772688883,50.14583588,4974.683105,0.001082104,1.62E-05,1,0.999253354,40.02988815,1.988933638,10.28999966,0.011264351,0.004384777,0.25,0.000208439,0.001079793,0.000216341,50.14596176,50.14596176,4969.404785,4979.961426,44.52468697,17.53786864,43.58094788,0,0,0,40,49.86725998,1,6,1,1.955718994,62.56109619,,,,,,,,,,,,,,,,
3772688905,50.1455555,4755.965332,0.000216078,2.02E-05,1,0.999253354,40.02988815,1.989095974,10.28000005,0.002025809,0.002098267,0.25,0.000154928,0.000214772,0.000156425,50.1456871,50.1456871,4751.35498,4760.575684,44.43323643,17.54208984,43.58205795,0,0,0,40,49.86703491,1,6,1,1.942138672,62.56109619,,,,,,,,,,,,,,,,
3772688927,50.1455555,4537.302734,-0.00050159,1.15E-05,1,0.999253354,40.02988815,1.98905589,10.28999966,-0.005665399,0.00039368,0.25,0.000128236,-0.000502181,0.000124413,50.1456871,50.1456871,4532.098145,4542.507324,44.31052076,17.53963318,43.57562256,0,0,0,40,49.86785507,1,6,1,1.947784424,62.56109619,,,,,,,,,,,,,,,,
3772688949,50.14587593,4317.755615,-0.000904612,1.18E-05,1,0.999253354,40.02988815,1.988916412,10.28000005,-0.00994074,-0.000798691,0.25,9.14E-05,-0.000904629,8.47E-05,50.14582825,50.14582825,4313.104004,4322.407227,44.50827277,17.54360253,43.57007217,0,0,0,40,49.86717987,1,6,1,1.951904297,62.0723381,,,,,,,,,,,,,,,,
3772688971,50.14579964,4097.715332,-0.001138839,1.90E-05,1,0.999253354,40.02988815,1.988823293,10.28000005,-0.012615507,-0.000450364,0.25,0.000166574,-0.001139232,0.000157981,50.14573288,50.14573288,4091.234375,4104.196289,44.82639558,17.539138,43.57406616,0,0,0,40,49.86811829,1,6,1,1.956787109,59.62854385,,,,,,,,,,,,,,,,
3772688993,50.1462841,3880.108154,-0.001412489,1.57E-05,1,0.999253354,40.02988815,1.988843952,10.28999966,-0.015322151,-0.002333804,0.25,4.21E-05,-0.001411739,3.15E-05,50.14616394,50.14616394,3876.226074,3883.990234,44.17608065,17.54049683,43.57051849,0,0,0,40,49.86808014,1,6,1,1.956634521,61.09482193,,,,,,,,,,,,,,,,
3772689015,50.14574623,3660.961914,-0.00149426,1.22E-05,1,0.999253354,40.02988815,1.988998795,10.28000005,-0.016269608,-0.002144372,0.25,7.46E-05,-0.001493676,6.34E-05,50.14570999,50.14570999,3655.729736,3666.194092,44.48326066,17.54104976,43.56496811,0,0,0,40,49.86715317,1,6,1,1.949157715,63.04985428,,,,,,,,,,,,,,,,
3772689037,50.14562607,3442.778442,-0.001564255,1.08E-05,1,0.999253354,40.02988815,1.988887332,10.28000005,-0.016982621,-0.002507224,0.25,5.37E-05,-0.001563448,4.21E-05,50.14546967,50.14546967,3437.527832,3448.029053,44.59268865,17.54097522,43.56874084,0,0,0,40,49.86887741,1,6,1,1.959228516,62.0723381,,,,,,,,,,,,,,,,
3772689059,50.14609146,3223.985107,-0.00169733,1.21E-05,1,0.999253354,40.02988815,1.989001888,10.28999966,-0.018405583,-0.002844352,0.25,4.69E-05,-0.001696353,3.42E-05,50.14609146,50.14609146,3218.828857,3229.141357,44.45199552,17.54035173,43.56740952,0,0,0,40,49.8677597,1,6,1,1.955566406,63.04985428,,,,,,,,,,,,,,,,
3772689081,50.14509964,3006.21875,-0.001792043,1.14E-05,1,0.999253354,40.02988815,1.988977809,10.28000005,-0.019391498,-0.003225659,0.25,2.88E-05,-0.001790841,1.55E-05,50.1450882,50.1450882,3001.087891,3011.349609,44.38477546,17.53925104,43.57251358,0,0,0,40,49.86872482,1,6,1,1.947784424,62.56109619,,,,,,,,,,,,,,,,
3772689103,50.14682198,2784.957397,-0.001902959,1.23E-05,1,0.999253354,40.02988815,1.988917711,10.28000005,-0.02059527,-0.003401501,0.25,3.28E-05,-0.001901682,1.86E-05,50.14678574,50.14678574,2779.075439,2790.839355,44.58799888,17.53692959,43.57118225,0,0,0,40,49.86765289,1,6,1,1.9581604,62.0723381,,,,,,,,,,,,,,,,
3772689125,50.14642715,2566.13147,-0.001908919,1.17E-05,1,0.999253354,40.02988815,1.988866628,10.28000005,-0.020623479,-0.003606639,0.25,1.49E-05,-0.001907486,6.66E-07,50.14637756,50.14637756,2562.251709,2570.01123,44.52937674,17.53987436,43.57073975,0,0,0,40,49.86805725,1,6,1,1.957702637,62.56109619,,,,,,,,,,,,,,,,
3772689147,50.14624786,2346.563599,-0.001953689,1.13E-05,1,0.999253354,40.02988815,1.98886118,10.28000005,-0.021111033,-0.00366868,0.25,1.73E-05,-0.00195222,2.77E-06,50.14604568,50.14604568,2342.041016,2351.086182,44.41447735,17.54328615,43.57162476,0,0,0,40,49.86811829,1,6,1,1.947631836,62.56109619,,,,,,,,,,,,,,,,
3772689169,50.14563179,2126.689087,-0.002051497,7.36E-06,1,0.999253354,40.02988815,1.988884658,10.28999966,-0.022153612,-0.00393083,0.25,1.09E-05,-0.002049882,-4.36E-06,50.1455307,50.1455307,2120.922363,2132.455811,44.00959378,17.54687217,43.57229233,0,0,0,40,49.86738205,1,6,1,1.957244873,62.56109619,,,,,,,,,,,,,,,,
3772689191,50.14682198,1907.879211,-0.001977142,1.01E-05,1,0.999253354,40.02988815,1.988804389,10.28000005,-0.02137904,-0.003627686,0.25,2.54E-05,-0.00197568,1.07E-05,50.14685822,50.14685822,1902.688354,1913.070068,44.70524316,17.54978795,43.55831146,0,0,0,40,49.86840439,1,6,1,1.955871582,62.56109619,,,,,,,,,,,,,,,,
3772689213,50.14587784,1689.320557,-0.002001911,1.16E-05,1,0.999253354,40.02988815,1.988673038,10.28999966,-0.021690162,-0.003427752,0.25,4.84E-05,-0.002000582,3.35E-05,50.14599609,50.14599609,1684.712646,1693.928467,44.47388112,17.54568056,43.55253983,0,0,0,40,49.86779785,1,6,1,1.959381104,63.04985428,,,,,,,,,,,,,,,,
3772689235,50.14648056,1470.012878,-0.002067155,1.01E-05,1,0.999253354,40.02988815,1.98885436,10.28000005,-0.022286396,-0.004154369,0.25,-6.98E-06,-0.002065343,-2.23E-05,50.14624786,50.14624786,1464.253052,1475.772705,44.45277715,17.54090989,43.54965591,0,0,0,40,49.86878204,1,6,1,1.957397461,62.0723381,,,,,,,,,,,,,,,,
3772689257,50.14671898,1250.090271,-0.002116592,5.28E-06,1,0.999253354,40.02988815,1.988942485,10.28000005,-0.022784364,-0.004449547,0.25,-2.53E-05,-0.002114585,-4.10E-05,50.14682007,50.14682007,1244.8396,1255.340942,44.3144289,17.54234404,43.54655075,0,0,0,40,49.86898422,1,6,1,1.951293945,63.04985428,,,,,,,,,,,,,,,,
3772689279,50.14587593,1032.222595,-0.002184696,8.38E-06,1,0.999253354,40.02988815,1.98880799,10.28000005,-0.023525927,-0.004536989,0.25,-2.10E-05,-0.002182646,-3.72E-05,50.14592361,50.14592361,1027.130859,1037.314331,44.39493664,17.54132134,43.54166794,0,0,0,40,49.86849594,1,6,1,1.958465576,62.0723381,,,,,,,,,,,,,,,,
3772689301,50.14693451,809.9199829,-0.002171737,7.63E-06,1,0.999253354,40.02988815,1.98884888,10.28000005,-0.023398058,-0.004447852,0.25,-1.51E-05,-0.002169726,-3.12E-05,50.14699936,50.14699936,804.0403442,815.7996216,44.43089155,17.54215377,43.53900528,0,0,0,40,49.86933136,1,6,1,1.942901611,62.56109619,,,,,,,,,,,,,,,,
3772689323,50.1456852,593.0776062,-0.002207179,4.64E-06,1,0.999253354,40.02988815,1.988854357,10.28000005,-0.023781781,-0.004509551,0.25,-1.43E-05,-0.002205127,-3.07E-05,50.14573288,50.14573288,587.9121704,598.243042,44.29723307,17.54881584,43.53811646,0,0,0,40,49.86872482,1,6,1,1.936035156,62.56109619,,,,,,,,,,,,,,,,
3772689345,50.14690399,373.491272,-0.002220408,4.75E-06,1,0.999253354,40.02988815,1.988804499,10.28000005,-0.023833917,-0.005026752,0.25,-5.98E-05,-0.002217992,-7.63E-05,50.14690399,50.14690399,368.9225464,378.0599976,44.25502513,17.54286049,43.52790833,0,0,0,40,49.86861801,1,6,1,1.954498291,62.56109619,,,,,,,,,,,,,,,,
3772689367,50.1460743,153.6307602,-0.002243182,4.87E-06,1,0.999253354,40.02988815,1.988634204,10.28000005,-0.024086028,-0.005024584,0.25,-5.55E-05,-0.002240765,-7.21E-05,50.14623642,50.14623642,148.3846893,158.8768311,44.41838549,17.54320121,43.52768707,0,0,0,40,49.86849594,1,6,1,1.943664551,62.56109619,,,,,,,,,,,,,,,,
3772689389,50.14587021,-65.317379,-0.002230988,5.05E-06,1,0.999253354,40.02988815,1.98876103,10.28000005,-0.024044188,-0.00451812,0.25,-1.08E-05,-0.002228909,-2.73E-05,50.14591217,50.14591217,-70.52198029,-60.11277771,44.33944101,17.54891328,43.52302551,0,0,0,40,49.86837769,1,6,1,1.957092285,62.0723381,,,,,,,,,,,,,,,,
3772689436,50.14737129,-532.4276428,-0.002178213,9.51E-06,1,0.999253354,40.02988815,2.000892311,10.3000002,-0.023505854,-0.005013304,0.25,-6.37E-05,-0.002175817,-7.98E-05,50.14740753,50.14740753,-537.0516357,-527.8036499,44.13778085,17.53744615,43.52724075,0,0,0,40,49.86914063,1,6,1,1.971435547,61.58358002,,,,,,,,,,,,,,,,
3772689457,50.14770126,-750.742157,-0.002145556,7.07E-06,1,0.999253354,40.02988815,2.001028233,10.28999966,-0.02322634,-0.004548985,0.25,-2.68E-05,-0.002143478,-4.27E-05,50.14757538,50.14757538,-755.9352417,-745.5490723,44.41135083,17.53909078,43.53190231,0,0,0,40,49.86654663,1,6,1,1.970214844,61.58358002,,,,,,,,,,,,,,,,
3772689479,50.14666557,-969.139679,-0.002125676,4.06E-06,1,0.999253354,40.02988815,2.000935194,10.28999966,-0.022898868,-0.005115766,0.25,-8.27E-05,-0.002123215,-9.84E-05,50.14678574,50.14678574,-973.7867432,-964.4926147,44.51530743,17.5385903,43.52368927,0,0,0,40,49.86840439,1,6,1,1.961669922,62.0723381,,,,,,,,,,,,,,,,
3772689502,50.14636803,-1187.580994,-0.002072947,4.61E-06,1,0.999253354,40.02988815,2.000934793,10.3000002,-0.022337419,-0.004953827,0.25,-7.74E-05,-0.002070586,-9.27E-05,50.14640427,50.14640427,-1192.744141,-1182.417847,44.62629868,17.53691138,43.52835083,0,0,0,40,49.86872482,1,6,1,1.9581604,63.04985428,,,,,,,,,,,,,,,,
3772689523,50.1463623,-1405.34021,-0.002022334,5.24E-06,1,0.999253354,40.02988815,2.000989971,10.28999966,-0.021736566,-0.005140294,0.25,-0.000103833,-0.002019836,-0.000118775,50.14614105,50.14614105,-1410.540161,-1400.140259,44.62942519,17.53973595,43.52391434,0,0,0,40,49.86738205,1,6,1,1.961975098,63.04985428,,,,,,,,,,,,,,,,
3772689545,50.14596558,-1623.910522,-0.001902976,9.61E-06,1,0.999253354,40.02988815,2.00076001,10.3000002,-0.020561914,-0.004233434,0.25,-4.21E-05,-0.001901054,-5.62E-05,50.14592361,50.14592361,-1629.188843,-1618.632202,44.30426773,17.54444351,43.53034973,0,0,0,40,49.86834335,1,6,1,1.968536377,62.56109619,,,,,,,,,,,,,,,,
3772689567,50.14686966,-1844.766174,-0.001957062,4.03E-06,1,0.999253354,40.02988815,2.001003041,10.28999966,-0.021035458,-0.004974669,0.25,-0.000100496,-0.001954677,-0.000114959,50.14676285,50.14676285,-1850.459229,-1839.07312,44.34882055,17.5419732,43.53434372,0,0,0,40,49.86900711,1,6,1,1.960601807,63.04985428,,,,,,,,,,,,,,,,
3772689589,50.14600754,-2064.564575,-0.001872879,6.70E-06,1,0.999253354,40.02988815,2.001082976,10.3000002,-0.020059875,-0.005152691,0.25,-0.000132279,-0.001870343,-0.000146092,50.14600754,50.14600754,-2069.172363,-2059.956787,44.30270447,17.54230573,43.53678513,0,0,0,40,49.86869812,1,6,1,1.96685791,62.56109619,,,,,,,,,,,,,,,,
3772689611,50.14662933,-2282.519653,-0.001840353,8.72E-06,1,0.999253354,40.02988815,2.000922027,10.28999966,-0.019727273,-0.004969394,0.25,-0.000121366,-0.001837942,-0.000134948,50.14654541,50.14654541,-2287.093018,-2277.946289,44.57783771,17.54268681,43.52990341,0,0,0,40,49.86840439,1,6,1,1.968994141,62.56109619,,,,,,,,,,,,,,,,
3772689633,50.14655304,-2502.684448,-0.001840336,8.65E-06,1,0.999253354,40.02988815,2.00104953,10.28999966,-0.019753866,-0.004830773,0.25,-0.000108562,-0.001838036,-0.000122156,50.14666748,50.14666748,-2507.935059,-2497.433838,44.93426031,17.54325104,43.53101349,0,0,0,40,49.86785507,1,6,1,1.963653564,63.04985428,,,,,,,,,,,,,,,,
3772689655,50.14649773,-2720.466797,-0.001728457,1.24E-05,1,0.999253354,40.02988815,2.001004286,10.28999966,-0.01857982,-0.004389004,0.25,-8.83E-05,-0.001726414,-0.000101099,50.14645004,50.14645004,-2724.952637,-2715.980957,43.87828018,17.54429422,43.53456497,0,0,0,40,49.86797333,1,6,1,1.960144043,63.04985428,,,,,,,,,,,,,,,,
3772689677,50.1467247,-2939.947021,-0.001744368,1.47E-05,1,0.999253354,40.02988815,2.000983281,10.28999966,-0.018692113,-0.004750447,0.25,-0.000118719,-0.001742102,-0.000131594,50.14662933,50.14662933,-2945.195313,-2934.69873,44.32927984,17.54025114,43.54610443,0,0,0,40,49.86782074,1,6,1,1.960449219,63.04985428,,,,,,,,,,,,,,,,
3772689699,50.14756393,-3157.916138,-0.001619359,1.67E-05,1,0.999253354,40.02988815,2.000874672,10.28999966,-0.017334284,-0.004505772,0.25,-0.000119053,-0.001617205,-0.000131001,50.14776611,50.14776611,-3163.074707,-3152.757568,44.52468697,17.54633581,43.54322052,0,0,0,40,49.86811829,1,6,1,1.968078613,63.53861237,,,,,,,,,,,,,,,,
3772689721,50.14699554,-3375.756104,-0.001481745,1.71E-05,1,0.999253354,40.02988815,2.001058618,10.28999966,-0.015762921,-0.004668905,0.25,-0.000159219,-0.001479414,-0.000170113,50.14720535,50.14720535,-3381.004639,-3370.507568,44.37148778,17.54432326,43.54743576,0,0,0,40,49.86828232,1,6,1,1.9581604,62.56109619,,,,,,,,,,,,,,,,
3772689743,50.14683914,-3597.425049,-0.001567851,1.42E-05,1,0.999253354,40.02988815,2.001045223,10.3000002,-0.016689287,-0.004883899,0.25,-0.000163279,-0.001565438,-0.000174813,50.14685822,50.14685822,-3601.97998,-3592.870117,44.4816974,17.54865802,43.54211044,0,0,0,40,49.86785507,1,6,1,1.960296631,62.0723381,,,,,,,,,,,,,,,,
3772689765,50.14560127,-3816.089844,-0.001521409,1.22E-05,1,0.999253354,40.02988815,2.001097487,10.28999966,-0.016215173,-0.004631703,0.25,-0.000148518,-0.001519155,-0.00015972,50.14563751,50.14563751,-3821.287354,-3810.892334,44.79513044,17.55273301,43.53811646,0,0,0,40,49.86898422,1,6,1,1.969909668,62.0723381,,,,,,,,,,,,,,,,
3772689787,50.14633179,-4034.708374,-0.001415746,1.37E-05,1,0.999253354,40.02988815,2.000835409,10.28999966,-0.015148293,-0.003976083,0.25,-0.000107472,-0.001413892,-0.00011792,50.14614105,50.14614105,-4039.875977,-4029.540771,44.74354295,17.53846408,43.53123474,0,0,0,40,49.86898422,1,6,1,1.960906982,63.04985428,,,,,,,,,,,,,,,,
3772689809,50.14608002,-4254.04834,-0.001484843,1.35E-05,1,0.999253354,40.02988815,2.001095792,10.28999966,-0.015787266,-0.004730841,0.25,-0.000164334,-0.001482528,-0.000175256,50.14616394,50.14616394,-4258.617188,-4249.479492,44.69039222,17.55034984,43.54100037,0,0,0,40,49.86759567,1,6,1,1.969604492,64.51612854,,,,,,,,,,,,,,,,
3772689831,50.14670372,-4473.950195,-0.001436889,1.28E-05,1,0.999253354,40.02988815,2.000970772,10.28999966,-0.015283456,-0.00454068,0.25,-0.000155603,-0.001434689,-0.000166176,50.14693069,50.14693069,-4479.113281,-4468.787109,44.51139928,17.54647889,43.53855896,0,0,0,40,49.86805725,1,6,1,1.969299316,63.53861237,,,,,,,,,,,,,,,,
3772689853,50.14679909,-4693.331543,-0.001381058,1.26E-05,1,0.999253354,40.02988815,2.00078251,10.28999966,-0.014878737,-0.00332365,0.25,-5.37E-05,-0.001379671,-6.39E-05,50.14673996,50.14673996,-4698.577637,-4688.085449,44.05102009,17.54009387,43.53767014,0,0,0,40,49.86846161,1,6,1,1.970367432,64.02737427,,,,,,,,,,,,,,,,
3772689875,50.14710808,-4910.657959,-0.001272997,2.10E-05,1,0.999253354,40.02988815,2.000829267,10.28999966,-0.013846305,-0.002345787,0.25,1.67E-05,-0.001272223,7.20E-06,50.14716721,50.14716721,-4915.78418,-4905.531738,44.43010992,17.54080737,43.5338974,0,0,0,40,49.86796188,1,6,1,1.957244873,63.53861237,,,,,,,,,,,,,,,,
3772689885,50.14707184,-5000.484131,-0.000851778,2.10E-05,1,0.999253354,40.02988815,2.000650568,10.28999966,-0.00921897,-0.001815586,0.25,-1.15E-05,-0.000851095,-1.79E-05,50.14697647,50.14697647,-5000.845703,-5000.122559,44.56611328,17.53941023,43.52368927,0,0,0,40,49.86802292,1,4,1,1.960449219,63.04985428,,,,,,,,,,,,,,,,